package com.jtrent238.epicproportions.worldgen.structures;

import java.util.Random;

import com.jtrent238.epicproportions.BlockLoader;
import com.jtrent238.epicproportions.EpicProportionsMod;

import cpw.mods.fml.common.IWorldGenerator;
import net.minecraft.block.Block;
import net.minecraft.init.Blocks;
import net.minecraft.tileentity.TileEntityMobSpawner;
import net.minecraft.world.World;
import net.minecraft.world.chunk.IChunkProvider;
import net.minecraft.world.gen.feature.WorldGenerator;



public class WorldGenHouseOfEpicProportions extends WorldGenerator implements IWorldGenerator
{
    public boolean generate(World world, Random par2Random, int i, int j, int k)
    {
        while (world.isAirBlock(i, j, k) && j > 2000)
        {
            --j;
        }

    	

    	
        return true;
    }


    public void generate(Random random, int i2, int k2, World world, IChunkProvider chunkGenerator,
			IChunkProvider chunkProvider) {
		

		int i = i2 + random.nextInt(15);
		int k = k2 + random.nextInt(15);
		int j = world.getHeightValue(i, k) - 1;
		//int i = chunkX;
		//int j = 0;
		//int k = chunkZ;
		world.getHeightValue(j, j);
		
		while (world.isAirBlock(i, j, k) && j > 2000)
        {
            --j;
        }
		
		if(random.nextInt(100) < 10000){

			world.setBlock(i+0, j+0, k+0, Block.getBlockById(2));
			world.setBlock(i+1, j+0, k+0, Block.getBlockById(2));
			world.setBlock(i+2, j+0, k+0, Block.getBlockById(2));
			world.setBlock(i+3, j+0, k+0, Block.getBlockById(2));
			world.setBlock(i+4, j+0, k+0, Block.getBlockById(2));
			world.setBlock(i+5, j+0, k+0, Block.getBlockById(2));
			world.setBlock(i+6, j+0, k+0, Block.getBlockById(2));
			world.setBlock(i+7, j+0, k+0, Block.getBlockById(3));
			world.setBlock(i+8, j+0, k+0, Block.getBlockById(3));
			world.setBlock(i+9, j+0, k+0, Block.getBlockById(3));
			world.setBlock(i+10, j+0, k+0, Block.getBlockById(3));
			world.setBlock(i+11, j+0, k+0, Block.getBlockById(3));
			world.setBlock(i+12, j+0, k+0, Block.getBlockById(3));
			world.setBlock(i+13, j+0, k+0, Block.getBlockById(3));
			world.setBlock(i+14, j+0, k+0, Block.getBlockById(3));
			world.setBlock(i+0, j+0, k+1, Block.getBlockById(2));
			world.setBlock(i+1, j+0, k+1, Block.getBlockById(2));
			world.setBlock(i+2, j+0, k+1, Block.getBlockById(2));
			world.setBlock(i+3, j+0, k+1, Block.getBlockById(2));
			world.setBlock(i+4, j+0, k+1, Block.getBlockById(2));
			world.setBlock(i+5, j+0, k+1, Block.getBlockById(2));
			world.setBlock(i+6, j+0, k+1, Block.getBlockById(2));
			world.setBlock(i+7, j+0, k+1, Block.getBlockById(3));
			world.setBlock(i+8, j+0, k+1, Block.getBlockById(5));
			world.setBlockMetadataWithNotify(i+8, j+0, k+1, 2, 2);
			world.setBlock(i+9, j+0, k+1, Block.getBlockById(5));
			world.setBlockMetadataWithNotify(i+9, j+0, k+1, 2, 2);
			world.setBlock(i+10, j+0, k+1, Block.getBlockById(35));
			world.setBlockMetadataWithNotify(i+10, j+0, k+1, 6, 6);
			world.setBlock(i+11, j+0, k+1, Block.getBlockById(35));
			world.setBlockMetadataWithNotify(i+11, j+0, k+1, 6, 6);
			world.setBlock(i+12, j+0, k+1, Block.getBlockById(5));
			world.setBlockMetadataWithNotify(i+12, j+0, k+1, 2, 2);
			world.setBlock(i+13, j+0, k+1, Block.getBlockById(5));
			world.setBlockMetadataWithNotify(i+13, j+0, k+1, 2, 2);
			world.setBlock(i+14, j+0, k+1, Block.getBlockById(5));
			world.setBlockMetadataWithNotify(i+14, j+0, k+1, 2, 2);
			world.setBlock(i+0, j+0, k+2, Block.getBlockById(2));
			world.setBlock(i+1, j+0, k+2, Block.getBlockById(2));
			world.setBlock(i+2, j+0, k+2, Block.getBlockById(2));
			world.setBlock(i+3, j+0, k+2, Block.getBlockById(2));
			world.setBlock(i+4, j+0, k+2, Block.getBlockById(2));
			world.setBlock(i+5, j+0, k+2, Block.getBlockById(2));
			world.setBlock(i+6, j+0, k+2, Block.getBlockById(2));
			world.setBlock(i+7, j+0, k+2, Block.getBlockById(3));
			world.setBlock(i+8, j+0, k+2, Block.getBlockById(5));
			world.setBlockMetadataWithNotify(i+8, j+0, k+2, 2, 2);
			world.setBlock(i+9, j+0, k+2, Block.getBlockById(5));
			world.setBlockMetadataWithNotify(i+9, j+0, k+2, 2, 2);
			world.setBlock(i+10, j+0, k+2, Block.getBlockById(35));
			world.setBlockMetadataWithNotify(i+10, j+0, k+2, 6, 6);
			world.setBlock(i+11, j+0, k+2, Block.getBlockById(35));
			world.setBlockMetadataWithNotify(i+11, j+0, k+2, 6, 6);
			world.setBlock(i+12, j+0, k+2, Block.getBlockById(35));
			world.setBlockMetadataWithNotify(i+12, j+0, k+2, 6, 6);
			world.setBlock(i+13, j+0, k+2, Block.getBlockById(35));
			world.setBlockMetadataWithNotify(i+13, j+0, k+2, 6, 6);
			world.setBlock(i+14, j+0, k+2, Block.getBlockById(5));
			world.setBlockMetadataWithNotify(i+14, j+0, k+2, 2, 2);
			world.setBlock(i+0, j+0, k+3, Block.getBlockById(2));
			world.setBlock(i+1, j+0, k+3, Block.getBlockById(2));
			world.setBlock(i+2, j+0, k+3, Block.getBlockById(2));
			world.setBlock(i+3, j+0, k+3, Block.getBlockById(2));
			world.setBlock(i+4, j+0, k+3, Block.getBlockById(2));
			world.setBlock(i+5, j+0, k+3, Block.getBlockById(2));
			world.setBlock(i+6, j+0, k+3, Block.getBlockById(2));
			world.setBlock(i+7, j+0, k+3, Block.getBlockById(3));
			world.setBlock(i+8, j+0, k+3, Block.getBlockById(5));
			world.setBlockMetadataWithNotify(i+8, j+0, k+3, 2, 2);
			world.setBlock(i+9, j+0, k+3, Block.getBlockById(35));
			world.setBlockMetadataWithNotify(i+9, j+0, k+3, 6, 6);
			world.setBlock(i+10, j+0, k+3, Block.getBlockById(35));
			world.setBlockMetadataWithNotify(i+10, j+0, k+3, 6, 6);
			world.setBlock(i+11, j+0, k+3, Block.getBlockById(35));
			world.setBlockMetadataWithNotify(i+11, j+0, k+3, 6, 6);
			world.setBlock(i+12, j+0, k+3, Block.getBlockById(35));
			world.setBlockMetadataWithNotify(i+12, j+0, k+3, 6, 6);
			world.setBlock(i+13, j+0, k+3, Block.getBlockById(35));
			world.setBlockMetadataWithNotify(i+13, j+0, k+3, 6, 6);
			world.setBlock(i+14, j+0, k+3, Block.getBlockById(5));
			world.setBlockMetadataWithNotify(i+14, j+0, k+3, 2, 2);
			world.setBlock(i+0, j+0, k+4, Block.getBlockById(2));
			world.setBlock(i+1, j+0, k+4, Block.getBlockById(2));
			world.setBlock(i+2, j+0, k+4, Block.getBlockById(2));
			world.setBlock(i+3, j+0, k+4, Block.getBlockById(2));
			world.setBlock(i+4, j+0, k+4, Block.getBlockById(2));
			world.setBlock(i+5, j+0, k+4, Block.getBlockById(2));
			world.setBlock(i+6, j+0, k+4, Block.getBlockById(2));
			world.setBlock(i+7, j+0, k+4, Block.getBlockById(3));
			world.setBlock(i+8, j+0, k+4, Block.getBlockById(35));
			world.setBlockMetadataWithNotify(i+8, j+0, k+4, 6, 6);
			world.setBlock(i+9, j+0, k+4, Block.getBlockById(35));
			world.setBlockMetadataWithNotify(i+9, j+0, k+4, 6, 6);
			world.setBlock(i+10, j+0, k+4, Block.getBlockById(35));
			world.setBlockMetadataWithNotify(i+10, j+0, k+4, 6, 6);
			world.setBlock(i+11, j+0, k+4, Block.getBlockById(35));
			world.setBlockMetadataWithNotify(i+11, j+0, k+4, 6, 6);
			world.setBlock(i+12, j+0, k+4, Block.getBlockById(35));
			world.setBlockMetadataWithNotify(i+12, j+0, k+4, 6, 6);
			world.setBlock(i+13, j+0, k+4, Block.getBlockById(5));
			world.setBlockMetadataWithNotify(i+13, j+0, k+4, 2, 2);
			world.setBlock(i+14, j+0, k+4, Block.getBlockById(5));
			world.setBlockMetadataWithNotify(i+14, j+0, k+4, 2, 2);
			world.setBlock(i+0, j+0, k+5, Block.getBlockById(2));
			world.setBlock(i+1, j+0, k+5, Block.getBlockById(2));
			world.setBlock(i+2, j+0, k+5, Block.getBlockById(2));
			world.setBlock(i+3, j+0, k+5, Block.getBlockById(2));
			world.setBlock(i+4, j+0, k+5, Block.getBlockById(2));
			world.setBlock(i+5, j+0, k+5, Block.getBlockById(2));
			world.setBlock(i+6, j+0, k+5, Block.getBlockById(2));
			world.setBlock(i+7, j+0, k+5, Block.getBlockById(3));
			world.setBlock(i+8, j+0, k+5, Block.getBlockById(5));
			world.setBlockMetadataWithNotify(i+8, j+0, k+5, 2, 2);
			world.setBlock(i+9, j+0, k+5, Block.getBlockById(35));
			world.setBlockMetadataWithNotify(i+9, j+0, k+5, 6, 6);
			world.setBlock(i+10, j+0, k+5, Block.getBlockById(35));
			world.setBlockMetadataWithNotify(i+10, j+0, k+5, 6, 6);
			world.setBlock(i+11, j+0, k+5, Block.getBlockById(35));
			world.setBlockMetadataWithNotify(i+11, j+0, k+5, 6, 6);
			world.setBlock(i+12, j+0, k+5, Block.getBlockById(35));
			world.setBlockMetadataWithNotify(i+12, j+0, k+5, 6, 6);
			world.setBlock(i+13, j+0, k+5, Block.getBlockById(35));
			world.setBlockMetadataWithNotify(i+13, j+0, k+5, 6, 6);
			world.setBlock(i+14, j+0, k+5, Block.getBlockById(5));
			world.setBlockMetadataWithNotify(i+14, j+0, k+5, 2, 2);
			world.setBlock(i+0, j+0, k+6, Block.getBlockById(2));
			world.setBlock(i+1, j+0, k+6, Block.getBlockById(2));
			world.setBlock(i+2, j+0, k+6, Block.getBlockById(2));
			world.setBlock(i+3, j+0, k+6, Block.getBlockById(2));
			world.setBlock(i+4, j+0, k+6, Block.getBlockById(2));
			world.setBlock(i+5, j+0, k+6, Block.getBlockById(2));
			world.setBlock(i+6, j+0, k+6, Block.getBlockById(2));
			world.setBlock(i+7, j+0, k+6, Block.getBlockById(3));
			world.setBlock(i+8, j+0, k+6, Block.getBlockById(5));
			world.setBlockMetadataWithNotify(i+8, j+0, k+6, 2, 2);
			world.setBlock(i+9, j+0, k+6, Block.getBlockById(5));
			world.setBlockMetadataWithNotify(i+9, j+0, k+6, 2, 2);
			world.setBlock(i+10, j+0, k+6, Block.getBlockById(35));
			world.setBlockMetadataWithNotify(i+10, j+0, k+6, 6, 6);
			world.setBlock(i+11, j+0, k+6, Block.getBlockById(35));
			world.setBlockMetadataWithNotify(i+11, j+0, k+6, 6, 6);
			world.setBlock(i+12, j+0, k+6, Block.getBlockById(35));
			world.setBlockMetadataWithNotify(i+12, j+0, k+6, 6, 6);
			world.setBlock(i+13, j+0, k+6, Block.getBlockById(35));
			world.setBlockMetadataWithNotify(i+13, j+0, k+6, 6, 6);
			world.setBlock(i+14, j+0, k+6, Block.getBlockById(5));
			world.setBlockMetadataWithNotify(i+14, j+0, k+6, 2, 2);
			world.setBlock(i+0, j+0, k+7, Block.getBlockById(2));
			world.setBlock(i+1, j+0, k+7, Block.getBlockById(2));
			world.setBlock(i+2, j+0, k+7, Block.getBlockById(2));
			world.setBlock(i+3, j+0, k+7, Block.getBlockById(2));
			world.setBlock(i+4, j+0, k+7, Block.getBlockById(2));
			world.setBlock(i+5, j+0, k+7, Block.getBlockById(2));
			world.setBlock(i+6, j+0, k+7, Block.getBlockById(2));
			world.setBlock(i+7, j+0, k+7, Block.getBlockById(3));
			world.setBlock(i+8, j+0, k+7, Block.getBlockById(5));
			world.setBlockMetadataWithNotify(i+8, j+0, k+7, 2, 2);
			world.setBlock(i+9, j+0, k+7, Block.getBlockById(5));
			world.setBlockMetadataWithNotify(i+9, j+0, k+7, 2, 2);
			world.setBlock(i+10, j+0, k+7, Block.getBlockById(35));
			world.setBlockMetadataWithNotify(i+10, j+0, k+7, 6, 6);
			world.setBlock(i+11, j+0, k+7, Block.getBlockById(35));
			world.setBlockMetadataWithNotify(i+11, j+0, k+7, 6, 6);
			world.setBlock(i+12, j+0, k+7, Block.getBlockById(5));
			world.setBlockMetadataWithNotify(i+12, j+0, k+7, 2, 2);
			world.setBlock(i+13, j+0, k+7, Block.getBlockById(5));
			world.setBlockMetadataWithNotify(i+13, j+0, k+7, 2, 2);
			world.setBlock(i+14, j+0, k+7, Block.getBlockById(5));
			world.setBlockMetadataWithNotify(i+14, j+0, k+7, 2, 2);
			world.setBlock(i+0, j+0, k+8, Block.getBlockById(2));
			world.setBlock(i+1, j+0, k+8, Block.getBlockById(2));
			world.setBlock(i+2, j+0, k+8, Block.getBlockById(2));
			world.setBlock(i+3, j+0, k+8, Block.getBlockById(2));
			world.setBlock(i+4, j+0, k+8, Block.getBlockById(2));
			world.setBlock(i+5, j+0, k+8, Block.getBlockById(2));
			world.setBlock(i+6, j+0, k+8, Block.getBlockById(2));
			world.setBlock(i+7, j+0, k+8, Block.getBlockById(3));
			world.setBlock(i+8, j+0, k+8, Block.getBlockById(5));
			world.setBlock(i+9, j+0, k+8, Block.getBlockById(5));
			world.setBlock(i+10, j+0, k+8, Block.getBlockById(5));
			world.setBlock(i+11, j+0, k+8, Block.getBlockById(5));
			world.setBlock(i+12, j+0, k+8, Block.getBlockById(5));
			world.setBlock(i+13, j+0, k+8, Block.getBlockById(5));
			world.setBlock(i+14, j+0, k+8, Block.getBlockById(5));
			world.setBlock(i+0, j+0, k+9, Block.getBlockById(2));
			world.setBlock(i+1, j+0, k+9, Block.getBlockById(2));
			world.setBlock(i+2, j+0, k+9, Block.getBlockById(2));
			world.setBlock(i+3, j+0, k+9, Block.getBlockById(2));
			world.setBlock(i+4, j+0, k+9, Block.getBlockById(2));
			world.setBlock(i+5, j+0, k+9, Block.getBlockById(2));
			world.setBlock(i+6, j+0, k+9, Block.getBlockById(2));
			world.setBlock(i+7, j+0, k+9, Block.getBlockById(3));
			world.setBlock(i+8, j+0, k+9, Block.getBlockById(5));
			world.setBlock(i+9, j+0, k+9, Block.getBlockById(5));
			world.setBlock(i+10, j+0, k+9, Block.getBlockById(5));
			world.setBlock(i+11, j+0, k+9, Block.getBlockById(5));
			world.setBlock(i+12, j+0, k+9, Block.getBlockById(5));
			world.setBlock(i+13, j+0, k+9, Block.getBlockById(5));
			world.setBlock(i+14, j+0, k+9, Block.getBlockById(5));
			world.setBlock(i+0, j+0, k+10, Block.getBlockById(2));
			world.setBlock(i+1, j+0, k+10, Block.getBlockById(2));
			world.setBlock(i+2, j+0, k+10, Block.getBlockById(2));
			world.setBlock(i+3, j+0, k+10, Block.getBlockById(2));
			world.setBlock(i+4, j+0, k+10, Block.getBlockById(2));
			world.setBlock(i+5, j+0, k+10, Block.getBlockById(2));
			world.setBlock(i+6, j+0, k+10, Block.getBlockById(3));
			world.setBlock(i+7, j+0, k+10, Block.getBlockById(3));
			world.setBlock(i+8, j+0, k+10, Block.getBlockById(5));
			world.setBlock(i+9, j+0, k+10, Block.getBlockById(5));
			world.setBlock(i+10, j+0, k+10, Block.getBlockById(5));
			world.setBlock(i+11, j+0, k+10, Block.getBlockById(5));
			world.setBlock(i+12, j+0, k+10, Block.getBlockById(5));
			world.setBlock(i+13, j+0, k+10, Block.getBlockById(5));
			world.setBlock(i+14, j+0, k+10, Block.getBlockById(5));
			world.setBlock(i+0, j+0, k+11, Block.getBlockById(2));
			world.setBlock(i+1, j+0, k+11, Block.getBlockById(2));
			world.setBlock(i+2, j+0, k+11, Block.getBlockById(2));
			world.setBlock(i+3, j+0, k+11, Block.getBlockById(2));
			world.setBlock(i+4, j+0, k+11, Block.getBlockById(2));
			world.setBlock(i+5, j+0, k+11, Block.getBlockById(2));
			world.setBlock(i+6, j+0, k+11, Block.getBlockById(3));
			world.setBlock(i+7, j+0, k+11, Block.getBlockById(3));
			world.setBlock(i+8, j+0, k+11, Block.getBlockById(5));
			world.setBlock(i+9, j+0, k+11, Block.getBlockById(5));
			world.setBlock(i+10, j+0, k+11, Block.getBlockById(5));
			world.setBlock(i+11, j+0, k+11, Block.getBlockById(5));
			world.setBlock(i+12, j+0, k+11, Block.getBlockById(5));
			world.setBlock(i+13, j+0, k+11, Block.getBlockById(5));
			world.setBlock(i+14, j+0, k+11, Block.getBlockById(5));
			world.setBlock(i+0, j+0, k+12, Block.getBlockById(43));
			world.setBlock(i+1, j+0, k+12, Block.getBlockById(43));
			world.setBlock(i+2, j+0, k+12, Block.getBlockById(43));
			world.setBlock(i+3, j+0, k+12, Block.getBlockById(43));
			world.setBlock(i+4, j+0, k+12, Block.getBlockById(43));
			world.setBlock(i+5, j+0, k+12, Block.getBlockById(43));
			world.setBlock(i+6, j+0, k+12, Block.getBlockById(43));
			world.setBlock(i+7, j+0, k+12, Block.getBlockById(5));
			world.setBlock(i+8, j+0, k+12, Block.getBlockById(5));
			world.setBlock(i+9, j+0, k+12, Block.getBlockById(5));
			world.setBlock(i+10, j+0, k+12, Block.getBlockById(5));
			world.setBlock(i+11, j+0, k+12, Block.getBlockById(5));
			world.setBlock(i+12, j+0, k+12, Block.getBlockById(5));
			world.setBlock(i+13, j+0, k+12, Block.getBlockById(5));
			world.setBlock(i+14, j+0, k+12, Block.getBlockById(5));
			world.setBlock(i+0, j+0, k+13, Block.getBlockById(2));
			world.setBlock(i+1, j+0, k+13, Block.getBlockById(2));
			world.setBlock(i+2, j+0, k+13, Block.getBlockById(2));
			world.setBlock(i+3, j+0, k+13, Block.getBlockById(2));
			world.setBlock(i+4, j+0, k+13, Block.getBlockById(2));
			world.setBlock(i+5, j+0, k+13, Block.getBlockById(2));
			world.setBlock(i+6, j+0, k+13, Block.getBlockById(3));
			world.setBlock(i+7, j+0, k+13, Block.getBlockById(3));
			world.setBlock(i+8, j+0, k+13, Block.getBlockById(5));
			world.setBlock(i+9, j+0, k+13, Block.getBlockById(5));
			world.setBlock(i+10, j+0, k+13, Block.getBlockById(5));
			world.setBlock(i+11, j+0, k+13, Block.getBlockById(5));
			world.setBlock(i+12, j+0, k+13, Block.getBlockById(5));
			world.setBlock(i+13, j+0, k+13, Block.getBlockById(5));
			world.setBlock(i+14, j+0, k+13, Block.getBlockById(5));
			world.setBlock(i+0, j+0, k+14, Block.getBlockById(2));
			world.setBlock(i+1, j+0, k+14, Block.getBlockById(2));
			world.setBlock(i+2, j+0, k+14, Block.getBlockById(2));
			world.setBlock(i+3, j+0, k+14, Block.getBlockById(2));
			world.setBlock(i+4, j+0, k+14, Block.getBlockById(2));
			world.setBlock(i+5, j+0, k+14, Block.getBlockById(2));
			world.setBlock(i+6, j+0, k+14, Block.getBlockById(3));
			world.setBlock(i+7, j+0, k+14, Block.getBlockById(3));
			world.setBlock(i+8, j+0, k+14, Block.getBlockById(5));
			world.setBlock(i+9, j+0, k+14, Block.getBlockById(5));
			world.setBlock(i+10, j+0, k+14, Block.getBlockById(5));
			world.setBlock(i+11, j+0, k+14, Block.getBlockById(5));
			world.setBlock(i+12, j+0, k+14, Block.getBlockById(5));
			world.setBlock(i+13, j+0, k+14, Block.getBlockById(5));
			world.setBlock(i+14, j+0, k+14, Block.getBlockById(5));
			world.setBlock(i+0, j+0, k+15, Block.getBlockById(2));
			world.setBlock(i+1, j+0, k+15, Block.getBlockById(2));
			world.setBlock(i+2, j+0, k+15, Block.getBlockById(2));
			world.setBlock(i+3, j+0, k+15, Block.getBlockById(2));
			world.setBlock(i+4, j+0, k+15, Block.getBlockById(2));
			world.setBlock(i+5, j+0, k+15, Block.getBlockById(2));
			world.setBlock(i+6, j+0, k+15, Block.getBlockById(2));
			world.setBlock(i+7, j+0, k+15, Block.getBlockById(3));
			world.setBlock(i+8, j+0, k+15, Block.getBlockById(5));
			world.setBlock(i+9, j+0, k+15, Block.getBlockById(5));
			world.setBlock(i+10, j+0, k+15, Block.getBlockById(5));
			world.setBlock(i+11, j+0, k+15, Block.getBlockById(5));
			world.setBlock(i+12, j+0, k+15, Block.getBlockById(5));
			world.setBlock(i+13, j+0, k+15, Block.getBlockById(5));
			world.setBlock(i+14, j+0, k+15, Block.getBlockById(5));
			world.setBlock(i+0, j+0, k+16, Block.getBlockById(2));
			world.setBlock(i+1, j+0, k+16, Block.getBlockById(2));
			world.setBlock(i+2, j+0, k+16, Block.getBlockById(2));
			world.setBlock(i+3, j+0, k+16, Block.getBlockById(2));
			world.setBlock(i+4, j+0, k+16, Block.getBlockById(2));
			world.setBlock(i+5, j+0, k+16, Block.getBlockById(2));
			world.setBlock(i+6, j+0, k+16, Block.getBlockById(2));
			world.setBlock(i+7, j+0, k+16, Block.getBlockById(3));
			world.setBlock(i+8, j+0, k+16, Block.getBlockById(5));
			world.setBlock(i+9, j+0, k+16, Block.getBlockById(5));
			world.setBlock(i+10, j+0, k+16, Block.getBlockById(5));
			world.setBlock(i+11, j+0, k+16, Block.getBlockById(5));
			world.setBlock(i+12, j+0, k+16, Block.getBlockById(5));
			world.setBlock(i+13, j+0, k+16, Block.getBlockById(5));
			world.setBlock(i+14, j+0, k+16, Block.getBlockById(5));
			world.setBlock(i+0, j+0, k+17, Block.getBlockById(2));
			world.setBlock(i+1, j+0, k+17, Block.getBlockById(2));
			world.setBlock(i+2, j+0, k+17, Block.getBlockById(2));
			world.setBlock(i+3, j+0, k+17, Block.getBlockById(2));
			world.setBlock(i+4, j+0, k+17, Block.getBlockById(2));
			world.setBlock(i+5, j+0, k+17, Block.getBlockById(2));
			world.setBlock(i+6, j+0, k+17, Block.getBlockById(2));
			world.setBlock(i+7, j+0, k+17, Block.getBlockById(3));
			world.setBlock(i+8, j+0, k+17, Block.getBlockById(3));
			world.setBlock(i+9, j+0, k+17, Block.getBlockById(3));
			world.setBlock(i+10, j+0, k+17, Block.getBlockById(3));
			world.setBlock(i+11, j+0, k+17, Block.getBlockById(3));
			world.setBlock(i+12, j+0, k+17, Block.getBlockById(3));
			world.setBlock(i+13, j+0, k+17, Block.getBlockById(3));
			world.setBlock(i+14, j+0, k+17, Block.getBlockById(3));
			world.setBlock(i+0, j+0, k+18, Block.getBlockById(2));
			world.setBlock(i+1, j+0, k+18, Block.getBlockById(2));
			world.setBlock(i+2, j+0, k+18, Block.getBlockById(2));
			world.setBlock(i+3, j+0, k+18, Block.getBlockById(2));
			world.setBlock(i+4, j+0, k+18, Block.getBlockById(2));
			world.setBlock(i+5, j+0, k+18, Block.getBlockById(2));
			world.setBlock(i+6, j+0, k+18, Block.getBlockById(2));
			world.setBlock(i+7, j+0, k+18, Block.getBlockById(2));
			world.setBlock(i+8, j+0, k+18, Block.getBlockById(2));
			world.setBlock(i+9, j+0, k+18, Block.getBlockById(2));
			world.setBlock(i+10, j+0, k+18, Block.getBlockById(2));
			world.setBlock(i+11, j+0, k+18, Block.getBlockById(2));
			world.setBlock(i+12, j+0, k+18, Block.getBlockById(2));
			world.setBlock(i+13, j+0, k+18, Block.getBlockById(2));
			world.setBlock(i+14, j+0, k+18, Block.getBlockById(2));
			world.setBlock(i+7, j+1, k+0, Block.getBlockById(5));
			world.setBlockMetadataWithNotify(i+7, j+1, k+0, 2, 2);
			world.setBlock(i+8, j+1, k+0, Block.getBlockById(5));
			world.setBlockMetadataWithNotify(i+8, j+1, k+0, 2, 2);
			world.setBlock(i+9, j+1, k+0, Block.getBlockById(5));
			world.setBlockMetadataWithNotify(i+9, j+1, k+0, 2, 2);
			world.setBlock(i+10, j+1, k+0, Block.getBlockById(5));
			world.setBlockMetadataWithNotify(i+10, j+1, k+0, 2, 2);
			world.setBlock(i+11, j+1, k+0, Block.getBlockById(5));
			world.setBlockMetadataWithNotify(i+11, j+1, k+0, 2, 2);
			world.setBlock(i+12, j+1, k+0, Block.getBlockById(5));
			world.setBlockMetadataWithNotify(i+12, j+1, k+0, 2, 2);
			world.setBlock(i+13, j+1, k+0, Block.getBlockById(5));
			world.setBlockMetadataWithNotify(i+13, j+1, k+0, 2, 2);
			world.setBlock(i+14, j+1, k+0, Block.getBlockById(5));
			world.setBlockMetadataWithNotify(i+14, j+1, k+0, 2, 2);
			world.setBlock(i+6, j+1, k+1, Block.getBlockById(38));
			world.setBlockMetadataWithNotify(i+6, j+1, k+1, 8, 8);
			world.setBlock(i+7, j+1, k+1, Block.getBlockById(5));
			world.setBlockMetadataWithNotify(i+7, j+1, k+1, 2, 2);
			world.setBlock(i+8, j+1, k+1, Block.getBlockById(54));
			world.setBlockMetadataWithNotify(i+8, j+1, k+1, 5, 5);
			world.setBlock(i+10, j+1, k+1, Block.getBlockById(53));
			world.setBlockMetadataWithNotify(i+10, j+1, k+1, 3, 3);
			world.setBlock(i+11, j+1, k+1, Block.getBlockById(53));
			world.setBlockMetadataWithNotify(i+11, j+1, k+1, 3, 3);
			world.setBlock(i+14, j+1, k+1, Block.getBlockById(5));
			world.setBlockMetadataWithNotify(i+14, j+1, k+1, 2, 2);
			world.setBlock(i+6, j+1, k+2, Block.getBlockById(38));
			world.setBlockMetadataWithNotify(i+6, j+1, k+2, 8, 8);
			world.setBlock(i+7, j+1, k+2, Block.getBlockById(5));
			world.setBlockMetadataWithNotify(i+7, j+1, k+2, 2, 2);
			world.setBlock(i+8, j+1, k+2, Block.getBlockById(54));
			world.setBlockMetadataWithNotify(i+8, j+1, k+2, 5, 5);
			world.setBlock(i+14, j+1, k+2, Block.getBlockById(5));
			world.setBlockMetadataWithNotify(i+14, j+1, k+2, 2, 2);
			world.setBlock(i+6, j+1, k+3, Block.getBlockById(38));
			world.setBlockMetadataWithNotify(i+6, j+1, k+3, 8, 8);
			world.setBlock(i+7, j+1, k+3, Block.getBlockById(5));
			world.setBlockMetadataWithNotify(i+7, j+1, k+3, 2, 2);
			world.setBlock(i+14, j+1, k+3, Block.getBlockById(5));
			world.setBlockMetadataWithNotify(i+14, j+1, k+3, 2, 2);
			world.setBlock(i+6, j+1, k+4, Block.getBlockById(38));
			world.setBlockMetadataWithNotify(i+6, j+1, k+4, 8, 8);
			world.setBlock(i+7, j+1, k+4, Block.getBlockById(5));
			world.setBlockMetadataWithNotify(i+7, j+1, k+4, 2, 2);
			world.setBlock(i+10, j+1, k+4, Block.getBlockById(126));
			world.setBlock(i+11, j+1, k+4, Block.getBlockById(126));
			world.setBlock(i+14, j+1, k+4, Block.getBlockById(5));
			world.setBlockMetadataWithNotify(i+14, j+1, k+4, 2, 2);
			world.setBlock(i+6, j+1, k+5, Block.getBlockById(38));
			world.setBlockMetadataWithNotify(i+6, j+1, k+5, 8, 8);
			world.setBlock(i+7, j+1, k+5, Block.getBlockById(5));
			world.setBlockMetadataWithNotify(i+7, j+1, k+5, 2, 2);
			world.setBlock(i+14, j+1, k+5, Block.getBlockById(5));
			world.setBlockMetadataWithNotify(i+14, j+1, k+5, 2, 2);
			world.setBlock(i+7, j+1, k+6, Block.getBlockById(5));
			world.setBlockMetadataWithNotify(i+7, j+1, k+6, 2, 2);
			world.setBlock(i+8, j+1, k+6, Block.getBlockById(54));
			world.setBlockMetadataWithNotify(i+8, j+1, k+6, 5, 5);
			world.setBlock(i+14, j+1, k+6, Block.getBlockById(5));
			world.setBlockMetadataWithNotify(i+14, j+1, k+6, 2, 2);
			world.setBlock(i+7, j+1, k+7, Block.getBlockById(5));
			world.setBlockMetadataWithNotify(i+7, j+1, k+7, 2, 2);
			world.setBlock(i+8, j+1, k+7, Block.getBlockById(54));
			world.setBlockMetadataWithNotify(i+8, j+1, k+7, 5, 5);
			world.setBlock(i+10, j+1, k+7, Block.getBlockById(53));
			world.setBlockMetadataWithNotify(i+10, j+1, k+7, 2, 2);
			world.setBlock(i+11, j+1, k+7, Block.getBlockById(53));
			world.setBlockMetadataWithNotify(i+11, j+1, k+7, 2, 2);
			world.setBlock(i+14, j+1, k+7, Block.getBlockById(5));
			world.setBlockMetadataWithNotify(i+14, j+1, k+7, 2, 2);
			world.setBlock(i+7, j+1, k+8, Block.getBlockById(5));
			world.setBlockMetadataWithNotify(i+7, j+1, k+8, 2, 2);
			world.setBlock(i+8, j+1, k+8, Block.getBlockById(5));
			world.setBlockMetadataWithNotify(i+8, j+1, k+8, 2, 2);
			world.setBlock(i+9, j+1, k+8, Block.getBlockById(5));
			world.setBlockMetadataWithNotify(i+9, j+1, k+8, 2, 2);
			world.setBlock(i+10, j+1, k+8, Block.getBlockById(5));
			world.setBlockMetadataWithNotify(i+10, j+1, k+8, 2, 2);
			world.setBlock(i+11, j+1, k+8, Block.getBlockById(5));
			world.setBlockMetadataWithNotify(i+11, j+1, k+8, 2, 2);
			world.setBlock(i+13, j+1, k+8, Block.getBlockById(5));
			world.setBlockMetadataWithNotify(i+13, j+1, k+8, 2, 2);
			world.setBlock(i+14, j+1, k+8, Block.getBlockById(5));
			world.setBlockMetadataWithNotify(i+14, j+1, k+8, 2, 2);
			world.setBlock(i+7, j+1, k+9, Block.getBlockById(5));
			world.setBlockMetadataWithNotify(i+7, j+1, k+9, 2, 2);
			world.setBlock(i+13, j+1, k+9, Block.getBlockById(61));
			world.setBlockMetadataWithNotify(i+13, j+1, k+9, 4, 4);
			world.setBlock(i+14, j+1, k+9, Block.getBlockById(5));
			world.setBlockMetadataWithNotify(i+14, j+1, k+9, 2, 2);
			world.setBlock(i+6, j+1, k+10, Block.getBlockById(5));
			world.setBlock(i+7, j+1, k+10, Block.getBlockById(5));
			world.setBlockMetadataWithNotify(i+7, j+1, k+10, 2, 2);
			world.setBlock(i+13, j+1, k+10, Block.getBlockById(58));
			world.setBlock(i+14, j+1, k+10, Block.getBlockById(5));
			world.setBlockMetadataWithNotify(i+14, j+1, k+10, 2, 2);
			world.setBlock(i+4, j+1, k+11, Block.getBlockById(144));
			world.setBlockMetadataWithNotify(i+4, j+1, k+11, 1, 1);
			world.setBlock(i+5, j+1, k+11, Block.getBlockById(144));
			world.setBlockMetadataWithNotify(i+5, j+1, k+11, 1, 1);
			world.setBlock(i+6, j+1, k+11, Block.getBlockById(5));
			world.setBlock(i+7, j+1, k+11, Block.getBlockById(5));
			world.setBlockMetadataWithNotify(i+7, j+1, k+11, 2, 2);
			world.setBlock(i+13, j+1, k+11, Block.getBlockById(54));
			world.setBlockMetadataWithNotify(i+13, j+1, k+11, 4, 4);
			world.setBlock(i+14, j+1, k+11, Block.getBlockById(5));
			world.setBlockMetadataWithNotify(i+14, j+1, k+11, 2, 2);
			world.setBlock(i+13, j+1, k+12, Block.getBlockById(54));
			world.setBlockMetadataWithNotify(i+13, j+1, k+12, 4, 4);
			world.setBlock(i+14, j+1, k+12, Block.getBlockById(5));
			world.setBlockMetadataWithNotify(i+14, j+1, k+12, 2, 2);
			world.setBlock(i+4, j+1, k+13, Block.getBlockById(144));
			world.setBlockMetadataWithNotify(i+4, j+1, k+13, 1, 1);
			world.setBlock(i+5, j+1, k+13, Block.getBlockById(144));
			world.setBlockMetadataWithNotify(i+5, j+1, k+13, 1, 1);
			world.setBlock(i+6, j+1, k+13, Block.getBlockById(5));
			world.setBlock(i+7, j+1, k+13, Block.getBlockById(5));
			world.setBlockMetadataWithNotify(i+7, j+1, k+13, 2, 2);
			world.setBlock(i+14, j+1, k+13, Block.getBlockById(5));
			world.setBlockMetadataWithNotify(i+14, j+1, k+13, 2, 2);
			world.setBlock(i+6, j+1, k+14, Block.getBlockById(5));
			world.setBlock(i+7, j+1, k+14, Block.getBlockById(5));
			world.setBlockMetadataWithNotify(i+7, j+1, k+14, 2, 2);
			world.setBlock(i+14, j+1, k+14, Block.getBlockById(5));
			world.setBlockMetadataWithNotify(i+14, j+1, k+14, 2, 2);
			world.setBlock(i+7, j+1, k+15, Block.getBlockById(5));
			world.setBlockMetadataWithNotify(i+7, j+1, k+15, 2, 2);
			world.setBlock(i+8, j+1, k+15, Block.getBlockById(26));
			world.setBlockMetadataWithNotify(i+8, j+1, k+15, 9, 9);
			world.setBlock(i+9, j+1, k+15, Block.getBlockById(26));
			world.setBlockMetadataWithNotify(i+9, j+1, k+15, 1, 1);
			world.setBlock(i+14, j+1, k+15, Block.getBlockById(5));
			world.setBlockMetadataWithNotify(i+14, j+1, k+15, 2, 2);
			world.setBlock(i+7, j+1, k+16, Block.getBlockById(5));
			world.setBlockMetadataWithNotify(i+7, j+1, k+16, 2, 2);
			world.setBlock(i+8, j+1, k+16, Block.getBlockById(26));
			world.setBlockMetadataWithNotify(i+8, j+1, k+16, 9, 9);
			world.setBlock(i+9, j+1, k+16, Block.getBlockById(26));
			world.setBlockMetadataWithNotify(i+9, j+1, k+16, 1, 1);
			world.setBlock(i+14, j+1, k+16, Block.getBlockById(5));
			world.setBlockMetadataWithNotify(i+14, j+1, k+16, 2, 2);
			world.setBlock(i+7, j+1, k+17, Block.getBlockById(5));
			world.setBlockMetadataWithNotify(i+7, j+1, k+17, 2, 2);
			world.setBlock(i+8, j+1, k+17, Block.getBlockById(5));
			world.setBlockMetadataWithNotify(i+8, j+1, k+17, 2, 2);
			world.setBlock(i+9, j+1, k+17, Block.getBlockById(5));
			world.setBlockMetadataWithNotify(i+9, j+1, k+17, 2, 2);
			world.setBlock(i+10, j+1, k+17, Block.getBlockById(5));
			world.setBlockMetadataWithNotify(i+10, j+1, k+17, 2, 2);
			world.setBlock(i+11, j+1, k+17, Block.getBlockById(5));
			world.setBlockMetadataWithNotify(i+11, j+1, k+17, 2, 2);
			world.setBlock(i+12, j+1, k+17, Block.getBlockById(5));
			world.setBlockMetadataWithNotify(i+12, j+1, k+17, 2, 2);
			world.setBlock(i+13, j+1, k+17, Block.getBlockById(5));
			world.setBlockMetadataWithNotify(i+13, j+1, k+17, 2, 2);
			world.setBlock(i+14, j+1, k+17, Block.getBlockById(5));
			world.setBlockMetadataWithNotify(i+14, j+1, k+17, 2, 2);
			world.setBlock(i+7, j+2, k+0, Block.getBlockById(5));
			world.setBlockMetadataWithNotify(i+7, j+2, k+0, 2, 2);
			world.setBlock(i+8, j+2, k+0, Block.getBlockById(5));
			world.setBlockMetadataWithNotify(i+8, j+2, k+0, 2, 2);
			world.setBlock(i+9, j+2, k+0, Block.getBlockById(20));
			world.setBlock(i+10, j+2, k+0, Block.getBlockById(20));
			world.setBlock(i+11, j+2, k+0, Block.getBlockById(20));
			world.setBlock(i+12, j+2, k+0, Block.getBlockById(20));
			world.setBlock(i+13, j+2, k+0, Block.getBlockById(5));
			world.setBlockMetadataWithNotify(i+13, j+2, k+0, 2, 2);
			world.setBlock(i+14, j+2, k+0, Block.getBlockById(5));
			world.setBlockMetadataWithNotify(i+14, j+2, k+0, 2, 2);
			world.setBlock(i+6, j+2, k+1, Block.getBlockById(96));
			world.setBlockMetadataWithNotify(i+6, j+2, k+1, 14, 14);
			world.setBlock(i+7, j+2, k+1, Block.getBlockById(5));
			world.setBlockMetadataWithNotify(i+7, j+2, k+1, 2, 2);
			world.setBlock(i+14, j+2, k+1, Block.getBlockById(5));
			world.setBlockMetadataWithNotify(i+14, j+2, k+1, 2, 2);
			world.setBlock(i+7, j+2, k+2, Block.getBlockById(20));
			world.setBlock(i+14, j+2, k+2, Block.getBlockById(5));
			world.setBlockMetadataWithNotify(i+14, j+2, k+2, 2, 2);
			world.setBlock(i+7, j+2, k+3, Block.getBlockById(20));
			world.setBlock(i+14, j+2, k+3, Block.getBlockById(20));
			world.setBlock(i+7, j+2, k+4, Block.getBlockById(20));
			world.setBlock(i+14, j+2, k+4, Block.getBlockById(20));
			world.setBlock(i+6, j+2, k+5, Block.getBlockById(96));
			world.setBlockMetadataWithNotify(i+6, j+2, k+5, 6, 6);
			world.setBlock(i+7, j+2, k+5, Block.getBlockById(5));
			world.setBlockMetadataWithNotify(i+7, j+2, k+5, 2, 2);
			world.setBlock(i+14, j+2, k+5, Block.getBlockById(20));
			world.setBlock(i+7, j+2, k+6, Block.getBlockById(5));
			world.setBlockMetadataWithNotify(i+7, j+2, k+6, 2, 2);
			world.setBlock(i+14, j+2, k+6, Block.getBlockById(5));
			world.setBlockMetadataWithNotify(i+14, j+2, k+6, 2, 2);
			world.setBlock(i+7, j+2, k+7, Block.getBlockById(5));
			world.setBlockMetadataWithNotify(i+7, j+2, k+7, 2, 2);
			world.setBlock(i+14, j+2, k+7, Block.getBlockById(5));
			world.setBlockMetadataWithNotify(i+14, j+2, k+7, 2, 2);
			world.setBlock(i+7, j+2, k+8, Block.getBlockById(5));
			world.setBlockMetadataWithNotify(i+7, j+2, k+8, 2, 2);
			world.setBlock(i+8, j+2, k+8, Block.getBlockById(5));
			world.setBlockMetadataWithNotify(i+8, j+2, k+8, 2, 2);
			world.setBlock(i+9, j+2, k+8, Block.getBlockById(5));
			world.setBlockMetadataWithNotify(i+9, j+2, k+8, 2, 2);
			world.setBlock(i+10, j+2, k+8, Block.getBlockById(5));
			world.setBlockMetadataWithNotify(i+10, j+2, k+8, 2, 2);
			world.setBlock(i+11, j+2, k+8, Block.getBlockById(5));
			world.setBlockMetadataWithNotify(i+11, j+2, k+8, 2, 2);
			world.setBlock(i+13, j+2, k+8, Block.getBlockById(5));
			world.setBlockMetadataWithNotify(i+13, j+2, k+8, 2, 2);
			world.setBlock(i+14, j+2, k+8, Block.getBlockById(5));
			world.setBlockMetadataWithNotify(i+14, j+2, k+8, 2, 2);
			world.setBlock(i+7, j+2, k+9, Block.getBlockById(5));
			world.setBlockMetadataWithNotify(i+7, j+2, k+9, 2, 2);
			world.setBlock(i+14, j+2, k+9, Block.getBlockById(5));
			world.setBlockMetadataWithNotify(i+14, j+2, k+9, 2, 2);
			world.setBlock(i+7, j+2, k+10, Block.getBlockById(5));
			world.setBlockMetadataWithNotify(i+7, j+2, k+10, 2, 2);
			world.setBlock(i+14, j+2, k+10, Block.getBlockById(5));
			world.setBlockMetadataWithNotify(i+14, j+2, k+10, 2, 2);
			world.setBlock(i+6, j+2, k+11, Block.getBlockById(5));
			world.setBlock(i+7, j+2, k+11, Block.getBlockById(5));
			world.setBlockMetadataWithNotify(i+7, j+2, k+11, 2, 2);
			world.setBlock(i+14, j+2, k+11, Block.getBlockById(5));
			world.setBlockMetadataWithNotify(i+14, j+2, k+11, 2, 2);
			world.setBlock(i+14, j+2, k+12, Block.getBlockById(5));
			world.setBlockMetadataWithNotify(i+14, j+2, k+12, 2, 2);
			world.setBlock(i+6, j+2, k+13, Block.getBlockById(5));
			world.setBlock(i+7, j+2, k+13, Block.getBlockById(5));
			world.setBlockMetadataWithNotify(i+7, j+2, k+13, 2, 2);
			world.setBlock(i+14, j+2, k+13, Block.getBlockById(5));
			world.setBlockMetadataWithNotify(i+14, j+2, k+13, 2, 2);
			world.setBlock(i+7, j+2, k+14, Block.getBlockById(5));
			world.setBlockMetadataWithNotify(i+7, j+2, k+14, 2, 2);
			world.setBlock(i+14, j+2, k+14, Block.getBlockById(5));
			world.setBlockMetadataWithNotify(i+14, j+2, k+14, 2, 2);
			world.setBlock(i+7, j+2, k+15, Block.getBlockById(5));
			world.setBlockMetadataWithNotify(i+7, j+2, k+15, 2, 2);
			world.setBlock(i+14, j+2, k+15, Block.getBlockById(5));
			world.setBlockMetadataWithNotify(i+14, j+2, k+15, 2, 2);
			world.setBlock(i+7, j+2, k+16, Block.getBlockById(5));
			world.setBlockMetadataWithNotify(i+7, j+2, k+16, 2, 2);
			world.setBlock(i+14, j+2, k+16, Block.getBlockById(5));
			world.setBlockMetadataWithNotify(i+14, j+2, k+16, 2, 2);
			world.setBlock(i+7, j+2, k+17, Block.getBlockById(5));
			world.setBlockMetadataWithNotify(i+7, j+2, k+17, 2, 2);
			world.setBlock(i+8, j+2, k+17, Block.getBlockById(5));
			world.setBlockMetadataWithNotify(i+8, j+2, k+17, 2, 2);
			world.setBlock(i+9, j+2, k+17, Block.getBlockById(5));
			world.setBlockMetadataWithNotify(i+9, j+2, k+17, 2, 2);
			world.setBlock(i+10, j+2, k+17, Block.getBlockById(5));
			world.setBlockMetadataWithNotify(i+10, j+2, k+17, 2, 2);
			world.setBlock(i+11, j+2, k+17, Block.getBlockById(5));
			world.setBlockMetadataWithNotify(i+11, j+2, k+17, 2, 2);
			world.setBlock(i+12, j+2, k+17, Block.getBlockById(5));
			world.setBlockMetadataWithNotify(i+12, j+2, k+17, 2, 2);
			world.setBlock(i+13, j+2, k+17, Block.getBlockById(5));
			world.setBlockMetadataWithNotify(i+13, j+2, k+17, 2, 2);
			world.setBlock(i+14, j+2, k+17, Block.getBlockById(5));
			world.setBlockMetadataWithNotify(i+14, j+2, k+17, 2, 2);
			world.setBlock(i+7, j+3, k+0, Block.getBlockById(5));
			world.setBlockMetadataWithNotify(i+7, j+3, k+0, 2, 2);
			world.setBlock(i+8, j+3, k+0, Block.getBlockById(5));
			world.setBlockMetadataWithNotify(i+8, j+3, k+0, 2, 2);
			world.setBlock(i+9, j+3, k+0, Block.getBlockById(20));
			world.setBlock(i+10, j+3, k+0, Block.getBlockById(20));
			world.setBlock(i+11, j+3, k+0, Block.getBlockById(20));
			world.setBlock(i+12, j+3, k+0, Block.getBlockById(20));
			world.setBlock(i+13, j+3, k+0, Block.getBlockById(5));
			world.setBlockMetadataWithNotify(i+13, j+3, k+0, 2, 2);
			world.setBlock(i+14, j+3, k+0, Block.getBlockById(5));
			world.setBlockMetadataWithNotify(i+14, j+3, k+0, 2, 2);
			world.setBlock(i+6, j+3, k+1, Block.getBlockById(96));
			world.setBlockMetadataWithNotify(i+6, j+3, k+1, 6, 6);
			world.setBlock(i+7, j+3, k+1, Block.getBlockById(5));
			world.setBlockMetadataWithNotify(i+7, j+3, k+1, 2, 2);
			world.setBlock(i+14, j+3, k+1, Block.getBlockById(5));
			world.setBlockMetadataWithNotify(i+14, j+3, k+1, 2, 2);
			world.setBlock(i+7, j+3, k+2, Block.getBlockById(20));
			world.setBlock(i+14, j+3, k+2, Block.getBlockById(5));
			world.setBlockMetadataWithNotify(i+14, j+3, k+2, 2, 2);
			world.setBlock(i+7, j+3, k+3, Block.getBlockById(20));
			world.setBlock(i+14, j+3, k+3, Block.getBlockById(20));
			world.setBlock(i+7, j+3, k+4, Block.getBlockById(20));
			world.setBlock(i+14, j+3, k+4, Block.getBlockById(20));
			world.setBlock(i+6, j+3, k+5, Block.getBlockById(96));
			world.setBlockMetadataWithNotify(i+6, j+3, k+5, 6, 6);
			world.setBlock(i+7, j+3, k+5, Block.getBlockById(5));
			world.setBlockMetadataWithNotify(i+7, j+3, k+5, 2, 2);
			world.setBlock(i+14, j+3, k+5, Block.getBlockById(20));
			world.setBlock(i+7, j+3, k+6, Block.getBlockById(5));
			world.setBlockMetadataWithNotify(i+7, j+3, k+6, 2, 2);
			world.setBlock(i+14, j+3, k+6, Block.getBlockById(5));
			world.setBlockMetadataWithNotify(i+14, j+3, k+6, 2, 2);
			world.setBlock(i+6, j+3, k+7, Block.getBlockById(5));
			world.setBlock(i+7, j+3, k+7, Block.getBlockById(5));
			world.setBlockMetadataWithNotify(i+7, j+3, k+7, 2, 2);
			world.setBlock(i+14, j+3, k+7, Block.getBlockById(5));
			world.setBlockMetadataWithNotify(i+14, j+3, k+7, 2, 2);
			world.setBlock(i+6, j+3, k+8, Block.getBlockById(5));
			world.setBlock(i+7, j+3, k+8, Block.getBlockById(5));
			world.setBlockMetadataWithNotify(i+7, j+3, k+8, 2, 2);
			world.setBlock(i+8, j+3, k+8, Block.getBlockById(5));
			world.setBlockMetadataWithNotify(i+8, j+3, k+8, 2, 2);
			world.setBlock(i+9, j+3, k+8, Block.getBlockById(5));
			world.setBlockMetadataWithNotify(i+9, j+3, k+8, 2, 2);
			world.setBlock(i+10, j+3, k+8, Block.getBlockById(5));
			world.setBlockMetadataWithNotify(i+10, j+3, k+8, 2, 2);
			world.setBlock(i+11, j+3, k+8, Block.getBlockById(5));
			world.setBlockMetadataWithNotify(i+11, j+3, k+8, 2, 2);
			world.setBlock(i+12, j+3, k+8, Block.getBlockById(5));
			world.setBlockMetadataWithNotify(i+12, j+3, k+8, 2, 2);
			world.setBlock(i+13, j+3, k+8, Block.getBlockById(5));
			world.setBlockMetadataWithNotify(i+13, j+3, k+8, 2, 2);
			world.setBlock(i+14, j+3, k+8, Block.getBlockById(5));
			world.setBlockMetadataWithNotify(i+14, j+3, k+8, 2, 2);
			world.setBlock(i+7, j+3, k+9, Block.getBlockById(5));
			world.setBlockMetadataWithNotify(i+7, j+3, k+9, 2, 2);
			world.setBlock(i+14, j+3, k+9, Block.getBlockById(5));
			world.setBlockMetadataWithNotify(i+14, j+3, k+9, 2, 2);
			world.setBlock(i+7, j+3, k+10, Block.getBlockById(5));
			world.setBlockMetadataWithNotify(i+7, j+3, k+10, 2, 2);
			world.setBlock(i+14, j+3, k+10, Block.getBlockById(5));
			world.setBlockMetadataWithNotify(i+14, j+3, k+10, 2, 2);
			world.setBlock(i+6, j+3, k+11, Block.getBlockById(5));
			world.setBlockMetadataWithNotify(i+6, j+3, k+11, 2, 2);
			world.setBlock(i+7, j+3, k+11, Block.getBlockById(5));
			world.setBlockMetadataWithNotify(i+7, j+3, k+11, 2, 2);
			world.setBlock(i+8, j+3, k+11, Block.getBlockById(50));
			world.setBlockMetadataWithNotify(i+8, j+3, k+11, 1, 1);
			world.setBlock(i+14, j+3, k+11, Block.getBlockById(5));
			world.setBlockMetadataWithNotify(i+14, j+3, k+11, 2, 2);
			world.setBlock(i+6, j+3, k+12, Block.getBlockById(5));
			world.setBlockMetadataWithNotify(i+6, j+3, k+12, 2, 2);
			world.setBlock(i+7, j+3, k+12, Block.getBlockById(5));
			world.setBlockMetadataWithNotify(i+7, j+3, k+12, 2, 2);
			world.setBlock(i+14, j+3, k+12, Block.getBlockById(5));
			world.setBlockMetadataWithNotify(i+14, j+3, k+12, 2, 2);
			world.setBlock(i+6, j+3, k+13, Block.getBlockById(5));
			world.setBlockMetadataWithNotify(i+6, j+3, k+13, 2, 2);
			world.setBlock(i+7, j+3, k+13, Block.getBlockById(5));
			world.setBlockMetadataWithNotify(i+7, j+3, k+13, 2, 2);
			world.setBlock(i+8, j+3, k+13, Block.getBlockById(50));
			world.setBlockMetadataWithNotify(i+8, j+3, k+13, 1, 1);
			world.setBlock(i+14, j+3, k+13, Block.getBlockById(5));
			world.setBlockMetadataWithNotify(i+14, j+3, k+13, 2, 2);
			world.setBlock(i+7, j+3, k+14, Block.getBlockById(5));
			world.setBlockMetadataWithNotify(i+7, j+3, k+14, 2, 2);
			world.setBlock(i+14, j+3, k+14, Block.getBlockById(5));
			world.setBlockMetadataWithNotify(i+14, j+3, k+14, 2, 2);
			world.setBlock(i+7, j+3, k+15, Block.getBlockById(5));
			world.setBlockMetadataWithNotify(i+7, j+3, k+15, 2, 2);
			world.setBlock(i+14, j+3, k+15, Block.getBlockById(5));
			world.setBlockMetadataWithNotify(i+14, j+3, k+15, 2, 2);
			world.setBlock(i+6, j+3, k+16, Block.getBlockById(5));
			world.setBlock(i+7, j+3, k+16, Block.getBlockById(5));
			world.setBlockMetadataWithNotify(i+7, j+3, k+16, 2, 2);
			world.setBlock(i+14, j+3, k+16, Block.getBlockById(5));
			world.setBlockMetadataWithNotify(i+14, j+3, k+16, 2, 2);
			world.setBlock(i+6, j+3, k+17, Block.getBlockById(5));
			world.setBlock(i+7, j+3, k+17, Block.getBlockById(5));
			world.setBlockMetadataWithNotify(i+7, j+3, k+17, 2, 2);
			world.setBlock(i+8, j+3, k+17, Block.getBlockById(5));
			world.setBlockMetadataWithNotify(i+8, j+3, k+17, 2, 2);
			world.setBlock(i+9, j+3, k+17, Block.getBlockById(5));
			world.setBlockMetadataWithNotify(i+9, j+3, k+17, 2, 2);
			world.setBlock(i+10, j+3, k+17, Block.getBlockById(5));
			world.setBlockMetadataWithNotify(i+10, j+3, k+17, 2, 2);
			world.setBlock(i+11, j+3, k+17, Block.getBlockById(5));
			world.setBlockMetadataWithNotify(i+11, j+3, k+17, 2, 2);
			world.setBlock(i+12, j+3, k+17, Block.getBlockById(5));
			world.setBlockMetadataWithNotify(i+12, j+3, k+17, 2, 2);
			world.setBlock(i+13, j+3, k+17, Block.getBlockById(5));
			world.setBlockMetadataWithNotify(i+13, j+3, k+17, 2, 2);
			world.setBlock(i+14, j+3, k+17, Block.getBlockById(5));
			world.setBlockMetadataWithNotify(i+14, j+3, k+17, 2, 2);
			world.setBlock(i+7, j+4, k+0, Block.getBlockById(5));
			world.setBlockMetadataWithNotify(i+7, j+4, k+0, 2, 2);
			world.setBlock(i+8, j+4, k+0, Block.getBlockById(5));
			world.setBlockMetadataWithNotify(i+8, j+4, k+0, 2, 2);
			world.setBlock(i+9, j+4, k+0, Block.getBlockById(5));
			world.setBlockMetadataWithNotify(i+9, j+4, k+0, 2, 2);
			world.setBlock(i+10, j+4, k+0, Block.getBlockById(5));
			world.setBlockMetadataWithNotify(i+10, j+4, k+0, 2, 2);
			world.setBlock(i+11, j+4, k+0, Block.getBlockById(5));
			world.setBlockMetadataWithNotify(i+11, j+4, k+0, 2, 2);
			world.setBlock(i+12, j+4, k+0, Block.getBlockById(5));
			world.setBlockMetadataWithNotify(i+12, j+4, k+0, 2, 2);
			world.setBlock(i+13, j+4, k+0, Block.getBlockById(5));
			world.setBlockMetadataWithNotify(i+13, j+4, k+0, 2, 2);
			world.setBlock(i+14, j+4, k+0, Block.getBlockById(5));
			world.setBlockMetadataWithNotify(i+14, j+4, k+0, 2, 2);
			world.setBlock(i+7, j+4, k+1, Block.getBlockById(5));
			world.setBlockMetadataWithNotify(i+7, j+4, k+1, 2, 2);
			world.setBlock(i+8, j+4, k+1, Block.getBlockById(50));
			world.setBlockMetadataWithNotify(i+8, j+4, k+1, 1, 1);
			world.setBlock(i+13, j+4, k+1, Block.getBlockById(50));
			world.setBlockMetadataWithNotify(i+13, j+4, k+1, 2, 2);
			world.setBlock(i+14, j+4, k+1, Block.getBlockById(5));
			world.setBlockMetadataWithNotify(i+14, j+4, k+1, 2, 2);
			world.setBlock(i+7, j+4, k+2, Block.getBlockById(5));
			world.setBlockMetadataWithNotify(i+7, j+4, k+2, 2, 2);
			world.setBlock(i+14, j+4, k+2, Block.getBlockById(5));
			world.setBlockMetadataWithNotify(i+14, j+4, k+2, 2, 2);
			world.setBlock(i+7, j+4, k+3, Block.getBlockById(5));
			world.setBlockMetadataWithNotify(i+7, j+4, k+3, 2, 2);
			world.setBlock(i+14, j+4, k+3, Block.getBlockById(5));
			world.setBlockMetadataWithNotify(i+14, j+4, k+3, 2, 2);
			world.setBlock(i+7, j+4, k+4, Block.getBlockById(5));
			world.setBlockMetadataWithNotify(i+7, j+4, k+4, 2, 2);
			world.setBlock(i+14, j+4, k+4, Block.getBlockById(5));
			world.setBlockMetadataWithNotify(i+14, j+4, k+4, 2, 2);
			world.setBlock(i+7, j+4, k+5, Block.getBlockById(5));
			world.setBlockMetadataWithNotify(i+7, j+4, k+5, 2, 2);
			world.setBlock(i+14, j+4, k+5, Block.getBlockById(5));
			world.setBlockMetadataWithNotify(i+14, j+4, k+5, 2, 2);
			world.setBlock(i+7, j+4, k+6, Block.getBlockById(5));
			world.setBlockMetadataWithNotify(i+7, j+4, k+6, 2, 2);
			world.setBlock(i+14, j+4, k+6, Block.getBlockById(5));
			world.setBlockMetadataWithNotify(i+14, j+4, k+6, 2, 2);
			world.setBlock(i+7, j+4, k+7, Block.getBlockById(5));
			world.setBlockMetadataWithNotify(i+7, j+4, k+7, 2, 2);
			world.setBlock(i+8, j+4, k+7, Block.getBlockById(50));
			world.setBlockMetadataWithNotify(i+8, j+4, k+7, 1, 1);
			world.setBlock(i+13, j+4, k+7, Block.getBlockById(50));
			world.setBlockMetadataWithNotify(i+13, j+4, k+7, 2, 2);
			world.setBlock(i+14, j+4, k+7, Block.getBlockById(5));
			world.setBlockMetadataWithNotify(i+14, j+4, k+7, 2, 2);
			world.setBlock(i+6, j+4, k+8, Block.getBlockById(5));
			world.setBlock(i+7, j+4, k+8, Block.getBlockById(5));
			world.setBlockMetadataWithNotify(i+7, j+4, k+8, 2, 2);
			world.setBlock(i+8, j+4, k+8, Block.getBlockById(5));
			world.setBlockMetadataWithNotify(i+8, j+4, k+8, 2, 2);
			world.setBlock(i+9, j+4, k+8, Block.getBlockById(5));
			world.setBlockMetadataWithNotify(i+9, j+4, k+8, 2, 2);
			world.setBlock(i+10, j+4, k+8, Block.getBlockById(5));
			world.setBlockMetadataWithNotify(i+10, j+4, k+8, 2, 2);
			world.setBlock(i+11, j+4, k+8, Block.getBlockById(5));
			world.setBlockMetadataWithNotify(i+11, j+4, k+8, 2, 2);
			world.setBlock(i+12, j+4, k+8, Block.getBlockById(5));
			world.setBlockMetadataWithNotify(i+12, j+4, k+8, 2, 2);
			world.setBlock(i+13, j+4, k+8, Block.getBlockById(5));
			world.setBlockMetadataWithNotify(i+13, j+4, k+8, 2, 2);
			world.setBlock(i+14, j+4, k+8, Block.getBlockById(5));
			world.setBlockMetadataWithNotify(i+14, j+4, k+8, 2, 2);
			world.setBlock(i+6, j+4, k+9, Block.getBlockById(5));
			world.setBlock(i+7, j+4, k+9, Block.getBlockById(5));
			world.setBlockMetadataWithNotify(i+7, j+4, k+9, 2, 2);
			world.setBlock(i+14, j+4, k+9, Block.getBlockById(5));
			world.setBlockMetadataWithNotify(i+14, j+4, k+9, 2, 2);
			world.setBlock(i+7, j+4, k+10, Block.getBlockById(5));
			world.setBlockMetadataWithNotify(i+7, j+4, k+10, 2, 2);
			world.setBlock(i+14, j+4, k+10, Block.getBlockById(5));
			world.setBlockMetadataWithNotify(i+14, j+4, k+10, 2, 2);
			world.setBlock(i+6, j+4, k+11, Block.getBlockById(5));
			world.setBlockMetadataWithNotify(i+6, j+4, k+11, 2, 2);
			world.setBlock(i+7, j+4, k+11, Block.getBlockById(5));
			world.setBlockMetadataWithNotify(i+7, j+4, k+11, 2, 2);
			world.setBlock(i+14, j+4, k+11, Block.getBlockById(5));
			world.setBlockMetadataWithNotify(i+14, j+4, k+11, 2, 2);
			world.setBlock(i+6, j+4, k+12, Block.getBlockById(5));
			world.setBlockMetadataWithNotify(i+6, j+4, k+12, 2, 2);
			world.setBlock(i+7, j+4, k+12, Block.getBlockById(5));
			world.setBlockMetadataWithNotify(i+7, j+4, k+12, 2, 2);
			world.setBlock(i+14, j+4, k+12, Block.getBlockById(5));
			world.setBlockMetadataWithNotify(i+14, j+4, k+12, 2, 2);
			world.setBlock(i+6, j+4, k+13, Block.getBlockById(5));
			world.setBlockMetadataWithNotify(i+6, j+4, k+13, 2, 2);
			world.setBlock(i+7, j+4, k+13, Block.getBlockById(5));
			world.setBlockMetadataWithNotify(i+7, j+4, k+13, 2, 2);
			world.setBlock(i+14, j+4, k+13, Block.getBlockById(5));
			world.setBlockMetadataWithNotify(i+14, j+4, k+13, 2, 2);
			world.setBlock(i+7, j+4, k+14, Block.getBlockById(5));
			world.setBlockMetadataWithNotify(i+7, j+4, k+14, 2, 2);
			world.setBlock(i+14, j+4, k+14, Block.getBlockById(5));
			world.setBlockMetadataWithNotify(i+14, j+4, k+14, 2, 2);
			world.setBlock(i+6, j+4, k+15, Block.getBlockById(5));
			world.setBlock(i+7, j+4, k+15, Block.getBlockById(5));
			world.setBlockMetadataWithNotify(i+7, j+4, k+15, 2, 2);
			world.setBlock(i+14, j+4, k+15, Block.getBlockById(5));
			world.setBlockMetadataWithNotify(i+14, j+4, k+15, 2, 2);
			world.setBlock(i+6, j+4, k+16, Block.getBlockById(5));
			world.setBlock(i+7, j+4, k+16, Block.getBlockById(5));
			world.setBlockMetadataWithNotify(i+7, j+4, k+16, 2, 2);
			world.setBlock(i+14, j+4, k+16, Block.getBlockById(5));
			world.setBlockMetadataWithNotify(i+14, j+4, k+16, 2, 2);
			world.setBlock(i+7, j+4, k+17, Block.getBlockById(5));
			world.setBlockMetadataWithNotify(i+7, j+4, k+17, 2, 2);
			world.setBlock(i+8, j+4, k+17, Block.getBlockById(5));
			world.setBlockMetadataWithNotify(i+8, j+4, k+17, 2, 2);
			world.setBlock(i+9, j+4, k+17, Block.getBlockById(5));
			world.setBlockMetadataWithNotify(i+9, j+4, k+17, 2, 2);
			world.setBlock(i+10, j+4, k+17, Block.getBlockById(5));
			world.setBlockMetadataWithNotify(i+10, j+4, k+17, 2, 2);
			world.setBlock(i+11, j+4, k+17, Block.getBlockById(5));
			world.setBlockMetadataWithNotify(i+11, j+4, k+17, 2, 2);
			world.setBlock(i+12, j+4, k+17, Block.getBlockById(5));
			world.setBlockMetadataWithNotify(i+12, j+4, k+17, 2, 2);
			world.setBlock(i+13, j+4, k+17, Block.getBlockById(5));
			world.setBlockMetadataWithNotify(i+13, j+4, k+17, 2, 2);
			world.setBlock(i+14, j+4, k+17, Block.getBlockById(5));
			world.setBlockMetadataWithNotify(i+14, j+4, k+17, 2, 2);
			world.setBlock(i+7, j+5, k+0, Block.getBlockById(5));
			world.setBlockMetadataWithNotify(i+7, j+5, k+0, 2, 2);
			world.setBlock(i+8, j+5, k+0, Block.getBlockById(5));
			world.setBlockMetadataWithNotify(i+8, j+5, k+0, 2, 2);
			world.setBlock(i+9, j+5, k+0, Block.getBlockById(5));
			world.setBlockMetadataWithNotify(i+9, j+5, k+0, 2, 2);
			world.setBlock(i+10, j+5, k+0, Block.getBlockById(5));
			world.setBlockMetadataWithNotify(i+10, j+5, k+0, 2, 2);
			world.setBlock(i+11, j+5, k+0, Block.getBlockById(5));
			world.setBlockMetadataWithNotify(i+11, j+5, k+0, 2, 2);
			world.setBlock(i+12, j+5, k+0, Block.getBlockById(5));
			world.setBlockMetadataWithNotify(i+12, j+5, k+0, 2, 2);
			world.setBlock(i+13, j+5, k+0, Block.getBlockById(5));
			world.setBlockMetadataWithNotify(i+13, j+5, k+0, 2, 2);
			world.setBlock(i+14, j+5, k+0, Block.getBlockById(5));
			world.setBlockMetadataWithNotify(i+14, j+5, k+0, 2, 2);
			world.setBlock(i+7, j+5, k+1, Block.getBlockById(5));
			world.setBlockMetadataWithNotify(i+7, j+5, k+1, 2, 2);
			world.setBlock(i+8, j+5, k+1, Block.getBlockById(5));
			world.setBlockMetadataWithNotify(i+8, j+5, k+1, 2, 2);
			world.setBlock(i+9, j+5, k+1, Block.getBlockById(5));
			world.setBlockMetadataWithNotify(i+9, j+5, k+1, 2, 2);
			world.setBlock(i+10, j+5, k+1, Block.getBlockById(5));
			world.setBlockMetadataWithNotify(i+10, j+5, k+1, 2, 2);
			world.setBlock(i+11, j+5, k+1, Block.getBlockById(5));
			world.setBlockMetadataWithNotify(i+11, j+5, k+1, 2, 2);
			world.setBlock(i+12, j+5, k+1, Block.getBlockById(5));
			world.setBlockMetadataWithNotify(i+12, j+5, k+1, 2, 2);
			world.setBlock(i+13, j+5, k+1, Block.getBlockById(5));
			world.setBlockMetadataWithNotify(i+13, j+5, k+1, 2, 2);
			world.setBlock(i+14, j+5, k+1, Block.getBlockById(5));
			world.setBlockMetadataWithNotify(i+14, j+5, k+1, 2, 2);
			world.setBlock(i+7, j+5, k+2, Block.getBlockById(5));
			world.setBlockMetadataWithNotify(i+7, j+5, k+2, 2, 2);
			world.setBlock(i+8, j+5, k+2, Block.getBlockById(5));
			world.setBlockMetadataWithNotify(i+8, j+5, k+2, 2, 2);
			world.setBlock(i+9, j+5, k+2, Block.getBlockById(5));
			world.setBlockMetadataWithNotify(i+9, j+5, k+2, 2, 2);
			world.setBlock(i+10, j+5, k+2, Block.getBlockById(5));
			world.setBlockMetadataWithNotify(i+10, j+5, k+2, 2, 2);
			world.setBlock(i+11, j+5, k+2, Block.getBlockById(5));
			world.setBlockMetadataWithNotify(i+11, j+5, k+2, 2, 2);
			world.setBlock(i+12, j+5, k+2, Block.getBlockById(5));
			world.setBlockMetadataWithNotify(i+12, j+5, k+2, 2, 2);
			world.setBlock(i+13, j+5, k+2, Block.getBlockById(5));
			world.setBlockMetadataWithNotify(i+13, j+5, k+2, 2, 2);
			world.setBlock(i+14, j+5, k+2, Block.getBlockById(5));
			world.setBlockMetadataWithNotify(i+14, j+5, k+2, 2, 2);
			world.setBlock(i+7, j+5, k+3, Block.getBlockById(5));
			world.setBlockMetadataWithNotify(i+7, j+5, k+3, 2, 2);
			world.setBlock(i+8, j+5, k+3, Block.getBlockById(5));
			world.setBlockMetadataWithNotify(i+8, j+5, k+3, 2, 2);
			world.setBlock(i+9, j+5, k+3, Block.getBlockById(5));
			world.setBlockMetadataWithNotify(i+9, j+5, k+3, 2, 2);
			world.setBlock(i+10, j+5, k+3, Block.getBlockById(5));
			world.setBlockMetadataWithNotify(i+10, j+5, k+3, 2, 2);
			world.setBlock(i+11, j+5, k+3, Block.getBlockById(5));
			world.setBlockMetadataWithNotify(i+11, j+5, k+3, 2, 2);
			world.setBlock(i+12, j+5, k+3, Block.getBlockById(5));
			world.setBlockMetadataWithNotify(i+12, j+5, k+3, 2, 2);
			world.setBlock(i+13, j+5, k+3, Block.getBlockById(5));
			world.setBlockMetadataWithNotify(i+13, j+5, k+3, 2, 2);
			world.setBlock(i+14, j+5, k+3, Block.getBlockById(5));
			world.setBlockMetadataWithNotify(i+14, j+5, k+3, 2, 2);
			world.setBlock(i+7, j+5, k+4, Block.getBlockById(5));
			world.setBlockMetadataWithNotify(i+7, j+5, k+4, 2, 2);
			world.setBlock(i+8, j+5, k+4, Block.getBlockById(5));
			world.setBlockMetadataWithNotify(i+8, j+5, k+4, 2, 2);
			world.setBlock(i+9, j+5, k+4, Block.getBlockById(5));
			world.setBlockMetadataWithNotify(i+9, j+5, k+4, 2, 2);
			world.setBlock(i+10, j+5, k+4, Block.getBlockById(5));
			world.setBlockMetadataWithNotify(i+10, j+5, k+4, 2, 2);
			world.setBlock(i+11, j+5, k+4, Block.getBlockById(5));
			world.setBlockMetadataWithNotify(i+11, j+5, k+4, 2, 2);
			world.setBlock(i+12, j+5, k+4, Block.getBlockById(5));
			world.setBlockMetadataWithNotify(i+12, j+5, k+4, 2, 2);
			world.setBlock(i+13, j+5, k+4, Block.getBlockById(5));
			world.setBlockMetadataWithNotify(i+13, j+5, k+4, 2, 2);
			world.setBlock(i+14, j+5, k+4, Block.getBlockById(5));
			world.setBlockMetadataWithNotify(i+14, j+5, k+4, 2, 2);
			world.setBlock(i+7, j+5, k+5, Block.getBlockById(5));
			world.setBlockMetadataWithNotify(i+7, j+5, k+5, 2, 2);
			world.setBlock(i+8, j+5, k+5, Block.getBlockById(5));
			world.setBlockMetadataWithNotify(i+8, j+5, k+5, 2, 2);
			world.setBlock(i+9, j+5, k+5, Block.getBlockById(5));
			world.setBlockMetadataWithNotify(i+9, j+5, k+5, 2, 2);
			world.setBlock(i+10, j+5, k+5, Block.getBlockById(5));
			world.setBlockMetadataWithNotify(i+10, j+5, k+5, 2, 2);
			world.setBlock(i+11, j+5, k+5, Block.getBlockById(5));
			world.setBlockMetadataWithNotify(i+11, j+5, k+5, 2, 2);
			world.setBlock(i+12, j+5, k+5, Block.getBlockById(5));
			world.setBlockMetadataWithNotify(i+12, j+5, k+5, 2, 2);
			world.setBlock(i+13, j+5, k+5, Block.getBlockById(5));
			world.setBlockMetadataWithNotify(i+13, j+5, k+5, 2, 2);
			world.setBlock(i+14, j+5, k+5, Block.getBlockById(5));
			world.setBlockMetadataWithNotify(i+14, j+5, k+5, 2, 2);
			world.setBlock(i+7, j+5, k+6, Block.getBlockById(5));
			world.setBlockMetadataWithNotify(i+7, j+5, k+6, 2, 2);
			world.setBlock(i+8, j+5, k+6, Block.getBlockById(5));
			world.setBlockMetadataWithNotify(i+8, j+5, k+6, 2, 2);
			world.setBlock(i+9, j+5, k+6, Block.getBlockById(5));
			world.setBlockMetadataWithNotify(i+9, j+5, k+6, 2, 2);
			world.setBlock(i+10, j+5, k+6, Block.getBlockById(5));
			world.setBlockMetadataWithNotify(i+10, j+5, k+6, 2, 2);
			world.setBlock(i+11, j+5, k+6, Block.getBlockById(5));
			world.setBlockMetadataWithNotify(i+11, j+5, k+6, 2, 2);
			world.setBlock(i+12, j+5, k+6, Block.getBlockById(5));
			world.setBlockMetadataWithNotify(i+12, j+5, k+6, 2, 2);
			world.setBlock(i+13, j+5, k+6, Block.getBlockById(5));
			world.setBlockMetadataWithNotify(i+13, j+5, k+6, 2, 2);
			world.setBlock(i+14, j+5, k+6, Block.getBlockById(5));
			world.setBlockMetadataWithNotify(i+14, j+5, k+6, 2, 2);
			world.setBlock(i+7, j+5, k+7, Block.getBlockById(5));
			world.setBlockMetadataWithNotify(i+7, j+5, k+7, 2, 2);
			world.setBlock(i+8, j+5, k+7, Block.getBlockById(5));
			world.setBlockMetadataWithNotify(i+8, j+5, k+7, 2, 2);
			world.setBlock(i+9, j+5, k+7, Block.getBlockById(5));
			world.setBlockMetadataWithNotify(i+9, j+5, k+7, 2, 2);
			world.setBlock(i+10, j+5, k+7, Block.getBlockById(5));
			world.setBlockMetadataWithNotify(i+10, j+5, k+7, 2, 2);
			world.setBlock(i+11, j+5, k+7, Block.getBlockById(5));
			world.setBlockMetadataWithNotify(i+11, j+5, k+7, 2, 2);
			world.setBlock(i+12, j+5, k+7, Block.getBlockById(5));
			world.setBlockMetadataWithNotify(i+12, j+5, k+7, 2, 2);
			world.setBlock(i+13, j+5, k+7, Block.getBlockById(5));
			world.setBlockMetadataWithNotify(i+13, j+5, k+7, 2, 2);
			world.setBlock(i+14, j+5, k+7, Block.getBlockById(5));
			world.setBlockMetadataWithNotify(i+14, j+5, k+7, 2, 2);
			world.setBlock(i+7, j+5, k+8, Block.getBlockById(5));
			world.setBlockMetadataWithNotify(i+7, j+5, k+8, 2, 2);
			world.setBlock(i+8, j+5, k+8, Block.getBlockById(5));
			world.setBlockMetadataWithNotify(i+8, j+5, k+8, 2, 2);
			world.setBlock(i+9, j+5, k+8, Block.getBlockById(5));
			world.setBlockMetadataWithNotify(i+9, j+5, k+8, 2, 2);
			world.setBlock(i+10, j+5, k+8, Block.getBlockById(5));
			world.setBlockMetadataWithNotify(i+10, j+5, k+8, 2, 2);
			world.setBlock(i+11, j+5, k+8, Block.getBlockById(5));
			world.setBlockMetadataWithNotify(i+11, j+5, k+8, 2, 2);
			world.setBlock(i+12, j+5, k+8, Block.getBlockById(5));
			world.setBlockMetadataWithNotify(i+12, j+5, k+8, 2, 2);
			world.setBlock(i+13, j+5, k+8, Block.getBlockById(5));
			world.setBlockMetadataWithNotify(i+13, j+5, k+8, 2, 2);
			world.setBlock(i+14, j+5, k+8, Block.getBlockById(5));
			world.setBlockMetadataWithNotify(i+14, j+5, k+8, 2, 2);
			world.setBlock(i+6, j+5, k+9, Block.getBlockById(5));
			world.setBlock(i+7, j+5, k+9, Block.getBlockById(5));
			world.setBlockMetadataWithNotify(i+7, j+5, k+9, 2, 2);
			world.setBlock(i+8, j+5, k+9, Block.getBlockById(5));
			world.setBlockMetadataWithNotify(i+8, j+5, k+9, 2, 2);
			world.setBlock(i+9, j+5, k+9, Block.getBlockById(5));
			world.setBlockMetadataWithNotify(i+9, j+5, k+9, 2, 2);
			world.setBlock(i+10, j+5, k+9, Block.getBlockById(5));
			world.setBlockMetadataWithNotify(i+10, j+5, k+9, 2, 2);
			world.setBlock(i+11, j+5, k+9, Block.getBlockById(5));
			world.setBlockMetadataWithNotify(i+11, j+5, k+9, 2, 2);
			world.setBlock(i+12, j+5, k+9, Block.getBlockById(5));
			world.setBlockMetadataWithNotify(i+12, j+5, k+9, 2, 2);
			world.setBlock(i+13, j+5, k+9, Block.getBlockById(5));
			world.setBlockMetadataWithNotify(i+13, j+5, k+9, 2, 2);
			world.setBlock(i+14, j+5, k+9, Block.getBlockById(5));
			world.setBlockMetadataWithNotify(i+14, j+5, k+9, 2, 2);
			world.setBlock(i+6, j+5, k+10, Block.getBlockById(5));
			world.setBlock(i+7, j+5, k+10, Block.getBlockById(5));
			world.setBlockMetadataWithNotify(i+7, j+5, k+10, 2, 2);
			world.setBlock(i+8, j+5, k+10, Block.getBlockById(5));
			world.setBlockMetadataWithNotify(i+8, j+5, k+10, 2, 2);
			world.setBlock(i+9, j+5, k+10, Block.getBlockById(5));
			world.setBlockMetadataWithNotify(i+9, j+5, k+10, 2, 2);
			world.setBlock(i+10, j+5, k+10, Block.getBlockById(5));
			world.setBlockMetadataWithNotify(i+10, j+5, k+10, 2, 2);
			world.setBlock(i+11, j+5, k+10, Block.getBlockById(5));
			world.setBlockMetadataWithNotify(i+11, j+5, k+10, 2, 2);
			world.setBlock(i+12, j+5, k+10, Block.getBlockById(5));
			world.setBlockMetadataWithNotify(i+12, j+5, k+10, 2, 2);
			world.setBlock(i+13, j+5, k+10, Block.getBlockById(5));
			world.setBlockMetadataWithNotify(i+13, j+5, k+10, 2, 2);
			world.setBlock(i+14, j+5, k+10, Block.getBlockById(5));
			world.setBlockMetadataWithNotify(i+14, j+5, k+10, 2, 2);
			world.setBlock(i+6, j+5, k+11, Block.getBlockById(5));
			world.setBlock(i+7, j+5, k+11, Block.getBlockById(5));
			world.setBlockMetadataWithNotify(i+7, j+5, k+11, 2, 2);
			world.setBlock(i+8, j+5, k+11, Block.getBlockById(5));
			world.setBlockMetadataWithNotify(i+8, j+5, k+11, 2, 2);
			world.setBlock(i+9, j+5, k+11, Block.getBlockById(5));
			world.setBlockMetadataWithNotify(i+9, j+5, k+11, 2, 2);
			world.setBlock(i+10, j+5, k+11, Block.getBlockById(5));
			world.setBlockMetadataWithNotify(i+10, j+5, k+11, 2, 2);
			world.setBlock(i+11, j+5, k+11, Block.getBlockById(5));
			world.setBlockMetadataWithNotify(i+11, j+5, k+11, 2, 2);
			world.setBlock(i+12, j+5, k+11, Block.getBlockById(5));
			world.setBlockMetadataWithNotify(i+12, j+5, k+11, 2, 2);
			world.setBlock(i+13, j+5, k+11, Block.getBlockById(5));
			world.setBlockMetadataWithNotify(i+13, j+5, k+11, 2, 2);
			world.setBlock(i+14, j+5, k+11, Block.getBlockById(5));
			world.setBlockMetadataWithNotify(i+14, j+5, k+11, 2, 2);
			world.setBlock(i+6, j+5, k+12, Block.getBlockById(5));
			world.setBlock(i+7, j+5, k+12, Block.getBlockById(5));
			world.setBlockMetadataWithNotify(i+7, j+5, k+12, 2, 2);
			world.setBlock(i+8, j+5, k+12, Block.getBlockById(5));
			world.setBlockMetadataWithNotify(i+8, j+5, k+12, 2, 2);
			world.setBlock(i+9, j+5, k+12, Block.getBlockById(5));
			world.setBlockMetadataWithNotify(i+9, j+5, k+12, 2, 2);
			world.setBlock(i+10, j+5, k+12, Block.getBlockById(5));
			world.setBlockMetadataWithNotify(i+10, j+5, k+12, 2, 2);
			world.setBlock(i+11, j+5, k+12, Block.getBlockById(5));
			world.setBlockMetadataWithNotify(i+11, j+5, k+12, 2, 2);
			world.setBlock(i+12, j+5, k+12, Block.getBlockById(5));
			world.setBlockMetadataWithNotify(i+12, j+5, k+12, 2, 2);
			world.setBlock(i+13, j+5, k+12, Block.getBlockById(5));
			world.setBlockMetadataWithNotify(i+13, j+5, k+12, 2, 2);
			world.setBlock(i+14, j+5, k+12, Block.getBlockById(5));
			world.setBlockMetadataWithNotify(i+14, j+5, k+12, 2, 2);
			world.setBlock(i+6, j+5, k+13, Block.getBlockById(5));
			world.setBlock(i+7, j+5, k+13, Block.getBlockById(5));
			world.setBlockMetadataWithNotify(i+7, j+5, k+13, 2, 2);
			world.setBlock(i+8, j+5, k+13, Block.getBlockById(5));
			world.setBlockMetadataWithNotify(i+8, j+5, k+13, 2, 2);
			world.setBlock(i+9, j+5, k+13, Block.getBlockById(5));
			world.setBlockMetadataWithNotify(i+9, j+5, k+13, 2, 2);
			world.setBlock(i+10, j+5, k+13, Block.getBlockById(5));
			world.setBlockMetadataWithNotify(i+10, j+5, k+13, 2, 2);
			world.setBlock(i+11, j+5, k+13, Block.getBlockById(5));
			world.setBlockMetadataWithNotify(i+11, j+5, k+13, 2, 2);
			world.setBlock(i+12, j+5, k+13, Block.getBlockById(5));
			world.setBlockMetadataWithNotify(i+12, j+5, k+13, 2, 2);
			world.setBlock(i+13, j+5, k+13, Block.getBlockById(5));
			world.setBlockMetadataWithNotify(i+13, j+5, k+13, 2, 2);
			world.setBlock(i+14, j+5, k+13, Block.getBlockById(5));
			world.setBlockMetadataWithNotify(i+14, j+5, k+13, 2, 2);
			world.setBlock(i+6, j+5, k+14, Block.getBlockById(5));
			world.setBlock(i+7, j+5, k+14, Block.getBlockById(5));
			world.setBlockMetadataWithNotify(i+7, j+5, k+14, 2, 2);
			world.setBlock(i+8, j+5, k+14, Block.getBlockById(5));
			world.setBlockMetadataWithNotify(i+8, j+5, k+14, 2, 2);
			world.setBlock(i+9, j+5, k+14, Block.getBlockById(5));
			world.setBlockMetadataWithNotify(i+9, j+5, k+14, 2, 2);
			world.setBlock(i+10, j+5, k+14, Block.getBlockById(5));
			world.setBlockMetadataWithNotify(i+10, j+5, k+14, 2, 2);
			world.setBlock(i+11, j+5, k+14, Block.getBlockById(5));
			world.setBlockMetadataWithNotify(i+11, j+5, k+14, 2, 2);
			world.setBlock(i+12, j+5, k+14, Block.getBlockById(5));
			world.setBlockMetadataWithNotify(i+12, j+5, k+14, 2, 2);
			world.setBlock(i+13, j+5, k+14, Block.getBlockById(5));
			world.setBlockMetadataWithNotify(i+13, j+5, k+14, 2, 2);
			world.setBlock(i+14, j+5, k+14, Block.getBlockById(5));
			world.setBlockMetadataWithNotify(i+14, j+5, k+14, 2, 2);
			world.setBlock(i+6, j+5, k+15, Block.getBlockById(5));
			world.setBlock(i+7, j+5, k+15, Block.getBlockById(5));
			world.setBlockMetadataWithNotify(i+7, j+5, k+15, 2, 2);
			world.setBlock(i+8, j+5, k+15, Block.getBlockById(5));
			world.setBlockMetadataWithNotify(i+8, j+5, k+15, 2, 2);
			world.setBlock(i+9, j+5, k+15, Block.getBlockById(5));
			world.setBlockMetadataWithNotify(i+9, j+5, k+15, 2, 2);
			world.setBlock(i+10, j+5, k+15, Block.getBlockById(5));
			world.setBlockMetadataWithNotify(i+10, j+5, k+15, 2, 2);
			world.setBlock(i+11, j+5, k+15, Block.getBlockById(5));
			world.setBlockMetadataWithNotify(i+11, j+5, k+15, 2, 2);
			world.setBlock(i+12, j+5, k+15, Block.getBlockById(5));
			world.setBlockMetadataWithNotify(i+12, j+5, k+15, 2, 2);
			world.setBlock(i+13, j+5, k+15, Block.getBlockById(5));
			world.setBlockMetadataWithNotify(i+13, j+5, k+15, 2, 2);
			world.setBlock(i+14, j+5, k+15, Block.getBlockById(5));
			world.setBlockMetadataWithNotify(i+14, j+5, k+15, 2, 2);
			world.setBlock(i+7, j+5, k+16, Block.getBlockById(5));
			world.setBlockMetadataWithNotify(i+7, j+5, k+16, 2, 2);
			world.setBlock(i+8, j+5, k+16, Block.getBlockById(5));
			world.setBlockMetadataWithNotify(i+8, j+5, k+16, 2, 2);
			world.setBlock(i+9, j+5, k+16, Block.getBlockById(5));
			world.setBlockMetadataWithNotify(i+9, j+5, k+16, 2, 2);
			world.setBlock(i+10, j+5, k+16, Block.getBlockById(5));
			world.setBlockMetadataWithNotify(i+10, j+5, k+16, 2, 2);
			world.setBlock(i+11, j+5, k+16, Block.getBlockById(5));
			world.setBlockMetadataWithNotify(i+11, j+5, k+16, 2, 2);
			world.setBlock(i+12, j+5, k+16, Block.getBlockById(5));
			world.setBlockMetadataWithNotify(i+12, j+5, k+16, 2, 2);
			world.setBlock(i+13, j+5, k+16, Block.getBlockById(5));
			world.setBlockMetadataWithNotify(i+13, j+5, k+16, 2, 2);
			world.setBlock(i+14, j+5, k+16, Block.getBlockById(5));
			world.setBlockMetadataWithNotify(i+14, j+5, k+16, 2, 2);
			world.setBlock(i+7, j+5, k+17, Block.getBlockById(5));
			world.setBlockMetadataWithNotify(i+7, j+5, k+17, 2, 2);
			world.setBlock(i+8, j+5, k+17, Block.getBlockById(5));
			world.setBlockMetadataWithNotify(i+8, j+5, k+17, 2, 2);
			world.setBlock(i+9, j+5, k+17, Block.getBlockById(5));
			world.setBlockMetadataWithNotify(i+9, j+5, k+17, 2, 2);
			world.setBlock(i+10, j+5, k+17, Block.getBlockById(5));
			world.setBlockMetadataWithNotify(i+10, j+5, k+17, 2, 2);
			world.setBlock(i+11, j+5, k+17, Block.getBlockById(5));
			world.setBlockMetadataWithNotify(i+11, j+5, k+17, 2, 2);
			world.setBlock(i+12, j+5, k+17, Block.getBlockById(5));
			world.setBlockMetadataWithNotify(i+12, j+5, k+17, 2, 2);
			world.setBlock(i+13, j+5, k+17, Block.getBlockById(5));
			world.setBlockMetadataWithNotify(i+13, j+5, k+17, 2, 2);
			world.setBlock(i+14, j+5, k+17, Block.getBlockById(5));
			world.setBlockMetadataWithNotify(i+14, j+5, k+17, 2, 2);
			world.setBlock(i+6, j+6, k+11, Block.getBlockById(46));
			world.setBlock(i+6, j+6, k+12, Block.getBlockById(46));
			world.setBlock(i+6, j+6, k+13, Block.getBlockById(46));
			world.setBlock(i+6, j+7, k+11, Block.getBlockById(46));
			world.setBlock(i+6, j+7, k+12, Block.getBlockById(46));
			world.setBlock(i+6, j+7, k+13, Block.getBlockById(46));
			world.setBlock(i+6, j+8, k+11, Block.getBlockById(46));
			world.setBlock(i+6, j+8, k+12, Block.getBlockById(46));
			world.setBlock(i+6, j+8, k+13, Block.getBlockById(46));
			world.setBlock(i+6, j+9, k+11, Block.getBlockById(46));
			world.setBlock(i+6, j+9, k+12, Block.getBlockById(46));
			world.setBlock(i+6, j+9, k+13, Block.getBlockById(46));
			world.setBlock(i+6, j+10, k+11, Block.getBlockById(46));
			world.setBlock(i+6, j+10, k+12, Block.getBlockById(46));
			world.setBlock(i+6, j+10, k+13, Block.getBlockById(46));
			world.setBlock(i+6, j+11, k+11, Block.getBlockById(46));
			world.setBlock(i+6, j+11, k+12, Block.getBlockById(46));
			world.setBlock(i+6, j+11, k+13, Block.getBlockById(46));
			world.setBlock(i+6, j+12, k+11, Block.getBlockById(46));
			world.setBlock(i+6, j+12, k+12, Block.getBlockById(46));
			world.setBlock(i+6, j+12, k+13, Block.getBlockById(46));
			world.setBlock(i+6, j+13, k+11, Block.getBlockById(46));
			world.setBlock(i+6, j+13, k+12, Block.getBlockById(46));
			world.setBlock(i+6, j+13, k+13, Block.getBlockById(46));
			world.setBlock(i+6, j+14, k+12, Block.getBlockById(46));
			world.setBlock(i+14, j+16, k+0, Block.getBlockById(35));
			world.setBlockMetadataWithNotify(i+14, j+16, k+0, 10, 10);
		if(EpicProportionsMod.ENABLE_DEVLOGGING == true){
			
		System.out.println(EpicProportionsMod.MODID + ">> House Of EpicProportions Structure Generated at: " + i2 + "," + k2);
		
		}
		}
	}


	
	
}