package com.jtrent238.epicproportions.worldgen.structures;

import java.util.Random;

import com.jtrent238.epicproportions.EpicProportionsMod;

import cpw.mods.fml.common.IWorldGenerator;
import net.minecraft.block.Block;
import net.minecraft.init.Blocks;
import net.minecraft.tileentity.TileEntityMobSpawner;
import net.minecraft.world.World;
import net.minecraft.world.chunk.IChunkProvider;
import net.minecraft.world.gen.feature.WorldGenerator;



public class WorldGenBomby extends WorldGenerator implements IWorldGenerator
{
    public boolean generate(World world, Random par2Random, int i, int j, int k)
    {
        while (world.isAirBlock(i, j, k) && j > 2000)
        {
            --j;
        }

    	
    	if(EpicProportionsMod.ENABLE_DEVLOGGING == true){
			
    		System.out.println(EpicProportionsMod.MODID + ">> Bomby Structure Generated at: X" + i + ", Y" + j + "," + k);
    		
    		}
    	
        return true;
    }

    private void generateSpawner(World world, int x, int y, int z, String entityName) {
		world.setBlock(x, y, z, Blocks.mob_spawner);
		TileEntityMobSpawner spawner = (TileEntityMobSpawner) world.getTileEntity(x, y, z);
		spawner.func_145881_a().setEntityName(entityName);
		//Logger.info("%s spawner at %d %d %d", entityName, x, y, z);
	}
    public void generate(Random random, int i2, int k2, World world, IChunkProvider chunkGenerator,
			IChunkProvider chunkProvider) {
		

		int i = i2 + random.nextInt(15);
		int k = k2 + random.nextInt(15);
		int j = world.getHeightValue(i, k) - 1;
		//int i = chunkX;
		//int j = 0;
		//int k = chunkZ;
		world.getHeightValue(j, j);
		
		while (world.isAirBlock(i, j, k) && j > 2000)
        {
            --j;
        }
		
		if(random.nextInt(100) < 0.15){
			

			world.setBlock(i+0, j+0, k+0, Block.getBlockById(133));
			world.setBlock(i+1, j+0, k+0, Block.getBlockById(133));
			world.setBlock(i+2, j+0, k+0, Block.getBlockById(133));
			world.setBlock(i+7, j+0, k+0, Block.getBlockById(133));
			world.setBlock(i+8, j+0, k+0, Block.getBlockById(133));
			world.setBlock(i+9, j+0, k+0, Block.getBlockById(133));
			world.setBlock(i+0, j+0, k+1, Block.getBlockById(133));
			world.setBlock(i+1, j+0, k+1, Block.getBlockById(133));
			world.setBlock(i+2, j+0, k+1, Block.getBlockById(133));
			world.setBlock(i+7, j+0, k+1, Block.getBlockById(133));
			world.setBlock(i+8, j+0, k+1, Block.getBlockById(133));
			world.setBlock(i+9, j+0, k+1, Block.getBlockById(133));
			world.setBlock(i+0, j+0, k+2, Block.getBlockById(133));
			world.setBlock(i+1, j+0, k+2, Block.getBlockById(133));
			world.setBlock(i+2, j+0, k+2, Block.getBlockById(133));
			world.setBlock(i+7, j+0, k+2, Block.getBlockById(133));
			world.setBlock(i+8, j+0, k+2, Block.getBlockById(133));
			world.setBlock(i+9, j+0, k+2, Block.getBlockById(133));
			world.setBlock(i+0, j+0, k+7, Block.getBlockById(133));
			world.setBlock(i+1, j+0, k+7, Block.getBlockById(133));
			world.setBlock(i+2, j+0, k+7, Block.getBlockById(133));
			world.setBlock(i+7, j+0, k+7, Block.getBlockById(133));
			world.setBlock(i+8, j+0, k+7, Block.getBlockById(133));
			world.setBlock(i+9, j+0, k+7, Block.getBlockById(133));
			world.setBlock(i+0, j+0, k+8, Block.getBlockById(133));
			world.setBlock(i+1, j+0, k+8, Block.getBlockById(133));
			world.setBlock(i+2, j+0, k+8, Block.getBlockById(133));
			world.setBlock(i+7, j+0, k+8, Block.getBlockById(133));
			world.setBlock(i+8, j+0, k+8, Block.getBlockById(133));
			world.setBlock(i+9, j+0, k+8, Block.getBlockById(133));
			world.setBlock(i+0, j+0, k+9, Block.getBlockById(133));
			world.setBlock(i+1, j+0, k+9, Block.getBlockById(133));
			world.setBlock(i+2, j+0, k+9, Block.getBlockById(133));
			world.setBlock(i+7, j+0, k+9, Block.getBlockById(133));
			world.setBlock(i+8, j+0, k+9, Block.getBlockById(133));
			world.setBlock(i+9, j+0, k+9, Block.getBlockById(133));
			world.setBlock(i+0, j+1, k+0, Block.getBlockById(133));
			world.setBlock(i+1, j+1, k+0, Block.getBlockById(133));
			world.setBlock(i+2, j+1, k+0, Block.getBlockById(133));
			world.setBlock(i+7, j+1, k+0, Block.getBlockById(133));
			world.setBlock(i+8, j+1, k+0, Block.getBlockById(133));
			world.setBlock(i+9, j+1, k+0, Block.getBlockById(133));
			world.setBlock(i+0, j+1, k+1, Block.getBlockById(133));
			world.setBlock(i+1, j+1, k+1, Block.getBlockById(52));
			world.setBlock(i+2, j+1, k+1, Block.getBlockById(133));
			world.setBlock(i+7, j+1, k+1, Block.getBlockById(133));
			world.setBlock(i+8, j+1, k+1, Block.getBlockById(52));
			world.setBlock(i+9, j+1, k+1, Block.getBlockById(133));
			world.setBlock(i+0, j+1, k+2, Block.getBlockById(133));
			world.setBlock(i+1, j+1, k+2, Block.getBlockById(133));
			world.setBlock(i+2, j+1, k+2, Block.getBlockById(133));
			world.setBlock(i+7, j+1, k+2, Block.getBlockById(133));
			world.setBlock(i+8, j+1, k+2, Block.getBlockById(133));
			world.setBlock(i+9, j+1, k+2, Block.getBlockById(133));
			world.setBlock(i+0, j+1, k+7, Block.getBlockById(133));
			world.setBlock(i+1, j+1, k+7, Block.getBlockById(133));
			world.setBlock(i+2, j+1, k+7, Block.getBlockById(133));
			world.setBlock(i+7, j+1, k+7, Block.getBlockById(133));
			world.setBlock(i+8, j+1, k+7, Block.getBlockById(133));
			world.setBlock(i+9, j+1, k+7, Block.getBlockById(133));
			world.setBlock(i+0, j+1, k+8, Block.getBlockById(133));
			world.setBlock(i+1, j+1, k+8, Block.getBlockById(52));
			world.setBlock(i+2, j+1, k+8, Block.getBlockById(133));
			world.setBlock(i+7, j+1, k+8, Block.getBlockById(133));
			world.setBlock(i+8, j+1, k+8, Block.getBlockById(52));
			world.setBlock(i+9, j+1, k+8, Block.getBlockById(133));
			world.setBlock(i+0, j+1, k+9, Block.getBlockById(133));
			world.setBlock(i+1, j+1, k+9, Block.getBlockById(133));
			world.setBlock(i+2, j+1, k+9, Block.getBlockById(133));
			world.setBlock(i+7, j+1, k+9, Block.getBlockById(133));
			world.setBlock(i+8, j+1, k+9, Block.getBlockById(133));
			world.setBlock(i+9, j+1, k+9, Block.getBlockById(133));
			world.setBlock(i+0, j+2, k+0, Block.getBlockById(133));
			world.setBlock(i+1, j+2, k+0, Block.getBlockById(133));
			world.setBlock(i+2, j+2, k+0, Block.getBlockById(133));
			world.setBlock(i+7, j+2, k+0, Block.getBlockById(133));
			world.setBlock(i+8, j+2, k+0, Block.getBlockById(133));
			world.setBlock(i+9, j+2, k+0, Block.getBlockById(133));
			world.setBlock(i+0, j+2, k+1, Block.getBlockById(133));
			world.setBlock(i+1, j+2, k+1, Block.getBlockById(133));
			world.setBlock(i+2, j+2, k+1, Block.getBlockById(133));
			world.setBlock(i+7, j+2, k+1, Block.getBlockById(133));
			world.setBlock(i+8, j+2, k+1, Block.getBlockById(133));
			world.setBlock(i+9, j+2, k+1, Block.getBlockById(133));
			world.setBlock(i+0, j+2, k+2, Block.getBlockById(133));
			world.setBlock(i+1, j+2, k+2, Block.getBlockById(133));
			world.setBlock(i+2, j+2, k+2, Block.getBlockById(133));
			world.setBlock(i+7, j+2, k+2, Block.getBlockById(133));
			world.setBlock(i+8, j+2, k+2, Block.getBlockById(133));
			world.setBlock(i+9, j+2, k+2, Block.getBlockById(133));
			world.setBlock(i+3, j+2, k+3, Block.getBlockById(133));
			world.setBlock(i+4, j+2, k+3, Block.getBlockById(133));
			world.setBlock(i+5, j+2, k+3, Block.getBlockById(133));
			world.setBlock(i+6, j+2, k+3, Block.getBlockById(133));
			world.setBlock(i+3, j+2, k+4, Block.getBlockById(133));
			world.setBlock(i+4, j+2, k+4, Block.getBlockById(133));
			world.setBlock(i+5, j+2, k+4, Block.getBlockById(133));
			world.setBlock(i+6, j+2, k+4, Block.getBlockById(133));
			world.setBlock(i+3, j+2, k+5, Block.getBlockById(133));
			world.setBlock(i+4, j+2, k+5, Block.getBlockById(133));
			world.setBlock(i+5, j+2, k+5, Block.getBlockById(133));
			world.setBlock(i+6, j+2, k+5, Block.getBlockById(133));
			world.setBlock(i+3, j+2, k+6, Block.getBlockById(133));
			world.setBlock(i+4, j+2, k+6, Block.getBlockById(133));
			world.setBlock(i+5, j+2, k+6, Block.getBlockById(133));
			world.setBlock(i+6, j+2, k+6, Block.getBlockById(133));
			world.setBlock(i+0, j+2, k+7, Block.getBlockById(133));
			world.setBlock(i+1, j+2, k+7, Block.getBlockById(133));
			world.setBlock(i+2, j+2, k+7, Block.getBlockById(133));
			world.setBlock(i+7, j+2, k+7, Block.getBlockById(133));
			world.setBlock(i+8, j+2, k+7, Block.getBlockById(133));
			world.setBlock(i+9, j+2, k+7, Block.getBlockById(133));
			world.setBlock(i+0, j+2, k+8, Block.getBlockById(133));
			world.setBlock(i+1, j+2, k+8, Block.getBlockById(133));
			world.setBlock(i+2, j+2, k+8, Block.getBlockById(133));
			world.setBlock(i+7, j+2, k+8, Block.getBlockById(133));
			world.setBlock(i+8, j+2, k+8, Block.getBlockById(133));
			world.setBlock(i+9, j+2, k+8, Block.getBlockById(133));
			world.setBlock(i+0, j+2, k+9, Block.getBlockById(133));
			world.setBlock(i+1, j+2, k+9, Block.getBlockById(133));
			world.setBlock(i+2, j+2, k+9, Block.getBlockById(133));
			world.setBlock(i+7, j+2, k+9, Block.getBlockById(133));
			world.setBlock(i+8, j+2, k+9, Block.getBlockById(133));
			world.setBlock(i+9, j+2, k+9, Block.getBlockById(133));
			world.setBlock(i+3, j+3, k+3, Block.getBlockById(133));
			world.setBlock(i+4, j+3, k+3, Block.getBlockById(64));
			world.setBlockMetadataWithNotify(i+4, j+3, k+3, 1, 1);
			world.setBlock(i+5, j+3, k+3, Block.getBlockById(64));
			world.setBlockMetadataWithNotify(i+5, j+3, k+3, 1, 1);
			world.setBlock(i+6, j+3, k+3, Block.getBlockById(133));
			world.setBlock(i+3, j+3, k+4, Block.getBlockById(133));
			world.setBlock(i+4, j+3, k+4, Block.getBlockById(65));
			world.setBlockMetadataWithNotify(i+4, j+3, k+4, 5, 5);
			world.setBlock(i+5, j+3, k+4, Block.getBlockById(65));
			world.setBlockMetadataWithNotify(i+5, j+3, k+4, 4, 4);
			world.setBlock(i+6, j+3, k+4, Block.getBlockById(133));
			world.setBlock(i+3, j+3, k+5, Block.getBlockById(133));
			world.setBlock(i+4, j+3, k+5, Block.getBlockById(65));
			world.setBlockMetadataWithNotify(i+4, j+3, k+5, 5, 5);
			world.setBlock(i+5, j+3, k+5, Block.getBlockById(65));
			world.setBlockMetadataWithNotify(i+5, j+3, k+5, 4, 4);
			world.setBlock(i+6, j+3, k+5, Block.getBlockById(133));
			world.setBlock(i+3, j+3, k+6, Block.getBlockById(133));
			world.setBlock(i+4, j+3, k+6, Block.getBlockById(64));
			world.setBlockMetadataWithNotify(i+4, j+3, k+6, 3, 3);
			world.setBlock(i+5, j+3, k+6, Block.getBlockById(64));
			world.setBlockMetadataWithNotify(i+5, j+3, k+6, 3, 3);
			world.setBlock(i+6, j+3, k+6, Block.getBlockById(133));
			world.setBlock(i+3, j+4, k+3, Block.getBlockById(133));
			world.setBlock(i+4, j+4, k+3, Block.getBlockById(64));
			world.setBlockMetadataWithNotify(i+4, j+4, k+3, 9, 9);
			world.setBlock(i+5, j+4, k+3, Block.getBlockById(64));
			world.setBlockMetadataWithNotify(i+5, j+4, k+3, 8, 8);
			world.setBlock(i+6, j+4, k+3, Block.getBlockById(133));
			world.setBlock(i+3, j+4, k+4, Block.getBlockById(133));
			world.setBlock(i+4, j+4, k+4, Block.getBlockById(65));
			world.setBlockMetadataWithNotify(i+4, j+4, k+4, 5, 5);
			world.setBlock(i+5, j+4, k+4, Block.getBlockById(65));
			world.setBlockMetadataWithNotify(i+5, j+4, k+4, 4, 4);
			world.setBlock(i+6, j+4, k+4, Block.getBlockById(133));
			world.setBlock(i+3, j+4, k+5, Block.getBlockById(133));
			world.setBlock(i+4, j+4, k+5, Block.getBlockById(65));
			world.setBlockMetadataWithNotify(i+4, j+4, k+5, 5, 5);
			world.setBlock(i+5, j+4, k+5, Block.getBlockById(65));
			world.setBlockMetadataWithNotify(i+5, j+4, k+5, 4, 4);
			world.setBlock(i+6, j+4, k+5, Block.getBlockById(133));
			world.setBlock(i+3, j+4, k+6, Block.getBlockById(133));
			world.setBlock(i+4, j+4, k+6, Block.getBlockById(64));
			world.setBlockMetadataWithNotify(i+4, j+4, k+6, 8, 8);
			world.setBlock(i+5, j+4, k+6, Block.getBlockById(64));
			world.setBlockMetadataWithNotify(i+5, j+4, k+6, 9, 9);
			world.setBlock(i+6, j+4, k+6, Block.getBlockById(133));
			world.setBlock(i+3, j+5, k+3, Block.getBlockById(133));
			world.setBlock(i+4, j+5, k+3, Block.getBlockById(133));
			world.setBlock(i+5, j+5, k+3, Block.getBlockById(133));
			world.setBlock(i+6, j+5, k+3, Block.getBlockById(133));
			world.setBlock(i+3, j+5, k+4, Block.getBlockById(133));
			world.setBlock(i+4, j+5, k+4, Block.getBlockById(65));
			world.setBlockMetadataWithNotify(i+4, j+5, k+4, 5, 5);
			world.setBlock(i+5, j+5, k+4, Block.getBlockById(65));
			world.setBlockMetadataWithNotify(i+5, j+5, k+4, 4, 4);
			world.setBlock(i+6, j+5, k+4, Block.getBlockById(133));
			world.setBlock(i+3, j+5, k+5, Block.getBlockById(133));
			world.setBlock(i+4, j+5, k+5, Block.getBlockById(65));
			world.setBlockMetadataWithNotify(i+4, j+5, k+5, 5, 5);
			world.setBlock(i+5, j+5, k+5, Block.getBlockById(65));
			world.setBlockMetadataWithNotify(i+5, j+5, k+5, 4, 4);
			world.setBlock(i+6, j+5, k+5, Block.getBlockById(133));
			world.setBlock(i+3, j+5, k+6, Block.getBlockById(133));
			world.setBlock(i+4, j+5, k+6, Block.getBlockById(133));
			world.setBlock(i+5, j+5, k+6, Block.getBlockById(133));
			world.setBlock(i+6, j+5, k+6, Block.getBlockById(133));
			world.setBlock(i+3, j+6, k+3, Block.getBlockById(133));
			world.setBlock(i+4, j+6, k+3, Block.getBlockById(133));
			world.setBlock(i+5, j+6, k+3, Block.getBlockById(133));
			world.setBlock(i+6, j+6, k+3, Block.getBlockById(133));
			world.setBlock(i+3, j+6, k+4, Block.getBlockById(133));
			world.setBlock(i+4, j+6, k+4, Block.getBlockById(65));
			world.setBlockMetadataWithNotify(i+4, j+6, k+4, 5, 5);
			world.setBlock(i+5, j+6, k+4, Block.getBlockById(65));
			world.setBlockMetadataWithNotify(i+5, j+6, k+4, 4, 4);
			world.setBlock(i+6, j+6, k+4, Block.getBlockById(133));
			world.setBlock(i+3, j+6, k+5, Block.getBlockById(133));
			world.setBlock(i+4, j+6, k+5, Block.getBlockById(65));
			world.setBlockMetadataWithNotify(i+4, j+6, k+5, 5, 5);
			world.setBlock(i+5, j+6, k+5, Block.getBlockById(65));
			world.setBlockMetadataWithNotify(i+5, j+6, k+5, 4, 4);
			world.setBlock(i+6, j+6, k+5, Block.getBlockById(133));
			world.setBlock(i+3, j+6, k+6, Block.getBlockById(133));
			world.setBlock(i+4, j+6, k+6, Block.getBlockById(133));
			world.setBlock(i+5, j+6, k+6, Block.getBlockById(133));
			world.setBlock(i+6, j+6, k+6, Block.getBlockById(133));
			world.setBlock(i+3, j+7, k+3, Block.getBlockById(133));
			world.setBlock(i+4, j+7, k+3, Block.getBlockById(133));
			world.setBlock(i+5, j+7, k+3, Block.getBlockById(133));
			world.setBlock(i+6, j+7, k+3, Block.getBlockById(133));
			world.setBlock(i+3, j+7, k+4, Block.getBlockById(133));
			world.setBlock(i+4, j+7, k+4, Block.getBlockById(65));
			world.setBlockMetadataWithNotify(i+4, j+7, k+4, 5, 5);
			world.setBlock(i+5, j+7, k+4, Block.getBlockById(65));
			world.setBlockMetadataWithNotify(i+5, j+7, k+4, 4, 4);
			world.setBlock(i+6, j+7, k+4, Block.getBlockById(133));
			world.setBlock(i+3, j+7, k+5, Block.getBlockById(133));
			world.setBlock(i+4, j+7, k+5, Block.getBlockById(65));
			world.setBlockMetadataWithNotify(i+4, j+7, k+5, 5, 5);
			world.setBlock(i+5, j+7, k+5, Block.getBlockById(65));
			world.setBlockMetadataWithNotify(i+5, j+7, k+5, 4, 4);
			world.setBlock(i+6, j+7, k+5, Block.getBlockById(133));
			world.setBlock(i+3, j+7, k+6, Block.getBlockById(133));
			world.setBlock(i+4, j+7, k+6, Block.getBlockById(133));
			world.setBlock(i+5, j+7, k+6, Block.getBlockById(133));
			world.setBlock(i+6, j+7, k+6, Block.getBlockById(133));
			world.setBlock(i+3, j+8, k+3, Block.getBlockById(133));
			world.setBlock(i+4, j+8, k+3, Block.getBlockById(133));
			world.setBlock(i+5, j+8, k+3, Block.getBlockById(133));
			world.setBlock(i+6, j+8, k+3, Block.getBlockById(133));
			world.setBlock(i+3, j+8, k+4, Block.getBlockById(133));
			world.setBlock(i+4, j+8, k+4, Block.getBlockById(65));
			world.setBlockMetadataWithNotify(i+4, j+8, k+4, 5, 5);
			world.setBlock(i+5, j+8, k+4, Block.getBlockById(65));
			world.setBlockMetadataWithNotify(i+5, j+8, k+4, 4, 4);
			world.setBlock(i+6, j+8, k+4, Block.getBlockById(133));
			world.setBlock(i+3, j+8, k+5, Block.getBlockById(133));
			world.setBlock(i+4, j+8, k+5, Block.getBlockById(65));
			world.setBlockMetadataWithNotify(i+4, j+8, k+5, 5, 5);
			world.setBlock(i+5, j+8, k+5, Block.getBlockById(65));
			world.setBlockMetadataWithNotify(i+5, j+8, k+5, 4, 4);
			world.setBlock(i+6, j+8, k+5, Block.getBlockById(133));
			world.setBlock(i+3, j+8, k+6, Block.getBlockById(133));
			world.setBlock(i+4, j+8, k+6, Block.getBlockById(133));
			world.setBlock(i+5, j+8, k+6, Block.getBlockById(133));
			world.setBlock(i+6, j+8, k+6, Block.getBlockById(133));
			world.setBlock(i+3, j+9, k+3, Block.getBlockById(133));
			world.setBlock(i+4, j+9, k+3, Block.getBlockById(133));
			world.setBlock(i+5, j+9, k+3, Block.getBlockById(133));
			world.setBlock(i+6, j+9, k+3, Block.getBlockById(133));
			world.setBlock(i+3, j+9, k+4, Block.getBlockById(133));
			world.setBlock(i+4, j+9, k+4, Block.getBlockById(65));
			world.setBlockMetadataWithNotify(i+4, j+9, k+4, 5, 5);
			world.setBlock(i+5, j+9, k+4, Block.getBlockById(65));
			world.setBlockMetadataWithNotify(i+5, j+9, k+4, 4, 4);
			world.setBlock(i+6, j+9, k+4, Block.getBlockById(133));
			world.setBlock(i+3, j+9, k+5, Block.getBlockById(133));
			world.setBlock(i+4, j+9, k+5, Block.getBlockById(65));
			world.setBlockMetadataWithNotify(i+4, j+9, k+5, 5, 5);
			world.setBlock(i+5, j+9, k+5, Block.getBlockById(65));
			world.setBlockMetadataWithNotify(i+5, j+9, k+5, 4, 4);
			world.setBlock(i+6, j+9, k+5, Block.getBlockById(133));
			world.setBlock(i+3, j+9, k+6, Block.getBlockById(133));
			world.setBlock(i+4, j+9, k+6, Block.getBlockById(133));
			world.setBlock(i+5, j+9, k+6, Block.getBlockById(133));
			world.setBlock(i+6, j+9, k+6, Block.getBlockById(133));
			world.setBlock(i+1, j+10, k+1, Block.getBlockById(133));
			world.setBlock(i+2, j+10, k+1, Block.getBlockById(133));
			world.setBlock(i+3, j+10, k+1, Block.getBlockById(133));
			world.setBlock(i+4, j+10, k+1, Block.getBlockById(133));
			world.setBlock(i+5, j+10, k+1, Block.getBlockById(133));
			world.setBlock(i+6, j+10, k+1, Block.getBlockById(133));
			world.setBlock(i+7, j+10, k+1, Block.getBlockById(133));
			world.setBlock(i+8, j+10, k+1, Block.getBlockById(133));
			world.setBlock(i+1, j+10, k+2, Block.getBlockById(133));
			world.setBlock(i+2, j+10, k+2, Block.getBlockById(133));
			world.setBlock(i+3, j+10, k+2, Block.getBlockById(133));
			world.setBlock(i+4, j+10, k+2, Block.getBlockById(133));
			world.setBlock(i+5, j+10, k+2, Block.getBlockById(133));
			world.setBlock(i+6, j+10, k+2, Block.getBlockById(133));
			world.setBlock(i+7, j+10, k+2, Block.getBlockById(133));
			world.setBlock(i+8, j+10, k+2, Block.getBlockById(133));
			world.setBlock(i+1, j+10, k+3, Block.getBlockById(133));
			world.setBlock(i+2, j+10, k+3, Block.getBlockById(133));
			world.setBlock(i+3, j+10, k+3, Block.getBlockById(133));
			world.setBlock(i+4, j+10, k+3, Block.getBlockById(133));
			world.setBlock(i+5, j+10, k+3, Block.getBlockById(133));
			world.setBlock(i+6, j+10, k+3, Block.getBlockById(133));
			world.setBlock(i+7, j+10, k+3, Block.getBlockById(133));
			world.setBlock(i+8, j+10, k+3, Block.getBlockById(133));
			world.setBlock(i+1, j+10, k+4, Block.getBlockById(133));
			world.setBlock(i+2, j+10, k+4, Block.getBlockById(133));
			world.setBlock(i+3, j+10, k+4, Block.getBlockById(133));
			world.setBlock(i+4, j+10, k+4, Block.getBlockById(65));
			world.setBlockMetadataWithNotify(i+4, j+10, k+4, 5, 5);
			world.setBlock(i+5, j+10, k+4, Block.getBlockById(65));
			world.setBlockMetadataWithNotify(i+5, j+10, k+4, 4, 4);
			world.setBlock(i+6, j+10, k+4, Block.getBlockById(133));
			world.setBlock(i+7, j+10, k+4, Block.getBlockById(133));
			world.setBlock(i+8, j+10, k+4, Block.getBlockById(133));
			world.setBlock(i+1, j+10, k+5, Block.getBlockById(133));
			world.setBlock(i+2, j+10, k+5, Block.getBlockById(133));
			world.setBlock(i+3, j+10, k+5, Block.getBlockById(133));
			world.setBlock(i+4, j+10, k+5, Block.getBlockById(65));
			world.setBlockMetadataWithNotify(i+4, j+10, k+5, 5, 5);
			world.setBlock(i+5, j+10, k+5, Block.getBlockById(65));
			world.setBlockMetadataWithNotify(i+5, j+10, k+5, 4, 4);
			world.setBlock(i+6, j+10, k+5, Block.getBlockById(133));
			world.setBlock(i+7, j+10, k+5, Block.getBlockById(133));
			world.setBlock(i+8, j+10, k+5, Block.getBlockById(133));
			world.setBlock(i+1, j+10, k+6, Block.getBlockById(133));
			world.setBlock(i+2, j+10, k+6, Block.getBlockById(133));
			world.setBlock(i+3, j+10, k+6, Block.getBlockById(133));
			world.setBlock(i+4, j+10, k+6, Block.getBlockById(133));
			world.setBlock(i+5, j+10, k+6, Block.getBlockById(133));
			world.setBlock(i+6, j+10, k+6, Block.getBlockById(133));
			world.setBlock(i+7, j+10, k+6, Block.getBlockById(133));
			world.setBlock(i+8, j+10, k+6, Block.getBlockById(133));
			world.setBlock(i+1, j+10, k+7, Block.getBlockById(133));
			world.setBlock(i+2, j+10, k+7, Block.getBlockById(133));
			world.setBlock(i+3, j+10, k+7, Block.getBlockById(133));
			world.setBlock(i+4, j+10, k+7, Block.getBlockById(133));
			world.setBlock(i+5, j+10, k+7, Block.getBlockById(133));
			world.setBlock(i+6, j+10, k+7, Block.getBlockById(133));
			world.setBlock(i+7, j+10, k+7, Block.getBlockById(133));
			world.setBlock(i+8, j+10, k+7, Block.getBlockById(133));
			world.setBlock(i+1, j+10, k+8, Block.getBlockById(133));
			world.setBlock(i+2, j+10, k+8, Block.getBlockById(133));
			world.setBlock(i+3, j+10, k+8, Block.getBlockById(133));
			world.setBlock(i+4, j+10, k+8, Block.getBlockById(133));
			world.setBlock(i+5, j+10, k+8, Block.getBlockById(133));
			world.setBlock(i+6, j+10, k+8, Block.getBlockById(133));
			world.setBlock(i+7, j+10, k+8, Block.getBlockById(133));
			world.setBlock(i+8, j+10, k+8, Block.getBlockById(133));
			world.setBlock(i+1, j+11, k+1, Block.getBlockById(133));
			world.setBlock(i+2, j+11, k+1, Block.getBlockById(133));
			world.setBlock(i+3, j+11, k+1, Block.getBlockById(133));
			world.setBlock(i+4, j+11, k+1, Block.getBlockById(133));
			world.setBlock(i+5, j+11, k+1, Block.getBlockById(133));
			world.setBlock(i+6, j+11, k+1, Block.getBlockById(133));
			world.setBlock(i+7, j+11, k+1, Block.getBlockById(133));
			world.setBlock(i+8, j+11, k+1, Block.getBlockById(133));
			world.setBlock(i+1, j+11, k+2, Block.getBlockById(133));
			world.setBlock(i+2, j+11, k+2, Block.getBlockById(133));
			world.setBlock(i+3, j+11, k+2, Block.getBlockById(133));
			world.setBlock(i+4, j+11, k+2, Block.getBlockById(133));
			world.setBlock(i+5, j+11, k+2, Block.getBlockById(133));
			world.setBlock(i+6, j+11, k+2, Block.getBlockById(133));
			world.setBlock(i+7, j+11, k+2, Block.getBlockById(133));
			world.setBlock(i+8, j+11, k+2, Block.getBlockById(133));
			world.setBlock(i+1, j+11, k+3, Block.getBlockById(173));
			world.setBlock(i+2, j+11, k+3, Block.getBlockById(133));
			world.setBlock(i+3, j+11, k+3, Block.getBlockById(133));
			world.setBlock(i+4, j+11, k+3, Block.getBlockById(133));
			world.setBlock(i+5, j+11, k+3, Block.getBlockById(133));
			world.setBlock(i+6, j+11, k+3, Block.getBlockById(133));
			world.setBlock(i+7, j+11, k+3, Block.getBlockById(133));
			world.setBlock(i+8, j+11, k+3, Block.getBlockById(133));
			world.setBlock(i+1, j+11, k+4, Block.getBlockById(133));
			world.setBlock(i+2, j+11, k+4, Block.getBlockById(133));
			world.setBlock(i+3, j+11, k+4, Block.getBlockById(133));
			world.setBlock(i+4, j+11, k+4, Block.getBlockById(65));
			world.setBlockMetadataWithNotify(i+4, j+11, k+4, 5, 5);
			world.setBlock(i+5, j+11, k+4, Block.getBlockById(65));
			world.setBlockMetadataWithNotify(i+5, j+11, k+4, 4, 4);
			world.setBlock(i+6, j+11, k+4, Block.getBlockById(133));
			world.setBlock(i+7, j+11, k+4, Block.getBlockById(133));
			world.setBlock(i+8, j+11, k+4, Block.getBlockById(133));
			world.setBlock(i+1, j+11, k+5, Block.getBlockById(133));
			world.setBlock(i+2, j+11, k+5, Block.getBlockById(133));
			world.setBlock(i+3, j+11, k+5, Block.getBlockById(133));
			world.setBlock(i+4, j+11, k+5, Block.getBlockById(65));
			world.setBlockMetadataWithNotify(i+4, j+11, k+5, 5, 5);
			world.setBlock(i+5, j+11, k+5, Block.getBlockById(65));
			world.setBlockMetadataWithNotify(i+5, j+11, k+5, 4, 4);
			world.setBlock(i+6, j+11, k+5, Block.getBlockById(133));
			world.setBlock(i+7, j+11, k+5, Block.getBlockById(133));
			world.setBlock(i+8, j+11, k+5, Block.getBlockById(133));
			world.setBlock(i+1, j+11, k+6, Block.getBlockById(173));
			world.setBlock(i+2, j+11, k+6, Block.getBlockById(133));
			world.setBlock(i+3, j+11, k+6, Block.getBlockById(133));
			world.setBlock(i+4, j+11, k+6, Block.getBlockById(133));
			world.setBlock(i+5, j+11, k+6, Block.getBlockById(133));
			world.setBlock(i+6, j+11, k+6, Block.getBlockById(133));
			world.setBlock(i+7, j+11, k+6, Block.getBlockById(133));
			world.setBlock(i+8, j+11, k+6, Block.getBlockById(133));
			world.setBlock(i+1, j+11, k+7, Block.getBlockById(133));
			world.setBlock(i+2, j+11, k+7, Block.getBlockById(133));
			world.setBlock(i+3, j+11, k+7, Block.getBlockById(133));
			world.setBlock(i+4, j+11, k+7, Block.getBlockById(133));
			world.setBlock(i+5, j+11, k+7, Block.getBlockById(133));
			world.setBlock(i+6, j+11, k+7, Block.getBlockById(133));
			world.setBlock(i+7, j+11, k+7, Block.getBlockById(133));
			world.setBlock(i+8, j+11, k+7, Block.getBlockById(133));
			world.setBlock(i+1, j+11, k+8, Block.getBlockById(133));
			world.setBlock(i+2, j+11, k+8, Block.getBlockById(133));
			world.setBlock(i+3, j+11, k+8, Block.getBlockById(133));
			world.setBlock(i+4, j+11, k+8, Block.getBlockById(133));
			world.setBlock(i+5, j+11, k+8, Block.getBlockById(133));
			world.setBlock(i+6, j+11, k+8, Block.getBlockById(133));
			world.setBlock(i+7, j+11, k+8, Block.getBlockById(133));
			world.setBlock(i+8, j+11, k+8, Block.getBlockById(133));
			world.setBlock(i+1, j+12, k+1, Block.getBlockById(133));
			world.setBlock(i+2, j+12, k+1, Block.getBlockById(133));
			world.setBlock(i+3, j+12, k+1, Block.getBlockById(133));
			world.setBlock(i+4, j+12, k+1, Block.getBlockById(133));
			world.setBlock(i+5, j+12, k+1, Block.getBlockById(133));
			world.setBlock(i+6, j+12, k+1, Block.getBlockById(133));
			world.setBlock(i+7, j+12, k+1, Block.getBlockById(133));
			world.setBlock(i+8, j+12, k+1, Block.getBlockById(133));
			world.setBlock(i+1, j+12, k+2, Block.getBlockById(133));
			world.setBlock(i+2, j+12, k+2, Block.getBlockById(52));
			world.setBlock(i+3, j+12, k+2, Block.getBlockById(89));
			world.setBlock(i+4, j+12, k+2, Block.getBlockById(54));
			world.setBlockMetadataWithNotify(i+4, j+12, k+2, 3, 3);
			world.setBlock(i+5, j+12, k+2, Block.getBlockById(54));
			world.setBlockMetadataWithNotify(i+5, j+12, k+2, 3, 3);
			world.setBlock(i+6, j+12, k+2, Block.getBlockById(89));
			world.setBlock(i+7, j+12, k+2, Block.getBlockById(52));
			world.setBlock(i+8, j+12, k+2, Block.getBlockById(133));
			world.setBlock(i+1, j+12, k+3, Block.getBlockById(173));
			world.setBlock(i+2, j+12, k+3, Block.getBlockById(89));
			world.setBlock(i+3, j+12, k+3, Block.getBlockById(52));
			world.setBlock(i+6, j+12, k+3, Block.getBlockById(52));
			world.setBlock(i+7, j+12, k+3, Block.getBlockById(89));
			world.setBlock(i+8, j+12, k+3, Block.getBlockById(133));
			world.setBlock(i+1, j+12, k+4, Block.getBlockById(173));
			world.setBlock(i+2, j+12, k+4, Block.getBlockById(54));
			world.setBlockMetadataWithNotify(i+2, j+12, k+4, 5, 5);
			world.setBlock(i+7, j+12, k+4, Block.getBlockById(54));
			world.setBlockMetadataWithNotify(i+7, j+12, k+4, 4, 4);
			world.setBlock(i+8, j+12, k+4, Block.getBlockById(133));
			world.setBlock(i+1, j+12, k+5, Block.getBlockById(173));
			world.setBlock(i+2, j+12, k+5, Block.getBlockById(54));
			world.setBlockMetadataWithNotify(i+2, j+12, k+5, 5, 5);
			world.setBlock(i+7, j+12, k+5, Block.getBlockById(54));
			world.setBlockMetadataWithNotify(i+7, j+12, k+5, 4, 4);
			world.setBlock(i+8, j+12, k+5, Block.getBlockById(133));
			world.setBlock(i+1, j+12, k+6, Block.getBlockById(173));
			world.setBlock(i+2, j+12, k+6, Block.getBlockById(89));
			world.setBlock(i+3, j+12, k+6, Block.getBlockById(52));
			world.setBlock(i+6, j+12, k+6, Block.getBlockById(52));
			world.setBlock(i+7, j+12, k+6, Block.getBlockById(89));
			world.setBlock(i+8, j+12, k+6, Block.getBlockById(133));
			world.setBlock(i+1, j+12, k+7, Block.getBlockById(133));
			world.setBlock(i+2, j+12, k+7, Block.getBlockById(52));
			world.setBlock(i+3, j+12, k+7, Block.getBlockById(89));
			world.setBlock(i+4, j+12, k+7, Block.getBlockById(54));
			world.setBlockMetadataWithNotify(i+4, j+12, k+7, 2, 2);
			world.setBlock(i+5, j+12, k+7, Block.getBlockById(54));
			world.setBlockMetadataWithNotify(i+5, j+12, k+7, 2, 2);
			world.setBlock(i+6, j+12, k+7, Block.getBlockById(89));
			world.setBlock(i+7, j+12, k+7, Block.getBlockById(52));
			world.setBlock(i+8, j+12, k+7, Block.getBlockById(133));
			world.setBlock(i+1, j+12, k+8, Block.getBlockById(133));
			world.setBlock(i+2, j+12, k+8, Block.getBlockById(133));
			world.setBlock(i+3, j+12, k+8, Block.getBlockById(133));
			world.setBlock(i+4, j+12, k+8, Block.getBlockById(133));
			world.setBlock(i+5, j+12, k+8, Block.getBlockById(133));
			world.setBlock(i+6, j+12, k+8, Block.getBlockById(133));
			world.setBlock(i+7, j+12, k+8, Block.getBlockById(133));
			world.setBlock(i+8, j+12, k+8, Block.getBlockById(133));
			world.setBlock(i+1, j+13, k+1, Block.getBlockById(133));
			world.setBlock(i+2, j+13, k+1, Block.getBlockById(133));
			world.setBlock(i+3, j+13, k+1, Block.getBlockById(133));
			world.setBlock(i+4, j+13, k+1, Block.getBlockById(133));
			world.setBlock(i+5, j+13, k+1, Block.getBlockById(133));
			world.setBlock(i+6, j+13, k+1, Block.getBlockById(133));
			world.setBlock(i+7, j+13, k+1, Block.getBlockById(133));
			world.setBlock(i+8, j+13, k+1, Block.getBlockById(133));
			world.setBlock(i+1, j+13, k+2, Block.getBlockById(133));
			world.setBlock(i+2, j+13, k+2, Block.getBlockById(46));
			world.setBlock(i+3, j+13, k+2, Block.getBlockById(89));
			world.setBlock(i+6, j+13, k+2, Block.getBlockById(89));
			world.setBlock(i+7, j+13, k+2, Block.getBlockById(46));
			world.setBlock(i+8, j+13, k+2, Block.getBlockById(133));
			world.setBlock(i+1, j+13, k+3, Block.getBlockById(173));
			world.setBlock(i+2, j+13, k+3, Block.getBlockById(89));
			world.setBlock(i+7, j+13, k+3, Block.getBlockById(89));
			world.setBlock(i+8, j+13, k+3, Block.getBlockById(133));
			world.setBlock(i+1, j+13, k+4, Block.getBlockById(173));
			world.setBlock(i+8, j+13, k+4, Block.getBlockById(133));
			world.setBlock(i+1, j+13, k+5, Block.getBlockById(173));
			world.setBlock(i+8, j+13, k+5, Block.getBlockById(133));
			world.setBlock(i+1, j+13, k+6, Block.getBlockById(173));
			world.setBlock(i+2, j+13, k+6, Block.getBlockById(89));
			world.setBlock(i+7, j+13, k+6, Block.getBlockById(89));
			world.setBlock(i+8, j+13, k+6, Block.getBlockById(133));
			world.setBlock(i+1, j+13, k+7, Block.getBlockById(133));
			world.setBlock(i+2, j+13, k+7, Block.getBlockById(46));
			world.setBlock(i+3, j+13, k+7, Block.getBlockById(89));
			world.setBlock(i+6, j+13, k+7, Block.getBlockById(89));
			world.setBlock(i+7, j+13, k+7, Block.getBlockById(46));
			world.setBlock(i+8, j+13, k+7, Block.getBlockById(133));
			world.setBlock(i+1, j+13, k+8, Block.getBlockById(133));
			world.setBlock(i+2, j+13, k+8, Block.getBlockById(133));
			world.setBlock(i+3, j+13, k+8, Block.getBlockById(133));
			world.setBlock(i+4, j+13, k+8, Block.getBlockById(133));
			world.setBlock(i+5, j+13, k+8, Block.getBlockById(133));
			world.setBlock(i+6, j+13, k+8, Block.getBlockById(133));
			world.setBlock(i+7, j+13, k+8, Block.getBlockById(133));
			world.setBlock(i+8, j+13, k+8, Block.getBlockById(133));
			world.setBlock(i+1, j+14, k+1, Block.getBlockById(133));
			world.setBlock(i+2, j+14, k+1, Block.getBlockById(133));
			world.setBlock(i+3, j+14, k+1, Block.getBlockById(133));
			world.setBlock(i+4, j+14, k+1, Block.getBlockById(133));
			world.setBlock(i+5, j+14, k+1, Block.getBlockById(133));
			world.setBlock(i+6, j+14, k+1, Block.getBlockById(133));
			world.setBlock(i+7, j+14, k+1, Block.getBlockById(133));
			world.setBlock(i+8, j+14, k+1, Block.getBlockById(133));
			world.setBlock(i+1, j+14, k+2, Block.getBlockById(133));
			world.setBlock(i+2, j+14, k+2, Block.getBlockById(46));
			world.setBlock(i+3, j+14, k+2, Block.getBlockById(89));
			world.setBlock(i+6, j+14, k+2, Block.getBlockById(89));
			world.setBlock(i+7, j+14, k+2, Block.getBlockById(46));
			world.setBlock(i+8, j+14, k+2, Block.getBlockById(133));
			world.setBlock(i+1, j+14, k+3, Block.getBlockById(133));
			world.setBlock(i+2, j+14, k+3, Block.getBlockById(89));
			world.setBlock(i+7, j+14, k+3, Block.getBlockById(89));
			world.setBlock(i+8, j+14, k+3, Block.getBlockById(133));
			world.setBlock(i+1, j+14, k+4, Block.getBlockById(173));
			world.setBlock(i+8, j+14, k+4, Block.getBlockById(133));
			world.setBlock(i+1, j+14, k+5, Block.getBlockById(173));
			world.setBlock(i+8, j+14, k+5, Block.getBlockById(133));
			world.setBlock(i+1, j+14, k+6, Block.getBlockById(133));
			world.setBlock(i+2, j+14, k+6, Block.getBlockById(89));
			world.setBlock(i+7, j+14, k+6, Block.getBlockById(89));
			world.setBlock(i+8, j+14, k+6, Block.getBlockById(133));
			world.setBlock(i+1, j+14, k+7, Block.getBlockById(133));
			world.setBlock(i+2, j+14, k+7, Block.getBlockById(46));
			world.setBlock(i+3, j+14, k+7, Block.getBlockById(89));
			world.setBlock(i+6, j+14, k+7, Block.getBlockById(89));
			world.setBlock(i+7, j+14, k+7, Block.getBlockById(46));
			world.setBlock(i+8, j+14, k+7, Block.getBlockById(133));
			world.setBlock(i+1, j+14, k+8, Block.getBlockById(133));
			world.setBlock(i+2, j+14, k+8, Block.getBlockById(133));
			world.setBlock(i+3, j+14, k+8, Block.getBlockById(133));
			world.setBlock(i+4, j+14, k+8, Block.getBlockById(133));
			world.setBlock(i+5, j+14, k+8, Block.getBlockById(133));
			world.setBlock(i+6, j+14, k+8, Block.getBlockById(133));
			world.setBlock(i+7, j+14, k+8, Block.getBlockById(133));
			world.setBlock(i+8, j+14, k+8, Block.getBlockById(133));
			world.setBlock(i+1, j+15, k+1, Block.getBlockById(133));
			world.setBlock(i+2, j+15, k+1, Block.getBlockById(133));
			world.setBlock(i+3, j+15, k+1, Block.getBlockById(133));
			world.setBlock(i+4, j+15, k+1, Block.getBlockById(133));
			world.setBlock(i+5, j+15, k+1, Block.getBlockById(133));
			world.setBlock(i+6, j+15, k+1, Block.getBlockById(133));
			world.setBlock(i+7, j+15, k+1, Block.getBlockById(133));
			world.setBlock(i+8, j+15, k+1, Block.getBlockById(133));
			world.setBlock(i+1, j+15, k+2, Block.getBlockById(173));
			world.setBlock(i+2, j+15, k+2, Block.getBlockById(46));
			world.setBlock(i+3, j+15, k+2, Block.getBlockById(89));
			world.setBlock(i+6, j+15, k+2, Block.getBlockById(89));
			world.setBlock(i+7, j+15, k+2, Block.getBlockById(46));
			world.setBlock(i+8, j+15, k+2, Block.getBlockById(133));
			world.setBlock(i+1, j+15, k+3, Block.getBlockById(173));
			world.setBlock(i+2, j+15, k+3, Block.getBlockById(89));
			world.setBlock(i+7, j+15, k+3, Block.getBlockById(89));
			world.setBlock(i+8, j+15, k+3, Block.getBlockById(133));
			world.setBlock(i+1, j+15, k+4, Block.getBlockById(133));
			world.setBlock(i+8, j+15, k+4, Block.getBlockById(133));
			world.setBlock(i+1, j+15, k+5, Block.getBlockById(133));
			world.setBlock(i+8, j+15, k+5, Block.getBlockById(133));
			world.setBlock(i+1, j+15, k+6, Block.getBlockById(173));
			world.setBlock(i+2, j+15, k+6, Block.getBlockById(89));
			world.setBlock(i+7, j+15, k+6, Block.getBlockById(89));
			world.setBlock(i+8, j+15, k+6, Block.getBlockById(133));
			world.setBlock(i+1, j+15, k+7, Block.getBlockById(173));
			world.setBlock(i+2, j+15, k+7, Block.getBlockById(46));
			world.setBlock(i+3, j+15, k+7, Block.getBlockById(89));
			world.setBlock(i+6, j+15, k+7, Block.getBlockById(89));
			world.setBlock(i+7, j+15, k+7, Block.getBlockById(46));
			world.setBlock(i+8, j+15, k+7, Block.getBlockById(133));
			world.setBlock(i+1, j+15, k+8, Block.getBlockById(133));
			world.setBlock(i+2, j+15, k+8, Block.getBlockById(133));
			world.setBlock(i+3, j+15, k+8, Block.getBlockById(133));
			world.setBlock(i+4, j+15, k+8, Block.getBlockById(133));
			world.setBlock(i+5, j+15, k+8, Block.getBlockById(133));
			world.setBlock(i+6, j+15, k+8, Block.getBlockById(133));
			world.setBlock(i+7, j+15, k+8, Block.getBlockById(133));
			world.setBlock(i+8, j+15, k+8, Block.getBlockById(133));
			world.setBlock(i+1, j+16, k+1, Block.getBlockById(133));
			world.setBlock(i+2, j+16, k+1, Block.getBlockById(133));
			world.setBlock(i+3, j+16, k+1, Block.getBlockById(133));
			world.setBlock(i+4, j+16, k+1, Block.getBlockById(133));
			world.setBlock(i+5, j+16, k+1, Block.getBlockById(133));
			world.setBlock(i+6, j+16, k+1, Block.getBlockById(133));
			world.setBlock(i+7, j+16, k+1, Block.getBlockById(133));
			world.setBlock(i+8, j+16, k+1, Block.getBlockById(133));
			world.setBlock(i+1, j+16, k+2, Block.getBlockById(173));
			world.setBlock(i+2, j+16, k+2, Block.getBlockById(46));
			world.setBlock(i+3, j+16, k+2, Block.getBlockById(89));
			world.setBlock(i+6, j+16, k+2, Block.getBlockById(89));
			world.setBlock(i+7, j+16, k+2, Block.getBlockById(46));
			world.setBlock(i+8, j+16, k+2, Block.getBlockById(133));
			world.setBlock(i+1, j+16, k+3, Block.getBlockById(173));
			world.setBlock(i+2, j+16, k+3, Block.getBlockById(89));
			world.setBlock(i+7, j+16, k+3, Block.getBlockById(89));
			world.setBlock(i+8, j+16, k+3, Block.getBlockById(133));
			world.setBlock(i+1, j+16, k+4, Block.getBlockById(133));
			world.setBlock(i+8, j+16, k+4, Block.getBlockById(133));
			world.setBlock(i+1, j+16, k+5, Block.getBlockById(133));
			world.setBlock(i+8, j+16, k+5, Block.getBlockById(133));
			world.setBlock(i+1, j+16, k+6, Block.getBlockById(173));
			world.setBlock(i+2, j+16, k+6, Block.getBlockById(89));
			world.setBlock(i+7, j+16, k+6, Block.getBlockById(89));
			world.setBlock(i+8, j+16, k+6, Block.getBlockById(133));
			world.setBlock(i+1, j+16, k+7, Block.getBlockById(173));
			world.setBlock(i+2, j+16, k+7, Block.getBlockById(46));
			world.setBlock(i+3, j+16, k+7, Block.getBlockById(89));
			world.setBlock(i+6, j+16, k+7, Block.getBlockById(89));
			world.setBlock(i+7, j+16, k+7, Block.getBlockById(46));
			world.setBlock(i+8, j+16, k+7, Block.getBlockById(133));
			world.setBlock(i+1, j+16, k+8, Block.getBlockById(133));
			world.setBlock(i+2, j+16, k+8, Block.getBlockById(133));
			world.setBlock(i+3, j+16, k+8, Block.getBlockById(133));
			world.setBlock(i+4, j+16, k+8, Block.getBlockById(133));
			world.setBlock(i+5, j+16, k+8, Block.getBlockById(133));
			world.setBlock(i+6, j+16, k+8, Block.getBlockById(133));
			world.setBlock(i+7, j+16, k+8, Block.getBlockById(133));
			world.setBlock(i+8, j+16, k+8, Block.getBlockById(133));
			world.setBlock(i+1, j+17, k+1, Block.getBlockById(133));
			world.setBlock(i+2, j+17, k+1, Block.getBlockById(133));
			world.setBlock(i+3, j+17, k+1, Block.getBlockById(133));
			world.setBlock(i+4, j+17, k+1, Block.getBlockById(133));
			world.setBlock(i+5, j+17, k+1, Block.getBlockById(133));
			world.setBlock(i+6, j+17, k+1, Block.getBlockById(133));
			world.setBlock(i+7, j+17, k+1, Block.getBlockById(133));
			world.setBlock(i+8, j+17, k+1, Block.getBlockById(133));
			world.setBlock(i+1, j+17, k+2, Block.getBlockById(133));
			world.setBlock(i+2, j+17, k+2, Block.getBlockById(133));
			world.setBlock(i+3, j+17, k+2, Block.getBlockById(133));
			world.setBlock(i+4, j+17, k+2, Block.getBlockById(133));
			world.setBlock(i+5, j+17, k+2, Block.getBlockById(133));
			world.setBlock(i+6, j+17, k+2, Block.getBlockById(133));
			world.setBlock(i+7, j+17, k+2, Block.getBlockById(133));
			world.setBlock(i+8, j+17, k+2, Block.getBlockById(133));
			world.setBlock(i+1, j+17, k+3, Block.getBlockById(133));
			world.setBlock(i+2, j+17, k+3, Block.getBlockById(133));
			world.setBlock(i+3, j+17, k+3, Block.getBlockById(133));
			world.setBlock(i+4, j+17, k+3, Block.getBlockById(133));
			world.setBlock(i+5, j+17, k+3, Block.getBlockById(133));
			world.setBlock(i+6, j+17, k+3, Block.getBlockById(133));
			world.setBlock(i+7, j+17, k+3, Block.getBlockById(133));
			world.setBlock(i+8, j+17, k+3, Block.getBlockById(133));
			world.setBlock(i+1, j+17, k+4, Block.getBlockById(133));
			world.setBlock(i+2, j+17, k+4, Block.getBlockById(133));
			world.setBlock(i+3, j+17, k+4, Block.getBlockById(133));
			world.setBlock(i+4, j+17, k+4, Block.getBlockById(133));
			world.setBlock(i+5, j+17, k+4, Block.getBlockById(133));
			world.setBlock(i+6, j+17, k+4, Block.getBlockById(133));
			world.setBlock(i+7, j+17, k+4, Block.getBlockById(133));
			world.setBlock(i+8, j+17, k+4, Block.getBlockById(133));
			world.setBlock(i+1, j+17, k+5, Block.getBlockById(133));
			world.setBlock(i+2, j+17, k+5, Block.getBlockById(133));
			world.setBlock(i+3, j+17, k+5, Block.getBlockById(133));
			world.setBlock(i+4, j+17, k+5, Block.getBlockById(133));
			world.setBlock(i+5, j+17, k+5, Block.getBlockById(133));
			world.setBlock(i+6, j+17, k+5, Block.getBlockById(133));
			world.setBlock(i+7, j+17, k+5, Block.getBlockById(133));
			world.setBlock(i+8, j+17, k+5, Block.getBlockById(133));
			world.setBlock(i+1, j+17, k+6, Block.getBlockById(133));
			world.setBlock(i+2, j+17, k+6, Block.getBlockById(133));
			world.setBlock(i+3, j+17, k+6, Block.getBlockById(133));
			world.setBlock(i+4, j+17, k+6, Block.getBlockById(133));
			world.setBlock(i+5, j+17, k+6, Block.getBlockById(133));
			world.setBlock(i+6, j+17, k+6, Block.getBlockById(133));
			world.setBlock(i+7, j+17, k+6, Block.getBlockById(133));
			world.setBlock(i+8, j+17, k+6, Block.getBlockById(133));
			world.setBlock(i+1, j+17, k+7, Block.getBlockById(133));
			world.setBlock(i+2, j+17, k+7, Block.getBlockById(133));
			world.setBlock(i+3, j+17, k+7, Block.getBlockById(133));
			world.setBlock(i+4, j+17, k+7, Block.getBlockById(133));
			world.setBlock(i+5, j+17, k+7, Block.getBlockById(133));
			world.setBlock(i+6, j+17, k+7, Block.getBlockById(133));
			world.setBlock(i+7, j+17, k+7, Block.getBlockById(133));
			world.setBlock(i+8, j+17, k+7, Block.getBlockById(133));
			world.setBlock(i+1, j+17, k+8, Block.getBlockById(133));
			world.setBlock(i+2, j+17, k+8, Block.getBlockById(133));
			world.setBlock(i+3, j+17, k+8, Block.getBlockById(133));
			world.setBlock(i+4, j+17, k+8, Block.getBlockById(133));
			world.setBlock(i+5, j+17, k+8, Block.getBlockById(133));
			world.setBlock(i+6, j+17, k+8, Block.getBlockById(133));
			world.setBlock(i+7, j+17, k+8, Block.getBlockById(133));
			world.setBlock(i+8, j+17, k+8, Block.getBlockById(133));
			world.setBlock(i+9, j+17, k+9, Block.getBlockById(1));
		
		if(EpicProportionsMod.ENABLE_DEVLOGGING == true){
			
		System.out.println(EpicProportionsMod.MODID + ">> Bomby Structure Generated at: " + i2 + "," + k2);
		
		}
		}
	}


	
	
}