package com.jtrent238.epicproportions.items.structureplacers;

import com.jtrent238.epicproportions.EpicProportionsMod;

import net.minecraft.block.Block;
import net.minecraft.client.Minecraft;
import net.minecraft.creativetab.CreativeTabs;
import net.minecraft.entity.player.EntityPlayer;
import net.minecraft.entity.projectile.EntitySnowball;
import net.minecraft.inventory.IInventory;
import net.minecraft.item.Item;
import net.minecraft.item.ItemStack;
import net.minecraft.world.World;

public class itemTNTCastlePlacer extends Item{

public itemTNTCastlePlacer(int par1){
setMaxDamage(0);
maxStackSize = 1;
setUnlocalizedName("itemTNTCastlePlacer");
setTextureName("epicproportionsmod:itemTNTCastlePlacer");
setCreativeTab(EpicProportionsMod.EpicProportionsMod);
}
public int getItemEnchantability()
{
    return 0;
}
public int getMaxItemUseDuration(ItemStack par1ItemStack)
{
    return 1;
}
public float getStrVsBlock(ItemStack par1ItemStack, Block par2Block)
{
    return 1.0F;
}
public boolean onItemUse(ItemStack itemStack, EntityPlayer entity, World world, int i, int j, int k, int l, float a, float b, float c){
float var4 = 1.0F;

if(true){
boolean place = true;

if(place){
	world.setBlock(i+1, j+0, k+0, Block.getBlockById(0), 0, 2);
	world.setBlock(i+2, j+0, k+0, Block.getBlockById(0), 0, 2);
	world.setBlock(i+3, j+0, k+0, Block.getBlockById(0), 0, 2);
	world.setBlock(i+4, j+0, k+0, Block.getBlockById(0), 0, 2);
	world.setBlock(i+5, j+0, k+0, Block.getBlockById(0), 0, 2);
	world.setBlock(i+6, j+0, k+0, Block.getBlockById(0), 0, 2);
	world.setBlock(i+7, j+0, k+0, Block.getBlockById(0), 0, 2);
	world.setBlock(i+8, j+0, k+0, Block.getBlockById(0), 0, 2);
	world.setBlock(i+9, j+0, k+0, Block.getBlockById(0), 0, 2);
	world.setBlock(i+10, j+0, k+0, Block.getBlockById(0), 0, 2);
	world.setBlock(i+11, j+0, k+0, Block.getBlockById(0), 0, 2);
	world.setBlock(i+12, j+0, k+0, Block.getBlockById(0), 0, 2);
	world.setBlock(i+13, j+0, k+0, Block.getBlockById(0), 0, 2);
	world.setBlock(i+0, j+0, k+1, Block.getBlockById(0), 0, 2);
	world.setBlock(i+1, j+0, k+1, Block.getBlockById(0), 0, 2);
	world.setBlock(i+2, j+0, k+1, Block.getBlockById(0), 0, 2);
	world.setBlock(i+3, j+0, k+1, Block.getBlockById(0), 0, 2);
	world.setBlock(i+4, j+0, k+1, Block.getBlockById(0), 0, 2);
	world.setBlock(i+5, j+0, k+1, Block.getBlockById(0), 0, 2);
	world.setBlock(i+6, j+0, k+1, Block.getBlockById(0), 0, 2);
	world.setBlock(i+7, j+0, k+1, Block.getBlockById(0), 0, 2);
	world.setBlock(i+8, j+0, k+1, Block.getBlockById(0), 0, 2);
	world.setBlock(i+9, j+0, k+1, Block.getBlockById(0), 0, 2);
	world.setBlock(i+10, j+0, k+1, Block.getBlockById(0), 0, 2);
	world.setBlock(i+11, j+0, k+1, Block.getBlockById(0), 0, 2);
	world.setBlock(i+12, j+0, k+1, Block.getBlockById(0), 0, 2);
	world.setBlock(i+13, j+0, k+1, Block.getBlockById(0), 0, 2);
	world.setBlock(i+0, j+0, k+2, Block.getBlockById(0), 0, 2);
	world.setBlock(i+1, j+0, k+2, Block.getBlockById(0), 0, 2);
	world.setBlock(i+2, j+0, k+2, Block.getBlockById(0), 0, 2);
	world.setBlock(i+3, j+0, k+2, Block.getBlockById(0), 0, 2);
	world.setBlock(i+4, j+0, k+2, Block.getBlockById(0), 0, 2);
	world.setBlock(i+5, j+0, k+2, Block.getBlockById(0), 0, 2);
	world.setBlock(i+6, j+0, k+2, Block.getBlockById(0), 0, 2);
	world.setBlock(i+7, j+0, k+2, Block.getBlockById(0), 0, 2);
	world.setBlock(i+8, j+0, k+2, Block.getBlockById(0), 0, 2);
	world.setBlock(i+9, j+0, k+2, Block.getBlockById(0), 0, 2);
	world.setBlock(i+10, j+0, k+2, Block.getBlockById(0), 0, 2);
	world.setBlock(i+11, j+0, k+2, Block.getBlockById(0), 0, 2);
	world.setBlock(i+12, j+0, k+2, Block.getBlockById(0), 0, 2);
	world.setBlock(i+13, j+0, k+2, Block.getBlockById(0), 0, 2);
	world.setBlock(i+0, j+0, k+3, Block.getBlockById(0), 0, 2);
	world.setBlock(i+1, j+0, k+3, Block.getBlockById(0), 0, 2);
	world.setBlock(i+2, j+0, k+3, Block.getBlockById(0), 0, 2);
	world.setBlock(i+3, j+0, k+3, Block.getBlockById(0), 0, 2);
	world.setBlock(i+4, j+0, k+3, Block.getBlockById(0), 0, 2);
	world.setBlock(i+5, j+0, k+3, Block.getBlockById(0), 0, 2);
	world.setBlock(i+6, j+0, k+3, Block.getBlockById(0), 0, 2);
	world.setBlock(i+7, j+0, k+3, Block.getBlockById(0), 0, 2);
	world.setBlock(i+8, j+0, k+3, Block.getBlockById(0), 0, 2);
	world.setBlock(i+9, j+0, k+3, Block.getBlockById(0), 0, 2);
	world.setBlock(i+10, j+0, k+3, Block.getBlockById(0), 0, 2);
	world.setBlock(i+11, j+0, k+3, Block.getBlockById(0), 0, 2);
	world.setBlock(i+12, j+0, k+3, Block.getBlockById(0), 0, 2);
	world.setBlock(i+13, j+0, k+3, Block.getBlockById(0), 0, 2);
	world.setBlock(i+0, j+0, k+4, Block.getBlockById(0), 0, 2);
	world.setBlock(i+1, j+0, k+4, Block.getBlockById(0), 0, 2);
	world.setBlock(i+2, j+0, k+4, Block.getBlockById(0), 0, 2);
	world.setBlock(i+3, j+0, k+4, Block.getBlockById(0), 0, 2);
	world.setBlock(i+4, j+0, k+4, Block.getBlockById(0), 0, 2);
	world.setBlock(i+5, j+0, k+4, Block.getBlockById(0), 0, 2);
	world.setBlock(i+6, j+0, k+4, Block.getBlockById(0), 0, 2);
	world.setBlock(i+7, j+0, k+4, Block.getBlockById(0), 0, 2);
	world.setBlock(i+8, j+0, k+4, Block.getBlockById(0), 0, 2);
	world.setBlock(i+9, j+0, k+4, Block.getBlockById(0), 0, 2);
	world.setBlock(i+10, j+0, k+4, Block.getBlockById(0), 0, 2);
	world.setBlock(i+11, j+0, k+4, Block.getBlockById(0), 0, 2);
	world.setBlock(i+12, j+0, k+4, Block.getBlockById(0), 0, 2);
	world.setBlock(i+13, j+0, k+4, Block.getBlockById(0), 0, 2);
	world.setBlock(i+0, j+0, k+5, Block.getBlockById(0), 0, 2);
	world.setBlock(i+1, j+0, k+5, Block.getBlockById(0), 0, 2);
	world.setBlock(i+2, j+0, k+5, Block.getBlockById(0), 0, 2);
	world.setBlock(i+3, j+0, k+5, Block.getBlockById(0), 0, 2);
	world.setBlock(i+4, j+0, k+5, Block.getBlockById(0), 0, 2);
	world.setBlock(i+5, j+0, k+5, Block.getBlockById(0), 0, 2);
	world.setBlock(i+6, j+0, k+5, Block.getBlockById(0), 0, 2);
	world.setBlock(i+7, j+0, k+5, Block.getBlockById(0), 0, 2);
	world.setBlock(i+8, j+0, k+5, Block.getBlockById(0), 0, 2);
	world.setBlock(i+9, j+0, k+5, Block.getBlockById(0), 0, 2);
	world.setBlock(i+10, j+0, k+5, Block.getBlockById(0), 0, 2);
	world.setBlock(i+11, j+0, k+5, Block.getBlockById(0), 0, 2);
	world.setBlock(i+12, j+0, k+5, Block.getBlockById(0), 0, 2);
	world.setBlock(i+13, j+0, k+5, Block.getBlockById(0), 0, 2);
	world.setBlock(i+0, j+0, k+6, Block.getBlockById(0), 0, 2);
	world.setBlock(i+1, j+0, k+6, Block.getBlockById(0), 0, 2);
	world.setBlock(i+2, j+0, k+6, Block.getBlockById(0), 0, 2);
	world.setBlock(i+3, j+0, k+6, Block.getBlockById(0), 0, 2);
	world.setBlock(i+4, j+0, k+6, Block.getBlockById(0), 0, 2);
	world.setBlock(i+5, j+0, k+6, Block.getBlockById(0), 0, 2);
	world.setBlock(i+6, j+0, k+6, Block.getBlockById(0), 0, 2);
	world.setBlock(i+7, j+0, k+6, Block.getBlockById(0), 0, 2);
	world.setBlock(i+8, j+0, k+6, Block.getBlockById(0), 0, 2);
	world.setBlock(i+9, j+0, k+6, Block.getBlockById(0), 0, 2);
	world.setBlock(i+10, j+0, k+6, Block.getBlockById(0), 0, 2);
	world.setBlock(i+11, j+0, k+6, Block.getBlockById(0), 0, 2);
	world.setBlock(i+12, j+0, k+6, Block.getBlockById(0), 0, 2);
	world.setBlock(i+13, j+0, k+6, Block.getBlockById(0), 0, 2);
	world.setBlock(i+0, j+0, k+7, Block.getBlockById(0), 0, 2);
	world.setBlock(i+1, j+0, k+7, Block.getBlockById(0), 0, 2);
	world.setBlock(i+2, j+0, k+7, Block.getBlockById(0), 0, 2);
	world.setBlock(i+3, j+0, k+7, Block.getBlockById(0), 0, 2);
	world.setBlock(i+4, j+0, k+7, Block.getBlockById(0), 0, 2);
	world.setBlock(i+5, j+0, k+7, Block.getBlockById(0), 0, 2);
	world.setBlock(i+6, j+0, k+7, Block.getBlockById(0), 0, 2);
	world.setBlock(i+7, j+0, k+7, Block.getBlockById(0), 0, 2);
	world.setBlock(i+8, j+0, k+7, Block.getBlockById(0), 0, 2);
	world.setBlock(i+9, j+0, k+7, Block.getBlockById(0), 0, 2);
	world.setBlock(i+10, j+0, k+7, Block.getBlockById(0), 0, 2);
	world.setBlock(i+11, j+0, k+7, Block.getBlockById(0), 0, 2);
	world.setBlock(i+12, j+0, k+7, Block.getBlockById(0), 0, 2);
	world.setBlock(i+13, j+0, k+7, Block.getBlockById(0), 0, 2);
	world.setBlock(i+0, j+0, k+8, Block.getBlockById(0), 0, 2);
	world.setBlock(i+1, j+0, k+8, Block.getBlockById(0), 0, 2);
	world.setBlock(i+2, j+0, k+8, Block.getBlockById(0), 0, 2);
	world.setBlock(i+3, j+0, k+8, Block.getBlockById(0), 0, 2);
	world.setBlock(i+4, j+0, k+8, Block.getBlockById(0), 0, 2);
	world.setBlock(i+5, j+0, k+8, Block.getBlockById(0), 0, 2);
	world.setBlock(i+6, j+0, k+8, Block.getBlockById(0), 0, 2);
	world.setBlock(i+7, j+0, k+8, Block.getBlockById(0), 0, 2);
	world.setBlock(i+8, j+0, k+8, Block.getBlockById(0), 0, 2);
	world.setBlock(i+9, j+0, k+8, Block.getBlockById(0), 0, 2);
	world.setBlock(i+10, j+0, k+8, Block.getBlockById(0), 0, 2);
	world.setBlock(i+11, j+0, k+8, Block.getBlockById(0), 0, 2);
	world.setBlock(i+12, j+0, k+8, Block.getBlockById(0), 0, 2);
	world.setBlock(i+13, j+0, k+8, Block.getBlockById(0), 0, 2);
	world.setBlock(i+0, j+0, k+9, Block.getBlockById(0), 0, 2);
	world.setBlock(i+1, j+0, k+9, Block.getBlockById(0), 0, 2);
	world.setBlock(i+2, j+0, k+9, Block.getBlockById(0), 0, 2);
	world.setBlock(i+3, j+0, k+9, Block.getBlockById(0), 0, 2);
	world.setBlock(i+4, j+0, k+9, Block.getBlockById(0), 0, 2);
	world.setBlock(i+5, j+0, k+9, Block.getBlockById(0), 0, 2);
	world.setBlock(i+6, j+0, k+9, Block.getBlockById(0), 0, 2);
	world.setBlock(i+7, j+0, k+9, Block.getBlockById(0), 0, 2);
	world.setBlock(i+8, j+0, k+9, Block.getBlockById(0), 0, 2);
	world.setBlock(i+9, j+0, k+9, Block.getBlockById(0), 0, 2);
	world.setBlock(i+10, j+0, k+9, Block.getBlockById(0), 0, 2);
	world.setBlock(i+11, j+0, k+9, Block.getBlockById(0), 0, 2);
	world.setBlock(i+12, j+0, k+9, Block.getBlockById(0), 0, 2);
	world.setBlock(i+13, j+0, k+9, Block.getBlockById(0), 0, 2);
	world.setBlock(i+0, j+0, k+10, Block.getBlockById(0), 0, 2);
	world.setBlock(i+1, j+0, k+10, Block.getBlockById(0), 0, 2);
	world.setBlock(i+2, j+0, k+10, Block.getBlockById(0), 0, 2);
	world.setBlock(i+3, j+0, k+10, Block.getBlockById(0), 0, 2);
	world.setBlock(i+4, j+0, k+10, Block.getBlockById(0), 0, 2);
	world.setBlock(i+5, j+0, k+10, Block.getBlockById(0), 0, 2);
	world.setBlock(i+6, j+0, k+10, Block.getBlockById(0), 0, 2);
	world.setBlock(i+7, j+0, k+10, Block.getBlockById(0), 0, 2);
	world.setBlock(i+8, j+0, k+10, Block.getBlockById(0), 0, 2);
	world.setBlock(i+9, j+0, k+10, Block.getBlockById(0), 0, 2);
	world.setBlock(i+10, j+0, k+10, Block.getBlockById(0), 0, 2);
	world.setBlock(i+11, j+0, k+10, Block.getBlockById(0), 0, 2);
	world.setBlock(i+12, j+0, k+10, Block.getBlockById(0), 0, 2);
	world.setBlock(i+13, j+0, k+10, Block.getBlockById(0), 0, 2);
	world.setBlock(i+0, j+0, k+11, Block.getBlockById(0), 0, 2);
	world.setBlock(i+1, j+0, k+11, Block.getBlockById(0), 0, 2);
	world.setBlock(i+2, j+0, k+11, Block.getBlockById(0), 0, 2);
	world.setBlock(i+3, j+0, k+11, Block.getBlockById(0), 0, 2);
	world.setBlock(i+4, j+0, k+11, Block.getBlockById(0), 0, 2);
	world.setBlock(i+5, j+0, k+11, Block.getBlockById(0), 0, 2);
	world.setBlock(i+6, j+0, k+11, Block.getBlockById(0), 0, 2);
	world.setBlock(i+7, j+0, k+11, Block.getBlockById(0), 0, 2);
	world.setBlock(i+8, j+0, k+11, Block.getBlockById(0), 0, 2);
	world.setBlock(i+9, j+0, k+11, Block.getBlockById(0), 0, 2);
	world.setBlock(i+10, j+0, k+11, Block.getBlockById(0), 0, 2);
	world.setBlock(i+11, j+0, k+11, Block.getBlockById(0), 0, 2);
	world.setBlock(i+12, j+0, k+11, Block.getBlockById(0), 0, 2);
	world.setBlock(i+13, j+0, k+11, Block.getBlockById(0), 0, 2);
	world.setBlock(i+0, j+0, k+12, Block.getBlockById(0), 0, 2);
	world.setBlock(i+1, j+0, k+12, Block.getBlockById(0), 0, 2);
	world.setBlock(i+2, j+0, k+12, Block.getBlockById(0), 0, 2);
	world.setBlock(i+3, j+0, k+12, Block.getBlockById(0), 0, 2);
	world.setBlock(i+4, j+0, k+12, Block.getBlockById(0), 0, 2);
	world.setBlock(i+5, j+0, k+12, Block.getBlockById(0), 0, 2);
	world.setBlock(i+6, j+0, k+12, Block.getBlockById(0), 0, 2);
	world.setBlock(i+7, j+0, k+12, Block.getBlockById(0), 0, 2);
	world.setBlock(i+8, j+0, k+12, Block.getBlockById(0), 0, 2);
	world.setBlock(i+9, j+0, k+12, Block.getBlockById(0), 0, 2);
	world.setBlock(i+10, j+0, k+12, Block.getBlockById(0), 0, 2);
	world.setBlock(i+11, j+0, k+12, Block.getBlockById(0), 0, 2);
	world.setBlock(i+12, j+0, k+12, Block.getBlockById(0), 0, 2);
	world.setBlock(i+13, j+0, k+12, Block.getBlockById(0), 0, 2);
	world.setBlock(i+0, j+0, k+13, Block.getBlockById(0), 0, 2);
	world.setBlock(i+1, j+0, k+13, Block.getBlockById(0), 0, 2);
	world.setBlock(i+2, j+0, k+13, Block.getBlockById(0), 0, 2);
	world.setBlock(i+3, j+0, k+13, Block.getBlockById(0), 0, 2);
	world.setBlock(i+4, j+0, k+13, Block.getBlockById(0), 0, 2);
	world.setBlock(i+5, j+0, k+13, Block.getBlockById(0), 0, 2);
	world.setBlock(i+6, j+0, k+13, Block.getBlockById(0), 0, 2);
	world.setBlock(i+7, j+0, k+13, Block.getBlockById(0), 0, 2);
	world.setBlock(i+8, j+0, k+13, Block.getBlockById(0), 0, 2);
	world.setBlock(i+9, j+0, k+13, Block.getBlockById(0), 0, 2);
	world.setBlock(i+10, j+0, k+13, Block.getBlockById(0), 0, 2);
	world.setBlock(i+11, j+0, k+13, Block.getBlockById(0), 0, 2);
	world.setBlock(i+12, j+0, k+13, Block.getBlockById(0), 0, 2);
	world.setBlock(i+13, j+0, k+13, Block.getBlockById(0), 0, 2);
	world.setBlock(i+0, j+1, k+0, Block.getBlockById(0), 0, 2);
	world.setBlock(i+1, j+1, k+0, Block.getBlockById(0), 0, 2);
	world.setBlock(i+2, j+1, k+0, Block.getBlockById(46), 0, 2);
	world.setBlock(i+3, j+1, k+0, Block.getBlockById(0), 0, 2);
	world.setBlock(i+4, j+1, k+0, Block.getBlockById(0), 0, 2);
	world.setBlock(i+5, j+1, k+0, Block.getBlockById(0), 0, 2);
	world.setBlock(i+6, j+1, k+0, Block.getBlockById(0), 0, 2);
	world.setBlock(i+7, j+1, k+0, Block.getBlockById(0), 0, 2);
	world.setBlock(i+8, j+1, k+0, Block.getBlockById(0), 0, 2);
	world.setBlock(i+9, j+1, k+0, Block.getBlockById(0), 0, 2);
	world.setBlock(i+10, j+1, k+0, Block.getBlockById(46), 0, 2);
	world.setBlock(i+11, j+1, k+0, Block.getBlockById(0), 0, 2);
	world.setBlock(i+12, j+1, k+0, Block.getBlockById(0), 0, 2);
	world.setBlock(i+13, j+1, k+0, Block.getBlockById(0), 0, 2);
	world.setBlock(i+0, j+1, k+1, Block.getBlockById(0), 0, 2);
	world.setBlock(i+1, j+1, k+1, Block.getBlockById(46), 0, 2);
	world.setBlock(i+2, j+1, k+1, Block.getBlockById(46), 0, 2);
	world.setBlock(i+3, j+1, k+1, Block.getBlockById(46), 0, 2);
	world.setBlock(i+4, j+1, k+1, Block.getBlockById(0), 0, 2);
	world.setBlock(i+5, j+1, k+1, Block.getBlockById(0), 0, 2);
	world.setBlock(i+6, j+1, k+1, Block.getBlockById(0), 0, 2);
	world.setBlock(i+7, j+1, k+1, Block.getBlockById(0), 0, 2);
	world.setBlock(i+8, j+1, k+1, Block.getBlockById(0), 0, 2);
	world.setBlock(i+9, j+1, k+1, Block.getBlockById(46), 0, 2);
	world.setBlock(i+10, j+1, k+1, Block.getBlockById(46), 0, 2);
	world.setBlock(i+11, j+1, k+1, Block.getBlockById(46), 0, 2);
	world.setBlock(i+12, j+1, k+1, Block.getBlockById(0), 0, 2);
	world.setBlock(i+13, j+1, k+1, Block.getBlockById(0), 0, 2);
	world.setBlock(i+0, j+1, k+2, Block.getBlockById(46), 0, 2);
	world.setBlock(i+1, j+1, k+2, Block.getBlockById(46), 0, 2);
	world.setBlock(i+2, j+1, k+2, Block.getBlockById(46), 0, 2);
	world.setBlock(i+3, j+1, k+2, Block.getBlockById(46), 0, 2);
	world.setBlock(i+4, j+1, k+2, Block.getBlockById(46), 0, 2);
	world.setBlock(i+5, j+1, k+2, Block.getBlockById(0), 0, 2);
	world.setBlock(i+6, j+1, k+2, Block.getBlockById(0), 0, 2);
	world.setBlock(i+7, j+1, k+2, Block.getBlockById(0), 0, 2);
	world.setBlock(i+8, j+1, k+2, Block.getBlockById(46), 0, 2);
	world.setBlock(i+9, j+1, k+2, Block.getBlockById(46), 0, 2);
	world.setBlock(i+10, j+1, k+2, Block.getBlockById(46), 0, 2);
	world.setBlock(i+11, j+1, k+2, Block.getBlockById(46), 0, 2);
	world.setBlock(i+12, j+1, k+2, Block.getBlockById(46), 0, 2);
	world.setBlock(i+13, j+1, k+2, Block.getBlockById(0), 0, 2);
	world.setBlock(i+0, j+1, k+3, Block.getBlockById(0), 0, 2);
	world.setBlock(i+1, j+1, k+3, Block.getBlockById(46), 0, 2);
	world.setBlock(i+2, j+1, k+3, Block.getBlockById(46), 0, 2);
	world.setBlock(i+3, j+1, k+3, Block.getBlockById(46), 0, 2);
	world.setBlock(i+4, j+1, k+3, Block.getBlockById(46), 0, 2);
	world.setBlock(i+5, j+1, k+3, Block.getBlockById(46), 0, 2);
	world.setBlock(i+6, j+1, k+3, Block.getBlockById(46), 0, 2);
	world.setBlock(i+7, j+1, k+3, Block.getBlockById(46), 0, 2);
	world.setBlock(i+8, j+1, k+3, Block.getBlockById(46), 0, 2);
	world.setBlock(i+9, j+1, k+3, Block.getBlockById(46), 0, 2);
	world.setBlock(i+10, j+1, k+3, Block.getBlockById(46), 0, 2);
	world.setBlock(i+11, j+1, k+3, Block.getBlockById(46), 0, 2);
	world.setBlock(i+12, j+1, k+3, Block.getBlockById(0), 0, 2);
	world.setBlock(i+13, j+1, k+3, Block.getBlockById(0), 0, 2);
	world.setBlock(i+0, j+1, k+4, Block.getBlockById(0), 0, 2);
	world.setBlock(i+1, j+1, k+4, Block.getBlockById(0), 0, 2);
	world.setBlock(i+2, j+1, k+4, Block.getBlockById(46), 0, 2);
	world.setBlock(i+3, j+1, k+4, Block.getBlockById(46), 0, 2);
	world.setBlock(i+4, j+1, k+4, Block.getBlockById(46), 0, 2);
	world.setBlock(i+5, j+1, k+4, Block.getBlockById(46), 0, 2);
	world.setBlock(i+6, j+1, k+4, Block.getBlockById(46), 0, 2);
	world.setBlock(i+7, j+1, k+4, Block.getBlockById(46), 0, 2);
	world.setBlock(i+8, j+1, k+4, Block.getBlockById(46), 0, 2);
	world.setBlock(i+9, j+1, k+4, Block.getBlockById(46), 0, 2);
	world.setBlock(i+10, j+1, k+4, Block.getBlockById(46), 0, 2);
	world.setBlock(i+11, j+1, k+4, Block.getBlockById(0), 0, 2);
	world.setBlock(i+12, j+1, k+4, Block.getBlockById(0), 0, 2);
	world.setBlock(i+13, j+1, k+4, Block.getBlockById(0), 0, 2);
	world.setBlock(i+0, j+1, k+5, Block.getBlockById(0), 0, 2);
	world.setBlock(i+1, j+1, k+5, Block.getBlockById(0), 0, 2);
	world.setBlock(i+2, j+1, k+5, Block.getBlockById(0), 0, 2);
	world.setBlock(i+3, j+1, k+5, Block.getBlockById(46), 0, 2);
	world.setBlock(i+4, j+1, k+5, Block.getBlockById(46), 0, 2);
	world.setBlock(i+5, j+1, k+5, Block.getBlockById(46), 0, 2);
	world.setBlock(i+6, j+1, k+5, Block.getBlockById(46), 0, 2);
	world.setBlock(i+7, j+1, k+5, Block.getBlockById(46), 0, 2);
	world.setBlock(i+8, j+1, k+5, Block.getBlockById(46), 0, 2);
	world.setBlock(i+9, j+1, k+5, Block.getBlockById(46), 0, 2);
	world.setBlock(i+10, j+1, k+5, Block.getBlockById(0), 0, 2);
	world.setBlock(i+11, j+1, k+5, Block.getBlockById(0), 0, 2);
	world.setBlock(i+12, j+1, k+5, Block.getBlockById(0), 0, 2);
	world.setBlock(i+13, j+1, k+5, Block.getBlockById(0), 0, 2);
	world.setBlock(i+0, j+1, k+6, Block.getBlockById(0), 0, 2);
	world.setBlock(i+1, j+1, k+6, Block.getBlockById(0), 0, 2);
	world.setBlock(i+2, j+1, k+6, Block.getBlockById(0), 0, 2);
	world.setBlock(i+3, j+1, k+6, Block.getBlockById(46), 0, 2);
	world.setBlock(i+4, j+1, k+6, Block.getBlockById(46), 0, 2);
	world.setBlock(i+5, j+1, k+6, Block.getBlockById(46), 0, 2);
	world.setBlock(i+6, j+1, k+6, Block.getBlockById(46), 0, 2);
	world.setBlock(i+7, j+1, k+6, Block.getBlockById(46), 0, 2);
	world.setBlock(i+8, j+1, k+6, Block.getBlockById(46), 0, 2);
	world.setBlock(i+9, j+1, k+6, Block.getBlockById(46), 0, 2);
	world.setBlock(i+10, j+1, k+6, Block.getBlockById(0), 0, 2);
	world.setBlock(i+11, j+1, k+6, Block.getBlockById(0), 0, 2);
	world.setBlock(i+12, j+1, k+6, Block.getBlockById(0), 0, 2);
	world.setBlock(i+13, j+1, k+6, Block.getBlockById(0), 0, 2);
	world.setBlock(i+0, j+1, k+7, Block.getBlockById(0), 0, 2);
	world.setBlock(i+1, j+1, k+7, Block.getBlockById(0), 0, 2);
	world.setBlock(i+2, j+1, k+7, Block.getBlockById(0), 0, 2);
	world.setBlock(i+3, j+1, k+7, Block.getBlockById(46), 0, 2);
	world.setBlock(i+4, j+1, k+7, Block.getBlockById(46), 0, 2);
	world.setBlock(i+5, j+1, k+7, Block.getBlockById(46), 0, 2);
	world.setBlock(i+6, j+1, k+7, Block.getBlockById(46), 0, 2);
	world.setBlock(i+7, j+1, k+7, Block.getBlockById(46), 0, 2);
	world.setBlock(i+8, j+1, k+7, Block.getBlockById(46), 0, 2);
	world.setBlock(i+9, j+1, k+7, Block.getBlockById(46), 0, 2);
	world.setBlock(i+10, j+1, k+7, Block.getBlockById(0), 0, 2);
	world.setBlock(i+11, j+1, k+7, Block.getBlockById(0), 0, 2);
	world.setBlock(i+12, j+1, k+7, Block.getBlockById(0), 0, 2);
	world.setBlock(i+13, j+1, k+7, Block.getBlockById(0), 0, 2);
	world.setBlock(i+0, j+1, k+8, Block.getBlockById(0), 0, 2);
	world.setBlock(i+1, j+1, k+8, Block.getBlockById(0), 0, 2);
	world.setBlock(i+2, j+1, k+8, Block.getBlockById(46), 0, 2);
	world.setBlock(i+3, j+1, k+8, Block.getBlockById(46), 0, 2);
	world.setBlock(i+4, j+1, k+8, Block.getBlockById(46), 0, 2);
	world.setBlock(i+5, j+1, k+8, Block.getBlockById(46), 0, 2);
	world.setBlock(i+6, j+1, k+8, Block.getBlockById(46), 0, 2);
	world.setBlock(i+7, j+1, k+8, Block.getBlockById(46), 0, 2);
	world.setBlock(i+8, j+1, k+8, Block.getBlockById(46), 0, 2);
	world.setBlock(i+9, j+1, k+8, Block.getBlockById(46), 0, 2);
	world.setBlock(i+10, j+1, k+8, Block.getBlockById(0), 0, 2);
	world.setBlock(i+11, j+1, k+8, Block.getBlockById(0), 0, 2);
	world.setBlock(i+12, j+1, k+8, Block.getBlockById(0), 0, 2);
	world.setBlock(i+13, j+1, k+8, Block.getBlockById(0), 0, 2);
	world.setBlock(i+0, j+1, k+9, Block.getBlockById(0), 0, 2);
	world.setBlock(i+1, j+1, k+9, Block.getBlockById(46), 0, 2);
	world.setBlock(i+2, j+1, k+9, Block.getBlockById(46), 0, 2);
	world.setBlock(i+3, j+1, k+9, Block.getBlockById(46), 0, 2);
	world.setBlock(i+4, j+1, k+9, Block.getBlockById(46), 0, 2);
	world.setBlock(i+5, j+1, k+9, Block.getBlockById(46), 0, 2);
	world.setBlock(i+6, j+1, k+9, Block.getBlockById(46), 0, 2);
	world.setBlock(i+7, j+1, k+9, Block.getBlockById(46), 0, 2);
	world.setBlock(i+8, j+1, k+9, Block.getBlockById(46), 0, 2);
	world.setBlock(i+9, j+1, k+9, Block.getBlockById(46), 0, 2);
	world.setBlock(i+10, j+1, k+9, Block.getBlockById(0), 0, 2);
	world.setBlock(i+11, j+1, k+9, Block.getBlockById(46), 0, 2);
	world.setBlock(i+12, j+1, k+9, Block.getBlockById(0), 0, 2);
	world.setBlock(i+13, j+1, k+9, Block.getBlockById(0), 0, 2);
	world.setBlock(i+0, j+1, k+10, Block.getBlockById(46), 0, 2);
	world.setBlock(i+1, j+1, k+10, Block.getBlockById(46), 0, 2);
	world.setBlock(i+2, j+1, k+10, Block.getBlockById(46), 0, 2);
	world.setBlock(i+3, j+1, k+10, Block.getBlockById(46), 0, 2);
	world.setBlock(i+4, j+1, k+10, Block.getBlockById(46), 0, 2);
	world.setBlock(i+5, j+1, k+10, Block.getBlockById(0), 0, 2);
	world.setBlock(i+6, j+1, k+10, Block.getBlockById(0), 0, 2);
	world.setBlock(i+7, j+1, k+10, Block.getBlockById(0), 0, 2);
	world.setBlock(i+8, j+1, k+10, Block.getBlockById(46), 0, 2);
	world.setBlock(i+9, j+1, k+10, Block.getBlockById(46), 0, 2);
	world.setBlock(i+10, j+1, k+10, Block.getBlockById(46), 0, 2);
	world.setBlock(i+11, j+1, k+10, Block.getBlockById(46), 0, 2);
	world.setBlock(i+12, j+1, k+10, Block.getBlockById(46), 0, 2);
	world.setBlock(i+13, j+1, k+10, Block.getBlockById(0), 0, 2);
	world.setBlock(i+0, j+1, k+11, Block.getBlockById(0), 0, 2);
	world.setBlock(i+1, j+1, k+11, Block.getBlockById(46), 0, 2);
	world.setBlock(i+2, j+1, k+11, Block.getBlockById(46), 0, 2);
	world.setBlock(i+3, j+1, k+11, Block.getBlockById(46), 0, 2);
	world.setBlock(i+4, j+1, k+11, Block.getBlockById(0), 0, 2);
	world.setBlock(i+5, j+1, k+11, Block.getBlockById(0), 0, 2);
	world.setBlock(i+6, j+1, k+11, Block.getBlockById(0), 0, 2);
	world.setBlock(i+7, j+1, k+11, Block.getBlockById(0), 0, 2);
	world.setBlock(i+8, j+1, k+11, Block.getBlockById(0), 0, 2);
	world.setBlock(i+9, j+1, k+11, Block.getBlockById(46), 0, 2);
	world.setBlock(i+10, j+1, k+11, Block.getBlockById(46), 0, 2);
	world.setBlock(i+11, j+1, k+11, Block.getBlockById(46), 0, 2);
	world.setBlock(i+12, j+1, k+11, Block.getBlockById(46), 0, 2);
	world.setBlock(i+13, j+1, k+11, Block.getBlockById(46), 0, 2);
	world.setBlock(i+0, j+1, k+12, Block.getBlockById(0), 0, 2);
	world.setBlock(i+1, j+1, k+12, Block.getBlockById(0), 0, 2);
	world.setBlock(i+2, j+1, k+12, Block.getBlockById(46), 0, 2);
	world.setBlock(i+3, j+1, k+12, Block.getBlockById(0), 0, 2);
	world.setBlock(i+4, j+1, k+12, Block.getBlockById(0), 0, 2);
	world.setBlock(i+5, j+1, k+12, Block.getBlockById(0), 0, 2);
	world.setBlock(i+6, j+1, k+12, Block.getBlockById(0), 0, 2);
	world.setBlock(i+7, j+1, k+12, Block.getBlockById(0), 0, 2);
	world.setBlock(i+8, j+1, k+12, Block.getBlockById(0), 0, 2);
	world.setBlock(i+9, j+1, k+12, Block.getBlockById(0), 0, 2);
	world.setBlock(i+10, j+1, k+12, Block.getBlockById(46), 0, 2);
	world.setBlock(i+11, j+1, k+12, Block.getBlockById(46), 0, 2);
	world.setBlock(i+12, j+1, k+12, Block.getBlockById(46), 0, 2);
	world.setBlock(i+13, j+1, k+12, Block.getBlockById(0), 0, 2);
	world.setBlock(i+0, j+1, k+13, Block.getBlockById(0), 0, 2);
	world.setBlock(i+1, j+1, k+13, Block.getBlockById(0), 0, 2);
	world.setBlock(i+2, j+1, k+13, Block.getBlockById(0), 0, 2);
	world.setBlock(i+3, j+1, k+13, Block.getBlockById(0), 0, 2);
	world.setBlock(i+4, j+1, k+13, Block.getBlockById(0), 0, 2);
	world.setBlock(i+5, j+1, k+13, Block.getBlockById(0), 0, 2);
	world.setBlock(i+6, j+1, k+13, Block.getBlockById(0), 0, 2);
	world.setBlock(i+7, j+1, k+13, Block.getBlockById(0), 0, 2);
	world.setBlock(i+8, j+1, k+13, Block.getBlockById(0), 0, 2);
	world.setBlock(i+9, j+1, k+13, Block.getBlockById(0), 0, 2);
	world.setBlock(i+10, j+1, k+13, Block.getBlockById(0), 0, 2);
	world.setBlock(i+11, j+1, k+13, Block.getBlockById(46), 0, 2);
	world.setBlock(i+12, j+1, k+13, Block.getBlockById(0), 0, 2);
	world.setBlock(i+13, j+1, k+13, Block.getBlockById(0), 0, 2);
	world.setBlock(i+0, j+2, k+0, Block.getBlockById(0), 0, 2);
	world.setBlock(i+1, j+2, k+0, Block.getBlockById(0), 0, 2);
	world.setBlock(i+2, j+2, k+0, Block.getBlockById(46), 0, 2);
	world.setBlock(i+3, j+2, k+0, Block.getBlockById(0), 0, 2);
	world.setBlock(i+4, j+2, k+0, Block.getBlockById(0), 0, 2);
	world.setBlock(i+5, j+2, k+0, Block.getBlockById(0), 0, 2);
	world.setBlock(i+6, j+2, k+0, Block.getBlockById(0), 0, 2);
	world.setBlock(i+7, j+2, k+0, Block.getBlockById(0), 0, 2);
	world.setBlock(i+8, j+2, k+0, Block.getBlockById(0), 0, 2);
	world.setBlock(i+9, j+2, k+0, Block.getBlockById(0), 0, 2);
	world.setBlock(i+10, j+2, k+0, Block.getBlockById(46), 0, 2);
	world.setBlock(i+11, j+2, k+0, Block.getBlockById(0), 0, 2);
	world.setBlock(i+12, j+2, k+0, Block.getBlockById(0), 0, 2);
	world.setBlock(i+13, j+2, k+0, Block.getBlockById(0), 0, 2);
	world.setBlock(i+0, j+2, k+1, Block.getBlockById(0), 0, 2);
	world.setBlock(i+1, j+2, k+1, Block.getBlockById(46), 0, 2);
	world.setBlock(i+2, j+2, k+1, Block.getBlockById(46), 0, 2);
	world.setBlock(i+3, j+2, k+1, Block.getBlockById(46), 0, 2);
	world.setBlock(i+4, j+2, k+1, Block.getBlockById(0), 0, 2);
	world.setBlock(i+5, j+2, k+1, Block.getBlockById(0), 0, 2);
	world.setBlock(i+6, j+2, k+1, Block.getBlockById(0), 0, 2);
	world.setBlock(i+7, j+2, k+1, Block.getBlockById(0), 0, 2);
	world.setBlock(i+8, j+2, k+1, Block.getBlockById(0), 0, 2);
	world.setBlock(i+9, j+2, k+1, Block.getBlockById(46), 0, 2);
	world.setBlock(i+10, j+2, k+1, Block.getBlockById(46), 0, 2);
	world.setBlock(i+11, j+2, k+1, Block.getBlockById(46), 0, 2);
	world.setBlock(i+12, j+2, k+1, Block.getBlockById(0), 0, 2);
	world.setBlock(i+13, j+2, k+1, Block.getBlockById(0), 0, 2);
	world.setBlock(i+0, j+2, k+2, Block.getBlockById(46), 0, 2);
	world.setBlock(i+1, j+2, k+2, Block.getBlockById(46), 0, 2);
	world.setBlock(i+2, j+2, k+2, Block.getBlockById(46), 0, 2);
	world.setBlock(i+3, j+2, k+2, Block.getBlockById(46), 0, 2);
	world.setBlock(i+4, j+2, k+2, Block.getBlockById(46), 0, 2);
	world.setBlock(i+5, j+2, k+2, Block.getBlockById(0), 0, 2);
	world.setBlock(i+6, j+2, k+2, Block.getBlockById(0), 0, 2);
	world.setBlock(i+7, j+2, k+2, Block.getBlockById(0), 0, 2);
	world.setBlock(i+8, j+2, k+2, Block.getBlockById(46), 0, 2);
	world.setBlock(i+9, j+2, k+2, Block.getBlockById(46), 0, 2);
	world.setBlock(i+10, j+2, k+2, Block.getBlockById(46), 0, 2);
	world.setBlock(i+11, j+2, k+2, Block.getBlockById(46), 0, 2);
	world.setBlock(i+12, j+2, k+2, Block.getBlockById(46), 0, 2);
	world.setBlock(i+13, j+2, k+2, Block.getBlockById(0), 0, 2);
	world.setBlock(i+0, j+2, k+3, Block.getBlockById(0), 0, 2);
	world.setBlock(i+1, j+2, k+3, Block.getBlockById(46), 0, 2);
	world.setBlock(i+2, j+2, k+3, Block.getBlockById(46), 0, 2);
	world.setBlock(i+3, j+2, k+3, Block.getBlockById(46), 0, 2);
	world.setBlock(i+4, j+2, k+3, Block.getBlockById(46), 0, 2);
	world.setBlock(i+5, j+2, k+3, Block.getBlockById(46), 0, 2);
	world.setBlock(i+6, j+2, k+3, Block.getBlockById(46), 0, 2);
	world.setBlock(i+7, j+2, k+3, Block.getBlockById(46), 0, 2);
	world.setBlock(i+8, j+2, k+3, Block.getBlockById(46), 0, 2);
	world.setBlock(i+9, j+2, k+3, Block.getBlockById(46), 0, 2);
	world.setBlock(i+10, j+2, k+3, Block.getBlockById(46), 0, 2);
	world.setBlock(i+11, j+2, k+3, Block.getBlockById(46), 0, 2);
	world.setBlock(i+12, j+2, k+3, Block.getBlockById(0), 0, 2);
	world.setBlock(i+13, j+2, k+3, Block.getBlockById(0), 0, 2);
	world.setBlock(i+0, j+2, k+4, Block.getBlockById(0), 0, 2);
	world.setBlock(i+1, j+2, k+4, Block.getBlockById(0), 0, 2);
	world.setBlock(i+2, j+2, k+4, Block.getBlockById(46), 0, 2);
	world.setBlock(i+3, j+2, k+4, Block.getBlockById(46), 0, 2);
	world.setBlock(i+4, j+2, k+4, Block.getBlockById(58), 0, 2);
	world.setBlock(i+5, j+2, k+4, Block.getBlockById(0), 0, 2);
	world.setBlock(i+6, j+2, k+4, Block.getBlockById(26), 10, 2);
	world.setBlock(i+7, j+2, k+4, Block.getBlockById(0), 0, 2);
	world.setBlock(i+8, j+2, k+4, Block.getBlockById(54), 4, 2);
	world.setBlock(i+9, j+2, k+4, Block.getBlockById(46), 0, 2);
	world.setBlock(i+10, j+2, k+4, Block.getBlockById(46), 0, 2);
	world.setBlock(i+11, j+2, k+4, Block.getBlockById(0), 0, 2);
	world.setBlock(i+12, j+2, k+4, Block.getBlockById(0), 0, 2);
	world.setBlock(i+13, j+2, k+4, Block.getBlockById(0), 0, 2);
	world.setBlock(i+0, j+2, k+5, Block.getBlockById(0), 0, 2);
	world.setBlock(i+1, j+2, k+5, Block.getBlockById(0), 0, 2);
	world.setBlock(i+2, j+2, k+5, Block.getBlockById(0), 0, 2);
	world.setBlock(i+3, j+2, k+5, Block.getBlockById(46), 0, 2);
	world.setBlock(i+4, j+2, k+5, Block.getBlockById(61), 5, 2);
	world.setBlock(i+5, j+2, k+5, Block.getBlockById(0), 0, 2);
	world.setBlock(i+6, j+2, k+5, Block.getBlockById(26), 2, 2);
	world.setBlock(i+7, j+2, k+5, Block.getBlockById(0), 0, 2);
	world.setBlock(i+8, j+2, k+5, Block.getBlockById(54), 4, 2);
	world.setBlock(i+9, j+2, k+5, Block.getBlockById(46), 0, 2);
	world.setBlock(i+10, j+2, k+5, Block.getBlockById(0), 0, 2);
	world.setBlock(i+11, j+2, k+5, Block.getBlockById(0), 0, 2);
	world.setBlock(i+12, j+2, k+5, Block.getBlockById(0), 0, 2);
	world.setBlock(i+13, j+2, k+5, Block.getBlockById(0), 0, 2);
	world.setBlock(i+0, j+2, k+6, Block.getBlockById(0), 0, 2);
	world.setBlock(i+1, j+2, k+6, Block.getBlockById(0), 0, 2);
	world.setBlock(i+2, j+2, k+6, Block.getBlockById(0), 0, 2);
	world.setBlock(i+3, j+2, k+6, Block.getBlockById(46), 0, 2);
	world.setBlock(i+4, j+2, k+6, Block.getBlockById(0), 0, 2);
	world.setBlock(i+5, j+2, k+6, Block.getBlockById(0), 0, 2);
	world.setBlock(i+6, j+2, k+6, Block.getBlockById(0), 0, 2);
	world.setBlock(i+7, j+2, k+6, Block.getBlockById(0), 0, 2);
	world.setBlock(i+8, j+2, k+6, Block.getBlockById(0), 0, 2);
	world.setBlock(i+9, j+2, k+6, Block.getBlockById(46), 0, 2);
	world.setBlock(i+10, j+2, k+6, Block.getBlockById(0), 0, 2);
	world.setBlock(i+11, j+2, k+6, Block.getBlockById(0), 0, 2);
	world.setBlock(i+12, j+2, k+6, Block.getBlockById(0), 0, 2);
	world.setBlock(i+13, j+2, k+6, Block.getBlockById(0), 0, 2);
	world.setBlock(i+0, j+2, k+7, Block.getBlockById(0), 0, 2);
	world.setBlock(i+1, j+2, k+7, Block.getBlockById(0), 0, 2);
	world.setBlock(i+2, j+2, k+7, Block.getBlockById(0), 0, 2);
	world.setBlock(i+3, j+2, k+7, Block.getBlockById(46), 0, 2);
	world.setBlock(i+4, j+2, k+7, Block.getBlockById(0), 0, 2);
	world.setBlock(i+5, j+2, k+7, Block.getBlockById(0), 0, 2);
	world.setBlock(i+6, j+2, k+7, Block.getBlockById(0), 0, 2);
	world.setBlock(i+7, j+2, k+7, Block.getBlockById(0), 0, 2);
	world.setBlock(i+8, j+2, k+7, Block.getBlockById(0), 0, 2);
	world.setBlock(i+9, j+2, k+7, Block.getBlockById(46), 0, 2);
	world.setBlock(i+10, j+2, k+7, Block.getBlockById(0), 0, 2);
	world.setBlock(i+11, j+2, k+7, Block.getBlockById(0), 0, 2);
	world.setBlock(i+12, j+2, k+7, Block.getBlockById(0), 0, 2);
	world.setBlock(i+13, j+2, k+7, Block.getBlockById(0), 0, 2);
	world.setBlock(i+0, j+2, k+8, Block.getBlockById(0), 0, 2);
	world.setBlock(i+1, j+2, k+8, Block.getBlockById(0), 0, 2);
	world.setBlock(i+2, j+2, k+8, Block.getBlockById(46), 0, 2);
	world.setBlock(i+3, j+2, k+8, Block.getBlockById(46), 0, 2);
	world.setBlock(i+4, j+2, k+8, Block.getBlockById(0), 0, 2);
	world.setBlock(i+5, j+2, k+8, Block.getBlockById(0), 0, 2);
	world.setBlock(i+6, j+2, k+8, Block.getBlockById(0), 0, 2);
	world.setBlock(i+7, j+2, k+8, Block.getBlockById(0), 0, 2);
	world.setBlock(i+8, j+2, k+8, Block.getBlockById(0), 0, 2);
	world.setBlock(i+9, j+2, k+8, Block.getBlockById(46), 0, 2);
	world.setBlock(i+10, j+2, k+8, Block.getBlockById(0), 0, 2);
	world.setBlock(i+11, j+2, k+8, Block.getBlockById(0), 0, 2);
	world.setBlock(i+12, j+2, k+8, Block.getBlockById(0), 0, 2);
	world.setBlock(i+13, j+2, k+8, Block.getBlockById(0), 0, 2);
	world.setBlock(i+0, j+2, k+9, Block.getBlockById(0), 0, 2);
	world.setBlock(i+1, j+2, k+9, Block.getBlockById(46), 0, 2);
	world.setBlock(i+2, j+2, k+9, Block.getBlockById(46), 0, 2);
	world.setBlock(i+3, j+2, k+9, Block.getBlockById(46), 0, 2);
	world.setBlock(i+4, j+2, k+9, Block.getBlockById(46), 0, 2);
	world.setBlock(i+5, j+2, k+9, Block.getBlockById(46), 0, 2);
	world.setBlock(i+6, j+2, k+9, Block.getBlockById(64), 0, 2);
	world.setBlock(i+7, j+2, k+9, Block.getBlockById(46), 0, 2);
	world.setBlock(i+8, j+2, k+9, Block.getBlockById(46), 0, 2);
	world.setBlock(i+9, j+2, k+9, Block.getBlockById(46), 0, 2);
	world.setBlock(i+10, j+2, k+9, Block.getBlockById(0), 0, 2);
	world.setBlock(i+11, j+2, k+9, Block.getBlockById(46), 0, 2);
	world.setBlock(i+12, j+2, k+9, Block.getBlockById(0), 0, 2);
	world.setBlock(i+13, j+2, k+9, Block.getBlockById(0), 0, 2);
	world.setBlock(i+0, j+2, k+10, Block.getBlockById(46), 0, 2);
	world.setBlock(i+1, j+2, k+10, Block.getBlockById(46), 0, 2);
	world.setBlock(i+2, j+2, k+10, Block.getBlockById(46), 0, 2);
	world.setBlock(i+3, j+2, k+10, Block.getBlockById(46), 0, 2);
	world.setBlock(i+4, j+2, k+10, Block.getBlockById(46), 0, 2);
	world.setBlock(i+5, j+2, k+10, Block.getBlockById(0), 0, 2);
	world.setBlock(i+6, j+2, k+10, Block.getBlockById(0), 0, 2);
	world.setBlock(i+7, j+2, k+10, Block.getBlockById(0), 0, 2);
	world.setBlock(i+8, j+2, k+10, Block.getBlockById(46), 0, 2);
	world.setBlock(i+9, j+2, k+10, Block.getBlockById(46), 0, 2);
	world.setBlock(i+10, j+2, k+10, Block.getBlockById(46), 0, 2);
	world.setBlock(i+11, j+2, k+10, Block.getBlockById(46), 0, 2);
	world.setBlock(i+12, j+2, k+10, Block.getBlockById(46), 0, 2);
	world.setBlock(i+13, j+2, k+10, Block.getBlockById(0), 0, 2);
	world.setBlock(i+0, j+2, k+11, Block.getBlockById(0), 0, 2);
	world.setBlock(i+1, j+2, k+11, Block.getBlockById(46), 0, 2);
	world.setBlock(i+2, j+2, k+11, Block.getBlockById(46), 0, 2);
	world.setBlock(i+3, j+2, k+11, Block.getBlockById(46), 0, 2);
	world.setBlock(i+4, j+2, k+11, Block.getBlockById(0), 0, 2);
	world.setBlock(i+5, j+2, k+11, Block.getBlockById(0), 0, 2);
	world.setBlock(i+6, j+2, k+11, Block.getBlockById(0), 0, 2);
	world.setBlock(i+7, j+2, k+11, Block.getBlockById(0), 0, 2);
	world.setBlock(i+8, j+2, k+11, Block.getBlockById(0), 0, 2);
	world.setBlock(i+9, j+2, k+11, Block.getBlockById(46), 0, 2);
	world.setBlock(i+10, j+2, k+11, Block.getBlockById(46), 0, 2);
	world.setBlock(i+11, j+2, k+11, Block.getBlockById(46), 0, 2);
	world.setBlock(i+12, j+2, k+11, Block.getBlockById(46), 0, 2);
	world.setBlock(i+13, j+2, k+11, Block.getBlockById(46), 0, 2);
	world.setBlock(i+0, j+2, k+12, Block.getBlockById(0), 0, 2);
	world.setBlock(i+1, j+2, k+12, Block.getBlockById(0), 0, 2);
	world.setBlock(i+2, j+2, k+12, Block.getBlockById(46), 0, 2);
	world.setBlock(i+3, j+2, k+12, Block.getBlockById(0), 0, 2);
	world.setBlock(i+4, j+2, k+12, Block.getBlockById(0), 0, 2);
	world.setBlock(i+5, j+2, k+12, Block.getBlockById(0), 0, 2);
	world.setBlock(i+6, j+2, k+12, Block.getBlockById(0), 0, 2);
	world.setBlock(i+7, j+2, k+12, Block.getBlockById(0), 0, 2);
	world.setBlock(i+8, j+2, k+12, Block.getBlockById(0), 0, 2);
	world.setBlock(i+9, j+2, k+12, Block.getBlockById(0), 0, 2);
	world.setBlock(i+10, j+2, k+12, Block.getBlockById(46), 0, 2);
	world.setBlock(i+11, j+2, k+12, Block.getBlockById(46), 0, 2);
	world.setBlock(i+12, j+2, k+12, Block.getBlockById(46), 0, 2);
	world.setBlock(i+13, j+2, k+12, Block.getBlockById(0), 0, 2);
	world.setBlock(i+0, j+2, k+13, Block.getBlockById(0), 0, 2);
	world.setBlock(i+1, j+2, k+13, Block.getBlockById(0), 0, 2);
	world.setBlock(i+2, j+2, k+13, Block.getBlockById(0), 0, 2);
	world.setBlock(i+3, j+2, k+13, Block.getBlockById(0), 0, 2);
	world.setBlock(i+4, j+2, k+13, Block.getBlockById(0), 0, 2);
	world.setBlock(i+5, j+2, k+13, Block.getBlockById(0), 0, 2);
	world.setBlock(i+6, j+2, k+13, Block.getBlockById(0), 0, 2);
	world.setBlock(i+7, j+2, k+13, Block.getBlockById(0), 0, 2);
	world.setBlock(i+8, j+2, k+13, Block.getBlockById(0), 0, 2);
	world.setBlock(i+9, j+2, k+13, Block.getBlockById(0), 0, 2);
	world.setBlock(i+10, j+2, k+13, Block.getBlockById(0), 0, 2);
	world.setBlock(i+11, j+2, k+13, Block.getBlockById(46), 0, 2);
	world.setBlock(i+12, j+2, k+13, Block.getBlockById(0), 0, 2);
	world.setBlock(i+13, j+2, k+13, Block.getBlockById(0), 0, 2);
	world.setBlock(i+0, j+3, k+0, Block.getBlockById(0), 0, 2);
	world.setBlock(i+1, j+3, k+0, Block.getBlockById(0), 0, 2);
	world.setBlock(i+2, j+3, k+0, Block.getBlockById(46), 0, 2);
	world.setBlock(i+3, j+3, k+0, Block.getBlockById(0), 0, 2);
	world.setBlock(i+4, j+3, k+0, Block.getBlockById(0), 0, 2);
	world.setBlock(i+5, j+3, k+0, Block.getBlockById(0), 0, 2);
	world.setBlock(i+6, j+3, k+0, Block.getBlockById(0), 0, 2);
	world.setBlock(i+7, j+3, k+0, Block.getBlockById(0), 0, 2);
	world.setBlock(i+8, j+3, k+0, Block.getBlockById(0), 0, 2);
	world.setBlock(i+9, j+3, k+0, Block.getBlockById(0), 0, 2);
	world.setBlock(i+10, j+3, k+0, Block.getBlockById(46), 0, 2);
	world.setBlock(i+11, j+3, k+0, Block.getBlockById(0), 0, 2);
	world.setBlock(i+12, j+3, k+0, Block.getBlockById(0), 0, 2);
	world.setBlock(i+13, j+3, k+0, Block.getBlockById(0), 0, 2);
	world.setBlock(i+0, j+3, k+1, Block.getBlockById(0), 0, 2);
	world.setBlock(i+1, j+3, k+1, Block.getBlockById(46), 0, 2);
	world.setBlock(i+2, j+3, k+1, Block.getBlockById(46), 0, 2);
	world.setBlock(i+3, j+3, k+1, Block.getBlockById(46), 0, 2);
	world.setBlock(i+4, j+3, k+1, Block.getBlockById(0), 0, 2);
	world.setBlock(i+5, j+3, k+1, Block.getBlockById(0), 0, 2);
	world.setBlock(i+6, j+3, k+1, Block.getBlockById(0), 0, 2);
	world.setBlock(i+7, j+3, k+1, Block.getBlockById(0), 0, 2);
	world.setBlock(i+8, j+3, k+1, Block.getBlockById(0), 0, 2);
	world.setBlock(i+9, j+3, k+1, Block.getBlockById(46), 0, 2);
	world.setBlock(i+10, j+3, k+1, Block.getBlockById(46), 0, 2);
	world.setBlock(i+11, j+3, k+1, Block.getBlockById(46), 0, 2);
	world.setBlock(i+12, j+3, k+1, Block.getBlockById(0), 0, 2);
	world.setBlock(i+13, j+3, k+1, Block.getBlockById(0), 0, 2);
	world.setBlock(i+0, j+3, k+2, Block.getBlockById(46), 0, 2);
	world.setBlock(i+1, j+3, k+2, Block.getBlockById(46), 0, 2);
	world.setBlock(i+2, j+3, k+2, Block.getBlockById(46), 0, 2);
	world.setBlock(i+3, j+3, k+2, Block.getBlockById(46), 0, 2);
	world.setBlock(i+4, j+3, k+2, Block.getBlockById(46), 0, 2);
	world.setBlock(i+5, j+3, k+2, Block.getBlockById(0), 0, 2);
	world.setBlock(i+6, j+3, k+2, Block.getBlockById(0), 0, 2);
	world.setBlock(i+7, j+3, k+2, Block.getBlockById(0), 0, 2);
	world.setBlock(i+8, j+3, k+2, Block.getBlockById(46), 0, 2);
	world.setBlock(i+9, j+3, k+2, Block.getBlockById(46), 0, 2);
	world.setBlock(i+10, j+3, k+2, Block.getBlockById(46), 0, 2);
	world.setBlock(i+11, j+3, k+2, Block.getBlockById(46), 0, 2);
	world.setBlock(i+12, j+3, k+2, Block.getBlockById(46), 0, 2);
	world.setBlock(i+13, j+3, k+2, Block.getBlockById(0), 0, 2);
	world.setBlock(i+0, j+3, k+3, Block.getBlockById(0), 0, 2);
	world.setBlock(i+1, j+3, k+3, Block.getBlockById(46), 0, 2);
	world.setBlock(i+2, j+3, k+3, Block.getBlockById(46), 0, 2);
	world.setBlock(i+3, j+3, k+3, Block.getBlockById(46), 0, 2);
	world.setBlock(i+4, j+3, k+3, Block.getBlockById(46), 0, 2);
	world.setBlock(i+5, j+3, k+3, Block.getBlockById(46), 0, 2);
	world.setBlock(i+6, j+3, k+3, Block.getBlockById(46), 0, 2);
	world.setBlock(i+7, j+3, k+3, Block.getBlockById(46), 0, 2);
	world.setBlock(i+8, j+3, k+3, Block.getBlockById(46), 0, 2);
	world.setBlock(i+9, j+3, k+3, Block.getBlockById(46), 0, 2);
	world.setBlock(i+10, j+3, k+3, Block.getBlockById(46), 0, 2);
	world.setBlock(i+11, j+3, k+3, Block.getBlockById(46), 0, 2);
	world.setBlock(i+12, j+3, k+3, Block.getBlockById(0), 0, 2);
	world.setBlock(i+13, j+3, k+3, Block.getBlockById(0), 0, 2);
	world.setBlock(i+0, j+3, k+4, Block.getBlockById(0), 0, 2);
	world.setBlock(i+1, j+3, k+4, Block.getBlockById(0), 0, 2);
	world.setBlock(i+2, j+3, k+4, Block.getBlockById(46), 0, 2);
	world.setBlock(i+3, j+3, k+4, Block.getBlockById(46), 0, 2);
	world.setBlock(i+4, j+3, k+4, Block.getBlockById(0), 0, 2);
	world.setBlock(i+5, j+3, k+4, Block.getBlockById(0), 0, 2);
	world.setBlock(i+6, j+3, k+4, Block.getBlockById(0), 0, 2);
	world.setBlock(i+7, j+3, k+4, Block.getBlockById(0), 0, 2);
	world.setBlock(i+8, j+3, k+4, Block.getBlockById(54), 4, 2);
	world.setBlock(i+9, j+3, k+4, Block.getBlockById(46), 0, 2);
	world.setBlock(i+10, j+3, k+4, Block.getBlockById(46), 0, 2);
	world.setBlock(i+11, j+3, k+4, Block.getBlockById(0), 0, 2);
	world.setBlock(i+12, j+3, k+4, Block.getBlockById(0), 0, 2);
	world.setBlock(i+13, j+3, k+4, Block.getBlockById(0), 0, 2);
	world.setBlock(i+0, j+3, k+5, Block.getBlockById(0), 0, 2);
	world.setBlock(i+1, j+3, k+5, Block.getBlockById(0), 0, 2);
	world.setBlock(i+2, j+3, k+5, Block.getBlockById(0), 0, 2);
	world.setBlock(i+3, j+3, k+5, Block.getBlockById(20), 0, 2);
	world.setBlock(i+4, j+3, k+5, Block.getBlockById(0), 0, 2);
	world.setBlock(i+5, j+3, k+5, Block.getBlockById(0), 0, 2);
	world.setBlock(i+6, j+3, k+5, Block.getBlockById(0), 0, 2);
	world.setBlock(i+7, j+3, k+5, Block.getBlockById(0), 0, 2);
	world.setBlock(i+8, j+3, k+5, Block.getBlockById(54), 4, 2);
	world.setBlock(i+9, j+3, k+5, Block.getBlockById(20), 0, 2);
	world.setBlock(i+10, j+3, k+5, Block.getBlockById(0), 0, 2);
	world.setBlock(i+11, j+3, k+5, Block.getBlockById(0), 0, 2);
	world.setBlock(i+12, j+3, k+5, Block.getBlockById(0), 0, 2);
	world.setBlock(i+13, j+3, k+5, Block.getBlockById(0), 0, 2);
	world.setBlock(i+0, j+3, k+6, Block.getBlockById(0), 0, 2);
	world.setBlock(i+1, j+3, k+6, Block.getBlockById(0), 0, 2);
	world.setBlock(i+2, j+3, k+6, Block.getBlockById(0), 0, 2);
	world.setBlock(i+3, j+3, k+6, Block.getBlockById(20), 0, 2);
	world.setBlock(i+4, j+3, k+6, Block.getBlockById(0), 0, 2);
	world.setBlock(i+5, j+3, k+6, Block.getBlockById(0), 0, 2);
	world.setBlock(i+6, j+3, k+6, Block.getBlockById(0), 0, 2);
	world.setBlock(i+7, j+3, k+6, Block.getBlockById(0), 0, 2);
	world.setBlock(i+8, j+3, k+6, Block.getBlockById(0), 0, 2);
	world.setBlock(i+9, j+3, k+6, Block.getBlockById(20), 0, 2);
	world.setBlock(i+10, j+3, k+6, Block.getBlockById(0), 0, 2);
	world.setBlock(i+11, j+3, k+6, Block.getBlockById(0), 0, 2);
	world.setBlock(i+12, j+3, k+6, Block.getBlockById(0), 0, 2);
	world.setBlock(i+13, j+3, k+6, Block.getBlockById(0), 0, 2);
	world.setBlock(i+0, j+3, k+7, Block.getBlockById(0), 0, 2);
	world.setBlock(i+1, j+3, k+7, Block.getBlockById(0), 0, 2);
	world.setBlock(i+2, j+3, k+7, Block.getBlockById(0), 0, 2);
	world.setBlock(i+3, j+3, k+7, Block.getBlockById(20), 0, 2);
	world.setBlock(i+4, j+3, k+7, Block.getBlockById(0), 0, 2);
	world.setBlock(i+5, j+3, k+7, Block.getBlockById(0), 0, 2);
	world.setBlock(i+6, j+3, k+7, Block.getBlockById(0), 0, 2);
	world.setBlock(i+7, j+3, k+7, Block.getBlockById(0), 0, 2);
	world.setBlock(i+8, j+3, k+7, Block.getBlockById(0), 0, 2);
	world.setBlock(i+9, j+3, k+7, Block.getBlockById(20), 0, 2);
	world.setBlock(i+10, j+3, k+7, Block.getBlockById(0), 0, 2);
	world.setBlock(i+11, j+3, k+7, Block.getBlockById(0), 0, 2);
	world.setBlock(i+12, j+3, k+7, Block.getBlockById(0), 0, 2);
	world.setBlock(i+13, j+3, k+7, Block.getBlockById(0), 0, 2);
	world.setBlock(i+0, j+3, k+8, Block.getBlockById(0), 0, 2);
	world.setBlock(i+1, j+3, k+8, Block.getBlockById(0), 0, 2);
	world.setBlock(i+2, j+3, k+8, Block.getBlockById(46), 0, 2);
	world.setBlock(i+3, j+3, k+8, Block.getBlockById(46), 0, 2);
	world.setBlock(i+4, j+3, k+8, Block.getBlockById(0), 0, 2);
	world.setBlock(i+5, j+3, k+8, Block.getBlockById(0), 0, 2);
	world.setBlock(i+6, j+3, k+8, Block.getBlockById(0), 0, 2);
	world.setBlock(i+7, j+3, k+8, Block.getBlockById(0), 0, 2);
	world.setBlock(i+8, j+3, k+8, Block.getBlockById(0), 0, 2);
	world.setBlock(i+9, j+3, k+8, Block.getBlockById(46), 0, 2);
	world.setBlock(i+10, j+3, k+8, Block.getBlockById(0), 0, 2);
	world.setBlock(i+11, j+3, k+8, Block.getBlockById(0), 0, 2);
	world.setBlock(i+12, j+3, k+8, Block.getBlockById(0), 0, 2);
	world.setBlock(i+13, j+3, k+8, Block.getBlockById(0), 0, 2);
	world.setBlock(i+0, j+3, k+9, Block.getBlockById(0), 0, 2);
	world.setBlock(i+1, j+3, k+9, Block.getBlockById(46), 0, 2);
	world.setBlock(i+2, j+3, k+9, Block.getBlockById(46), 0, 2);
	world.setBlock(i+3, j+3, k+9, Block.getBlockById(46), 0, 2);
	world.setBlock(i+4, j+3, k+9, Block.getBlockById(0), 0, 2);
	world.setBlock(i+5, j+3, k+9, Block.getBlockById(46), 0, 2);
	world.setBlock(i+6, j+3, k+9, Block.getBlockById(0), 0, 2);
	world.setBlock(i+7, j+3, k+9, Block.getBlockById(46), 0, 2);
	world.setBlock(i+8, j+3, k+9, Block.getBlockById(0), 0, 2);
	world.setBlock(i+9, j+3, k+9, Block.getBlockById(46), 0, 2);
	world.setBlock(i+10, j+3, k+9, Block.getBlockById(0), 0, 2);
	world.setBlock(i+11, j+3, k+9, Block.getBlockById(46), 0, 2);
	world.setBlock(i+12, j+3, k+9, Block.getBlockById(0), 0, 2);
	world.setBlock(i+13, j+3, k+9, Block.getBlockById(0), 0, 2);
	world.setBlock(i+0, j+3, k+10, Block.getBlockById(46), 0, 2);
	world.setBlock(i+1, j+3, k+10, Block.getBlockById(46), 0, 2);
	world.setBlock(i+2, j+3, k+10, Block.getBlockById(46), 0, 2);
	world.setBlock(i+3, j+3, k+10, Block.getBlockById(46), 0, 2);
	world.setBlock(i+4, j+3, k+10, Block.getBlockById(20), 0, 2);
	world.setBlock(i+5, j+3, k+10, Block.getBlockById(0), 0, 2);
	world.setBlock(i+6, j+3, k+10, Block.getBlockById(0), 0, 2);
	world.setBlock(i+7, j+3, k+10, Block.getBlockById(0), 0, 2);
	world.setBlock(i+8, j+3, k+10, Block.getBlockById(20), 0, 2);
	world.setBlock(i+9, j+3, k+10, Block.getBlockById(46), 0, 2);
	world.setBlock(i+10, j+3, k+10, Block.getBlockById(46), 0, 2);
	world.setBlock(i+11, j+3, k+10, Block.getBlockById(46), 0, 2);
	world.setBlock(i+12, j+3, k+10, Block.getBlockById(46), 0, 2);
	world.setBlock(i+13, j+3, k+10, Block.getBlockById(0), 0, 2);
	world.setBlock(i+0, j+3, k+11, Block.getBlockById(0), 0, 2);
	world.setBlock(i+1, j+3, k+11, Block.getBlockById(46), 0, 2);
	world.setBlock(i+2, j+3, k+11, Block.getBlockById(46), 0, 2);
	world.setBlock(i+3, j+3, k+11, Block.getBlockById(46), 0, 2);
	world.setBlock(i+4, j+3, k+11, Block.getBlockById(0), 0, 2);
	world.setBlock(i+5, j+3, k+11, Block.getBlockById(0), 0, 2);
	world.setBlock(i+6, j+3, k+11, Block.getBlockById(0), 0, 2);
	world.setBlock(i+7, j+3, k+11, Block.getBlockById(0), 0, 2);
	world.setBlock(i+8, j+3, k+11, Block.getBlockById(0), 0, 2);
	world.setBlock(i+9, j+3, k+11, Block.getBlockById(46), 0, 2);
	world.setBlock(i+10, j+3, k+11, Block.getBlockById(46), 0, 2);
	world.setBlock(i+11, j+3, k+11, Block.getBlockById(46), 0, 2);
	world.setBlock(i+12, j+3, k+11, Block.getBlockById(46), 0, 2);
	world.setBlock(i+13, j+3, k+11, Block.getBlockById(46), 0, 2);
	world.setBlock(i+0, j+3, k+12, Block.getBlockById(0), 0, 2);
	world.setBlock(i+1, j+3, k+12, Block.getBlockById(0), 0, 2);
	world.setBlock(i+2, j+3, k+12, Block.getBlockById(46), 0, 2);
	world.setBlock(i+3, j+3, k+12, Block.getBlockById(0), 0, 2);
	world.setBlock(i+4, j+3, k+12, Block.getBlockById(0), 0, 2);
	world.setBlock(i+5, j+3, k+12, Block.getBlockById(0), 0, 2);
	world.setBlock(i+6, j+3, k+12, Block.getBlockById(0), 0, 2);
	world.setBlock(i+7, j+3, k+12, Block.getBlockById(0), 0, 2);
	world.setBlock(i+8, j+3, k+12, Block.getBlockById(0), 0, 2);
	world.setBlock(i+9, j+3, k+12, Block.getBlockById(0), 0, 2);
	world.setBlock(i+10, j+3, k+12, Block.getBlockById(46), 0, 2);
	world.setBlock(i+11, j+3, k+12, Block.getBlockById(46), 0, 2);
	world.setBlock(i+12, j+3, k+12, Block.getBlockById(46), 0, 2);
	world.setBlock(i+13, j+3, k+12, Block.getBlockById(0), 0, 2);
	world.setBlock(i+0, j+3, k+13, Block.getBlockById(0), 0, 2);
	world.setBlock(i+1, j+3, k+13, Block.getBlockById(0), 0, 2);
	world.setBlock(i+2, j+3, k+13, Block.getBlockById(0), 0, 2);
	world.setBlock(i+3, j+3, k+13, Block.getBlockById(0), 0, 2);
	world.setBlock(i+4, j+3, k+13, Block.getBlockById(0), 0, 2);
	world.setBlock(i+5, j+3, k+13, Block.getBlockById(0), 0, 2);
	world.setBlock(i+6, j+3, k+13, Block.getBlockById(0), 0, 2);
	world.setBlock(i+7, j+3, k+13, Block.getBlockById(0), 0, 2);
	world.setBlock(i+8, j+3, k+13, Block.getBlockById(0), 0, 2);
	world.setBlock(i+9, j+3, k+13, Block.getBlockById(0), 0, 2);
	world.setBlock(i+10, j+3, k+13, Block.getBlockById(0), 0, 2);
	world.setBlock(i+11, j+3, k+13, Block.getBlockById(46), 0, 2);
	world.setBlock(i+12, j+3, k+13, Block.getBlockById(0), 0, 2);
	world.setBlock(i+13, j+3, k+13, Block.getBlockById(0), 0, 2);
	world.setBlock(i+0, j+4, k+0, Block.getBlockById(0), 0, 2);
	world.setBlock(i+1, j+4, k+0, Block.getBlockById(0), 0, 2);
	world.setBlock(i+2, j+4, k+0, Block.getBlockById(46), 0, 2);
	world.setBlock(i+3, j+4, k+0, Block.getBlockById(0), 0, 2);
	world.setBlock(i+4, j+4, k+0, Block.getBlockById(0), 0, 2);
	world.setBlock(i+5, j+4, k+0, Block.getBlockById(0), 0, 2);
	world.setBlock(i+6, j+4, k+0, Block.getBlockById(0), 0, 2);
	world.setBlock(i+7, j+4, k+0, Block.getBlockById(0), 0, 2);
	world.setBlock(i+8, j+4, k+0, Block.getBlockById(0), 0, 2);
	world.setBlock(i+9, j+4, k+0, Block.getBlockById(0), 0, 2);
	world.setBlock(i+10, j+4, k+0, Block.getBlockById(46), 0, 2);
	world.setBlock(i+11, j+4, k+0, Block.getBlockById(0), 0, 2);
	world.setBlock(i+12, j+4, k+0, Block.getBlockById(0), 0, 2);
	world.setBlock(i+13, j+4, k+0, Block.getBlockById(0), 0, 2);
	world.setBlock(i+0, j+4, k+1, Block.getBlockById(0), 0, 2);
	world.setBlock(i+1, j+4, k+1, Block.getBlockById(46), 0, 2);
	world.setBlock(i+2, j+4, k+1, Block.getBlockById(46), 0, 2);
	world.setBlock(i+3, j+4, k+1, Block.getBlockById(46), 0, 2);
	world.setBlock(i+4, j+4, k+1, Block.getBlockById(0), 0, 2);
	world.setBlock(i+5, j+4, k+1, Block.getBlockById(0), 0, 2);
	world.setBlock(i+6, j+4, k+1, Block.getBlockById(0), 0, 2);
	world.setBlock(i+7, j+4, k+1, Block.getBlockById(0), 0, 2);
	world.setBlock(i+8, j+4, k+1, Block.getBlockById(0), 0, 2);
	world.setBlock(i+9, j+4, k+1, Block.getBlockById(46), 0, 2);
	world.setBlock(i+10, j+4, k+1, Block.getBlockById(46), 0, 2);
	world.setBlock(i+11, j+4, k+1, Block.getBlockById(46), 0, 2);
	world.setBlock(i+12, j+4, k+1, Block.getBlockById(0), 0, 2);
	world.setBlock(i+13, j+4, k+1, Block.getBlockById(0), 0, 2);
	world.setBlock(i+0, j+4, k+2, Block.getBlockById(46), 0, 2);
	world.setBlock(i+1, j+4, k+2, Block.getBlockById(46), 0, 2);
	world.setBlock(i+2, j+4, k+2, Block.getBlockById(46), 0, 2);
	world.setBlock(i+3, j+4, k+2, Block.getBlockById(46), 0, 2);
	world.setBlock(i+4, j+4, k+2, Block.getBlockById(46), 0, 2);
	world.setBlock(i+5, j+4, k+2, Block.getBlockById(0), 0, 2);
	world.setBlock(i+6, j+4, k+2, Block.getBlockById(0), 0, 2);
	world.setBlock(i+7, j+4, k+2, Block.getBlockById(0), 0, 2);
	world.setBlock(i+8, j+4, k+2, Block.getBlockById(46), 0, 2);
	world.setBlock(i+9, j+4, k+2, Block.getBlockById(46), 0, 2);
	world.setBlock(i+10, j+4, k+2, Block.getBlockById(46), 0, 2);
	world.setBlock(i+11, j+4, k+2, Block.getBlockById(46), 0, 2);
	world.setBlock(i+12, j+4, k+2, Block.getBlockById(46), 0, 2);
	world.setBlock(i+13, j+4, k+2, Block.getBlockById(0), 0, 2);
	world.setBlock(i+0, j+4, k+3, Block.getBlockById(0), 0, 2);
	world.setBlock(i+1, j+4, k+3, Block.getBlockById(46), 0, 2);
	world.setBlock(i+2, j+4, k+3, Block.getBlockById(46), 0, 2);
	world.setBlock(i+3, j+4, k+3, Block.getBlockById(46), 0, 2);
	world.setBlock(i+4, j+4, k+3, Block.getBlockById(46), 0, 2);
	world.setBlock(i+5, j+4, k+3, Block.getBlockById(46), 0, 2);
	world.setBlock(i+6, j+4, k+3, Block.getBlockById(46), 0, 2);
	world.setBlock(i+7, j+4, k+3, Block.getBlockById(46), 0, 2);
	world.setBlock(i+8, j+4, k+3, Block.getBlockById(46), 0, 2);
	world.setBlock(i+9, j+4, k+3, Block.getBlockById(46), 0, 2);
	world.setBlock(i+10, j+4, k+3, Block.getBlockById(46), 0, 2);
	world.setBlock(i+11, j+4, k+3, Block.getBlockById(46), 0, 2);
	world.setBlock(i+12, j+4, k+3, Block.getBlockById(0), 0, 2);
	world.setBlock(i+13, j+4, k+3, Block.getBlockById(0), 0, 2);
	world.setBlock(i+0, j+4, k+4, Block.getBlockById(0), 0, 2);
	world.setBlock(i+1, j+4, k+4, Block.getBlockById(0), 0, 2);
	world.setBlock(i+2, j+4, k+4, Block.getBlockById(46), 0, 2);
	world.setBlock(i+3, j+4, k+4, Block.getBlockById(46), 0, 2);
	world.setBlock(i+4, j+4, k+4, Block.getBlockById(0), 0, 2);
	world.setBlock(i+5, j+4, k+4, Block.getBlockById(0), 0, 2);
	world.setBlock(i+6, j+4, k+4, Block.getBlockById(50), 0, 2);
	world.setBlock(i+7, j+4, k+4, Block.getBlockById(0), 0, 2);
	world.setBlock(i+8, j+4, k+4, Block.getBlockById(0), 0, 2);
	world.setBlock(i+9, j+4, k+4, Block.getBlockById(46), 0, 2);
	world.setBlock(i+10, j+4, k+4, Block.getBlockById(46), 0, 2);
	world.setBlock(i+11, j+4, k+4, Block.getBlockById(0), 0, 2);
	world.setBlock(i+12, j+4, k+4, Block.getBlockById(0), 0, 2);
	world.setBlock(i+13, j+4, k+4, Block.getBlockById(0), 0, 2);
	world.setBlock(i+0, j+4, k+5, Block.getBlockById(0), 0, 2);
	world.setBlock(i+1, j+4, k+5, Block.getBlockById(0), 0, 2);
	world.setBlock(i+2, j+4, k+5, Block.getBlockById(0), 0, 2);
	world.setBlock(i+3, j+4, k+5, Block.getBlockById(46), 0, 2);
	world.setBlock(i+4, j+4, k+5, Block.getBlockById(0), 0, 2);
	world.setBlock(i+5, j+4, k+5, Block.getBlockById(0), 0, 2);
	world.setBlock(i+6, j+4, k+5, Block.getBlockById(0), 0, 2);
	world.setBlock(i+7, j+4, k+5, Block.getBlockById(0), 0, 2);
	world.setBlock(i+8, j+4, k+5, Block.getBlockById(0), 0, 2);
	world.setBlock(i+9, j+4, k+5, Block.getBlockById(46), 0, 2);
	world.setBlock(i+10, j+4, k+5, Block.getBlockById(0), 0, 2);
	world.setBlock(i+11, j+4, k+5, Block.getBlockById(0), 0, 2);
	world.setBlock(i+12, j+4, k+5, Block.getBlockById(0), 0, 2);
	world.setBlock(i+13, j+4, k+5, Block.getBlockById(0), 0, 2);
	world.setBlock(i+0, j+4, k+6, Block.getBlockById(0), 0, 2);
	world.setBlock(i+1, j+4, k+6, Block.getBlockById(0), 0, 2);
	world.setBlock(i+2, j+4, k+6, Block.getBlockById(0), 0, 2);
	world.setBlock(i+3, j+4, k+6, Block.getBlockById(46), 0, 2);
	world.setBlock(i+4, j+4, k+6, Block.getBlockById(0), 0, 2);
	world.setBlock(i+5, j+4, k+6, Block.getBlockById(0), 0, 2);
	world.setBlock(i+6, j+4, k+6, Block.getBlockById(0), 0, 2);
	world.setBlock(i+7, j+4, k+6, Block.getBlockById(0), 0, 2);
	world.setBlock(i+8, j+4, k+6, Block.getBlockById(0), 0, 2);
	world.setBlock(i+9, j+4, k+6, Block.getBlockById(46), 0, 2);
	world.setBlock(i+10, j+4, k+6, Block.getBlockById(0), 0, 2);
	world.setBlock(i+11, j+4, k+6, Block.getBlockById(0), 0, 2);
	world.setBlock(i+12, j+4, k+6, Block.getBlockById(0), 0, 2);
	world.setBlock(i+13, j+4, k+6, Block.getBlockById(0), 0, 2);
	world.setBlock(i+0, j+4, k+7, Block.getBlockById(0), 0, 2);
	world.setBlock(i+1, j+4, k+7, Block.getBlockById(0), 0, 2);
	world.setBlock(i+2, j+4, k+7, Block.getBlockById(0), 0, 2);
	world.setBlock(i+3, j+4, k+7, Block.getBlockById(46), 0, 2);
	world.setBlock(i+4, j+4, k+7, Block.getBlockById(0), 0, 2);
	world.setBlock(i+5, j+4, k+7, Block.getBlockById(0), 0, 2);
	world.setBlock(i+6, j+4, k+7, Block.getBlockById(0), 0, 2);
	world.setBlock(i+7, j+4, k+7, Block.getBlockById(0), 0, 2);
	world.setBlock(i+8, j+4, k+7, Block.getBlockById(0), 0, 2);
	world.setBlock(i+9, j+4, k+7, Block.getBlockById(46), 0, 2);
	world.setBlock(i+10, j+4, k+7, Block.getBlockById(0), 0, 2);
	world.setBlock(i+11, j+4, k+7, Block.getBlockById(0), 0, 2);
	world.setBlock(i+12, j+4, k+7, Block.getBlockById(0), 0, 2);
	world.setBlock(i+13, j+4, k+7, Block.getBlockById(0), 0, 2);
	world.setBlock(i+0, j+4, k+8, Block.getBlockById(0), 0, 2);
	world.setBlock(i+1, j+4, k+8, Block.getBlockById(0), 0, 2);
	world.setBlock(i+2, j+4, k+8, Block.getBlockById(46), 0, 2);
	world.setBlock(i+3, j+4, k+8, Block.getBlockById(46), 0, 2);
	world.setBlock(i+4, j+4, k+8, Block.getBlockById(0), 0, 2);
	world.setBlock(i+5, j+4, k+8, Block.getBlockById(50), 0, 2);
	world.setBlock(i+6, j+4, k+8, Block.getBlockById(0), 0, 2);
	world.setBlock(i+7, j+4, k+8, Block.getBlockById(50), 0, 2);
	world.setBlock(i+8, j+4, k+8, Block.getBlockById(0), 0, 2);
	world.setBlock(i+9, j+4, k+8, Block.getBlockById(46), 0, 2);
	world.setBlock(i+10, j+4, k+8, Block.getBlockById(0), 0, 2);
	world.setBlock(i+11, j+4, k+8, Block.getBlockById(0), 0, 2);
	world.setBlock(i+12, j+4, k+8, Block.getBlockById(0), 0, 2);
	world.setBlock(i+13, j+4, k+8, Block.getBlockById(0), 0, 2);
	world.setBlock(i+0, j+4, k+9, Block.getBlockById(0), 0, 2);
	world.setBlock(i+1, j+4, k+9, Block.getBlockById(46), 0, 2);
	world.setBlock(i+2, j+4, k+9, Block.getBlockById(46), 0, 2);
	world.setBlock(i+3, j+4, k+9, Block.getBlockById(46), 0, 2);
	world.setBlock(i+4, j+4, k+9, Block.getBlockById(46), 0, 2);
	world.setBlock(i+5, j+4, k+9, Block.getBlockById(46), 0, 2);
	world.setBlock(i+6, j+4, k+9, Block.getBlockById(46), 0, 2);
	world.setBlock(i+7, j+4, k+9, Block.getBlockById(46), 0, 2);
	world.setBlock(i+8, j+4, k+9, Block.getBlockById(46), 0, 2);
	world.setBlock(i+9, j+4, k+9, Block.getBlockById(46), 0, 2);
	world.setBlock(i+10, j+4, k+9, Block.getBlockById(0), 0, 2);
	world.setBlock(i+11, j+4, k+9, Block.getBlockById(46), 0, 2);
	world.setBlock(i+12, j+4, k+9, Block.getBlockById(0), 0, 2);
	world.setBlock(i+13, j+4, k+9, Block.getBlockById(0), 0, 2);
	world.setBlock(i+0, j+4, k+10, Block.getBlockById(46), 0, 2);
	world.setBlock(i+1, j+4, k+10, Block.getBlockById(46), 0, 2);
	world.setBlock(i+2, j+4, k+10, Block.getBlockById(46), 0, 2);
	world.setBlock(i+3, j+4, k+10, Block.getBlockById(46), 0, 2);
	world.setBlock(i+4, j+4, k+10, Block.getBlockById(46), 0, 2);
	world.setBlock(i+5, j+4, k+10, Block.getBlockById(0), 0, 2);
	world.setBlock(i+6, j+4, k+10, Block.getBlockById(0), 0, 2);
	world.setBlock(i+7, j+4, k+10, Block.getBlockById(0), 0, 2);
	world.setBlock(i+8, j+4, k+10, Block.getBlockById(46), 0, 2);
	world.setBlock(i+9, j+4, k+10, Block.getBlockById(46), 0, 2);
	world.setBlock(i+10, j+4, k+10, Block.getBlockById(46), 0, 2);
	world.setBlock(i+11, j+4, k+10, Block.getBlockById(46), 0, 2);
	world.setBlock(i+12, j+4, k+10, Block.getBlockById(46), 0, 2);
	world.setBlock(i+13, j+4, k+10, Block.getBlockById(0), 0, 2);
	world.setBlock(i+0, j+4, k+11, Block.getBlockById(0), 0, 2);
	world.setBlock(i+1, j+4, k+11, Block.getBlockById(46), 0, 2);
	world.setBlock(i+2, j+4, k+11, Block.getBlockById(46), 0, 2);
	world.setBlock(i+3, j+4, k+11, Block.getBlockById(46), 0, 2);
	world.setBlock(i+4, j+4, k+11, Block.getBlockById(0), 0, 2);
	world.setBlock(i+5, j+4, k+11, Block.getBlockById(0), 0, 2);
	world.setBlock(i+6, j+4, k+11, Block.getBlockById(0), 0, 2);
	world.setBlock(i+7, j+4, k+11, Block.getBlockById(0), 0, 2);
	world.setBlock(i+8, j+4, k+11, Block.getBlockById(0), 0, 2);
	world.setBlock(i+9, j+4, k+11, Block.getBlockById(46), 0, 2);
	world.setBlock(i+10, j+4, k+11, Block.getBlockById(46), 0, 2);
	world.setBlock(i+11, j+4, k+11, Block.getBlockById(46), 0, 2);
	world.setBlock(i+12, j+4, k+11, Block.getBlockById(46), 0, 2);
	world.setBlock(i+13, j+4, k+11, Block.getBlockById(46), 0, 2);
	world.setBlock(i+0, j+4, k+12, Block.getBlockById(0), 0, 2);
	world.setBlock(i+1, j+4, k+12, Block.getBlockById(0), 0, 2);
	world.setBlock(i+2, j+4, k+12, Block.getBlockById(46), 0, 2);
	world.setBlock(i+3, j+4, k+12, Block.getBlockById(0), 0, 2);
	world.setBlock(i+4, j+4, k+12, Block.getBlockById(0), 0, 2);
	world.setBlock(i+5, j+4, k+12, Block.getBlockById(0), 0, 2);
	world.setBlock(i+6, j+4, k+12, Block.getBlockById(0), 0, 2);
	world.setBlock(i+7, j+4, k+12, Block.getBlockById(0), 0, 2);
	world.setBlock(i+8, j+4, k+12, Block.getBlockById(0), 0, 2);
	world.setBlock(i+9, j+4, k+12, Block.getBlockById(0), 0, 2);
	world.setBlock(i+10, j+4, k+12, Block.getBlockById(46), 0, 2);
	world.setBlock(i+11, j+4, k+12, Block.getBlockById(46), 0, 2);
	world.setBlock(i+12, j+4, k+12, Block.getBlockById(46), 0, 2);
	world.setBlock(i+13, j+4, k+12, Block.getBlockById(0), 0, 2);
	world.setBlock(i+0, j+4, k+13, Block.getBlockById(0), 0, 2);
	world.setBlock(i+1, j+4, k+13, Block.getBlockById(0), 0, 2);
	world.setBlock(i+2, j+4, k+13, Block.getBlockById(0), 0, 2);
	world.setBlock(i+3, j+4, k+13, Block.getBlockById(0), 0, 2);
	world.setBlock(i+4, j+4, k+13, Block.getBlockById(0), 0, 2);
	world.setBlock(i+5, j+4, k+13, Block.getBlockById(0), 0, 2);
	world.setBlock(i+6, j+4, k+13, Block.getBlockById(0), 0, 2);
	world.setBlock(i+7, j+4, k+13, Block.getBlockById(0), 0, 2);
	world.setBlock(i+8, j+4, k+13, Block.getBlockById(0), 0, 2);
	world.setBlock(i+9, j+4, k+13, Block.getBlockById(0), 0, 2);
	world.setBlock(i+10, j+4, k+13, Block.getBlockById(0), 0, 2);
	world.setBlock(i+11, j+4, k+13, Block.getBlockById(46), 0, 2);
	world.setBlock(i+12, j+4, k+13, Block.getBlockById(0), 0, 2);
	world.setBlock(i+13, j+4, k+13, Block.getBlockById(0), 0, 2);
	world.setBlock(i+0, j+5, k+0, Block.getBlockById(0), 0, 2);
	world.setBlock(i+1, j+5, k+0, Block.getBlockById(0), 0, 2);
	world.setBlock(i+2, j+5, k+0, Block.getBlockById(46), 0, 2);
	world.setBlock(i+3, j+5, k+0, Block.getBlockById(0), 0, 2);
	world.setBlock(i+4, j+5, k+0, Block.getBlockById(0), 0, 2);
	world.setBlock(i+5, j+5, k+0, Block.getBlockById(0), 0, 2);
	world.setBlock(i+6, j+5, k+0, Block.getBlockById(0), 0, 2);
	world.setBlock(i+7, j+5, k+0, Block.getBlockById(0), 0, 2);
	world.setBlock(i+8, j+5, k+0, Block.getBlockById(0), 0, 2);
	world.setBlock(i+9, j+5, k+0, Block.getBlockById(0), 0, 2);
	world.setBlock(i+10, j+5, k+0, Block.getBlockById(46), 0, 2);
	world.setBlock(i+11, j+5, k+0, Block.getBlockById(0), 0, 2);
	world.setBlock(i+12, j+5, k+0, Block.getBlockById(0), 0, 2);
	world.setBlock(i+13, j+5, k+0, Block.getBlockById(0), 0, 2);
	world.setBlock(i+0, j+5, k+1, Block.getBlockById(0), 0, 2);
	world.setBlock(i+1, j+5, k+1, Block.getBlockById(46), 0, 2);
	world.setBlock(i+2, j+5, k+1, Block.getBlockById(46), 0, 2);
	world.setBlock(i+3, j+5, k+1, Block.getBlockById(46), 0, 2);
	world.setBlock(i+4, j+5, k+1, Block.getBlockById(0), 0, 2);
	world.setBlock(i+5, j+5, k+1, Block.getBlockById(0), 0, 2);
	world.setBlock(i+6, j+5, k+1, Block.getBlockById(0), 0, 2);
	world.setBlock(i+7, j+5, k+1, Block.getBlockById(0), 0, 2);
	world.setBlock(i+8, j+5, k+1, Block.getBlockById(0), 0, 2);
	world.setBlock(i+9, j+5, k+1, Block.getBlockById(46), 0, 2);
	world.setBlock(i+10, j+5, k+1, Block.getBlockById(46), 0, 2);
	world.setBlock(i+11, j+5, k+1, Block.getBlockById(46), 0, 2);
	world.setBlock(i+12, j+5, k+1, Block.getBlockById(0), 0, 2);
	world.setBlock(i+13, j+5, k+1, Block.getBlockById(0), 0, 2);
	world.setBlock(i+0, j+5, k+2, Block.getBlockById(46), 0, 2);
	world.setBlock(i+1, j+5, k+2, Block.getBlockById(46), 0, 2);
	world.setBlock(i+2, j+5, k+2, Block.getBlockById(46), 0, 2);
	world.setBlock(i+3, j+5, k+2, Block.getBlockById(46), 0, 2);
	world.setBlock(i+4, j+5, k+2, Block.getBlockById(46), 0, 2);
	world.setBlock(i+5, j+5, k+2, Block.getBlockById(0), 0, 2);
	world.setBlock(i+6, j+5, k+2, Block.getBlockById(0), 0, 2);
	world.setBlock(i+7, j+5, k+2, Block.getBlockById(0), 0, 2);
	world.setBlock(i+8, j+5, k+2, Block.getBlockById(46), 0, 2);
	world.setBlock(i+9, j+5, k+2, Block.getBlockById(46), 0, 2);
	world.setBlock(i+10, j+5, k+2, Block.getBlockById(46), 0, 2);
	world.setBlock(i+11, j+5, k+2, Block.getBlockById(46), 0, 2);
	world.setBlock(i+12, j+5, k+2, Block.getBlockById(46), 0, 2);
	world.setBlock(i+13, j+5, k+2, Block.getBlockById(0), 0, 2);
	world.setBlock(i+0, j+5, k+3, Block.getBlockById(0), 0, 2);
	world.setBlock(i+1, j+5, k+3, Block.getBlockById(46), 0, 2);
	world.setBlock(i+2, j+5, k+3, Block.getBlockById(46), 0, 2);
	world.setBlock(i+3, j+5, k+3, Block.getBlockById(46), 0, 2);
	world.setBlock(i+4, j+5, k+3, Block.getBlockById(46), 0, 2);
	world.setBlock(i+5, j+5, k+3, Block.getBlockById(46), 0, 2);
	world.setBlock(i+6, j+5, k+3, Block.getBlockById(46), 0, 2);
	world.setBlock(i+7, j+5, k+3, Block.getBlockById(46), 0, 2);
	world.setBlock(i+8, j+5, k+3, Block.getBlockById(46), 0, 2);
	world.setBlock(i+9, j+5, k+3, Block.getBlockById(46), 0, 2);
	world.setBlock(i+10, j+5, k+3, Block.getBlockById(46), 0, 2);
	world.setBlock(i+11, j+5, k+3, Block.getBlockById(46), 0, 2);
	world.setBlock(i+12, j+5, k+3, Block.getBlockById(0), 0, 2);
	world.setBlock(i+13, j+5, k+3, Block.getBlockById(0), 0, 2);
	world.setBlock(i+0, j+5, k+4, Block.getBlockById(0), 0, 2);
	world.setBlock(i+1, j+5, k+4, Block.getBlockById(0), 0, 2);
	world.setBlock(i+2, j+5, k+4, Block.getBlockById(46), 0, 2);
	world.setBlock(i+3, j+5, k+4, Block.getBlockById(46), 0, 2);
	world.setBlock(i+4, j+5, k+4, Block.getBlockById(46), 0, 2);
	world.setBlock(i+5, j+5, k+4, Block.getBlockById(46), 0, 2);
	world.setBlock(i+6, j+5, k+4, Block.getBlockById(46), 0, 2);
	world.setBlock(i+7, j+5, k+4, Block.getBlockById(46), 0, 2);
	world.setBlock(i+8, j+5, k+4, Block.getBlockById(46), 0, 2);
	world.setBlock(i+9, j+5, k+4, Block.getBlockById(46), 0, 2);
	world.setBlock(i+10, j+5, k+4, Block.getBlockById(46), 0, 2);
	world.setBlock(i+11, j+5, k+4, Block.getBlockById(0), 0, 2);
	world.setBlock(i+12, j+5, k+4, Block.getBlockById(0), 0, 2);
	world.setBlock(i+13, j+5, k+4, Block.getBlockById(0), 0, 2);
	world.setBlock(i+0, j+5, k+5, Block.getBlockById(0), 0, 2);
	world.setBlock(i+1, j+5, k+5, Block.getBlockById(0), 0, 2);
	world.setBlock(i+2, j+5, k+5, Block.getBlockById(0), 0, 2);
	world.setBlock(i+3, j+5, k+5, Block.getBlockById(46), 0, 2);
	world.setBlock(i+4, j+5, k+5, Block.getBlockById(46), 0, 2);
	world.setBlock(i+5, j+5, k+5, Block.getBlockById(46), 0, 2);
	world.setBlock(i+6, j+5, k+5, Block.getBlockById(46), 0, 2);
	world.setBlock(i+7, j+5, k+5, Block.getBlockById(46), 0, 2);
	world.setBlock(i+8, j+5, k+5, Block.getBlockById(46), 0, 2);
	world.setBlock(i+9, j+5, k+5, Block.getBlockById(46), 0, 2);
	world.setBlock(i+10, j+5, k+5, Block.getBlockById(0), 0, 2);
	world.setBlock(i+11, j+5, k+5, Block.getBlockById(0), 0, 2);
	world.setBlock(i+12, j+5, k+5, Block.getBlockById(0), 0, 2);
	world.setBlock(i+13, j+5, k+5, Block.getBlockById(0), 0, 2);
	world.setBlock(i+0, j+5, k+6, Block.getBlockById(0), 0, 2);
	world.setBlock(i+1, j+5, k+6, Block.getBlockById(0), 0, 2);
	world.setBlock(i+2, j+5, k+6, Block.getBlockById(0), 0, 2);
	world.setBlock(i+3, j+5, k+6, Block.getBlockById(46), 0, 2);
	world.setBlock(i+4, j+5, k+6, Block.getBlockById(46), 0, 2);
	world.setBlock(i+5, j+5, k+6, Block.getBlockById(46), 0, 2);
	world.setBlock(i+6, j+5, k+6, Block.getBlockById(46), 0, 2);
	world.setBlock(i+7, j+5, k+6, Block.getBlockById(46), 0, 2);
	world.setBlock(i+8, j+5, k+6, Block.getBlockById(46), 0, 2);
	world.setBlock(i+9, j+5, k+6, Block.getBlockById(46), 0, 2);
	world.setBlock(i+10, j+5, k+6, Block.getBlockById(0), 0, 2);
	world.setBlock(i+11, j+5, k+6, Block.getBlockById(0), 0, 2);
	world.setBlock(i+12, j+5, k+6, Block.getBlockById(0), 0, 2);
	world.setBlock(i+13, j+5, k+6, Block.getBlockById(0), 0, 2);
	world.setBlock(i+0, j+5, k+7, Block.getBlockById(0), 0, 2);
	world.setBlock(i+1, j+5, k+7, Block.getBlockById(0), 0, 2);
	world.setBlock(i+2, j+5, k+7, Block.getBlockById(0), 0, 2);
	world.setBlock(i+3, j+5, k+7, Block.getBlockById(46), 0, 2);
	world.setBlock(i+4, j+5, k+7, Block.getBlockById(46), 0, 2);
	world.setBlock(i+5, j+5, k+7, Block.getBlockById(46), 0, 2);
	world.setBlock(i+6, j+5, k+7, Block.getBlockById(46), 0, 2);
	world.setBlock(i+7, j+5, k+7, Block.getBlockById(46), 0, 2);
	world.setBlock(i+8, j+5, k+7, Block.getBlockById(46), 0, 2);
	world.setBlock(i+9, j+5, k+7, Block.getBlockById(46), 0, 2);
	world.setBlock(i+10, j+5, k+7, Block.getBlockById(0), 0, 2);
	world.setBlock(i+11, j+5, k+7, Block.getBlockById(0), 0, 2);
	world.setBlock(i+12, j+5, k+7, Block.getBlockById(0), 0, 2);
	world.setBlock(i+13, j+5, k+7, Block.getBlockById(0), 0, 2);
	world.setBlock(i+0, j+5, k+8, Block.getBlockById(0), 0, 2);
	world.setBlock(i+1, j+5, k+8, Block.getBlockById(0), 0, 2);
	world.setBlock(i+2, j+5, k+8, Block.getBlockById(46), 0, 2);
	world.setBlock(i+3, j+5, k+8, Block.getBlockById(46), 0, 2);
	world.setBlock(i+4, j+5, k+8, Block.getBlockById(46), 0, 2);
	world.setBlock(i+5, j+5, k+8, Block.getBlockById(46), 0, 2);
	world.setBlock(i+6, j+5, k+8, Block.getBlockById(46), 0, 2);
	world.setBlock(i+7, j+5, k+8, Block.getBlockById(46), 0, 2);
	world.setBlock(i+8, j+5, k+8, Block.getBlockById(46), 0, 2);
	world.setBlock(i+9, j+5, k+8, Block.getBlockById(46), 0, 2);
	world.setBlock(i+10, j+5, k+8, Block.getBlockById(0), 0, 2);
	world.setBlock(i+11, j+5, k+8, Block.getBlockById(0), 0, 2);
	world.setBlock(i+12, j+5, k+8, Block.getBlockById(0), 0, 2);
	world.setBlock(i+13, j+5, k+8, Block.getBlockById(0), 0, 2);
	world.setBlock(i+0, j+5, k+9, Block.getBlockById(0), 0, 2);
	world.setBlock(i+1, j+5, k+9, Block.getBlockById(46), 0, 2);
	world.setBlock(i+2, j+5, k+9, Block.getBlockById(46), 0, 2);
	world.setBlock(i+3, j+5, k+9, Block.getBlockById(46), 0, 2);
	world.setBlock(i+4, j+5, k+9, Block.getBlockById(46), 0, 2);
	world.setBlock(i+5, j+5, k+9, Block.getBlockById(46), 0, 2);
	world.setBlock(i+6, j+5, k+9, Block.getBlockById(46), 0, 2);
	world.setBlock(i+7, j+5, k+9, Block.getBlockById(46), 0, 2);
	world.setBlock(i+8, j+5, k+9, Block.getBlockById(46), 0, 2);
	world.setBlock(i+9, j+5, k+9, Block.getBlockById(46), 0, 2);
	world.setBlock(i+10, j+5, k+9, Block.getBlockById(0), 0, 2);
	world.setBlock(i+11, j+5, k+9, Block.getBlockById(46), 0, 2);
	world.setBlock(i+12, j+5, k+9, Block.getBlockById(0), 0, 2);
	world.setBlock(i+13, j+5, k+9, Block.getBlockById(0), 0, 2);
	world.setBlock(i+0, j+5, k+10, Block.getBlockById(46), 0, 2);
	world.setBlock(i+1, j+5, k+10, Block.getBlockById(46), 0, 2);
	world.setBlock(i+2, j+5, k+10, Block.getBlockById(46), 0, 2);
	world.setBlock(i+3, j+5, k+10, Block.getBlockById(46), 0, 2);
	world.setBlock(i+4, j+5, k+10, Block.getBlockById(46), 0, 2);
	world.setBlock(i+5, j+5, k+10, Block.getBlockById(0), 0, 2);
	world.setBlock(i+6, j+5, k+10, Block.getBlockById(0), 0, 2);
	world.setBlock(i+7, j+5, k+10, Block.getBlockById(0), 0, 2);
	world.setBlock(i+8, j+5, k+10, Block.getBlockById(46), 0, 2);
	world.setBlock(i+9, j+5, k+10, Block.getBlockById(46), 0, 2);
	world.setBlock(i+10, j+5, k+10, Block.getBlockById(46), 0, 2);
	world.setBlock(i+11, j+5, k+10, Block.getBlockById(46), 0, 2);
	world.setBlock(i+12, j+5, k+10, Block.getBlockById(46), 0, 2);
	world.setBlock(i+13, j+5, k+10, Block.getBlockById(0), 0, 2);
	world.setBlock(i+0, j+5, k+11, Block.getBlockById(0), 0, 2);
	world.setBlock(i+1, j+5, k+11, Block.getBlockById(46), 0, 2);
	world.setBlock(i+2, j+5, k+11, Block.getBlockById(46), 0, 2);
	world.setBlock(i+3, j+5, k+11, Block.getBlockById(46), 0, 2);
	world.setBlock(i+4, j+5, k+11, Block.getBlockById(0), 0, 2);
	world.setBlock(i+5, j+5, k+11, Block.getBlockById(0), 0, 2);
	world.setBlock(i+6, j+5, k+11, Block.getBlockById(0), 0, 2);
	world.setBlock(i+7, j+5, k+11, Block.getBlockById(0), 0, 2);
	world.setBlock(i+8, j+5, k+11, Block.getBlockById(0), 0, 2);
	world.setBlock(i+9, j+5, k+11, Block.getBlockById(46), 0, 2);
	world.setBlock(i+10, j+5, k+11, Block.getBlockById(46), 0, 2);
	world.setBlock(i+11, j+5, k+11, Block.getBlockById(46), 0, 2);
	world.setBlock(i+12, j+5, k+11, Block.getBlockById(46), 0, 2);
	world.setBlock(i+13, j+5, k+11, Block.getBlockById(46), 0, 2);
	world.setBlock(i+0, j+5, k+12, Block.getBlockById(0), 0, 2);
	world.setBlock(i+1, j+5, k+12, Block.getBlockById(0), 0, 2);
	world.setBlock(i+2, j+5, k+12, Block.getBlockById(46), 0, 2);
	world.setBlock(i+3, j+5, k+12, Block.getBlockById(0), 0, 2);
	world.setBlock(i+4, j+5, k+12, Block.getBlockById(0), 0, 2);
	world.setBlock(i+5, j+5, k+12, Block.getBlockById(0), 0, 2);
	world.setBlock(i+6, j+5, k+12, Block.getBlockById(0), 0, 2);
	world.setBlock(i+7, j+5, k+12, Block.getBlockById(0), 0, 2);
	world.setBlock(i+8, j+5, k+12, Block.getBlockById(0), 0, 2);
	world.setBlock(i+9, j+5, k+12, Block.getBlockById(0), 0, 2);
	world.setBlock(i+10, j+5, k+12, Block.getBlockById(46), 0, 2);
	world.setBlock(i+11, j+5, k+12, Block.getBlockById(46), 0, 2);
	world.setBlock(i+12, j+5, k+12, Block.getBlockById(46), 0, 2);
	world.setBlock(i+13, j+5, k+12, Block.getBlockById(0), 0, 2);
	world.setBlock(i+0, j+5, k+13, Block.getBlockById(0), 0, 2);
	world.setBlock(i+1, j+5, k+13, Block.getBlockById(0), 0, 2);
	world.setBlock(i+2, j+5, k+13, Block.getBlockById(0), 0, 2);
	world.setBlock(i+3, j+5, k+13, Block.getBlockById(0), 0, 2);
	world.setBlock(i+4, j+5, k+13, Block.getBlockById(0), 0, 2);
	world.setBlock(i+5, j+5, k+13, Block.getBlockById(0), 0, 2);
	world.setBlock(i+6, j+5, k+13, Block.getBlockById(0), 0, 2);
	world.setBlock(i+7, j+5, k+13, Block.getBlockById(0), 0, 2);
	world.setBlock(i+8, j+5, k+13, Block.getBlockById(0), 0, 2);
	world.setBlock(i+9, j+5, k+13, Block.getBlockById(0), 0, 2);
	world.setBlock(i+10, j+5, k+13, Block.getBlockById(0), 0, 2);
	world.setBlock(i+11, j+5, k+13, Block.getBlockById(46), 0, 2);
	world.setBlock(i+12, j+5, k+13, Block.getBlockById(0), 0, 2);
	world.setBlock(i+13, j+5, k+13, Block.getBlockById(0), 0, 2);
	world.setBlock(i+0, j+6, k+0, Block.getBlockById(0), 0, 2);
	world.setBlock(i+1, j+6, k+0, Block.getBlockById(0), 0, 2);
	world.setBlock(i+2, j+6, k+0, Block.getBlockById(46), 0, 2);
	world.setBlock(i+3, j+6, k+0, Block.getBlockById(0), 0, 2);
	world.setBlock(i+4, j+6, k+0, Block.getBlockById(0), 0, 2);
	world.setBlock(i+5, j+6, k+0, Block.getBlockById(0), 0, 2);
	world.setBlock(i+6, j+6, k+0, Block.getBlockById(0), 0, 2);
	world.setBlock(i+7, j+6, k+0, Block.getBlockById(0), 0, 2);
	world.setBlock(i+8, j+6, k+0, Block.getBlockById(0), 0, 2);
	world.setBlock(i+9, j+6, k+0, Block.getBlockById(0), 0, 2);
	world.setBlock(i+10, j+6, k+0, Block.getBlockById(46), 0, 2);
	world.setBlock(i+11, j+6, k+0, Block.getBlockById(0), 0, 2);
	world.setBlock(i+12, j+6, k+0, Block.getBlockById(0), 0, 2);
	world.setBlock(i+13, j+6, k+0, Block.getBlockById(0), 0, 2);
	world.setBlock(i+0, j+6, k+1, Block.getBlockById(0), 0, 2);
	world.setBlock(i+1, j+6, k+1, Block.getBlockById(0), 0, 2);
	world.setBlock(i+2, j+6, k+1, Block.getBlockById(0), 0, 2);
	world.setBlock(i+3, j+6, k+1, Block.getBlockById(0), 0, 2);
	world.setBlock(i+4, j+6, k+1, Block.getBlockById(0), 0, 2);
	world.setBlock(i+5, j+6, k+1, Block.getBlockById(0), 0, 2);
	world.setBlock(i+6, j+6, k+1, Block.getBlockById(0), 0, 2);
	world.setBlock(i+7, j+6, k+1, Block.getBlockById(0), 0, 2);
	world.setBlock(i+8, j+6, k+1, Block.getBlockById(0), 0, 2);
	world.setBlock(i+9, j+6, k+1, Block.getBlockById(0), 0, 2);
	world.setBlock(i+10, j+6, k+1, Block.getBlockById(0), 0, 2);
	world.setBlock(i+11, j+6, k+1, Block.getBlockById(0), 0, 2);
	world.setBlock(i+12, j+6, k+1, Block.getBlockById(0), 0, 2);
	world.setBlock(i+13, j+6, k+1, Block.getBlockById(0), 0, 2);
	world.setBlock(i+0, j+6, k+2, Block.getBlockById(46), 0, 2);
	world.setBlock(i+1, j+6, k+2, Block.getBlockById(0), 0, 2);
	world.setBlock(i+2, j+6, k+2, Block.getBlockById(0), 0, 2);
	world.setBlock(i+3, j+6, k+2, Block.getBlockById(0), 0, 2);
	world.setBlock(i+4, j+6, k+2, Block.getBlockById(46), 0, 2);
	world.setBlock(i+5, j+6, k+2, Block.getBlockById(0), 0, 2);
	world.setBlock(i+6, j+6, k+2, Block.getBlockById(0), 0, 2);
	world.setBlock(i+7, j+6, k+2, Block.getBlockById(0), 0, 2);
	world.setBlock(i+8, j+6, k+2, Block.getBlockById(46), 0, 2);
	world.setBlock(i+9, j+6, k+2, Block.getBlockById(0), 0, 2);
	world.setBlock(i+10, j+6, k+2, Block.getBlockById(0), 0, 2);
	world.setBlock(i+11, j+6, k+2, Block.getBlockById(0), 0, 2);
	world.setBlock(i+12, j+6, k+2, Block.getBlockById(46), 0, 2);
	world.setBlock(i+13, j+6, k+2, Block.getBlockById(0), 0, 2);
	world.setBlock(i+0, j+6, k+3, Block.getBlockById(0), 0, 2);
	world.setBlock(i+1, j+6, k+3, Block.getBlockById(0), 0, 2);
	world.setBlock(i+2, j+6, k+3, Block.getBlockById(0), 0, 2);
	world.setBlock(i+3, j+6, k+3, Block.getBlockById(0), 0, 2);
	world.setBlock(i+4, j+6, k+3, Block.getBlockById(0), 0, 2);
	world.setBlock(i+5, j+6, k+3, Block.getBlockById(0), 0, 2);
	world.setBlock(i+6, j+6, k+3, Block.getBlockById(0), 0, 2);
	world.setBlock(i+7, j+6, k+3, Block.getBlockById(0), 0, 2);
	world.setBlock(i+8, j+6, k+3, Block.getBlockById(0), 0, 2);
	world.setBlock(i+9, j+6, k+3, Block.getBlockById(0), 0, 2);
	world.setBlock(i+10, j+6, k+3, Block.getBlockById(0), 0, 2);
	world.setBlock(i+11, j+6, k+3, Block.getBlockById(0), 0, 2);
	world.setBlock(i+12, j+6, k+3, Block.getBlockById(0), 0, 2);
	world.setBlock(i+13, j+6, k+3, Block.getBlockById(0), 0, 2);
	world.setBlock(i+0, j+6, k+4, Block.getBlockById(0), 0, 2);
	world.setBlock(i+1, j+6, k+4, Block.getBlockById(0), 0, 2);
	world.setBlock(i+2, j+6, k+4, Block.getBlockById(46), 0, 2);
	world.setBlock(i+3, j+6, k+4, Block.getBlockById(0), 0, 2);
	world.setBlock(i+4, j+6, k+4, Block.getBlockById(0), 0, 2);
	world.setBlock(i+5, j+6, k+4, Block.getBlockById(0), 0, 2);
	world.setBlock(i+6, j+6, k+4, Block.getBlockById(0), 0, 2);
	world.setBlock(i+7, j+6, k+4, Block.getBlockById(0), 0, 2);
	world.setBlock(i+8, j+6, k+4, Block.getBlockById(0), 0, 2);
	world.setBlock(i+9, j+6, k+4, Block.getBlockById(0), 0, 2);
	world.setBlock(i+10, j+6, k+4, Block.getBlockById(46), 0, 2);
	world.setBlock(i+11, j+6, k+4, Block.getBlockById(0), 0, 2);
	world.setBlock(i+12, j+6, k+4, Block.getBlockById(0), 0, 2);
	world.setBlock(i+13, j+6, k+4, Block.getBlockById(0), 0, 2);
	world.setBlock(i+0, j+6, k+5, Block.getBlockById(0), 0, 2);
	world.setBlock(i+1, j+6, k+5, Block.getBlockById(0), 0, 2);
	world.setBlock(i+2, j+6, k+5, Block.getBlockById(0), 0, 2);
	world.setBlock(i+3, j+6, k+5, Block.getBlockById(0), 0, 2);
	world.setBlock(i+4, j+6, k+5, Block.getBlockById(0), 0, 2);
	world.setBlock(i+5, j+6, k+5, Block.getBlockById(0), 0, 2);
	world.setBlock(i+6, j+6, k+5, Block.getBlockById(0), 0, 2);
	world.setBlock(i+7, j+6, k+5, Block.getBlockById(0), 0, 2);
	world.setBlock(i+8, j+6, k+5, Block.getBlockById(0), 0, 2);
	world.setBlock(i+9, j+6, k+5, Block.getBlockById(0), 0, 2);
	world.setBlock(i+10, j+6, k+5, Block.getBlockById(0), 0, 2);
	world.setBlock(i+11, j+6, k+5, Block.getBlockById(0), 0, 2);
	world.setBlock(i+12, j+6, k+5, Block.getBlockById(0), 0, 2);
	world.setBlock(i+13, j+6, k+5, Block.getBlockById(0), 0, 2);
	world.setBlock(i+0, j+6, k+6, Block.getBlockById(0), 0, 2);
	world.setBlock(i+1, j+6, k+6, Block.getBlockById(0), 0, 2);
	world.setBlock(i+2, j+6, k+6, Block.getBlockById(0), 0, 2);
	world.setBlock(i+3, j+6, k+6, Block.getBlockById(0), 0, 2);
	world.setBlock(i+4, j+6, k+6, Block.getBlockById(0), 0, 2);
	world.setBlock(i+5, j+6, k+6, Block.getBlockById(0), 0, 2);
	world.setBlock(i+6, j+6, k+6, Block.getBlockById(0), 0, 2);
	world.setBlock(i+7, j+6, k+6, Block.getBlockById(0), 0, 2);
	world.setBlock(i+8, j+6, k+6, Block.getBlockById(0), 0, 2);
	world.setBlock(i+9, j+6, k+6, Block.getBlockById(0), 0, 2);
	world.setBlock(i+10, j+6, k+6, Block.getBlockById(0), 0, 2);
	world.setBlock(i+11, j+6, k+6, Block.getBlockById(0), 0, 2);
	world.setBlock(i+12, j+6, k+6, Block.getBlockById(0), 0, 2);
	world.setBlock(i+13, j+6, k+6, Block.getBlockById(0), 0, 2);
	world.setBlock(i+0, j+6, k+7, Block.getBlockById(0), 0, 2);
	world.setBlock(i+1, j+6, k+7, Block.getBlockById(0), 0, 2);
	world.setBlock(i+2, j+6, k+7, Block.getBlockById(0), 0, 2);
	world.setBlock(i+3, j+6, k+7, Block.getBlockById(0), 0, 2);
	world.setBlock(i+4, j+6, k+7, Block.getBlockById(0), 0, 2);
	world.setBlock(i+5, j+6, k+7, Block.getBlockById(0), 0, 2);
	world.setBlock(i+6, j+6, k+7, Block.getBlockById(0), 0, 2);
	world.setBlock(i+7, j+6, k+7, Block.getBlockById(0), 0, 2);
	world.setBlock(i+8, j+6, k+7, Block.getBlockById(0), 0, 2);
	world.setBlock(i+9, j+6, k+7, Block.getBlockById(0), 0, 2);
	world.setBlock(i+10, j+6, k+7, Block.getBlockById(0), 0, 2);
	world.setBlock(i+11, j+6, k+7, Block.getBlockById(0), 0, 2);
	world.setBlock(i+12, j+6, k+7, Block.getBlockById(0), 0, 2);
	world.setBlock(i+13, j+6, k+7, Block.getBlockById(0), 0, 2);
	world.setBlock(i+0, j+6, k+8, Block.getBlockById(0), 0, 2);
	world.setBlock(i+1, j+6, k+8, Block.getBlockById(0), 0, 2);
	world.setBlock(i+2, j+6, k+8, Block.getBlockById(46), 0, 2);
	world.setBlock(i+3, j+6, k+8, Block.getBlockById(0), 0, 2);
	world.setBlock(i+4, j+6, k+8, Block.getBlockById(0), 0, 2);
	world.setBlock(i+5, j+6, k+8, Block.getBlockById(0), 0, 2);
	world.setBlock(i+6, j+6, k+8, Block.getBlockById(0), 0, 2);
	world.setBlock(i+7, j+6, k+8, Block.getBlockById(0), 0, 2);
	world.setBlock(i+8, j+6, k+8, Block.getBlockById(0), 0, 2);
	world.setBlock(i+9, j+6, k+8, Block.getBlockById(0), 0, 2);
	world.setBlock(i+10, j+6, k+8, Block.getBlockById(0), 0, 2);
	world.setBlock(i+11, j+6, k+8, Block.getBlockById(0), 0, 2);
	world.setBlock(i+12, j+6, k+8, Block.getBlockById(0), 0, 2);
	world.setBlock(i+13, j+6, k+8, Block.getBlockById(0), 0, 2);
	world.setBlock(i+0, j+6, k+9, Block.getBlockById(0), 0, 2);
	world.setBlock(i+1, j+6, k+9, Block.getBlockById(0), 0, 2);
	world.setBlock(i+2, j+6, k+9, Block.getBlockById(0), 0, 2);
	world.setBlock(i+3, j+6, k+9, Block.getBlockById(0), 0, 2);
	world.setBlock(i+4, j+6, k+9, Block.getBlockById(0), 0, 2);
	world.setBlock(i+5, j+6, k+9, Block.getBlockById(0), 0, 2);
	world.setBlock(i+6, j+6, k+9, Block.getBlockById(0), 0, 2);
	world.setBlock(i+7, j+6, k+9, Block.getBlockById(0), 0, 2);
	world.setBlock(i+8, j+6, k+9, Block.getBlockById(0), 0, 2);
	world.setBlock(i+9, j+6, k+9, Block.getBlockById(0), 0, 2);
	world.setBlock(i+10, j+6, k+9, Block.getBlockById(0), 0, 2);
	world.setBlock(i+11, j+6, k+9, Block.getBlockById(46), 0, 2);
	world.setBlock(i+12, j+6, k+9, Block.getBlockById(0), 0, 2);
	world.setBlock(i+13, j+6, k+9, Block.getBlockById(0), 0, 2);
	world.setBlock(i+0, j+6, k+10, Block.getBlockById(46), 0, 2);
	world.setBlock(i+1, j+6, k+10, Block.getBlockById(0), 0, 2);
	world.setBlock(i+2, j+6, k+10, Block.getBlockById(0), 0, 2);
	world.setBlock(i+3, j+6, k+10, Block.getBlockById(0), 0, 2);
	world.setBlock(i+4, j+6, k+10, Block.getBlockById(46), 0, 2);
	world.setBlock(i+5, j+6, k+10, Block.getBlockById(0), 0, 2);
	world.setBlock(i+6, j+6, k+10, Block.getBlockById(0), 0, 2);
	world.setBlock(i+7, j+6, k+10, Block.getBlockById(0), 0, 2);
	world.setBlock(i+8, j+6, k+10, Block.getBlockById(46), 0, 2);
	world.setBlock(i+9, j+6, k+10, Block.getBlockById(0), 0, 2);
	world.setBlock(i+10, j+6, k+10, Block.getBlockById(0), 0, 2);
	world.setBlock(i+11, j+6, k+10, Block.getBlockById(0), 0, 2);
	world.setBlock(i+12, j+6, k+10, Block.getBlockById(0), 0, 2);
	world.setBlock(i+13, j+6, k+10, Block.getBlockById(0), 0, 2);
	world.setBlock(i+0, j+6, k+11, Block.getBlockById(0), 0, 2);
	world.setBlock(i+1, j+6, k+11, Block.getBlockById(0), 0, 2);
	world.setBlock(i+2, j+6, k+11, Block.getBlockById(0), 0, 2);
	world.setBlock(i+3, j+6, k+11, Block.getBlockById(0), 0, 2);
	world.setBlock(i+4, j+6, k+11, Block.getBlockById(0), 0, 2);
	world.setBlock(i+5, j+6, k+11, Block.getBlockById(0), 0, 2);
	world.setBlock(i+6, j+6, k+11, Block.getBlockById(0), 0, 2);
	world.setBlock(i+7, j+6, k+11, Block.getBlockById(0), 0, 2);
	world.setBlock(i+8, j+6, k+11, Block.getBlockById(0), 0, 2);
	world.setBlock(i+9, j+6, k+11, Block.getBlockById(46), 0, 2);
	world.setBlock(i+10, j+6, k+11, Block.getBlockById(0), 0, 2);
	world.setBlock(i+11, j+6, k+11, Block.getBlockById(0), 0, 2);
	world.setBlock(i+12, j+6, k+11, Block.getBlockById(0), 0, 2);
	world.setBlock(i+13, j+6, k+11, Block.getBlockById(46), 0, 2);
	world.setBlock(i+0, j+6, k+12, Block.getBlockById(0), 0, 2);
	world.setBlock(i+1, j+6, k+12, Block.getBlockById(0), 0, 2);
	world.setBlock(i+2, j+6, k+12, Block.getBlockById(46), 0, 2);
	world.setBlock(i+3, j+6, k+12, Block.getBlockById(0), 0, 2);
	world.setBlock(i+4, j+6, k+12, Block.getBlockById(0), 0, 2);
	world.setBlock(i+5, j+6, k+12, Block.getBlockById(0), 0, 2);
	world.setBlock(i+6, j+6, k+12, Block.getBlockById(0), 0, 2);
	world.setBlock(i+7, j+6, k+12, Block.getBlockById(0), 0, 2);
	world.setBlock(i+8, j+6, k+12, Block.getBlockById(0), 0, 2);
	world.setBlock(i+9, j+6, k+12, Block.getBlockById(0), 0, 2);
	world.setBlock(i+10, j+6, k+12, Block.getBlockById(0), 0, 2);
	world.setBlock(i+11, j+6, k+12, Block.getBlockById(0), 0, 2);
	world.setBlock(i+12, j+6, k+12, Block.getBlockById(0), 0, 2);
	world.setBlock(i+13, j+6, k+12, Block.getBlockById(0), 0, 2);
	world.setBlock(i+0, j+6, k+13, Block.getBlockById(0), 0, 2);
	world.setBlock(i+1, j+6, k+13, Block.getBlockById(0), 0, 2);
	world.setBlock(i+2, j+6, k+13, Block.getBlockById(0), 0, 2);
	world.setBlock(i+3, j+6, k+13, Block.getBlockById(0), 0, 2);
	world.setBlock(i+4, j+6, k+13, Block.getBlockById(0), 0, 2);
	world.setBlock(i+5, j+6, k+13, Block.getBlockById(0), 0, 2);
	world.setBlock(i+6, j+6, k+13, Block.getBlockById(0), 0, 2);
	world.setBlock(i+7, j+6, k+13, Block.getBlockById(0), 0, 2);
	world.setBlock(i+8, j+6, k+13, Block.getBlockById(0), 0, 2);
	world.setBlock(i+9, j+6, k+13, Block.getBlockById(0), 0, 2);
	world.setBlock(i+10, j+6, k+13, Block.getBlockById(0), 0, 2);
	world.setBlock(i+11, j+6, k+13, Block.getBlockById(46), 0, 2);
	world.setBlock(i+12, j+6, k+13, Block.getBlockById(0), 0, 2);
	world.setBlock(i+13, j+6, k+13, Block.getBlockById(0), 0, 2);
	world.setBlock(i+0, j+7, k+0, Block.getBlockById(0), 0, 2);
	world.setBlock(i+1, j+7, k+0, Block.getBlockById(0), 0, 2);
	world.setBlock(i+2, j+7, k+0, Block.getBlockById(0), 0, 2);
	world.setBlock(i+3, j+7, k+0, Block.getBlockById(0), 0, 2);
	world.setBlock(i+4, j+7, k+0, Block.getBlockById(0), 0, 2);
	world.setBlock(i+5, j+7, k+0, Block.getBlockById(0), 0, 2);
	world.setBlock(i+6, j+7, k+0, Block.getBlockById(0), 0, 2);
	world.setBlock(i+7, j+7, k+0, Block.getBlockById(0), 0, 2);
	world.setBlock(i+8, j+7, k+0, Block.getBlockById(0), 0, 2);
	world.setBlock(i+9, j+7, k+0, Block.getBlockById(0), 0, 2);
	world.setBlock(i+10, j+7, k+0, Block.getBlockById(0), 0, 2);
	world.setBlock(i+11, j+7, k+0, Block.getBlockById(0), 0, 2);
	world.setBlock(i+12, j+7, k+0, Block.getBlockById(0), 0, 2);
	world.setBlock(i+13, j+7, k+0, Block.getBlockById(0), 0, 2);
	world.setBlock(i+0, j+7, k+1, Block.getBlockById(0), 0, 2);
	world.setBlock(i+1, j+7, k+1, Block.getBlockById(0), 0, 2);
	world.setBlock(i+2, j+7, k+1, Block.getBlockById(0), 0, 2);
	world.setBlock(i+3, j+7, k+1, Block.getBlockById(0), 0, 2);
	world.setBlock(i+4, j+7, k+1, Block.getBlockById(0), 0, 2);
	world.setBlock(i+5, j+7, k+1, Block.getBlockById(0), 0, 2);
	world.setBlock(i+6, j+7, k+1, Block.getBlockById(0), 0, 2);
	world.setBlock(i+7, j+7, k+1, Block.getBlockById(0), 0, 2);
	world.setBlock(i+8, j+7, k+1, Block.getBlockById(0), 0, 2);
	world.setBlock(i+9, j+7, k+1, Block.getBlockById(0), 0, 2);
	world.setBlock(i+10, j+7, k+1, Block.getBlockById(0), 0, 2);
	world.setBlock(i+11, j+7, k+1, Block.getBlockById(0), 0, 2);
	world.setBlock(i+12, j+7, k+1, Block.getBlockById(0), 0, 2);
	world.setBlock(i+13, j+7, k+1, Block.getBlockById(0), 0, 2);
	world.setBlock(i+0, j+7, k+2, Block.getBlockById(0), 0, 2);
	world.setBlock(i+1, j+7, k+2, Block.getBlockById(0), 0, 2);
	world.setBlock(i+2, j+7, k+2, Block.getBlockById(0), 0, 2);
	world.setBlock(i+3, j+7, k+2, Block.getBlockById(0), 0, 2);
	world.setBlock(i+4, j+7, k+2, Block.getBlockById(0), 0, 2);
	world.setBlock(i+5, j+7, k+2, Block.getBlockById(0), 0, 2);
	world.setBlock(i+6, j+7, k+2, Block.getBlockById(0), 0, 2);
	world.setBlock(i+7, j+7, k+2, Block.getBlockById(0), 0, 2);
	world.setBlock(i+8, j+7, k+2, Block.getBlockById(0), 0, 2);
	world.setBlock(i+9, j+7, k+2, Block.getBlockById(0), 0, 2);
	world.setBlock(i+10, j+7, k+2, Block.getBlockById(0), 0, 2);
	world.setBlock(i+11, j+7, k+2, Block.getBlockById(0), 0, 2);
	world.setBlock(i+12, j+7, k+2, Block.getBlockById(0), 0, 2);
	world.setBlock(i+13, j+7, k+2, Block.getBlockById(0), 0, 2);
	world.setBlock(i+0, j+7, k+3, Block.getBlockById(0), 0, 2);
	world.setBlock(i+1, j+7, k+3, Block.getBlockById(0), 0, 2);
	world.setBlock(i+2, j+7, k+3, Block.getBlockById(0), 0, 2);
	world.setBlock(i+3, j+7, k+3, Block.getBlockById(0), 0, 2);
	world.setBlock(i+4, j+7, k+3, Block.getBlockById(0), 0, 2);
	world.setBlock(i+5, j+7, k+3, Block.getBlockById(0), 0, 2);
	world.setBlock(i+6, j+7, k+3, Block.getBlockById(0), 0, 2);
	world.setBlock(i+7, j+7, k+3, Block.getBlockById(0), 0, 2);
	world.setBlock(i+8, j+7, k+3, Block.getBlockById(0), 0, 2);
	world.setBlock(i+9, j+7, k+3, Block.getBlockById(0), 0, 2);
	world.setBlock(i+10, j+7, k+3, Block.getBlockById(0), 0, 2);
	world.setBlock(i+11, j+7, k+3, Block.getBlockById(0), 0, 2);
	world.setBlock(i+12, j+7, k+3, Block.getBlockById(0), 0, 2);
	world.setBlock(i+13, j+7, k+3, Block.getBlockById(0), 0, 2);
	world.setBlock(i+0, j+7, k+4, Block.getBlockById(0), 0, 2);
	world.setBlock(i+1, j+7, k+4, Block.getBlockById(0), 0, 2);
	world.setBlock(i+2, j+7, k+4, Block.getBlockById(0), 0, 2);
	world.setBlock(i+3, j+7, k+4, Block.getBlockById(0), 0, 2);
	world.setBlock(i+4, j+7, k+4, Block.getBlockById(0), 0, 2);
	world.setBlock(i+5, j+7, k+4, Block.getBlockById(0), 0, 2);
	world.setBlock(i+6, j+7, k+4, Block.getBlockById(0), 0, 2);
	world.setBlock(i+7, j+7, k+4, Block.getBlockById(0), 0, 2);
	world.setBlock(i+8, j+7, k+4, Block.getBlockById(0), 0, 2);
	world.setBlock(i+9, j+7, k+4, Block.getBlockById(0), 0, 2);
	world.setBlock(i+10, j+7, k+4, Block.getBlockById(0), 0, 2);
	world.setBlock(i+11, j+7, k+4, Block.getBlockById(0), 0, 2);
	world.setBlock(i+12, j+7, k+4, Block.getBlockById(0), 0, 2);
	world.setBlock(i+13, j+7, k+4, Block.getBlockById(0), 0, 2);
	world.setBlock(i+0, j+7, k+5, Block.getBlockById(0), 0, 2);
	world.setBlock(i+1, j+7, k+5, Block.getBlockById(0), 0, 2);
	world.setBlock(i+2, j+7, k+5, Block.getBlockById(0), 0, 2);
	world.setBlock(i+3, j+7, k+5, Block.getBlockById(0), 0, 2);
	world.setBlock(i+4, j+7, k+5, Block.getBlockById(0), 0, 2);
	world.setBlock(i+5, j+7, k+5, Block.getBlockById(0), 0, 2);
	world.setBlock(i+6, j+7, k+5, Block.getBlockById(0), 0, 2);
	world.setBlock(i+7, j+7, k+5, Block.getBlockById(0), 0, 2);
	world.setBlock(i+8, j+7, k+5, Block.getBlockById(0), 0, 2);
	world.setBlock(i+9, j+7, k+5, Block.getBlockById(0), 0, 2);
	world.setBlock(i+10, j+7, k+5, Block.getBlockById(0), 0, 2);
	world.setBlock(i+11, j+7, k+5, Block.getBlockById(0), 0, 2);
	world.setBlock(i+12, j+7, k+5, Block.getBlockById(0), 0, 2);
	world.setBlock(i+13, j+7, k+5, Block.getBlockById(0), 0, 2);
	world.setBlock(i+0, j+7, k+6, Block.getBlockById(0), 0, 2);
	world.setBlock(i+1, j+7, k+6, Block.getBlockById(0), 0, 2);
	world.setBlock(i+2, j+7, k+6, Block.getBlockById(0), 0, 2);
	world.setBlock(i+3, j+7, k+6, Block.getBlockById(0), 0, 2);
	world.setBlock(i+4, j+7, k+6, Block.getBlockById(0), 0, 2);
	world.setBlock(i+5, j+7, k+6, Block.getBlockById(0), 0, 2);
	world.setBlock(i+6, j+7, k+6, Block.getBlockById(0), 0, 2);
	world.setBlock(i+7, j+7, k+6, Block.getBlockById(0), 0, 2);
	world.setBlock(i+8, j+7, k+6, Block.getBlockById(0), 0, 2);
	world.setBlock(i+9, j+7, k+6, Block.getBlockById(0), 0, 2);
	world.setBlock(i+10, j+7, k+6, Block.getBlockById(0), 0, 2);
	world.setBlock(i+11, j+7, k+6, Block.getBlockById(0), 0, 2);
	world.setBlock(i+12, j+7, k+6, Block.getBlockById(0), 0, 2);
	world.setBlock(i+13, j+7, k+6, Block.getBlockById(0), 0, 2);
	world.setBlock(i+0, j+7, k+7, Block.getBlockById(0), 0, 2);
	world.setBlock(i+1, j+7, k+7, Block.getBlockById(0), 0, 2);
	world.setBlock(i+2, j+7, k+7, Block.getBlockById(0), 0, 2);
	world.setBlock(i+3, j+7, k+7, Block.getBlockById(0), 0, 2);
	world.setBlock(i+4, j+7, k+7, Block.getBlockById(0), 0, 2);
	world.setBlock(i+5, j+7, k+7, Block.getBlockById(0), 0, 2);
	world.setBlock(i+6, j+7, k+7, Block.getBlockById(0), 0, 2);
	world.setBlock(i+7, j+7, k+7, Block.getBlockById(0), 0, 2);
	world.setBlock(i+8, j+7, k+7, Block.getBlockById(0), 0, 2);
	world.setBlock(i+9, j+7, k+7, Block.getBlockById(0), 0, 2);
	world.setBlock(i+10, j+7, k+7, Block.getBlockById(0), 0, 2);
	world.setBlock(i+11, j+7, k+7, Block.getBlockById(0), 0, 2);
	world.setBlock(i+12, j+7, k+7, Block.getBlockById(0), 0, 2);
	world.setBlock(i+13, j+7, k+7, Block.getBlockById(0), 0, 2);
	world.setBlock(i+0, j+7, k+8, Block.getBlockById(0), 0, 2);
	world.setBlock(i+1, j+7, k+8, Block.getBlockById(0), 0, 2);
	world.setBlock(i+2, j+7, k+8, Block.getBlockById(0), 0, 2);
	world.setBlock(i+3, j+7, k+8, Block.getBlockById(0), 0, 2);
	world.setBlock(i+4, j+7, k+8, Block.getBlockById(0), 0, 2);
	world.setBlock(i+5, j+7, k+8, Block.getBlockById(0), 0, 2);
	world.setBlock(i+6, j+7, k+8, Block.getBlockById(0), 0, 2);
	world.setBlock(i+7, j+7, k+8, Block.getBlockById(0), 0, 2);
	world.setBlock(i+8, j+7, k+8, Block.getBlockById(0), 0, 2);
	world.setBlock(i+9, j+7, k+8, Block.getBlockById(0), 0, 2);
	world.setBlock(i+10, j+7, k+8, Block.getBlockById(0), 0, 2);
	world.setBlock(i+11, j+7, k+8, Block.getBlockById(0), 0, 2);
	world.setBlock(i+12, j+7, k+8, Block.getBlockById(0), 0, 2);
	world.setBlock(i+13, j+7, k+8, Block.getBlockById(0), 0, 2);
	world.setBlock(i+0, j+7, k+9, Block.getBlockById(0), 0, 2);
	world.setBlock(i+1, j+7, k+9, Block.getBlockById(0), 0, 2);
	world.setBlock(i+2, j+7, k+9, Block.getBlockById(0), 0, 2);
	world.setBlock(i+3, j+7, k+9, Block.getBlockById(0), 0, 2);
	world.setBlock(i+4, j+7, k+9, Block.getBlockById(0), 0, 2);
	world.setBlock(i+5, j+7, k+9, Block.getBlockById(0), 0, 2);
	world.setBlock(i+6, j+7, k+9, Block.getBlockById(0), 0, 2);
	world.setBlock(i+7, j+7, k+9, Block.getBlockById(0), 0, 2);
	world.setBlock(i+8, j+7, k+9, Block.getBlockById(0), 0, 2);
	world.setBlock(i+9, j+7, k+9, Block.getBlockById(0), 0, 2);
	world.setBlock(i+10, j+7, k+9, Block.getBlockById(0), 0, 2);
	world.setBlock(i+11, j+7, k+9, Block.getBlockById(0), 0, 2);
	world.setBlock(i+12, j+7, k+9, Block.getBlockById(0), 0, 2);
	world.setBlock(i+13, j+7, k+9, Block.getBlockById(0), 0, 2);
	world.setBlock(i+0, j+7, k+10, Block.getBlockById(0), 0, 2);
	world.setBlock(i+1, j+7, k+10, Block.getBlockById(0), 0, 2);
	world.setBlock(i+2, j+7, k+10, Block.getBlockById(0), 0, 2);
	world.setBlock(i+3, j+7, k+10, Block.getBlockById(0), 0, 2);
	world.setBlock(i+4, j+7, k+10, Block.getBlockById(46), 0, 2);
	world.setBlock(i+5, j+7, k+10, Block.getBlockById(0), 0, 2);
	world.setBlock(i+6, j+7, k+10, Block.getBlockById(0), 0, 2);
	world.setBlock(i+7, j+7, k+10, Block.getBlockById(0), 0, 2);
	world.setBlock(i+8, j+7, k+10, Block.getBlockById(46), 0, 2);
	world.setBlock(i+9, j+7, k+10, Block.getBlockById(0), 0, 2);
	world.setBlock(i+10, j+7, k+10, Block.getBlockById(0), 0, 2);
	world.setBlock(i+11, j+7, k+10, Block.getBlockById(0), 0, 2);
	world.setBlock(i+12, j+7, k+10, Block.getBlockById(0), 0, 2);
	world.setBlock(i+13, j+7, k+10, Block.getBlockById(0), 0, 2);
	world.setBlock(i+0, j+7, k+11, Block.getBlockById(0), 0, 2);
	world.setBlock(i+1, j+7, k+11, Block.getBlockById(0), 0, 2);
	world.setBlock(i+2, j+7, k+11, Block.getBlockById(0), 0, 2);
	world.setBlock(i+3, j+7, k+11, Block.getBlockById(0), 0, 2);
	world.setBlock(i+4, j+7, k+11, Block.getBlockById(0), 0, 2);
	world.setBlock(i+5, j+7, k+11, Block.getBlockById(0), 0, 2);
	world.setBlock(i+6, j+7, k+11, Block.getBlockById(0), 0, 2);
	world.setBlock(i+7, j+7, k+11, Block.getBlockById(0), 0, 2);
	world.setBlock(i+8, j+7, k+11, Block.getBlockById(0), 0, 2);
	world.setBlock(i+9, j+7, k+11, Block.getBlockById(0), 0, 2);
	world.setBlock(i+10, j+7, k+11, Block.getBlockById(0), 0, 2);
	world.setBlock(i+11, j+7, k+11, Block.getBlockById(0), 0, 2);
	world.setBlock(i+12, j+7, k+11, Block.getBlockById(0), 0, 2);
	world.setBlock(i+13, j+7, k+11, Block.getBlockById(0), 0, 2);
	world.setBlock(i+0, j+7, k+12, Block.getBlockById(0), 0, 2);
	world.setBlock(i+1, j+7, k+12, Block.getBlockById(0), 0, 2);
	world.setBlock(i+2, j+7, k+12, Block.getBlockById(0), 0, 2);
	world.setBlock(i+3, j+7, k+12, Block.getBlockById(0), 0, 2);
	world.setBlock(i+4, j+7, k+12, Block.getBlockById(0), 0, 2);
	world.setBlock(i+5, j+7, k+12, Block.getBlockById(0), 0, 2);
	world.setBlock(i+6, j+7, k+12, Block.getBlockById(0), 0, 2);
	world.setBlock(i+7, j+7, k+12, Block.getBlockById(0), 0, 2);
	world.setBlock(i+8, j+7, k+12, Block.getBlockById(0), 0, 2);
	world.setBlock(i+9, j+7, k+12, Block.getBlockById(0), 0, 2);
	world.setBlock(i+10, j+7, k+12, Block.getBlockById(0), 0, 2);
	world.setBlock(i+11, j+7, k+12, Block.getBlockById(0), 0, 2);
	world.setBlock(i+12, j+7, k+12, Block.getBlockById(0), 0, 2);
	world.setBlock(i+13, j+7, k+12, Block.getBlockById(0), 0, 2);
	world.setBlock(i+0, j+7, k+13, Block.getBlockById(0), 0, 2);
	world.setBlock(i+1, j+7, k+13, Block.getBlockById(0), 0, 2);
	world.setBlock(i+2, j+7, k+13, Block.getBlockById(0), 0, 2);
	world.setBlock(i+3, j+7, k+13, Block.getBlockById(0), 0, 2);
	world.setBlock(i+4, j+7, k+13, Block.getBlockById(0), 0, 2);
	world.setBlock(i+5, j+7, k+13, Block.getBlockById(0), 0, 2);
	world.setBlock(i+6, j+7, k+13, Block.getBlockById(0), 0, 2);
	world.setBlock(i+7, j+7, k+13, Block.getBlockById(0), 0, 2);
	world.setBlock(i+8, j+7, k+13, Block.getBlockById(0), 0, 2);
	world.setBlock(i+9, j+7, k+13, Block.getBlockById(0), 0, 2);
	world.setBlock(i+10, j+7, k+13, Block.getBlockById(0), 0, 2);
	world.setBlock(i+11, j+7, k+13, Block.getBlockById(0), 0, 2);
	world.setBlock(i+12, j+7, k+13, Block.getBlockById(0), 0, 2);
}
}


return true;
}


public void removeItem(EntityPlayer ep, ItemStack removeitem) {
	IInventory inv = ep.inventory;
	for(int i=0; i < inv.getSizeInventory(); i++)
	{
		if(inv.getStackInSlot(i) != null)
		{
			ItemStack j = inv.getStackInSlot(i);
			if(j.getItem() != null && j.getItem() == removeitem.getItem())
			{
				inv.setInventorySlotContents(i, null);
			}
		}
	}
}

}
