package com.jtrent238.epicproportions.items.structureplacers;

import net.minecraft.block.Block;
import net.minecraft.entity.player.EntityPlayer;
import net.minecraft.item.Item;
import net.minecraft.item.ItemStack;
import net.minecraft.world.World;

public class itemBombyStructurePlacer extends Item{

public itemBombyStructurePlacer(int par1){
setMaxDamage(0);
maxStackSize = 1;
setUnlocalizedName("itemBombyStructurePlacer");
setTextureName("epicproportionsmod:itemBombyStructurePlacer");
//setCreativeTab(EpicProportionsMod.EpicProportionsMod);
}
public int getItemEnchantability()
{
    return 0;
}
public int getMaxItemUseDuration(ItemStack par1ItemStack)
{
    return 0;
}
public float getStrVsBlock(ItemStack par1ItemStack, Block par2Block)
{
    return 1.0F;
}

public boolean onItemUse(ItemStack itemStack, EntityPlayer entity, World world, int i, int j, int k, int l, float a, float b, float c){
float var4 = 1.0F;

if(true){
boolean place = true;

if(place){
	world.setBlock(i+0, j+0, k+0, Block.getBlockById(133), 0, 2);
	world.setBlock(i+1, j+0, k+0, Block.getBlockById(133), 0, 2);
	world.setBlock(i+2, j+0, k+0, Block.getBlockById(133), 0, 2);
	world.setBlock(i+3, j+0, k+0, Block.getBlockById(0), 0, 2);
	world.setBlock(i+4, j+0, k+0, Block.getBlockById(0), 0, 2);
	world.setBlock(i+5, j+0, k+0, Block.getBlockById(0), 0, 2);
	world.setBlock(i+6, j+0, k+0, Block.getBlockById(0), 0, 2);
	world.setBlock(i+7, j+0, k+0, Block.getBlockById(133), 0, 2);
	world.setBlock(i+8, j+0, k+0, Block.getBlockById(133), 0, 2);
	world.setBlock(i+9, j+0, k+0, Block.getBlockById(133), 0, 2);
	world.setBlock(i+0, j+0, k+1, Block.getBlockById(133), 0, 2);
	world.setBlock(i+1, j+0, k+1, Block.getBlockById(133), 0, 2);
	world.setBlock(i+2, j+0, k+1, Block.getBlockById(133), 0, 2);
	world.setBlock(i+3, j+0, k+1, Block.getBlockById(0), 0, 2);
	world.setBlock(i+4, j+0, k+1, Block.getBlockById(0), 0, 2);
	world.setBlock(i+5, j+0, k+1, Block.getBlockById(0), 0, 2);
	world.setBlock(i+6, j+0, k+1, Block.getBlockById(0), 0, 2);
	world.setBlock(i+7, j+0, k+1, Block.getBlockById(133), 0, 2);
	world.setBlock(i+8, j+0, k+1, Block.getBlockById(133), 0, 2);
	world.setBlock(i+9, j+0, k+1, Block.getBlockById(133), 0, 2);
	world.setBlock(i+0, j+0, k+2, Block.getBlockById(133), 0, 2);
	world.setBlock(i+1, j+0, k+2, Block.getBlockById(133), 0, 2);
	world.setBlock(i+2, j+0, k+2, Block.getBlockById(133), 0, 2);
	world.setBlock(i+3, j+0, k+2, Block.getBlockById(0), 0, 2);
	world.setBlock(i+4, j+0, k+2, Block.getBlockById(0), 0, 2);
	world.setBlock(i+5, j+0, k+2, Block.getBlockById(0), 0, 2);
	world.setBlock(i+6, j+0, k+2, Block.getBlockById(0), 0, 2);
	world.setBlock(i+7, j+0, k+2, Block.getBlockById(133), 0, 2);
	world.setBlock(i+8, j+0, k+2, Block.getBlockById(133), 0, 2);
	world.setBlock(i+9, j+0, k+2, Block.getBlockById(133), 0, 2);
	world.setBlock(i+0, j+0, k+3, Block.getBlockById(0), 0, 2);
	world.setBlock(i+1, j+0, k+3, Block.getBlockById(0), 0, 2);
	world.setBlock(i+2, j+0, k+3, Block.getBlockById(0), 0, 2);
	world.setBlock(i+3, j+0, k+3, Block.getBlockById(0), 0, 2);
	world.setBlock(i+4, j+0, k+3, Block.getBlockById(0), 0, 2);
	world.setBlock(i+5, j+0, k+3, Block.getBlockById(0), 0, 2);
	world.setBlock(i+6, j+0, k+3, Block.getBlockById(0), 0, 2);
	world.setBlock(i+7, j+0, k+3, Block.getBlockById(0), 0, 2);
	world.setBlock(i+8, j+0, k+3, Block.getBlockById(0), 0, 2);
	world.setBlock(i+9, j+0, k+3, Block.getBlockById(0), 0, 2);
	world.setBlock(i+0, j+0, k+4, Block.getBlockById(0), 0, 2);
	world.setBlock(i+1, j+0, k+4, Block.getBlockById(0), 0, 2);
	world.setBlock(i+2, j+0, k+4, Block.getBlockById(0), 0, 2);
	world.setBlock(i+3, j+0, k+4, Block.getBlockById(0), 0, 2);
	world.setBlock(i+4, j+0, k+4, Block.getBlockById(0), 0, 2);
	world.setBlock(i+5, j+0, k+4, Block.getBlockById(0), 0, 2);
	world.setBlock(i+6, j+0, k+4, Block.getBlockById(0), 0, 2);
	world.setBlock(i+7, j+0, k+4, Block.getBlockById(0), 0, 2);
	world.setBlock(i+8, j+0, k+4, Block.getBlockById(0), 0, 2);
	world.setBlock(i+9, j+0, k+4, Block.getBlockById(0), 0, 2);
	world.setBlock(i+0, j+0, k+5, Block.getBlockById(0), 0, 2);
	world.setBlock(i+1, j+0, k+5, Block.getBlockById(0), 0, 2);
	world.setBlock(i+2, j+0, k+5, Block.getBlockById(0), 0, 2);
	world.setBlock(i+3, j+0, k+5, Block.getBlockById(0), 0, 2);
	world.setBlock(i+4, j+0, k+5, Block.getBlockById(0), 0, 2);
	world.setBlock(i+5, j+0, k+5, Block.getBlockById(0), 0, 2);
	world.setBlock(i+6, j+0, k+5, Block.getBlockById(0), 0, 2);
	world.setBlock(i+7, j+0, k+5, Block.getBlockById(0), 0, 2);
	world.setBlock(i+8, j+0, k+5, Block.getBlockById(0), 0, 2);
	world.setBlock(i+9, j+0, k+5, Block.getBlockById(0), 0, 2);
	world.setBlock(i+0, j+0, k+6, Block.getBlockById(0), 0, 2);
	world.setBlock(i+1, j+0, k+6, Block.getBlockById(0), 0, 2);
	world.setBlock(i+2, j+0, k+6, Block.getBlockById(0), 0, 2);
	world.setBlock(i+3, j+0, k+6, Block.getBlockById(0), 0, 2);
	world.setBlock(i+4, j+0, k+6, Block.getBlockById(0), 0, 2);
	world.setBlock(i+5, j+0, k+6, Block.getBlockById(0), 0, 2);
	world.setBlock(i+6, j+0, k+6, Block.getBlockById(0), 0, 2);
	world.setBlock(i+7, j+0, k+6, Block.getBlockById(0), 0, 2);
	world.setBlock(i+8, j+0, k+6, Block.getBlockById(0), 0, 2);
	world.setBlock(i+9, j+0, k+6, Block.getBlockById(0), 0, 2);
	world.setBlock(i+0, j+0, k+7, Block.getBlockById(133), 0, 2);
	world.setBlock(i+1, j+0, k+7, Block.getBlockById(133), 0, 2);
	world.setBlock(i+2, j+0, k+7, Block.getBlockById(133), 0, 2);
	world.setBlock(i+3, j+0, k+7, Block.getBlockById(0), 0, 2);
	world.setBlock(i+4, j+0, k+7, Block.getBlockById(0), 0, 2);
	world.setBlock(i+5, j+0, k+7, Block.getBlockById(0), 0, 2);
	world.setBlock(i+6, j+0, k+7, Block.getBlockById(0), 0, 2);
	world.setBlock(i+7, j+0, k+7, Block.getBlockById(133), 0, 2);
	world.setBlock(i+8, j+0, k+7, Block.getBlockById(133), 0, 2);
	world.setBlock(i+9, j+0, k+7, Block.getBlockById(133), 0, 2);
	world.setBlock(i+0, j+0, k+8, Block.getBlockById(133), 0, 2);
	world.setBlock(i+1, j+0, k+8, Block.getBlockById(133), 0, 2);
	world.setBlock(i+2, j+0, k+8, Block.getBlockById(133), 0, 2);
	world.setBlock(i+3, j+0, k+8, Block.getBlockById(0), 0, 2);
	world.setBlock(i+4, j+0, k+8, Block.getBlockById(0), 0, 2);
	world.setBlock(i+5, j+0, k+8, Block.getBlockById(0), 0, 2);
	world.setBlock(i+6, j+0, k+8, Block.getBlockById(0), 0, 2);
	world.setBlock(i+7, j+0, k+8, Block.getBlockById(133), 0, 2);
	world.setBlock(i+8, j+0, k+8, Block.getBlockById(133), 0, 2);
	world.setBlock(i+9, j+0, k+8, Block.getBlockById(133), 0, 2);
	world.setBlock(i+0, j+0, k+9, Block.getBlockById(133), 0, 2);
	world.setBlock(i+1, j+0, k+9, Block.getBlockById(133), 0, 2);
	world.setBlock(i+2, j+0, k+9, Block.getBlockById(133), 0, 2);
	world.setBlock(i+3, j+0, k+9, Block.getBlockById(0), 0, 2);
	world.setBlock(i+4, j+0, k+9, Block.getBlockById(0), 0, 2);
	world.setBlock(i+5, j+0, k+9, Block.getBlockById(0), 0, 2);
	world.setBlock(i+6, j+0, k+9, Block.getBlockById(0), 0, 2);
	world.setBlock(i+7, j+0, k+9, Block.getBlockById(133), 0, 2);
	world.setBlock(i+8, j+0, k+9, Block.getBlockById(133), 0, 2);
	world.setBlock(i+9, j+0, k+9, Block.getBlockById(133), 0, 2);
	world.setBlock(i+0, j+1, k+0, Block.getBlockById(133), 0, 2);
	world.setBlock(i+1, j+1, k+0, Block.getBlockById(133), 0, 2);
	world.setBlock(i+2, j+1, k+0, Block.getBlockById(133), 0, 2);
	world.setBlock(i+3, j+1, k+0, Block.getBlockById(0), 0, 2);
	world.setBlock(i+4, j+1, k+0, Block.getBlockById(0), 0, 2);
	world.setBlock(i+5, j+1, k+0, Block.getBlockById(0), 0, 2);
	world.setBlock(i+6, j+1, k+0, Block.getBlockById(0), 0, 2);
	world.setBlock(i+7, j+1, k+0, Block.getBlockById(133), 0, 2);
	world.setBlock(i+8, j+1, k+0, Block.getBlockById(133), 0, 2);
	world.setBlock(i+9, j+1, k+0, Block.getBlockById(133), 0, 2);
	world.setBlock(i+0, j+1, k+1, Block.getBlockById(133), 0, 2);
	world.setBlock(i+1, j+1, k+1, Block.getBlockById(52), 1, 50);
	world.setBlock(i+2, j+1, k+1, Block.getBlockById(133), 0, 2);
	world.setBlock(i+3, j+1, k+1, Block.getBlockById(0), 0, 2);
	world.setBlock(i+4, j+1, k+1, Block.getBlockById(0), 0, 2);
	world.setBlock(i+5, j+1, k+1, Block.getBlockById(0), 0, 2);
	world.setBlock(i+6, j+1, k+1, Block.getBlockById(0), 0, 2);
	world.setBlock(i+7, j+1, k+1, Block.getBlockById(133), 0, 2);
	world.setBlock(i+8, j+1, k+1, Block.getBlockById(52), 1, 50);
	world.setBlock(i+9, j+1, k+1, Block.getBlockById(133), 0, 2);
	world.setBlock(i+0, j+1, k+2, Block.getBlockById(133), 0, 2);
	world.setBlock(i+1, j+1, k+2, Block.getBlockById(133), 0, 2);
	world.setBlock(i+2, j+1, k+2, Block.getBlockById(133), 0, 2);
	world.setBlock(i+3, j+1, k+2, Block.getBlockById(0), 0, 2);
	world.setBlock(i+4, j+1, k+2, Block.getBlockById(0), 0, 2);
	world.setBlock(i+5, j+1, k+2, Block.getBlockById(0), 0, 2);
	world.setBlock(i+6, j+1, k+2, Block.getBlockById(0), 0, 2);
	world.setBlock(i+7, j+1, k+2, Block.getBlockById(133), 0, 2);
	world.setBlock(i+8, j+1, k+2, Block.getBlockById(133), 0, 2);
	world.setBlock(i+9, j+1, k+2, Block.getBlockById(133), 0, 2);
	world.setBlock(i+0, j+1, k+3, Block.getBlockById(0), 0, 2);
	world.setBlock(i+1, j+1, k+3, Block.getBlockById(0), 0, 2);
	world.setBlock(i+2, j+1, k+3, Block.getBlockById(0), 0, 2);
	world.setBlock(i+3, j+1, k+3, Block.getBlockById(0), 0, 2);
	world.setBlock(i+4, j+1, k+3, Block.getBlockById(0), 0, 2);
	world.setBlock(i+5, j+1, k+3, Block.getBlockById(0), 0, 2);
	world.setBlock(i+6, j+1, k+3, Block.getBlockById(0), 0, 2);
	world.setBlock(i+7, j+1, k+3, Block.getBlockById(0), 0, 2);
	world.setBlock(i+8, j+1, k+3, Block.getBlockById(0), 0, 2);
	world.setBlock(i+9, j+1, k+3, Block.getBlockById(0), 0, 2);
	world.setBlock(i+0, j+1, k+4, Block.getBlockById(0), 0, 2);
	world.setBlock(i+1, j+1, k+4, Block.getBlockById(0), 0, 2);
	world.setBlock(i+2, j+1, k+4, Block.getBlockById(0), 0, 2);
	world.setBlock(i+3, j+1, k+4, Block.getBlockById(0), 0, 2);
	world.setBlock(i+4, j+1, k+4, Block.getBlockById(0), 0, 2);
	world.setBlock(i+5, j+1, k+4, Block.getBlockById(0), 0, 2);
	world.setBlock(i+6, j+1, k+4, Block.getBlockById(0), 0, 2);
	world.setBlock(i+7, j+1, k+4, Block.getBlockById(0), 0, 2);
	world.setBlock(i+8, j+1, k+4, Block.getBlockById(0), 0, 2);
	world.setBlock(i+9, j+1, k+4, Block.getBlockById(0), 0, 2);
	world.setBlock(i+0, j+1, k+5, Block.getBlockById(0), 0, 2);
	world.setBlock(i+1, j+1, k+5, Block.getBlockById(0), 0, 2);
	world.setBlock(i+2, j+1, k+5, Block.getBlockById(0), 0, 2);
	world.setBlock(i+3, j+1, k+5, Block.getBlockById(0), 0, 2);
	world.setBlock(i+4, j+1, k+5, Block.getBlockById(0), 0, 2);
	world.setBlock(i+5, j+1, k+5, Block.getBlockById(0), 0, 2);
	world.setBlock(i+6, j+1, k+5, Block.getBlockById(0), 0, 2);
	world.setBlock(i+7, j+1, k+5, Block.getBlockById(0), 0, 2);
	world.setBlock(i+8, j+1, k+5, Block.getBlockById(0), 0, 2);
	world.setBlock(i+9, j+1, k+5, Block.getBlockById(0), 0, 2);
	world.setBlock(i+0, j+1, k+6, Block.getBlockById(0), 0, 2);
	world.setBlock(i+1, j+1, k+6, Block.getBlockById(0), 0, 2);
	world.setBlock(i+2, j+1, k+6, Block.getBlockById(0), 0, 2);
	world.setBlock(i+3, j+1, k+6, Block.getBlockById(0), 0, 2);
	world.setBlock(i+4, j+1, k+6, Block.getBlockById(0), 0, 2);
	world.setBlock(i+5, j+1, k+6, Block.getBlockById(0), 0, 2);
	world.setBlock(i+6, j+1, k+6, Block.getBlockById(0), 0, 2);
	world.setBlock(i+7, j+1, k+6, Block.getBlockById(0), 0, 2);
	world.setBlock(i+8, j+1, k+6, Block.getBlockById(0), 0, 2);
	world.setBlock(i+9, j+1, k+6, Block.getBlockById(0), 0, 2);
	world.setBlock(i+0, j+1, k+7, Block.getBlockById(133), 0, 2);
	world.setBlock(i+1, j+1, k+7, Block.getBlockById(133), 0, 2);
	world.setBlock(i+2, j+1, k+7, Block.getBlockById(133), 0, 2);
	world.setBlock(i+3, j+1, k+7, Block.getBlockById(0), 0, 2);
	world.setBlock(i+4, j+1, k+7, Block.getBlockById(0), 0, 2);
	world.setBlock(i+5, j+1, k+7, Block.getBlockById(0), 0, 2);
	world.setBlock(i+6, j+1, k+7, Block.getBlockById(0), 0, 2);
	world.setBlock(i+7, j+1, k+7, Block.getBlockById(133), 0, 2);
	world.setBlock(i+8, j+1, k+7, Block.getBlockById(133), 0, 2);
	world.setBlock(i+9, j+1, k+7, Block.getBlockById(133), 0, 2);
	world.setBlock(i+0, j+1, k+8, Block.getBlockById(133), 0, 2);
	world.setBlock(i+1, j+1, k+8, Block.getBlockById(52), 1, 50);
	world.setBlock(i+2, j+1, k+8, Block.getBlockById(133), 0, 2);
	world.setBlock(i+3, j+1, k+8, Block.getBlockById(0), 0, 2);
	world.setBlock(i+4, j+1, k+8, Block.getBlockById(0), 0, 2);
	world.setBlock(i+5, j+1, k+8, Block.getBlockById(0), 0, 2);
	world.setBlock(i+6, j+1, k+8, Block.getBlockById(0), 0, 2);
	world.setBlock(i+7, j+1, k+8, Block.getBlockById(133), 0, 2);
	world.setBlock(i+8, j+1, k+8, Block.getBlockById(52), 1, 50);
	world.setBlock(i+9, j+1, k+8, Block.getBlockById(133), 0, 2);
	world.setBlock(i+0, j+1, k+9, Block.getBlockById(133), 0, 2);
	world.setBlock(i+1, j+1, k+9, Block.getBlockById(133), 0, 2);
	world.setBlock(i+2, j+1, k+9, Block.getBlockById(133), 0, 2);
	world.setBlock(i+3, j+1, k+9, Block.getBlockById(0), 0, 2);
	world.setBlock(i+4, j+1, k+9, Block.getBlockById(0), 0, 2);
	world.setBlock(i+5, j+1, k+9, Block.getBlockById(0), 0, 2);
	world.setBlock(i+6, j+1, k+9, Block.getBlockById(0), 0, 2);
	world.setBlock(i+7, j+1, k+9, Block.getBlockById(133), 0, 2);
	world.setBlock(i+8, j+1, k+9, Block.getBlockById(133), 0, 2);
	world.setBlock(i+9, j+1, k+9, Block.getBlockById(133), 0, 2);
	world.setBlock(i+0, j+2, k+0, Block.getBlockById(133), 0, 2);
	world.setBlock(i+1, j+2, k+0, Block.getBlockById(133), 0, 2);
	world.setBlock(i+2, j+2, k+0, Block.getBlockById(133), 0, 2);
	world.setBlock(i+3, j+2, k+0, Block.getBlockById(0), 0, 2);
	world.setBlock(i+4, j+2, k+0, Block.getBlockById(0), 0, 2);
	world.setBlock(i+5, j+2, k+0, Block.getBlockById(0), 0, 2);
	world.setBlock(i+6, j+2, k+0, Block.getBlockById(0), 0, 2);
	world.setBlock(i+7, j+2, k+0, Block.getBlockById(133), 0, 2);
	world.setBlock(i+8, j+2, k+0, Block.getBlockById(133), 0, 2);
	world.setBlock(i+9, j+2, k+0, Block.getBlockById(133), 0, 2);
	world.setBlock(i+0, j+2, k+1, Block.getBlockById(133), 0, 2);
	world.setBlock(i+1, j+2, k+1, Block.getBlockById(133), 0, 2);
	world.setBlock(i+2, j+2, k+1, Block.getBlockById(133), 0, 2);
	world.setBlock(i+3, j+2, k+1, Block.getBlockById(0), 0, 2);
	world.setBlock(i+4, j+2, k+1, Block.getBlockById(0), 0, 2);
	world.setBlock(i+5, j+2, k+1, Block.getBlockById(0), 0, 2);
	world.setBlock(i+6, j+2, k+1, Block.getBlockById(0), 0, 2);
	world.setBlock(i+7, j+2, k+1, Block.getBlockById(133), 0, 2);
	world.setBlock(i+8, j+2, k+1, Block.getBlockById(133), 0, 2);
	world.setBlock(i+9, j+2, k+1, Block.getBlockById(133), 0, 2);
	world.setBlock(i+0, j+2, k+2, Block.getBlockById(133), 0, 2);
	world.setBlock(i+1, j+2, k+2, Block.getBlockById(133), 0, 2);
	world.setBlock(i+2, j+2, k+2, Block.getBlockById(133), 0, 2);
	world.setBlock(i+3, j+2, k+2, Block.getBlockById(0), 0, 2);
	world.setBlock(i+4, j+2, k+2, Block.getBlockById(0), 0, 2);
	world.setBlock(i+5, j+2, k+2, Block.getBlockById(0), 0, 2);
	world.setBlock(i+6, j+2, k+2, Block.getBlockById(0), 0, 2);
	world.setBlock(i+7, j+2, k+2, Block.getBlockById(133), 0, 2);
	world.setBlock(i+8, j+2, k+2, Block.getBlockById(133), 0, 2);
	world.setBlock(i+9, j+2, k+2, Block.getBlockById(133), 0, 2);
	world.setBlock(i+0, j+2, k+3, Block.getBlockById(0), 0, 2);
	world.setBlock(i+1, j+2, k+3, Block.getBlockById(0), 0, 2);
	world.setBlock(i+2, j+2, k+3, Block.getBlockById(0), 0, 2);
	world.setBlock(i+3, j+2, k+3, Block.getBlockById(133), 0, 2);
	world.setBlock(i+4, j+2, k+3, Block.getBlockById(133), 0, 2);
	world.setBlock(i+5, j+2, k+3, Block.getBlockById(133), 0, 2);
	world.setBlock(i+6, j+2, k+3, Block.getBlockById(133), 0, 2);
	world.setBlock(i+7, j+2, k+3, Block.getBlockById(0), 0, 2);
	world.setBlock(i+8, j+2, k+3, Block.getBlockById(0), 0, 2);
	world.setBlock(i+9, j+2, k+3, Block.getBlockById(0), 0, 2);
	world.setBlock(i+0, j+2, k+4, Block.getBlockById(0), 0, 2);
	world.setBlock(i+1, j+2, k+4, Block.getBlockById(0), 0, 2);
	world.setBlock(i+2, j+2, k+4, Block.getBlockById(0), 0, 2);
	world.setBlock(i+3, j+2, k+4, Block.getBlockById(133), 0, 2);
	world.setBlock(i+4, j+2, k+4, Block.getBlockById(133), 0, 2);
	world.setBlock(i+5, j+2, k+4, Block.getBlockById(133), 0, 2);
	world.setBlock(i+6, j+2, k+4, Block.getBlockById(133), 0, 2);
	world.setBlock(i+7, j+2, k+4, Block.getBlockById(0), 0, 2);
	world.setBlock(i+8, j+2, k+4, Block.getBlockById(0), 0, 2);
	world.setBlock(i+9, j+2, k+4, Block.getBlockById(0), 0, 2);
	world.setBlock(i+0, j+2, k+5, Block.getBlockById(0), 0, 2);
	world.setBlock(i+1, j+2, k+5, Block.getBlockById(0), 0, 2);
	world.setBlock(i+2, j+2, k+5, Block.getBlockById(0), 0, 2);
	world.setBlock(i+3, j+2, k+5, Block.getBlockById(133), 0, 2);
	world.setBlock(i+4, j+2, k+5, Block.getBlockById(133), 0, 2);
	world.setBlock(i+5, j+2, k+5, Block.getBlockById(133), 0, 2);
	world.setBlock(i+6, j+2, k+5, Block.getBlockById(133), 0, 2);
	world.setBlock(i+7, j+2, k+5, Block.getBlockById(0), 0, 2);
	world.setBlock(i+8, j+2, k+5, Block.getBlockById(0), 0, 2);
	world.setBlock(i+9, j+2, k+5, Block.getBlockById(0), 0, 2);
	world.setBlock(i+0, j+2, k+6, Block.getBlockById(0), 0, 2);
	world.setBlock(i+1, j+2, k+6, Block.getBlockById(0), 0, 2);
	world.setBlock(i+2, j+2, k+6, Block.getBlockById(0), 0, 2);
	world.setBlock(i+3, j+2, k+6, Block.getBlockById(133), 0, 2);
	world.setBlock(i+4, j+2, k+6, Block.getBlockById(133), 0, 2);
	world.setBlock(i+5, j+2, k+6, Block.getBlockById(133), 0, 2);
	world.setBlock(i+6, j+2, k+6, Block.getBlockById(133), 0, 2);
	world.setBlock(i+7, j+2, k+6, Block.getBlockById(0), 0, 2);
	world.setBlock(i+8, j+2, k+6, Block.getBlockById(0), 0, 2);
	world.setBlock(i+9, j+2, k+6, Block.getBlockById(0), 0, 2);
	world.setBlock(i+0, j+2, k+7, Block.getBlockById(133), 0, 2);
	world.setBlock(i+1, j+2, k+7, Block.getBlockById(133), 0, 2);
	world.setBlock(i+2, j+2, k+7, Block.getBlockById(133), 0, 2);
	world.setBlock(i+3, j+2, k+7, Block.getBlockById(0), 0, 2);
	world.setBlock(i+4, j+2, k+7, Block.getBlockById(0), 0, 2);
	world.setBlock(i+5, j+2, k+7, Block.getBlockById(0), 0, 2);
	world.setBlock(i+6, j+2, k+7, Block.getBlockById(0), 0, 2);
	world.setBlock(i+7, j+2, k+7, Block.getBlockById(133), 0, 2);
	world.setBlock(i+8, j+2, k+7, Block.getBlockById(133), 0, 2);
	world.setBlock(i+9, j+2, k+7, Block.getBlockById(133), 0, 2);
	world.setBlock(i+0, j+2, k+8, Block.getBlockById(133), 0, 2);
	world.setBlock(i+1, j+2, k+8, Block.getBlockById(133), 0, 2);
	world.setBlock(i+2, j+2, k+8, Block.getBlockById(133), 0, 2);
	world.setBlock(i+3, j+2, k+8, Block.getBlockById(0), 0, 2);
	world.setBlock(i+4, j+2, k+8, Block.getBlockById(0), 0, 2);
	world.setBlock(i+5, j+2, k+8, Block.getBlockById(0), 0, 2);
	world.setBlock(i+6, j+2, k+8, Block.getBlockById(0), 0, 2);
	world.setBlock(i+7, j+2, k+8, Block.getBlockById(133), 0, 2);
	world.setBlock(i+8, j+2, k+8, Block.getBlockById(133), 0, 2);
	world.setBlock(i+9, j+2, k+8, Block.getBlockById(133), 0, 2);
	world.setBlock(i+0, j+2, k+9, Block.getBlockById(133), 0, 2);
	world.setBlock(i+1, j+2, k+9, Block.getBlockById(133), 0, 2);
	world.setBlock(i+2, j+2, k+9, Block.getBlockById(133), 0, 2);
	world.setBlock(i+3, j+2, k+9, Block.getBlockById(0), 0, 2);
	world.setBlock(i+4, j+2, k+9, Block.getBlockById(0), 0, 2);
	world.setBlock(i+5, j+2, k+9, Block.getBlockById(0), 0, 2);
	world.setBlock(i+6, j+2, k+9, Block.getBlockById(0), 0, 2);
	world.setBlock(i+7, j+2, k+9, Block.getBlockById(133), 0, 2);
	world.setBlock(i+8, j+2, k+9, Block.getBlockById(133), 0, 2);
	world.setBlock(i+9, j+2, k+9, Block.getBlockById(133), 0, 2);
	world.setBlock(i+0, j+3, k+0, Block.getBlockById(0), 0, 2);
	world.setBlock(i+1, j+3, k+0, Block.getBlockById(0), 0, 2);
	world.setBlock(i+2, j+3, k+0, Block.getBlockById(0), 0, 2);
	world.setBlock(i+3, j+3, k+0, Block.getBlockById(0), 0, 2);
	world.setBlock(i+4, j+3, k+0, Block.getBlockById(0), 0, 2);
	world.setBlock(i+5, j+3, k+0, Block.getBlockById(0), 0, 2);
	world.setBlock(i+6, j+3, k+0, Block.getBlockById(0), 0, 2);
	world.setBlock(i+7, j+3, k+0, Block.getBlockById(0), 0, 2);
	world.setBlock(i+8, j+3, k+0, Block.getBlockById(0), 0, 2);
	world.setBlock(i+9, j+3, k+0, Block.getBlockById(0), 0, 2);
	world.setBlock(i+0, j+3, k+1, Block.getBlockById(0), 0, 2);
	world.setBlock(i+1, j+3, k+1, Block.getBlockById(0), 0, 2);
	world.setBlock(i+2, j+3, k+1, Block.getBlockById(0), 0, 2);
	world.setBlock(i+3, j+3, k+1, Block.getBlockById(0), 0, 2);
	world.setBlock(i+4, j+3, k+1, Block.getBlockById(0), 0, 2);
	world.setBlock(i+5, j+3, k+1, Block.getBlockById(0), 0, 2);
	world.setBlock(i+6, j+3, k+1, Block.getBlockById(0), 0, 2);
	world.setBlock(i+7, j+3, k+1, Block.getBlockById(0), 0, 2);
	world.setBlock(i+8, j+3, k+1, Block.getBlockById(0), 0, 2);
	world.setBlock(i+9, j+3, k+1, Block.getBlockById(0), 0, 2);
	world.setBlock(i+0, j+3, k+2, Block.getBlockById(0), 0, 2);
	world.setBlock(i+1, j+3, k+2, Block.getBlockById(0), 0, 2);
	world.setBlock(i+2, j+3, k+2, Block.getBlockById(0), 0, 2);
	world.setBlock(i+3, j+3, k+2, Block.getBlockById(0), 0, 2);
	world.setBlock(i+4, j+3, k+2, Block.getBlockById(0), 0, 2);
	world.setBlock(i+5, j+3, k+2, Block.getBlockById(0), 0, 2);
	world.setBlock(i+6, j+3, k+2, Block.getBlockById(0), 0, 2);
	world.setBlock(i+7, j+3, k+2, Block.getBlockById(0), 0, 2);
	world.setBlock(i+8, j+3, k+2, Block.getBlockById(0), 0, 2);
	world.setBlock(i+9, j+3, k+2, Block.getBlockById(0), 0, 2);
	world.setBlock(i+0, j+3, k+3, Block.getBlockById(0), 0, 2);
	world.setBlock(i+1, j+3, k+3, Block.getBlockById(0), 0, 2);
	world.setBlock(i+2, j+3, k+3, Block.getBlockById(0), 0, 2);
	world.setBlock(i+3, j+3, k+3, Block.getBlockById(133), 0, 2);
	world.setBlock(i+4, j+3, k+3, Block.getBlockById(64), 1, 2);
	world.setBlock(i+5, j+3, k+3, Block.getBlockById(64), 1, 2);
	world.setBlock(i+6, j+3, k+3, Block.getBlockById(133), 0, 2);
	world.setBlock(i+7, j+3, k+3, Block.getBlockById(0), 0, 2);
	world.setBlock(i+8, j+3, k+3, Block.getBlockById(0), 0, 2);
	world.setBlock(i+9, j+3, k+3, Block.getBlockById(0), 0, 2);
	world.setBlock(i+0, j+3, k+4, Block.getBlockById(0), 0, 2);
	world.setBlock(i+1, j+3, k+4, Block.getBlockById(0), 0, 2);
	world.setBlock(i+2, j+3, k+4, Block.getBlockById(0), 0, 2);
	world.setBlock(i+3, j+3, k+4, Block.getBlockById(133), 0, 2);
	world.setBlock(i+4, j+3, k+4, Block.getBlockById(65), 5, 2);
	world.setBlock(i+5, j+3, k+4, Block.getBlockById(65), 4, 2);
	world.setBlock(i+6, j+3, k+4, Block.getBlockById(133), 0, 2);
	world.setBlock(i+7, j+3, k+4, Block.getBlockById(0), 0, 2);
	world.setBlock(i+8, j+3, k+4, Block.getBlockById(0), 0, 2);
	world.setBlock(i+9, j+3, k+4, Block.getBlockById(0), 0, 2);
	world.setBlock(i+0, j+3, k+5, Block.getBlockById(0), 0, 2);
	world.setBlock(i+1, j+3, k+5, Block.getBlockById(0), 0, 2);
	world.setBlock(i+2, j+3, k+5, Block.getBlockById(0), 0, 2);
	world.setBlock(i+3, j+3, k+5, Block.getBlockById(133), 0, 2);
	world.setBlock(i+4, j+3, k+5, Block.getBlockById(65), 5, 2);
	world.setBlock(i+5, j+3, k+5, Block.getBlockById(65), 4, 2);
	world.setBlock(i+6, j+3, k+5, Block.getBlockById(133), 0, 2);
	world.setBlock(i+7, j+3, k+5, Block.getBlockById(0), 0, 2);
	world.setBlock(i+8, j+3, k+5, Block.getBlockById(0), 0, 2);
	world.setBlock(i+9, j+3, k+5, Block.getBlockById(0), 0, 2);
	world.setBlock(i+0, j+3, k+6, Block.getBlockById(0), 0, 2);
	world.setBlock(i+1, j+3, k+6, Block.getBlockById(0), 0, 2);
	world.setBlock(i+2, j+3, k+6, Block.getBlockById(0), 0, 2);
	world.setBlock(i+3, j+3, k+6, Block.getBlockById(133), 0, 2);
	world.setBlock(i+4, j+3, k+6, Block.getBlockById(64), 3, 2);
	world.setBlock(i+5, j+3, k+6, Block.getBlockById(64), 3, 2);
	world.setBlock(i+6, j+3, k+6, Block.getBlockById(133), 0, 2);
	world.setBlock(i+7, j+3, k+6, Block.getBlockById(0), 0, 2);
	world.setBlock(i+8, j+3, k+6, Block.getBlockById(0), 0, 2);
	world.setBlock(i+9, j+3, k+6, Block.getBlockById(0), 0, 2);
	world.setBlock(i+0, j+3, k+7, Block.getBlockById(0), 0, 2);
	world.setBlock(i+1, j+3, k+7, Block.getBlockById(0), 0, 2);
	world.setBlock(i+2, j+3, k+7, Block.getBlockById(0), 0, 2);
	world.setBlock(i+3, j+3, k+7, Block.getBlockById(0), 0, 2);
	world.setBlock(i+4, j+3, k+7, Block.getBlockById(0), 0, 2);
	world.setBlock(i+5, j+3, k+7, Block.getBlockById(0), 0, 2);
	world.setBlock(i+6, j+3, k+7, Block.getBlockById(0), 0, 2);
	world.setBlock(i+7, j+3, k+7, Block.getBlockById(0), 0, 2);
	world.setBlock(i+8, j+3, k+7, Block.getBlockById(0), 0, 2);
	world.setBlock(i+9, j+3, k+7, Block.getBlockById(0), 0, 2);
	world.setBlock(i+0, j+3, k+8, Block.getBlockById(0), 0, 2);
	world.setBlock(i+1, j+3, k+8, Block.getBlockById(0), 0, 2);
	world.setBlock(i+2, j+3, k+8, Block.getBlockById(0), 0, 2);
	world.setBlock(i+3, j+3, k+8, Block.getBlockById(0), 0, 2);
	world.setBlock(i+4, j+3, k+8, Block.getBlockById(0), 0, 2);
	world.setBlock(i+5, j+3, k+8, Block.getBlockById(0), 0, 2);
	world.setBlock(i+6, j+3, k+8, Block.getBlockById(0), 0, 2);
	world.setBlock(i+7, j+3, k+8, Block.getBlockById(0), 0, 2);
	world.setBlock(i+8, j+3, k+8, Block.getBlockById(0), 0, 2);
	world.setBlock(i+9, j+3, k+8, Block.getBlockById(0), 0, 2);
	world.setBlock(i+0, j+3, k+9, Block.getBlockById(0), 0, 2);
	world.setBlock(i+1, j+3, k+9, Block.getBlockById(0), 0, 2);
	world.setBlock(i+2, j+3, k+9, Block.getBlockById(0), 0, 2);
	world.setBlock(i+3, j+3, k+9, Block.getBlockById(0), 0, 2);
	world.setBlock(i+4, j+3, k+9, Block.getBlockById(0), 0, 2);
	world.setBlock(i+5, j+3, k+9, Block.getBlockById(0), 0, 2);
	world.setBlock(i+6, j+3, k+9, Block.getBlockById(0), 0, 2);
	world.setBlock(i+7, j+3, k+9, Block.getBlockById(0), 0, 2);
	world.setBlock(i+8, j+3, k+9, Block.getBlockById(0), 0, 2);
	world.setBlock(i+9, j+3, k+9, Block.getBlockById(0), 0, 2);
	world.setBlock(i+0, j+4, k+0, Block.getBlockById(0), 0, 2);
	world.setBlock(i+1, j+4, k+0, Block.getBlockById(0), 0, 2);
	world.setBlock(i+2, j+4, k+0, Block.getBlockById(0), 0, 2);
	world.setBlock(i+3, j+4, k+0, Block.getBlockById(0), 0, 2);
	world.setBlock(i+4, j+4, k+0, Block.getBlockById(0), 0, 2);
	world.setBlock(i+5, j+4, k+0, Block.getBlockById(0), 0, 2);
	world.setBlock(i+6, j+4, k+0, Block.getBlockById(0), 0, 2);
	world.setBlock(i+7, j+4, k+0, Block.getBlockById(0), 0, 2);
	world.setBlock(i+8, j+4, k+0, Block.getBlockById(0), 0, 2);
	world.setBlock(i+9, j+4, k+0, Block.getBlockById(0), 0, 2);
	world.setBlock(i+0, j+4, k+1, Block.getBlockById(0), 0, 2);
	world.setBlock(i+1, j+4, k+1, Block.getBlockById(0), 0, 2);
	world.setBlock(i+2, j+4, k+1, Block.getBlockById(0), 0, 2);
	world.setBlock(i+3, j+4, k+1, Block.getBlockById(0), 0, 2);
	world.setBlock(i+4, j+4, k+1, Block.getBlockById(0), 0, 2);
	world.setBlock(i+5, j+4, k+1, Block.getBlockById(0), 0, 2);
	world.setBlock(i+6, j+4, k+1, Block.getBlockById(0), 0, 2);
	world.setBlock(i+7, j+4, k+1, Block.getBlockById(0), 0, 2);
	world.setBlock(i+8, j+4, k+1, Block.getBlockById(0), 0, 2);
	world.setBlock(i+9, j+4, k+1, Block.getBlockById(0), 0, 2);
	world.setBlock(i+0, j+4, k+2, Block.getBlockById(0), 0, 2);
	world.setBlock(i+1, j+4, k+2, Block.getBlockById(0), 0, 2);
	world.setBlock(i+2, j+4, k+2, Block.getBlockById(0), 0, 2);
	world.setBlock(i+3, j+4, k+2, Block.getBlockById(0), 0, 2);
	world.setBlock(i+4, j+4, k+2, Block.getBlockById(0), 0, 2);
	world.setBlock(i+5, j+4, k+2, Block.getBlockById(0), 0, 2);
	world.setBlock(i+6, j+4, k+2, Block.getBlockById(0), 0, 2);
	world.setBlock(i+7, j+4, k+2, Block.getBlockById(0), 0, 2);
	world.setBlock(i+8, j+4, k+2, Block.getBlockById(0), 0, 2);
	world.setBlock(i+9, j+4, k+2, Block.getBlockById(0), 0, 2);
	world.setBlock(i+0, j+4, k+3, Block.getBlockById(0), 0, 2);
	world.setBlock(i+1, j+4, k+3, Block.getBlockById(0), 0, 2);
	world.setBlock(i+2, j+4, k+3, Block.getBlockById(0), 0, 2);
	world.setBlock(i+3, j+4, k+3, Block.getBlockById(133), 0, 2);
	world.setBlock(i+4, j+4, k+3, Block.getBlockById(64), 9, 2);
	world.setBlock(i+5, j+4, k+3, Block.getBlockById(64), 8, 2);
	world.setBlock(i+6, j+4, k+3, Block.getBlockById(133), 0, 2);
	world.setBlock(i+7, j+4, k+3, Block.getBlockById(0), 0, 2);
	world.setBlock(i+8, j+4, k+3, Block.getBlockById(0), 0, 2);
	world.setBlock(i+9, j+4, k+3, Block.getBlockById(0), 0, 2);
	world.setBlock(i+0, j+4, k+4, Block.getBlockById(0), 0, 2);
	world.setBlock(i+1, j+4, k+4, Block.getBlockById(0), 0, 2);
	world.setBlock(i+2, j+4, k+4, Block.getBlockById(0), 0, 2);
	world.setBlock(i+3, j+4, k+4, Block.getBlockById(133), 0, 2);
	world.setBlock(i+4, j+4, k+4, Block.getBlockById(65), 5, 2);
	world.setBlock(i+5, j+4, k+4, Block.getBlockById(65), 4, 2);
	world.setBlock(i+6, j+4, k+4, Block.getBlockById(133), 0, 2);
	world.setBlock(i+7, j+4, k+4, Block.getBlockById(0), 0, 2);
	world.setBlock(i+8, j+4, k+4, Block.getBlockById(0), 0, 2);
	world.setBlock(i+9, j+4, k+4, Block.getBlockById(0), 0, 2);
	world.setBlock(i+0, j+4, k+5, Block.getBlockById(0), 0, 2);
	world.setBlock(i+1, j+4, k+5, Block.getBlockById(0), 0, 2);
	world.setBlock(i+2, j+4, k+5, Block.getBlockById(0), 0, 2);
	world.setBlock(i+3, j+4, k+5, Block.getBlockById(133), 0, 2);
	world.setBlock(i+4, j+4, k+5, Block.getBlockById(65), 5, 2);
	world.setBlock(i+5, j+4, k+5, Block.getBlockById(65), 4, 2);
	world.setBlock(i+6, j+4, k+5, Block.getBlockById(133), 0, 2);
	world.setBlock(i+7, j+4, k+5, Block.getBlockById(0), 0, 2);
	world.setBlock(i+8, j+4, k+5, Block.getBlockById(0), 0, 2);
	world.setBlock(i+9, j+4, k+5, Block.getBlockById(0), 0, 2);
	world.setBlock(i+0, j+4, k+6, Block.getBlockById(0), 0, 2);
	world.setBlock(i+1, j+4, k+6, Block.getBlockById(0), 0, 2);
	world.setBlock(i+2, j+4, k+6, Block.getBlockById(0), 0, 2);
	world.setBlock(i+3, j+4, k+6, Block.getBlockById(133), 0, 2);
	world.setBlock(i+4, j+4, k+6, Block.getBlockById(64), 8, 2);
	world.setBlock(i+5, j+4, k+6, Block.getBlockById(64), 9, 2);
	world.setBlock(i+6, j+4, k+6, Block.getBlockById(133), 0, 2);
	world.setBlock(i+7, j+4, k+6, Block.getBlockById(0), 0, 2);
	world.setBlock(i+8, j+4, k+6, Block.getBlockById(0), 0, 2);
	world.setBlock(i+9, j+4, k+6, Block.getBlockById(0), 0, 2);
	world.setBlock(i+0, j+4, k+7, Block.getBlockById(0), 0, 2);
	world.setBlock(i+1, j+4, k+7, Block.getBlockById(0), 0, 2);
	world.setBlock(i+2, j+4, k+7, Block.getBlockById(0), 0, 2);
	world.setBlock(i+3, j+4, k+7, Block.getBlockById(0), 0, 2);
	world.setBlock(i+4, j+4, k+7, Block.getBlockById(0), 0, 2);
	world.setBlock(i+5, j+4, k+7, Block.getBlockById(0), 0, 2);
	world.setBlock(i+6, j+4, k+7, Block.getBlockById(0), 0, 2);
	world.setBlock(i+7, j+4, k+7, Block.getBlockById(0), 0, 2);
	world.setBlock(i+8, j+4, k+7, Block.getBlockById(0), 0, 2);
	world.setBlock(i+9, j+4, k+7, Block.getBlockById(0), 0, 2);
	world.setBlock(i+0, j+4, k+8, Block.getBlockById(0), 0, 2);
	world.setBlock(i+1, j+4, k+8, Block.getBlockById(0), 0, 2);
	world.setBlock(i+2, j+4, k+8, Block.getBlockById(0), 0, 2);
	world.setBlock(i+3, j+4, k+8, Block.getBlockById(0), 0, 2);
	world.setBlock(i+4, j+4, k+8, Block.getBlockById(0), 0, 2);
	world.setBlock(i+5, j+4, k+8, Block.getBlockById(0), 0, 2);
	world.setBlock(i+6, j+4, k+8, Block.getBlockById(0), 0, 2);
	world.setBlock(i+7, j+4, k+8, Block.getBlockById(0), 0, 2);
	world.setBlock(i+8, j+4, k+8, Block.getBlockById(0), 0, 2);
	world.setBlock(i+9, j+4, k+8, Block.getBlockById(0), 0, 2);
	world.setBlock(i+0, j+4, k+9, Block.getBlockById(0), 0, 2);
	world.setBlock(i+1, j+4, k+9, Block.getBlockById(0), 0, 2);
	world.setBlock(i+2, j+4, k+9, Block.getBlockById(0), 0, 2);
	world.setBlock(i+3, j+4, k+9, Block.getBlockById(0), 0, 2);
	world.setBlock(i+4, j+4, k+9, Block.getBlockById(0), 0, 2);
	world.setBlock(i+5, j+4, k+9, Block.getBlockById(0), 0, 2);
	world.setBlock(i+6, j+4, k+9, Block.getBlockById(0), 0, 2);
	world.setBlock(i+7, j+4, k+9, Block.getBlockById(0), 0, 2);
	world.setBlock(i+8, j+4, k+9, Block.getBlockById(0), 0, 2);
	world.setBlock(i+9, j+4, k+9, Block.getBlockById(0), 0, 2);
	world.setBlock(i+0, j+5, k+0, Block.getBlockById(0), 0, 2);
	world.setBlock(i+1, j+5, k+0, Block.getBlockById(0), 0, 2);
	world.setBlock(i+2, j+5, k+0, Block.getBlockById(0), 0, 2);
	world.setBlock(i+3, j+5, k+0, Block.getBlockById(0), 0, 2);
	world.setBlock(i+4, j+5, k+0, Block.getBlockById(0), 0, 2);
	world.setBlock(i+5, j+5, k+0, Block.getBlockById(0), 0, 2);
	world.setBlock(i+6, j+5, k+0, Block.getBlockById(0), 0, 2);
	world.setBlock(i+7, j+5, k+0, Block.getBlockById(0), 0, 2);
	world.setBlock(i+8, j+5, k+0, Block.getBlockById(0), 0, 2);
	world.setBlock(i+9, j+5, k+0, Block.getBlockById(0), 0, 2);
	world.setBlock(i+0, j+5, k+1, Block.getBlockById(0), 0, 2);
	world.setBlock(i+1, j+5, k+1, Block.getBlockById(0), 0, 2);
	world.setBlock(i+2, j+5, k+1, Block.getBlockById(0), 0, 2);
	world.setBlock(i+3, j+5, k+1, Block.getBlockById(0), 0, 2);
	world.setBlock(i+4, j+5, k+1, Block.getBlockById(0), 0, 2);
	world.setBlock(i+5, j+5, k+1, Block.getBlockById(0), 0, 2);
	world.setBlock(i+6, j+5, k+1, Block.getBlockById(0), 0, 2);
	world.setBlock(i+7, j+5, k+1, Block.getBlockById(0), 0, 2);
	world.setBlock(i+8, j+5, k+1, Block.getBlockById(0), 0, 2);
	world.setBlock(i+9, j+5, k+1, Block.getBlockById(0), 0, 2);
	world.setBlock(i+0, j+5, k+2, Block.getBlockById(0), 0, 2);
	world.setBlock(i+1, j+5, k+2, Block.getBlockById(0), 0, 2);
	world.setBlock(i+2, j+5, k+2, Block.getBlockById(0), 0, 2);
	world.setBlock(i+3, j+5, k+2, Block.getBlockById(0), 0, 2);
	world.setBlock(i+4, j+5, k+2, Block.getBlockById(0), 0, 2);
	world.setBlock(i+5, j+5, k+2, Block.getBlockById(0), 0, 2);
	world.setBlock(i+6, j+5, k+2, Block.getBlockById(0), 0, 2);
	world.setBlock(i+7, j+5, k+2, Block.getBlockById(0), 0, 2);
	world.setBlock(i+8, j+5, k+2, Block.getBlockById(0), 0, 2);
	world.setBlock(i+9, j+5, k+2, Block.getBlockById(0), 0, 2);
	world.setBlock(i+0, j+5, k+3, Block.getBlockById(0), 0, 2);
	world.setBlock(i+1, j+5, k+3, Block.getBlockById(0), 0, 2);
	world.setBlock(i+2, j+5, k+3, Block.getBlockById(0), 0, 2);
	world.setBlock(i+3, j+5, k+3, Block.getBlockById(133), 0, 2);
	world.setBlock(i+4, j+5, k+3, Block.getBlockById(133), 0, 2);
	world.setBlock(i+5, j+5, k+3, Block.getBlockById(133), 0, 2);
	world.setBlock(i+6, j+5, k+3, Block.getBlockById(133), 0, 2);
	world.setBlock(i+7, j+5, k+3, Block.getBlockById(0), 0, 2);
	world.setBlock(i+8, j+5, k+3, Block.getBlockById(0), 0, 2);
	world.setBlock(i+9, j+5, k+3, Block.getBlockById(0), 0, 2);
	world.setBlock(i+0, j+5, k+4, Block.getBlockById(0), 0, 2);
	world.setBlock(i+1, j+5, k+4, Block.getBlockById(0), 0, 2);
	world.setBlock(i+2, j+5, k+4, Block.getBlockById(0), 0, 2);
	world.setBlock(i+3, j+5, k+4, Block.getBlockById(133), 0, 2);
	world.setBlock(i+4, j+5, k+4, Block.getBlockById(65), 5, 2);
	world.setBlock(i+5, j+5, k+4, Block.getBlockById(65), 4, 2);
	world.setBlock(i+6, j+5, k+4, Block.getBlockById(133), 0, 2);
	world.setBlock(i+7, j+5, k+4, Block.getBlockById(0), 0, 2);
	world.setBlock(i+8, j+5, k+4, Block.getBlockById(0), 0, 2);
	world.setBlock(i+9, j+5, k+4, Block.getBlockById(0), 0, 2);
	world.setBlock(i+0, j+5, k+5, Block.getBlockById(0), 0, 2);
	world.setBlock(i+1, j+5, k+5, Block.getBlockById(0), 0, 2);
	world.setBlock(i+2, j+5, k+5, Block.getBlockById(0), 0, 2);
	world.setBlock(i+3, j+5, k+5, Block.getBlockById(133), 0, 2);
	world.setBlock(i+4, j+5, k+5, Block.getBlockById(65), 5, 2);
	world.setBlock(i+5, j+5, k+5, Block.getBlockById(65), 4, 2);
	world.setBlock(i+6, j+5, k+5, Block.getBlockById(133), 0, 2);
	world.setBlock(i+7, j+5, k+5, Block.getBlockById(0), 0, 2);
	world.setBlock(i+8, j+5, k+5, Block.getBlockById(0), 0, 2);
	world.setBlock(i+9, j+5, k+5, Block.getBlockById(0), 0, 2);
	world.setBlock(i+0, j+5, k+6, Block.getBlockById(0), 0, 2);
	world.setBlock(i+1, j+5, k+6, Block.getBlockById(0), 0, 2);
	world.setBlock(i+2, j+5, k+6, Block.getBlockById(0), 0, 2);
	world.setBlock(i+3, j+5, k+6, Block.getBlockById(133), 0, 2);
	world.setBlock(i+4, j+5, k+6, Block.getBlockById(133), 0, 2);
	world.setBlock(i+5, j+5, k+6, Block.getBlockById(133), 0, 2);
	world.setBlock(i+6, j+5, k+6, Block.getBlockById(133), 0, 2);
	world.setBlock(i+7, j+5, k+6, Block.getBlockById(0), 0, 2);
	world.setBlock(i+8, j+5, k+6, Block.getBlockById(0), 0, 2);
	world.setBlock(i+9, j+5, k+6, Block.getBlockById(0), 0, 2);
	world.setBlock(i+0, j+5, k+7, Block.getBlockById(0), 0, 2);
	world.setBlock(i+1, j+5, k+7, Block.getBlockById(0), 0, 2);
	world.setBlock(i+2, j+5, k+7, Block.getBlockById(0), 0, 2);
	world.setBlock(i+3, j+5, k+7, Block.getBlockById(0), 0, 2);
	world.setBlock(i+4, j+5, k+7, Block.getBlockById(0), 0, 2);
	world.setBlock(i+5, j+5, k+7, Block.getBlockById(0), 0, 2);
	world.setBlock(i+6, j+5, k+7, Block.getBlockById(0), 0, 2);
	world.setBlock(i+7, j+5, k+7, Block.getBlockById(0), 0, 2);
	world.setBlock(i+8, j+5, k+7, Block.getBlockById(0), 0, 2);
	world.setBlock(i+9, j+5, k+7, Block.getBlockById(0), 0, 2);
	world.setBlock(i+0, j+5, k+8, Block.getBlockById(0), 0, 2);
	world.setBlock(i+1, j+5, k+8, Block.getBlockById(0), 0, 2);
	world.setBlock(i+2, j+5, k+8, Block.getBlockById(0), 0, 2);
	world.setBlock(i+3, j+5, k+8, Block.getBlockById(0), 0, 2);
	world.setBlock(i+4, j+5, k+8, Block.getBlockById(0), 0, 2);
	world.setBlock(i+5, j+5, k+8, Block.getBlockById(0), 0, 2);
	world.setBlock(i+6, j+5, k+8, Block.getBlockById(0), 0, 2);
	world.setBlock(i+7, j+5, k+8, Block.getBlockById(0), 0, 2);
	world.setBlock(i+8, j+5, k+8, Block.getBlockById(0), 0, 2);
	world.setBlock(i+9, j+5, k+8, Block.getBlockById(0), 0, 2);
	world.setBlock(i+0, j+5, k+9, Block.getBlockById(0), 0, 2);
	world.setBlock(i+1, j+5, k+9, Block.getBlockById(0), 0, 2);
	world.setBlock(i+2, j+5, k+9, Block.getBlockById(0), 0, 2);
	world.setBlock(i+3, j+5, k+9, Block.getBlockById(0), 0, 2);
	world.setBlock(i+4, j+5, k+9, Block.getBlockById(0), 0, 2);
	world.setBlock(i+5, j+5, k+9, Block.getBlockById(0), 0, 2);
	world.setBlock(i+6, j+5, k+9, Block.getBlockById(0), 0, 2);
	world.setBlock(i+7, j+5, k+9, Block.getBlockById(0), 0, 2);
	world.setBlock(i+8, j+5, k+9, Block.getBlockById(0), 0, 2);
	world.setBlock(i+9, j+5, k+9, Block.getBlockById(0), 0, 2);
	world.setBlock(i+0, j+6, k+0, Block.getBlockById(0), 0, 2);
	world.setBlock(i+1, j+6, k+0, Block.getBlockById(0), 0, 2);
	world.setBlock(i+2, j+6, k+0, Block.getBlockById(0), 0, 2);
	world.setBlock(i+3, j+6, k+0, Block.getBlockById(0), 0, 2);
	world.setBlock(i+4, j+6, k+0, Block.getBlockById(0), 0, 2);
	world.setBlock(i+5, j+6, k+0, Block.getBlockById(0), 0, 2);
	world.setBlock(i+6, j+6, k+0, Block.getBlockById(0), 0, 2);
	world.setBlock(i+7, j+6, k+0, Block.getBlockById(0), 0, 2);
	world.setBlock(i+8, j+6, k+0, Block.getBlockById(0), 0, 2);
	world.setBlock(i+9, j+6, k+0, Block.getBlockById(0), 0, 2);
	world.setBlock(i+0, j+6, k+1, Block.getBlockById(0), 0, 2);
	world.setBlock(i+1, j+6, k+1, Block.getBlockById(0), 0, 2);
	world.setBlock(i+2, j+6, k+1, Block.getBlockById(0), 0, 2);
	world.setBlock(i+3, j+6, k+1, Block.getBlockById(0), 0, 2);
	world.setBlock(i+4, j+6, k+1, Block.getBlockById(0), 0, 2);
	world.setBlock(i+5, j+6, k+1, Block.getBlockById(0), 0, 2);
	world.setBlock(i+6, j+6, k+1, Block.getBlockById(0), 0, 2);
	world.setBlock(i+7, j+6, k+1, Block.getBlockById(0), 0, 2);
	world.setBlock(i+8, j+6, k+1, Block.getBlockById(0), 0, 2);
	world.setBlock(i+9, j+6, k+1, Block.getBlockById(0), 0, 2);
	world.setBlock(i+0, j+6, k+2, Block.getBlockById(0), 0, 2);
	world.setBlock(i+1, j+6, k+2, Block.getBlockById(0), 0, 2);
	world.setBlock(i+2, j+6, k+2, Block.getBlockById(0), 0, 2);
	world.setBlock(i+3, j+6, k+2, Block.getBlockById(0), 0, 2);
	world.setBlock(i+4, j+6, k+2, Block.getBlockById(0), 0, 2);
	world.setBlock(i+5, j+6, k+2, Block.getBlockById(0), 0, 2);
	world.setBlock(i+6, j+6, k+2, Block.getBlockById(0), 0, 2);
	world.setBlock(i+7, j+6, k+2, Block.getBlockById(0), 0, 2);
	world.setBlock(i+8, j+6, k+2, Block.getBlockById(0), 0, 2);
	world.setBlock(i+9, j+6, k+2, Block.getBlockById(0), 0, 2);
	world.setBlock(i+0, j+6, k+3, Block.getBlockById(0), 0, 2);
	world.setBlock(i+1, j+6, k+3, Block.getBlockById(0), 0, 2);
	world.setBlock(i+2, j+6, k+3, Block.getBlockById(0), 0, 2);
	world.setBlock(i+3, j+6, k+3, Block.getBlockById(133), 0, 2);
	world.setBlock(i+4, j+6, k+3, Block.getBlockById(133), 0, 2);
	world.setBlock(i+5, j+6, k+3, Block.getBlockById(133), 0, 2);
	world.setBlock(i+6, j+6, k+3, Block.getBlockById(133), 0, 2);
	world.setBlock(i+7, j+6, k+3, Block.getBlockById(0), 0, 2);
	world.setBlock(i+8, j+6, k+3, Block.getBlockById(0), 0, 2);
	world.setBlock(i+9, j+6, k+3, Block.getBlockById(0), 0, 2);
	world.setBlock(i+0, j+6, k+4, Block.getBlockById(0), 0, 2);
	world.setBlock(i+1, j+6, k+4, Block.getBlockById(0), 0, 2);
	world.setBlock(i+2, j+6, k+4, Block.getBlockById(0), 0, 2);
	world.setBlock(i+3, j+6, k+4, Block.getBlockById(133), 0, 2);
	world.setBlock(i+4, j+6, k+4, Block.getBlockById(65), 5, 2);
	world.setBlock(i+5, j+6, k+4, Block.getBlockById(65), 4, 2);
	world.setBlock(i+6, j+6, k+4, Block.getBlockById(133), 0, 2);
	world.setBlock(i+7, j+6, k+4, Block.getBlockById(0), 0, 2);
	world.setBlock(i+8, j+6, k+4, Block.getBlockById(0), 0, 2);
	world.setBlock(i+9, j+6, k+4, Block.getBlockById(0), 0, 2);
	world.setBlock(i+0, j+6, k+5, Block.getBlockById(0), 0, 2);
	world.setBlock(i+1, j+6, k+5, Block.getBlockById(0), 0, 2);
	world.setBlock(i+2, j+6, k+5, Block.getBlockById(0), 0, 2);
	world.setBlock(i+3, j+6, k+5, Block.getBlockById(133), 0, 2);
	world.setBlock(i+4, j+6, k+5, Block.getBlockById(65), 5, 2);
	world.setBlock(i+5, j+6, k+5, Block.getBlockById(65), 4, 2);
	world.setBlock(i+6, j+6, k+5, Block.getBlockById(133), 0, 2);
	world.setBlock(i+7, j+6, k+5, Block.getBlockById(0), 0, 2);
	world.setBlock(i+8, j+6, k+5, Block.getBlockById(0), 0, 2);
	world.setBlock(i+9, j+6, k+5, Block.getBlockById(0), 0, 2);
	world.setBlock(i+0, j+6, k+6, Block.getBlockById(0), 0, 2);
	world.setBlock(i+1, j+6, k+6, Block.getBlockById(0), 0, 2);
	world.setBlock(i+2, j+6, k+6, Block.getBlockById(0), 0, 2);
	world.setBlock(i+3, j+6, k+6, Block.getBlockById(133), 0, 2);
	world.setBlock(i+4, j+6, k+6, Block.getBlockById(133), 0, 2);
	world.setBlock(i+5, j+6, k+6, Block.getBlockById(133), 0, 2);
	world.setBlock(i+6, j+6, k+6, Block.getBlockById(133), 0, 2);
	world.setBlock(i+7, j+6, k+6, Block.getBlockById(0), 0, 2);
	world.setBlock(i+8, j+6, k+6, Block.getBlockById(0), 0, 2);
	world.setBlock(i+9, j+6, k+6, Block.getBlockById(0), 0, 2);
	world.setBlock(i+0, j+6, k+7, Block.getBlockById(0), 0, 2);
	world.setBlock(i+1, j+6, k+7, Block.getBlockById(0), 0, 2);
	world.setBlock(i+2, j+6, k+7, Block.getBlockById(0), 0, 2);
	world.setBlock(i+3, j+6, k+7, Block.getBlockById(0), 0, 2);
	world.setBlock(i+4, j+6, k+7, Block.getBlockById(0), 0, 2);
	world.setBlock(i+5, j+6, k+7, Block.getBlockById(0), 0, 2);
	world.setBlock(i+6, j+6, k+7, Block.getBlockById(0), 0, 2);
	world.setBlock(i+7, j+6, k+7, Block.getBlockById(0), 0, 2);
	world.setBlock(i+8, j+6, k+7, Block.getBlockById(0), 0, 2);
	world.setBlock(i+9, j+6, k+7, Block.getBlockById(0), 0, 2);
	world.setBlock(i+0, j+6, k+8, Block.getBlockById(0), 0, 2);
	world.setBlock(i+1, j+6, k+8, Block.getBlockById(0), 0, 2);
	world.setBlock(i+2, j+6, k+8, Block.getBlockById(0), 0, 2);
	world.setBlock(i+3, j+6, k+8, Block.getBlockById(0), 0, 2);
	world.setBlock(i+4, j+6, k+8, Block.getBlockById(0), 0, 2);
	world.setBlock(i+5, j+6, k+8, Block.getBlockById(0), 0, 2);
	world.setBlock(i+6, j+6, k+8, Block.getBlockById(0), 0, 2);
	world.setBlock(i+7, j+6, k+8, Block.getBlockById(0), 0, 2);
	world.setBlock(i+8, j+6, k+8, Block.getBlockById(0), 0, 2);
	world.setBlock(i+9, j+6, k+8, Block.getBlockById(0), 0, 2);
	world.setBlock(i+0, j+6, k+9, Block.getBlockById(0), 0, 2);
	world.setBlock(i+1, j+6, k+9, Block.getBlockById(0), 0, 2);
	world.setBlock(i+2, j+6, k+9, Block.getBlockById(0), 0, 2);
	world.setBlock(i+3, j+6, k+9, Block.getBlockById(0), 0, 2);
	world.setBlock(i+4, j+6, k+9, Block.getBlockById(0), 0, 2);
	world.setBlock(i+5, j+6, k+9, Block.getBlockById(0), 0, 2);
	world.setBlock(i+6, j+6, k+9, Block.getBlockById(0), 0, 2);
	world.setBlock(i+7, j+6, k+9, Block.getBlockById(0), 0, 2);
	world.setBlock(i+8, j+6, k+9, Block.getBlockById(0), 0, 2);
	world.setBlock(i+9, j+6, k+9, Block.getBlockById(0), 0, 2);
	world.setBlock(i+0, j+7, k+0, Block.getBlockById(0), 0, 2);
	world.setBlock(i+1, j+7, k+0, Block.getBlockById(0), 0, 2);
	world.setBlock(i+2, j+7, k+0, Block.getBlockById(0), 0, 2);
	world.setBlock(i+3, j+7, k+0, Block.getBlockById(0), 0, 2);
	world.setBlock(i+4, j+7, k+0, Block.getBlockById(0), 0, 2);
	world.setBlock(i+5, j+7, k+0, Block.getBlockById(0), 0, 2);
	world.setBlock(i+6, j+7, k+0, Block.getBlockById(0), 0, 2);
	world.setBlock(i+7, j+7, k+0, Block.getBlockById(0), 0, 2);
	world.setBlock(i+8, j+7, k+0, Block.getBlockById(0), 0, 2);
	world.setBlock(i+9, j+7, k+0, Block.getBlockById(0), 0, 2);
	world.setBlock(i+0, j+7, k+1, Block.getBlockById(0), 0, 2);
	world.setBlock(i+1, j+7, k+1, Block.getBlockById(0), 0, 2);
	world.setBlock(i+2, j+7, k+1, Block.getBlockById(0), 0, 2);
	world.setBlock(i+3, j+7, k+1, Block.getBlockById(0), 0, 2);
	world.setBlock(i+4, j+7, k+1, Block.getBlockById(0), 0, 2);
	world.setBlock(i+5, j+7, k+1, Block.getBlockById(0), 0, 2);
	world.setBlock(i+6, j+7, k+1, Block.getBlockById(0), 0, 2);
	world.setBlock(i+7, j+7, k+1, Block.getBlockById(0), 0, 2);
	world.setBlock(i+8, j+7, k+1, Block.getBlockById(0), 0, 2);
	world.setBlock(i+9, j+7, k+1, Block.getBlockById(0), 0, 2);
	world.setBlock(i+0, j+7, k+2, Block.getBlockById(0), 0, 2);
	world.setBlock(i+1, j+7, k+2, Block.getBlockById(0), 0, 2);
	world.setBlock(i+2, j+7, k+2, Block.getBlockById(0), 0, 2);
	world.setBlock(i+3, j+7, k+2, Block.getBlockById(0), 0, 2);
	world.setBlock(i+4, j+7, k+2, Block.getBlockById(0), 0, 2);
	world.setBlock(i+5, j+7, k+2, Block.getBlockById(0), 0, 2);
	world.setBlock(i+6, j+7, k+2, Block.getBlockById(0), 0, 2);
	world.setBlock(i+7, j+7, k+2, Block.getBlockById(0), 0, 2);
	world.setBlock(i+8, j+7, k+2, Block.getBlockById(0), 0, 2);
	world.setBlock(i+9, j+7, k+2, Block.getBlockById(0), 0, 2);
	world.setBlock(i+0, j+7, k+3, Block.getBlockById(0), 0, 2);
	world.setBlock(i+1, j+7, k+3, Block.getBlockById(0), 0, 2);
	world.setBlock(i+2, j+7, k+3, Block.getBlockById(0), 0, 2);
	world.setBlock(i+3, j+7, k+3, Block.getBlockById(133), 0, 2);
	world.setBlock(i+4, j+7, k+3, Block.getBlockById(133), 0, 2);
	world.setBlock(i+5, j+7, k+3, Block.getBlockById(133), 0, 2);
	world.setBlock(i+6, j+7, k+3, Block.getBlockById(133), 0, 2);
	world.setBlock(i+7, j+7, k+3, Block.getBlockById(0), 0, 2);
	world.setBlock(i+8, j+7, k+3, Block.getBlockById(0), 0, 2);
	world.setBlock(i+9, j+7, k+3, Block.getBlockById(0), 0, 2);
	world.setBlock(i+0, j+7, k+4, Block.getBlockById(0), 0, 2);
	world.setBlock(i+1, j+7, k+4, Block.getBlockById(0), 0, 2);
	world.setBlock(i+2, j+7, k+4, Block.getBlockById(0), 0, 2);
	world.setBlock(i+3, j+7, k+4, Block.getBlockById(133), 0, 2);
	world.setBlock(i+4, j+7, k+4, Block.getBlockById(65), 5, 2);
	world.setBlock(i+5, j+7, k+4, Block.getBlockById(65), 4, 2);
	world.setBlock(i+6, j+7, k+4, Block.getBlockById(133), 0, 2);
	world.setBlock(i+7, j+7, k+4, Block.getBlockById(0), 0, 2);
	world.setBlock(i+8, j+7, k+4, Block.getBlockById(0), 0, 2);
	world.setBlock(i+9, j+7, k+4, Block.getBlockById(0), 0, 2);
	world.setBlock(i+0, j+7, k+5, Block.getBlockById(0), 0, 2);
	world.setBlock(i+1, j+7, k+5, Block.getBlockById(0), 0, 2);
	world.setBlock(i+2, j+7, k+5, Block.getBlockById(0), 0, 2);
	world.setBlock(i+3, j+7, k+5, Block.getBlockById(133), 0, 2);
	world.setBlock(i+4, j+7, k+5, Block.getBlockById(65), 5, 2);
	world.setBlock(i+5, j+7, k+5, Block.getBlockById(65), 4, 2);
	world.setBlock(i+6, j+7, k+5, Block.getBlockById(133), 0, 2);
	world.setBlock(i+7, j+7, k+5, Block.getBlockById(0), 0, 2);
	world.setBlock(i+8, j+7, k+5, Block.getBlockById(0), 0, 2);
	world.setBlock(i+9, j+7, k+5, Block.getBlockById(0), 0, 2);
	world.setBlock(i+0, j+7, k+6, Block.getBlockById(0), 0, 2);
	world.setBlock(i+1, j+7, k+6, Block.getBlockById(0), 0, 2);
	world.setBlock(i+2, j+7, k+6, Block.getBlockById(0), 0, 2);
	world.setBlock(i+3, j+7, k+6, Block.getBlockById(133), 0, 2);
	world.setBlock(i+4, j+7, k+6, Block.getBlockById(133), 0, 2);
	world.setBlock(i+5, j+7, k+6, Block.getBlockById(133), 0, 2);
	world.setBlock(i+6, j+7, k+6, Block.getBlockById(133), 0, 2);
	world.setBlock(i+7, j+7, k+6, Block.getBlockById(0), 0, 2);
	world.setBlock(i+8, j+7, k+6, Block.getBlockById(0), 0, 2);
	world.setBlock(i+9, j+7, k+6, Block.getBlockById(0), 0, 2);
	world.setBlock(i+0, j+7, k+7, Block.getBlockById(0), 0, 2);
	world.setBlock(i+1, j+7, k+7, Block.getBlockById(0), 0, 2);
	world.setBlock(i+2, j+7, k+7, Block.getBlockById(0), 0, 2);
	world.setBlock(i+3, j+7, k+7, Block.getBlockById(0), 0, 2);
	world.setBlock(i+4, j+7, k+7, Block.getBlockById(0), 0, 2);
	world.setBlock(i+5, j+7, k+7, Block.getBlockById(0), 0, 2);
	world.setBlock(i+6, j+7, k+7, Block.getBlockById(0), 0, 2);
	world.setBlock(i+7, j+7, k+7, Block.getBlockById(0), 0, 2);
	world.setBlock(i+8, j+7, k+7, Block.getBlockById(0), 0, 2);
	world.setBlock(i+9, j+7, k+7, Block.getBlockById(0), 0, 2);
	world.setBlock(i+0, j+7, k+8, Block.getBlockById(0), 0, 2);
	world.setBlock(i+1, j+7, k+8, Block.getBlockById(0), 0, 2);
	world.setBlock(i+2, j+7, k+8, Block.getBlockById(0), 0, 2);
	world.setBlock(i+3, j+7, k+8, Block.getBlockById(0), 0, 2);
	world.setBlock(i+4, j+7, k+8, Block.getBlockById(0), 0, 2);
	world.setBlock(i+5, j+7, k+8, Block.getBlockById(0), 0, 2);
	world.setBlock(i+6, j+7, k+8, Block.getBlockById(0), 0, 2);
	world.setBlock(i+7, j+7, k+8, Block.getBlockById(0), 0, 2);
	world.setBlock(i+8, j+7, k+8, Block.getBlockById(0), 0, 2);
	world.setBlock(i+9, j+7, k+8, Block.getBlockById(0), 0, 2);
	world.setBlock(i+0, j+7, k+9, Block.getBlockById(0), 0, 2);
	world.setBlock(i+1, j+7, k+9, Block.getBlockById(0), 0, 2);
	world.setBlock(i+2, j+7, k+9, Block.getBlockById(0), 0, 2);
	world.setBlock(i+3, j+7, k+9, Block.getBlockById(0), 0, 2);
	world.setBlock(i+4, j+7, k+9, Block.getBlockById(0), 0, 2);
	world.setBlock(i+5, j+7, k+9, Block.getBlockById(0), 0, 2);
	world.setBlock(i+6, j+7, k+9, Block.getBlockById(0), 0, 2);
	world.setBlock(i+7, j+7, k+9, Block.getBlockById(0), 0, 2);
	world.setBlock(i+8, j+7, k+9, Block.getBlockById(0), 0, 2);
	world.setBlock(i+9, j+7, k+9, Block.getBlockById(0), 0, 2);
	world.setBlock(i+0, j+8, k+0, Block.getBlockById(0), 0, 2);
	world.setBlock(i+1, j+8, k+0, Block.getBlockById(0), 0, 2);
	world.setBlock(i+2, j+8, k+0, Block.getBlockById(0), 0, 2);
	world.setBlock(i+3, j+8, k+0, Block.getBlockById(0), 0, 2);
	world.setBlock(i+4, j+8, k+0, Block.getBlockById(0), 0, 2);
	world.setBlock(i+5, j+8, k+0, Block.getBlockById(0), 0, 2);
	world.setBlock(i+6, j+8, k+0, Block.getBlockById(0), 0, 2);
	world.setBlock(i+7, j+8, k+0, Block.getBlockById(0), 0, 2);
	world.setBlock(i+8, j+8, k+0, Block.getBlockById(0), 0, 2);
	world.setBlock(i+9, j+8, k+0, Block.getBlockById(0), 0, 2);
	world.setBlock(i+0, j+8, k+1, Block.getBlockById(0), 0, 2);
	world.setBlock(i+1, j+8, k+1, Block.getBlockById(0), 0, 2);
	world.setBlock(i+2, j+8, k+1, Block.getBlockById(0), 0, 2);
	world.setBlock(i+3, j+8, k+1, Block.getBlockById(0), 0, 2);
	world.setBlock(i+4, j+8, k+1, Block.getBlockById(0), 0, 2);
	world.setBlock(i+5, j+8, k+1, Block.getBlockById(0), 0, 2);
	world.setBlock(i+6, j+8, k+1, Block.getBlockById(0), 0, 2);
	world.setBlock(i+7, j+8, k+1, Block.getBlockById(0), 0, 2);
	world.setBlock(i+8, j+8, k+1, Block.getBlockById(0), 0, 2);
	world.setBlock(i+9, j+8, k+1, Block.getBlockById(0), 0, 2);
	world.setBlock(i+0, j+8, k+2, Block.getBlockById(0), 0, 2);
	world.setBlock(i+1, j+8, k+2, Block.getBlockById(0), 0, 2);
	world.setBlock(i+2, j+8, k+2, Block.getBlockById(0), 0, 2);
	world.setBlock(i+3, j+8, k+2, Block.getBlockById(0), 0, 2);
	world.setBlock(i+4, j+8, k+2, Block.getBlockById(0), 0, 2);
	world.setBlock(i+5, j+8, k+2, Block.getBlockById(0), 0, 2);
	world.setBlock(i+6, j+8, k+2, Block.getBlockById(0), 0, 2);
	world.setBlock(i+7, j+8, k+2, Block.getBlockById(0), 0, 2);
	world.setBlock(i+8, j+8, k+2, Block.getBlockById(0), 0, 2);
	world.setBlock(i+9, j+8, k+2, Block.getBlockById(0), 0, 2);
	world.setBlock(i+0, j+8, k+3, Block.getBlockById(0), 0, 2);
	world.setBlock(i+1, j+8, k+3, Block.getBlockById(0), 0, 2);
	world.setBlock(i+2, j+8, k+3, Block.getBlockById(0), 0, 2);
	world.setBlock(i+3, j+8, k+3, Block.getBlockById(133), 0, 2);
	world.setBlock(i+4, j+8, k+3, Block.getBlockById(133), 0, 2);
	world.setBlock(i+5, j+8, k+3, Block.getBlockById(133), 0, 2);
	world.setBlock(i+6, j+8, k+3, Block.getBlockById(133), 0, 2);
	world.setBlock(i+7, j+8, k+3, Block.getBlockById(0), 0, 2);
	world.setBlock(i+8, j+8, k+3, Block.getBlockById(0), 0, 2);
	world.setBlock(i+9, j+8, k+3, Block.getBlockById(0), 0, 2);
	world.setBlock(i+0, j+8, k+4, Block.getBlockById(0), 0, 2);
	world.setBlock(i+1, j+8, k+4, Block.getBlockById(0), 0, 2);
	world.setBlock(i+2, j+8, k+4, Block.getBlockById(0), 0, 2);
	world.setBlock(i+3, j+8, k+4, Block.getBlockById(133), 0, 2);
	world.setBlock(i+4, j+8, k+4, Block.getBlockById(65), 5, 2);
	world.setBlock(i+5, j+8, k+4, Block.getBlockById(65), 4, 2);
	world.setBlock(i+6, j+8, k+4, Block.getBlockById(133), 0, 2);
	world.setBlock(i+7, j+8, k+4, Block.getBlockById(0), 0, 2);
	world.setBlock(i+8, j+8, k+4, Block.getBlockById(0), 0, 2);
	world.setBlock(i+9, j+8, k+4, Block.getBlockById(0), 0, 2);
	world.setBlock(i+0, j+8, k+5, Block.getBlockById(0), 0, 2);
	world.setBlock(i+1, j+8, k+5, Block.getBlockById(0), 0, 2);
	world.setBlock(i+2, j+8, k+5, Block.getBlockById(0), 0, 2);
	world.setBlock(i+3, j+8, k+5, Block.getBlockById(133), 0, 2);
	world.setBlock(i+4, j+8, k+5, Block.getBlockById(65), 5, 2);
	world.setBlock(i+5, j+8, k+5, Block.getBlockById(65), 4, 2);
	world.setBlock(i+6, j+8, k+5, Block.getBlockById(133), 0, 2);
	world.setBlock(i+7, j+8, k+5, Block.getBlockById(0), 0, 2);
	world.setBlock(i+8, j+8, k+5, Block.getBlockById(0), 0, 2);
	world.setBlock(i+9, j+8, k+5, Block.getBlockById(0), 0, 2);
	world.setBlock(i+0, j+8, k+6, Block.getBlockById(0), 0, 2);
	world.setBlock(i+1, j+8, k+6, Block.getBlockById(0), 0, 2);
	world.setBlock(i+2, j+8, k+6, Block.getBlockById(0), 0, 2);
	world.setBlock(i+3, j+8, k+6, Block.getBlockById(133), 0, 2);
	world.setBlock(i+4, j+8, k+6, Block.getBlockById(133), 0, 2);
	world.setBlock(i+5, j+8, k+6, Block.getBlockById(133), 0, 2);
	world.setBlock(i+6, j+8, k+6, Block.getBlockById(133), 0, 2);
	world.setBlock(i+7, j+8, k+6, Block.getBlockById(0), 0, 2);
	world.setBlock(i+8, j+8, k+6, Block.getBlockById(0), 0, 2);
	world.setBlock(i+9, j+8, k+6, Block.getBlockById(0), 0, 2);
	world.setBlock(i+0, j+8, k+7, Block.getBlockById(0), 0, 2);
	world.setBlock(i+1, j+8, k+7, Block.getBlockById(0), 0, 2);
	world.setBlock(i+2, j+8, k+7, Block.getBlockById(0), 0, 2);
	world.setBlock(i+3, j+8, k+7, Block.getBlockById(0), 0, 2);
	world.setBlock(i+4, j+8, k+7, Block.getBlockById(0), 0, 2);
	world.setBlock(i+5, j+8, k+7, Block.getBlockById(0), 0, 2);
	world.setBlock(i+6, j+8, k+7, Block.getBlockById(0), 0, 2);
	world.setBlock(i+7, j+8, k+7, Block.getBlockById(0), 0, 2);
	world.setBlock(i+8, j+8, k+7, Block.getBlockById(0), 0, 2);
	world.setBlock(i+9, j+8, k+7, Block.getBlockById(0), 0, 2);
	world.setBlock(i+0, j+8, k+8, Block.getBlockById(0), 0, 2);
	world.setBlock(i+1, j+8, k+8, Block.getBlockById(0), 0, 2);
	world.setBlock(i+2, j+8, k+8, Block.getBlockById(0), 0, 2);
	world.setBlock(i+3, j+8, k+8, Block.getBlockById(0), 0, 2);
	world.setBlock(i+4, j+8, k+8, Block.getBlockById(0), 0, 2);
	world.setBlock(i+5, j+8, k+8, Block.getBlockById(0), 0, 2);
	world.setBlock(i+6, j+8, k+8, Block.getBlockById(0), 0, 2);
	world.setBlock(i+7, j+8, k+8, Block.getBlockById(0), 0, 2);
	world.setBlock(i+8, j+8, k+8, Block.getBlockById(0), 0, 2);
	world.setBlock(i+9, j+8, k+8, Block.getBlockById(0), 0, 2);
	world.setBlock(i+0, j+8, k+9, Block.getBlockById(0), 0, 2);
	world.setBlock(i+1, j+8, k+9, Block.getBlockById(0), 0, 2);
	world.setBlock(i+2, j+8, k+9, Block.getBlockById(0), 0, 2);
	world.setBlock(i+3, j+8, k+9, Block.getBlockById(0), 0, 2);
	world.setBlock(i+4, j+8, k+9, Block.getBlockById(0), 0, 2);
	world.setBlock(i+5, j+8, k+9, Block.getBlockById(0), 0, 2);
	world.setBlock(i+6, j+8, k+9, Block.getBlockById(0), 0, 2);
	world.setBlock(i+7, j+8, k+9, Block.getBlockById(0), 0, 2);
	world.setBlock(i+8, j+8, k+9, Block.getBlockById(0), 0, 2);
	world.setBlock(i+9, j+8, k+9, Block.getBlockById(0), 0, 2);
	world.setBlock(i+0, j+9, k+0, Block.getBlockById(0), 0, 2);
	world.setBlock(i+1, j+9, k+0, Block.getBlockById(0), 0, 2);
	world.setBlock(i+2, j+9, k+0, Block.getBlockById(0), 0, 2);
	world.setBlock(i+3, j+9, k+0, Block.getBlockById(0), 0, 2);
	world.setBlock(i+4, j+9, k+0, Block.getBlockById(0), 0, 2);
	world.setBlock(i+5, j+9, k+0, Block.getBlockById(0), 0, 2);
	world.setBlock(i+6, j+9, k+0, Block.getBlockById(0), 0, 2);
	world.setBlock(i+7, j+9, k+0, Block.getBlockById(0), 0, 2);
	world.setBlock(i+8, j+9, k+0, Block.getBlockById(0), 0, 2);
	world.setBlock(i+9, j+9, k+0, Block.getBlockById(0), 0, 2);
	world.setBlock(i+0, j+9, k+1, Block.getBlockById(0), 0, 2);
	world.setBlock(i+1, j+9, k+1, Block.getBlockById(0), 0, 2);
	world.setBlock(i+2, j+9, k+1, Block.getBlockById(0), 0, 2);
	world.setBlock(i+3, j+9, k+1, Block.getBlockById(0), 0, 2);
	world.setBlock(i+4, j+9, k+1, Block.getBlockById(0), 0, 2);
	world.setBlock(i+5, j+9, k+1, Block.getBlockById(0), 0, 2);
	world.setBlock(i+6, j+9, k+1, Block.getBlockById(0), 0, 2);
	world.setBlock(i+7, j+9, k+1, Block.getBlockById(0), 0, 2);
	world.setBlock(i+8, j+9, k+1, Block.getBlockById(0), 0, 2);
	world.setBlock(i+9, j+9, k+1, Block.getBlockById(0), 0, 2);
	world.setBlock(i+0, j+9, k+2, Block.getBlockById(0), 0, 2);
	world.setBlock(i+1, j+9, k+2, Block.getBlockById(0), 0, 2);
	world.setBlock(i+2, j+9, k+2, Block.getBlockById(0), 0, 2);
	world.setBlock(i+3, j+9, k+2, Block.getBlockById(0), 0, 2);
	world.setBlock(i+4, j+9, k+2, Block.getBlockById(0), 0, 2);
	world.setBlock(i+5, j+9, k+2, Block.getBlockById(0), 0, 2);
	world.setBlock(i+6, j+9, k+2, Block.getBlockById(0), 0, 2);
	world.setBlock(i+7, j+9, k+2, Block.getBlockById(0), 0, 2);
	world.setBlock(i+8, j+9, k+2, Block.getBlockById(0), 0, 2);
	world.setBlock(i+9, j+9, k+2, Block.getBlockById(0), 0, 2);
	world.setBlock(i+0, j+9, k+3, Block.getBlockById(0), 0, 2);
	world.setBlock(i+1, j+9, k+3, Block.getBlockById(0), 0, 2);
	world.setBlock(i+2, j+9, k+3, Block.getBlockById(0), 0, 2);
	world.setBlock(i+3, j+9, k+3, Block.getBlockById(133), 0, 2);
	world.setBlock(i+4, j+9, k+3, Block.getBlockById(133), 0, 2);
	world.setBlock(i+5, j+9, k+3, Block.getBlockById(133), 0, 2);
	world.setBlock(i+6, j+9, k+3, Block.getBlockById(133), 0, 2);
	world.setBlock(i+7, j+9, k+3, Block.getBlockById(0), 0, 2);
	world.setBlock(i+8, j+9, k+3, Block.getBlockById(0), 0, 2);
	world.setBlock(i+9, j+9, k+3, Block.getBlockById(0), 0, 2);
	world.setBlock(i+0, j+9, k+4, Block.getBlockById(0), 0, 2);
	world.setBlock(i+1, j+9, k+4, Block.getBlockById(0), 0, 2);
	world.setBlock(i+2, j+9, k+4, Block.getBlockById(0), 0, 2);
	world.setBlock(i+3, j+9, k+4, Block.getBlockById(133), 0, 2);
	world.setBlock(i+4, j+9, k+4, Block.getBlockById(65), 5, 2);
	world.setBlock(i+5, j+9, k+4, Block.getBlockById(65), 4, 2);
	world.setBlock(i+6, j+9, k+4, Block.getBlockById(133), 0, 2);
	world.setBlock(i+7, j+9, k+4, Block.getBlockById(0), 0, 2);
	world.setBlock(i+8, j+9, k+4, Block.getBlockById(0), 0, 2);
	world.setBlock(i+9, j+9, k+4, Block.getBlockById(0), 0, 2);
	world.setBlock(i+0, j+9, k+5, Block.getBlockById(0), 0, 2);
	world.setBlock(i+1, j+9, k+5, Block.getBlockById(0), 0, 2);
	world.setBlock(i+2, j+9, k+5, Block.getBlockById(0), 0, 2);
	world.setBlock(i+3, j+9, k+5, Block.getBlockById(133), 0, 2);
	world.setBlock(i+4, j+9, k+5, Block.getBlockById(65), 5, 2);
	world.setBlock(i+5, j+9, k+5, Block.getBlockById(65), 4, 2);
	world.setBlock(i+6, j+9, k+5, Block.getBlockById(133), 0, 2);
	world.setBlock(i+7, j+9, k+5, Block.getBlockById(0), 0, 2);
	world.setBlock(i+8, j+9, k+5, Block.getBlockById(0), 0, 2);
	world.setBlock(i+9, j+9, k+5, Block.getBlockById(0), 0, 2);
	world.setBlock(i+0, j+9, k+6, Block.getBlockById(0), 0, 2);
	world.setBlock(i+1, j+9, k+6, Block.getBlockById(0), 0, 2);
	world.setBlock(i+2, j+9, k+6, Block.getBlockById(0), 0, 2);
	world.setBlock(i+3, j+9, k+6, Block.getBlockById(133), 0, 2);
	world.setBlock(i+4, j+9, k+6, Block.getBlockById(133), 0, 2);
	world.setBlock(i+5, j+9, k+6, Block.getBlockById(133), 0, 2);
	world.setBlock(i+6, j+9, k+6, Block.getBlockById(133), 0, 2);
	world.setBlock(i+7, j+9, k+6, Block.getBlockById(0), 0, 2);
	world.setBlock(i+8, j+9, k+6, Block.getBlockById(0), 0, 2);
	world.setBlock(i+9, j+9, k+6, Block.getBlockById(0), 0, 2);
	world.setBlock(i+0, j+9, k+7, Block.getBlockById(0), 0, 2);
	world.setBlock(i+1, j+9, k+7, Block.getBlockById(0), 0, 2);
	world.setBlock(i+2, j+9, k+7, Block.getBlockById(0), 0, 2);
	world.setBlock(i+3, j+9, k+7, Block.getBlockById(0), 0, 2);
	world.setBlock(i+4, j+9, k+7, Block.getBlockById(0), 0, 2);
	world.setBlock(i+5, j+9, k+7, Block.getBlockById(0), 0, 2);
	world.setBlock(i+6, j+9, k+7, Block.getBlockById(0), 0, 2);
	world.setBlock(i+7, j+9, k+7, Block.getBlockById(0), 0, 2);
	world.setBlock(i+8, j+9, k+7, Block.getBlockById(0), 0, 2);
	world.setBlock(i+9, j+9, k+7, Block.getBlockById(0), 0, 2);
	world.setBlock(i+0, j+9, k+8, Block.getBlockById(0), 0, 2);
	world.setBlock(i+1, j+9, k+8, Block.getBlockById(0), 0, 2);
	world.setBlock(i+2, j+9, k+8, Block.getBlockById(0), 0, 2);
	world.setBlock(i+3, j+9, k+8, Block.getBlockById(0), 0, 2);
	world.setBlock(i+4, j+9, k+8, Block.getBlockById(0), 0, 2);
	world.setBlock(i+5, j+9, k+8, Block.getBlockById(0), 0, 2);
	world.setBlock(i+6, j+9, k+8, Block.getBlockById(0), 0, 2);
	world.setBlock(i+7, j+9, k+8, Block.getBlockById(0), 0, 2);
	world.setBlock(i+8, j+9, k+8, Block.getBlockById(0), 0, 2);
	world.setBlock(i+9, j+9, k+8, Block.getBlockById(0), 0, 2);
	world.setBlock(i+0, j+9, k+9, Block.getBlockById(0), 0, 2);
	world.setBlock(i+1, j+9, k+9, Block.getBlockById(0), 0, 2);
	world.setBlock(i+2, j+9, k+9, Block.getBlockById(0), 0, 2);
	world.setBlock(i+3, j+9, k+9, Block.getBlockById(0), 0, 2);
	world.setBlock(i+4, j+9, k+9, Block.getBlockById(0), 0, 2);
	world.setBlock(i+5, j+9, k+9, Block.getBlockById(0), 0, 2);
	world.setBlock(i+6, j+9, k+9, Block.getBlockById(0), 0, 2);
	world.setBlock(i+7, j+9, k+9, Block.getBlockById(0), 0, 2);
	world.setBlock(i+8, j+9, k+9, Block.getBlockById(0), 0, 2);
	world.setBlock(i+9, j+9, k+9, Block.getBlockById(0), 0, 2);
	world.setBlock(i+0, j+10, k+0, Block.getBlockById(0), 0, 2);
	world.setBlock(i+1, j+10, k+0, Block.getBlockById(0), 0, 2);
	world.setBlock(i+2, j+10, k+0, Block.getBlockById(0), 0, 2);
	world.setBlock(i+3, j+10, k+0, Block.getBlockById(0), 0, 2);
	world.setBlock(i+4, j+10, k+0, Block.getBlockById(0), 0, 2);
	world.setBlock(i+5, j+10, k+0, Block.getBlockById(0), 0, 2);
	world.setBlock(i+6, j+10, k+0, Block.getBlockById(0), 0, 2);
	world.setBlock(i+7, j+10, k+0, Block.getBlockById(0), 0, 2);
	world.setBlock(i+8, j+10, k+0, Block.getBlockById(0), 0, 2);
	world.setBlock(i+9, j+10, k+0, Block.getBlockById(0), 0, 2);
	world.setBlock(i+0, j+10, k+1, Block.getBlockById(0), 0, 2);
	world.setBlock(i+1, j+10, k+1, Block.getBlockById(133), 0, 2);
	world.setBlock(i+2, j+10, k+1, Block.getBlockById(133), 0, 2);
	world.setBlock(i+3, j+10, k+1, Block.getBlockById(133), 0, 2);
	world.setBlock(i+4, j+10, k+1, Block.getBlockById(133), 0, 2);
	world.setBlock(i+5, j+10, k+1, Block.getBlockById(133), 0, 2);
	world.setBlock(i+6, j+10, k+1, Block.getBlockById(133), 0, 2);
	world.setBlock(i+7, j+10, k+1, Block.getBlockById(133), 0, 2);
	world.setBlock(i+8, j+10, k+1, Block.getBlockById(133), 0, 2);
	world.setBlock(i+9, j+10, k+1, Block.getBlockById(0), 0, 2);
	world.setBlock(i+0, j+10, k+2, Block.getBlockById(0), 0, 2);
	world.setBlock(i+1, j+10, k+2, Block.getBlockById(133), 0, 2);
	world.setBlock(i+2, j+10, k+2, Block.getBlockById(133), 0, 2);
	world.setBlock(i+3, j+10, k+2, Block.getBlockById(133), 0, 2);
	world.setBlock(i+4, j+10, k+2, Block.getBlockById(133), 0, 2);
	world.setBlock(i+5, j+10, k+2, Block.getBlockById(133), 0, 2);
	world.setBlock(i+6, j+10, k+2, Block.getBlockById(133), 0, 2);
	world.setBlock(i+7, j+10, k+2, Block.getBlockById(133), 0, 2);
	world.setBlock(i+8, j+10, k+2, Block.getBlockById(133), 0, 2);
	world.setBlock(i+9, j+10, k+2, Block.getBlockById(0), 0, 2);
	world.setBlock(i+0, j+10, k+3, Block.getBlockById(0), 0, 2);
	world.setBlock(i+1, j+10, k+3, Block.getBlockById(133), 0, 2);
	world.setBlock(i+2, j+10, k+3, Block.getBlockById(133), 0, 2);
	world.setBlock(i+3, j+10, k+3, Block.getBlockById(133), 0, 2);
	world.setBlock(i+4, j+10, k+3, Block.getBlockById(133), 0, 2);
	world.setBlock(i+5, j+10, k+3, Block.getBlockById(133), 0, 2);
	world.setBlock(i+6, j+10, k+3, Block.getBlockById(133), 0, 2);
	world.setBlock(i+7, j+10, k+3, Block.getBlockById(133), 0, 2);
	world.setBlock(i+8, j+10, k+3, Block.getBlockById(133), 0, 2);
	world.setBlock(i+9, j+10, k+3, Block.getBlockById(0), 0, 2);
	world.setBlock(i+0, j+10, k+4, Block.getBlockById(0), 0, 2);
	world.setBlock(i+1, j+10, k+4, Block.getBlockById(133), 0, 2);
	world.setBlock(i+2, j+10, k+4, Block.getBlockById(133), 0, 2);
	world.setBlock(i+3, j+10, k+4, Block.getBlockById(133), 0, 2);
	world.setBlock(i+4, j+10, k+4, Block.getBlockById(65), 5, 2);
	world.setBlock(i+5, j+10, k+4, Block.getBlockById(65), 4, 2);
	world.setBlock(i+6, j+10, k+4, Block.getBlockById(133), 0, 2);
	world.setBlock(i+7, j+10, k+4, Block.getBlockById(133), 0, 2);
	world.setBlock(i+8, j+10, k+4, Block.getBlockById(133), 0, 2);
	world.setBlock(i+9, j+10, k+4, Block.getBlockById(0), 0, 2);
	world.setBlock(i+0, j+10, k+5, Block.getBlockById(0), 0, 2);
	world.setBlock(i+1, j+10, k+5, Block.getBlockById(133), 0, 2);
	world.setBlock(i+2, j+10, k+5, Block.getBlockById(133), 0, 2);
	world.setBlock(i+3, j+10, k+5, Block.getBlockById(133), 0, 2);
	world.setBlock(i+4, j+10, k+5, Block.getBlockById(65), 5, 2);
	world.setBlock(i+5, j+10, k+5, Block.getBlockById(65), 4, 2);
	world.setBlock(i+6, j+10, k+5, Block.getBlockById(133), 0, 2);
	world.setBlock(i+7, j+10, k+5, Block.getBlockById(133), 0, 2);
	world.setBlock(i+8, j+10, k+5, Block.getBlockById(133), 0, 2);
	world.setBlock(i+9, j+10, k+5, Block.getBlockById(0), 0, 2);
	world.setBlock(i+0, j+10, k+6, Block.getBlockById(0), 0, 2);
	world.setBlock(i+1, j+10, k+6, Block.getBlockById(133), 0, 2);
	world.setBlock(i+2, j+10, k+6, Block.getBlockById(133), 0, 2);
	world.setBlock(i+3, j+10, k+6, Block.getBlockById(133), 0, 2);
	world.setBlock(i+4, j+10, k+6, Block.getBlockById(133), 0, 2);
	world.setBlock(i+5, j+10, k+6, Block.getBlockById(133), 0, 2);
	world.setBlock(i+6, j+10, k+6, Block.getBlockById(133), 0, 2);
	world.setBlock(i+7, j+10, k+6, Block.getBlockById(133), 0, 2);
	world.setBlock(i+8, j+10, k+6, Block.getBlockById(133), 0, 2);
	world.setBlock(i+9, j+10, k+6, Block.getBlockById(0), 0, 2);
	world.setBlock(i+0, j+10, k+7, Block.getBlockById(0), 0, 2);
	world.setBlock(i+1, j+10, k+7, Block.getBlockById(133), 0, 2);
	world.setBlock(i+2, j+10, k+7, Block.getBlockById(133), 0, 2);
	world.setBlock(i+3, j+10, k+7, Block.getBlockById(133), 0, 2);
	world.setBlock(i+4, j+10, k+7, Block.getBlockById(133), 0, 2);
	world.setBlock(i+5, j+10, k+7, Block.getBlockById(133), 0, 2);
	world.setBlock(i+6, j+10, k+7, Block.getBlockById(133), 0, 2);
	world.setBlock(i+7, j+10, k+7, Block.getBlockById(133), 0, 2);
	world.setBlock(i+8, j+10, k+7, Block.getBlockById(133), 0, 2);
	world.setBlock(i+9, j+10, k+7, Block.getBlockById(0), 0, 2);
	world.setBlock(i+0, j+10, k+8, Block.getBlockById(0), 0, 2);
	world.setBlock(i+1, j+10, k+8, Block.getBlockById(133), 0, 2);
	world.setBlock(i+2, j+10, k+8, Block.getBlockById(133), 0, 2);
	world.setBlock(i+3, j+10, k+8, Block.getBlockById(133), 0, 2);
	world.setBlock(i+4, j+10, k+8, Block.getBlockById(133), 0, 2);
	world.setBlock(i+5, j+10, k+8, Block.getBlockById(133), 0, 2);
	world.setBlock(i+6, j+10, k+8, Block.getBlockById(133), 0, 2);
	world.setBlock(i+7, j+10, k+8, Block.getBlockById(133), 0, 2);
	world.setBlock(i+8, j+10, k+8, Block.getBlockById(133), 0, 2);
	world.setBlock(i+9, j+10, k+8, Block.getBlockById(0), 0, 2);
	world.setBlock(i+0, j+10, k+9, Block.getBlockById(0), 0, 2);
	world.setBlock(i+1, j+10, k+9, Block.getBlockById(0), 0, 2);
	world.setBlock(i+2, j+10, k+9, Block.getBlockById(0), 0, 2);
	world.setBlock(i+3, j+10, k+9, Block.getBlockById(0), 0, 2);
	world.setBlock(i+4, j+10, k+9, Block.getBlockById(0), 0, 2);
	world.setBlock(i+5, j+10, k+9, Block.getBlockById(0), 0, 2);
	world.setBlock(i+6, j+10, k+9, Block.getBlockById(0), 0, 2);
	world.setBlock(i+7, j+10, k+9, Block.getBlockById(0), 0, 2);
	world.setBlock(i+8, j+10, k+9, Block.getBlockById(0), 0, 2);
	world.setBlock(i+9, j+10, k+9, Block.getBlockById(0), 0, 2);
	world.setBlock(i+0, j+11, k+0, Block.getBlockById(0), 0, 2);
	world.setBlock(i+1, j+11, k+0, Block.getBlockById(0), 0, 2);
	world.setBlock(i+2, j+11, k+0, Block.getBlockById(0), 0, 2);
	world.setBlock(i+3, j+11, k+0, Block.getBlockById(0), 0, 2);
	world.setBlock(i+4, j+11, k+0, Block.getBlockById(0), 0, 2);
	world.setBlock(i+5, j+11, k+0, Block.getBlockById(0), 0, 2);
	world.setBlock(i+6, j+11, k+0, Block.getBlockById(0), 0, 2);
	world.setBlock(i+7, j+11, k+0, Block.getBlockById(0), 0, 2);
	world.setBlock(i+8, j+11, k+0, Block.getBlockById(0), 0, 2);
	world.setBlock(i+9, j+11, k+0, Block.getBlockById(0), 0, 2);
	world.setBlock(i+0, j+11, k+1, Block.getBlockById(0), 0, 2);
	world.setBlock(i+1, j+11, k+1, Block.getBlockById(133), 0, 2);
	world.setBlock(i+2, j+11, k+1, Block.getBlockById(133), 0, 2);
	world.setBlock(i+3, j+11, k+1, Block.getBlockById(133), 0, 2);
	world.setBlock(i+4, j+11, k+1, Block.getBlockById(133), 0, 2);
	world.setBlock(i+5, j+11, k+1, Block.getBlockById(133), 0, 2);
	world.setBlock(i+6, j+11, k+1, Block.getBlockById(133), 0, 2);
	world.setBlock(i+7, j+11, k+1, Block.getBlockById(133), 0, 2);
	world.setBlock(i+8, j+11, k+1, Block.getBlockById(133), 0, 2);
	world.setBlock(i+9, j+11, k+1, Block.getBlockById(0), 0, 2);
	world.setBlock(i+0, j+11, k+2, Block.getBlockById(0), 0, 2);
	world.setBlock(i+1, j+11, k+2, Block.getBlockById(133), 0, 2);
	world.setBlock(i+2, j+11, k+2, Block.getBlockById(133), 0, 2);
	world.setBlock(i+3, j+11, k+2, Block.getBlockById(133), 0, 2);
	world.setBlock(i+4, j+11, k+2, Block.getBlockById(133), 0, 2);
	world.setBlock(i+5, j+11, k+2, Block.getBlockById(133), 0, 2);
	world.setBlock(i+6, j+11, k+2, Block.getBlockById(133), 0, 2);
	world.setBlock(i+7, j+11, k+2, Block.getBlockById(133), 0, 2);
	world.setBlock(i+8, j+11, k+2, Block.getBlockById(133), 0, 2);
	world.setBlock(i+9, j+11, k+2, Block.getBlockById(0), 0, 2);
	world.setBlock(i+0, j+11, k+3, Block.getBlockById(0), 0, 2);
	world.setBlock(i+1, j+11, k+3, Block.getBlockById(173), 0, 2);
	world.setBlock(i+2, j+11, k+3, Block.getBlockById(133), 0, 2);
	world.setBlock(i+3, j+11, k+3, Block.getBlockById(133), 0, 2);
	world.setBlock(i+4, j+11, k+3, Block.getBlockById(133), 0, 2);
	world.setBlock(i+5, j+11, k+3, Block.getBlockById(133), 0, 2);
	world.setBlock(i+6, j+11, k+3, Block.getBlockById(133), 0, 2);
	world.setBlock(i+7, j+11, k+3, Block.getBlockById(133), 0, 2);
	world.setBlock(i+8, j+11, k+3, Block.getBlockById(133), 0, 2);
	world.setBlock(i+9, j+11, k+3, Block.getBlockById(0), 0, 2);
	world.setBlock(i+0, j+11, k+4, Block.getBlockById(0), 0, 2);
	world.setBlock(i+1, j+11, k+4, Block.getBlockById(133), 0, 2);
	world.setBlock(i+2, j+11, k+4, Block.getBlockById(133), 0, 2);
	world.setBlock(i+3, j+11, k+4, Block.getBlockById(133), 0, 2);
	world.setBlock(i+4, j+11, k+4, Block.getBlockById(65), 5, 2);
	world.setBlock(i+5, j+11, k+4, Block.getBlockById(65), 4, 2);
	world.setBlock(i+6, j+11, k+4, Block.getBlockById(133), 0, 2);
	world.setBlock(i+7, j+11, k+4, Block.getBlockById(133), 0, 2);
	world.setBlock(i+8, j+11, k+4, Block.getBlockById(133), 0, 2);
	world.setBlock(i+9, j+11, k+4, Block.getBlockById(0), 0, 2);
	world.setBlock(i+0, j+11, k+5, Block.getBlockById(0), 0, 2);
	world.setBlock(i+1, j+11, k+5, Block.getBlockById(133), 0, 2);
	world.setBlock(i+2, j+11, k+5, Block.getBlockById(133), 0, 2);
	world.setBlock(i+3, j+11, k+5, Block.getBlockById(133), 0, 2);
	world.setBlock(i+4, j+11, k+5, Block.getBlockById(65), 5, 2);
	world.setBlock(i+5, j+11, k+5, Block.getBlockById(65), 4, 2);
	world.setBlock(i+6, j+11, k+5, Block.getBlockById(133), 0, 2);
	world.setBlock(i+7, j+11, k+5, Block.getBlockById(133), 0, 2);
	world.setBlock(i+8, j+11, k+5, Block.getBlockById(133), 0, 2);
	world.setBlock(i+9, j+11, k+5, Block.getBlockById(0), 0, 2);
	world.setBlock(i+0, j+11, k+6, Block.getBlockById(0), 0, 2);
	world.setBlock(i+1, j+11, k+6, Block.getBlockById(173), 0, 2);
	world.setBlock(i+2, j+11, k+6, Block.getBlockById(133), 0, 2);
	world.setBlock(i+3, j+11, k+6, Block.getBlockById(133), 0, 2);
	world.setBlock(i+4, j+11, k+6, Block.getBlockById(133), 0, 2);
	world.setBlock(i+5, j+11, k+6, Block.getBlockById(133), 0, 2);
	world.setBlock(i+6, j+11, k+6, Block.getBlockById(133), 0, 2);
	world.setBlock(i+7, j+11, k+6, Block.getBlockById(133), 0, 2);
	world.setBlock(i+8, j+11, k+6, Block.getBlockById(133), 0, 2);
	world.setBlock(i+9, j+11, k+6, Block.getBlockById(0), 0, 2);
	world.setBlock(i+0, j+11, k+7, Block.getBlockById(0), 0, 2);
	world.setBlock(i+1, j+11, k+7, Block.getBlockById(133), 0, 2);
	world.setBlock(i+2, j+11, k+7, Block.getBlockById(133), 0, 2);
	world.setBlock(i+3, j+11, k+7, Block.getBlockById(133), 0, 2);
	world.setBlock(i+4, j+11, k+7, Block.getBlockById(133), 0, 2);
	world.setBlock(i+5, j+11, k+7, Block.getBlockById(133), 0, 2);
	world.setBlock(i+6, j+11, k+7, Block.getBlockById(133), 0, 2);
	world.setBlock(i+7, j+11, k+7, Block.getBlockById(133), 0, 2);
	world.setBlock(i+8, j+11, k+7, Block.getBlockById(133), 0, 2);
	world.setBlock(i+9, j+11, k+7, Block.getBlockById(0), 0, 2);
	world.setBlock(i+0, j+11, k+8, Block.getBlockById(0), 0, 2);
	world.setBlock(i+1, j+11, k+8, Block.getBlockById(133), 0, 2);
	world.setBlock(i+2, j+11, k+8, Block.getBlockById(133), 0, 2);
	world.setBlock(i+3, j+11, k+8, Block.getBlockById(133), 0, 2);
	world.setBlock(i+4, j+11, k+8, Block.getBlockById(133), 0, 2);
	world.setBlock(i+5, j+11, k+8, Block.getBlockById(133), 0, 2);
	world.setBlock(i+6, j+11, k+8, Block.getBlockById(133), 0, 2);
	world.setBlock(i+7, j+11, k+8, Block.getBlockById(133), 0, 2);
	world.setBlock(i+8, j+11, k+8, Block.getBlockById(133), 0, 2);
	world.setBlock(i+9, j+11, k+8, Block.getBlockById(0), 0, 2);
	world.setBlock(i+0, j+11, k+9, Block.getBlockById(0), 0, 2);
	world.setBlock(i+1, j+11, k+9, Block.getBlockById(0), 0, 2);
	world.setBlock(i+2, j+11, k+9, Block.getBlockById(0), 0, 2);
	world.setBlock(i+3, j+11, k+9, Block.getBlockById(0), 0, 2);
	world.setBlock(i+4, j+11, k+9, Block.getBlockById(0), 0, 2);
	world.setBlock(i+5, j+11, k+9, Block.getBlockById(0), 0, 2);
	world.setBlock(i+6, j+11, k+9, Block.getBlockById(0), 0, 2);
	world.setBlock(i+7, j+11, k+9, Block.getBlockById(0), 0, 2);
	world.setBlock(i+8, j+11, k+9, Block.getBlockById(0), 0, 2);
	world.setBlock(i+9, j+11, k+9, Block.getBlockById(0), 0, 2);
	world.setBlock(i+0, j+12, k+0, Block.getBlockById(0), 0, 2);
	world.setBlock(i+1, j+12, k+0, Block.getBlockById(0), 0, 2);
	world.setBlock(i+2, j+12, k+0, Block.getBlockById(0), 0, 2);
	world.setBlock(i+3, j+12, k+0, Block.getBlockById(0), 0, 2);
	world.setBlock(i+4, j+12, k+0, Block.getBlockById(0), 0, 2);
	world.setBlock(i+5, j+12, k+0, Block.getBlockById(0), 0, 2);
	world.setBlock(i+6, j+12, k+0, Block.getBlockById(0), 0, 2);
	world.setBlock(i+7, j+12, k+0, Block.getBlockById(0), 0, 2);
	world.setBlock(i+8, j+12, k+0, Block.getBlockById(0), 0, 2);
	world.setBlock(i+9, j+12, k+0, Block.getBlockById(0), 0, 2);
	world.setBlock(i+0, j+12, k+1, Block.getBlockById(0), 0, 2);
	world.setBlock(i+1, j+12, k+1, Block.getBlockById(133), 0, 2);
	world.setBlock(i+2, j+12, k+1, Block.getBlockById(133), 0, 2);
	world.setBlock(i+3, j+12, k+1, Block.getBlockById(133), 0, 2);
	world.setBlock(i+4, j+12, k+1, Block.getBlockById(133), 0, 2);
	world.setBlock(i+5, j+12, k+1, Block.getBlockById(133), 0, 2);
	world.setBlock(i+6, j+12, k+1, Block.getBlockById(133), 0, 2);
	world.setBlock(i+7, j+12, k+1, Block.getBlockById(133), 0, 2);
	world.setBlock(i+8, j+12, k+1, Block.getBlockById(133), 0, 2);
	world.setBlock(i+9, j+12, k+1, Block.getBlockById(0), 0, 2);
	world.setBlock(i+0, j+12, k+2, Block.getBlockById(0), 0, 2);
	world.setBlock(i+1, j+12, k+2, Block.getBlockById(133), 0, 2);
	world.setBlock(i+2, j+12, k+2, Block.getBlockById(52), 1, 50);
	world.setBlock(i+3, j+12, k+2, Block.getBlockById(89), 0, 2);
	world.setBlock(i+4, j+12, k+2, Block.getBlockById(54), 3, 2);
	world.setBlock(i+5, j+12, k+2, Block.getBlockById(54), 3, 2);
	world.setBlock(i+6, j+12, k+2, Block.getBlockById(89), 0, 2);
	world.setBlock(i+7, j+12, k+2, Block.getBlockById(52), 1, 50);
	world.setBlock(i+8, j+12, k+2, Block.getBlockById(133), 0, 2);
	world.setBlock(i+9, j+12, k+2, Block.getBlockById(0), 0, 2);
	world.setBlock(i+0, j+12, k+3, Block.getBlockById(0), 0, 2);
	world.setBlock(i+1, j+12, k+3, Block.getBlockById(173), 0, 2);
	world.setBlock(i+2, j+12, k+3, Block.getBlockById(89), 0, 2);
	world.setBlock(i+3, j+12, k+3, Block.getBlockById(52), 1, 50);
	world.setBlock(i+4, j+12, k+3, Block.getBlockById(0), 0, 2);
	world.setBlock(i+5, j+12, k+3, Block.getBlockById(0), 0, 2);
	world.setBlock(i+6, j+12, k+3, Block.getBlockById(52), 1, 50);
	world.setBlock(i+7, j+12, k+3, Block.getBlockById(89), 0, 2);
	world.setBlock(i+8, j+12, k+3, Block.getBlockById(133), 0, 2);
	world.setBlock(i+9, j+12, k+3, Block.getBlockById(0), 0, 2);
	world.setBlock(i+0, j+12, k+4, Block.getBlockById(0), 0, 2);
	world.setBlock(i+1, j+12, k+4, Block.getBlockById(173), 0, 2);
	world.setBlock(i+2, j+12, k+4, Block.getBlockById(54), 5, 2);
	world.setBlock(i+3, j+12, k+4, Block.getBlockById(0), 0, 2);
	world.setBlock(i+4, j+12, k+4, Block.getBlockById(0), 0, 2);
	world.setBlock(i+5, j+12, k+4, Block.getBlockById(0), 0, 2);
	world.setBlock(i+6, j+12, k+4, Block.getBlockById(0), 0, 2);
	world.setBlock(i+7, j+12, k+4, Block.getBlockById(54), 4, 2);
	world.setBlock(i+8, j+12, k+4, Block.getBlockById(133), 0, 2);
	world.setBlock(i+9, j+12, k+4, Block.getBlockById(0), 0, 2);
	world.setBlock(i+0, j+12, k+5, Block.getBlockById(0), 0, 2);
	world.setBlock(i+1, j+12, k+5, Block.getBlockById(173), 0, 2);
	world.setBlock(i+2, j+12, k+5, Block.getBlockById(54), 5, 2);
	world.setBlock(i+3, j+12, k+5, Block.getBlockById(0), 0, 2);
	world.setBlock(i+4, j+12, k+5, Block.getBlockById(0), 0, 2);
	world.setBlock(i+5, j+12, k+5, Block.getBlockById(0), 0, 2);
	world.setBlock(i+6, j+12, k+5, Block.getBlockById(0), 0, 2);
	world.setBlock(i+7, j+12, k+5, Block.getBlockById(54), 4, 2);
	world.setBlock(i+8, j+12, k+5, Block.getBlockById(133), 0, 2);
	world.setBlock(i+9, j+12, k+5, Block.getBlockById(0), 0, 2);
	world.setBlock(i+0, j+12, k+6, Block.getBlockById(0), 0, 2);
	world.setBlock(i+1, j+12, k+6, Block.getBlockById(173), 0, 2);
	world.setBlock(i+2, j+12, k+6, Block.getBlockById(89), 0, 2);
	world.setBlock(i+3, j+12, k+6, Block.getBlockById(52), 1, 50);
	world.setBlock(i+4, j+12, k+6, Block.getBlockById(0), 0, 2);
	world.setBlock(i+5, j+12, k+6, Block.getBlockById(0), 0, 2);
	world.setBlock(i+6, j+12, k+6, Block.getBlockById(52), 1, 50);
	world.setBlock(i+7, j+12, k+6, Block.getBlockById(89), 0, 2);
	world.setBlock(i+8, j+12, k+6, Block.getBlockById(133), 0, 2);
	world.setBlock(i+9, j+12, k+6, Block.getBlockById(0), 0, 2);
	world.setBlock(i+0, j+12, k+7, Block.getBlockById(0), 0, 2);
	world.setBlock(i+1, j+12, k+7, Block.getBlockById(133), 0, 2);
	world.setBlock(i+2, j+12, k+7, Block.getBlockById(52), 1, 50);
	world.setBlock(i+3, j+12, k+7, Block.getBlockById(89), 0, 2);
	world.setBlock(i+4, j+12, k+7, Block.getBlockById(54), 2, 2);
	world.setBlock(i+5, j+12, k+7, Block.getBlockById(54), 2, 2);
	world.setBlock(i+6, j+12, k+7, Block.getBlockById(89), 0, 2);
	world.setBlock(i+7, j+12, k+7, Block.getBlockById(52), 1, 50);
	world.setBlock(i+8, j+12, k+7, Block.getBlockById(133), 0, 2);
	world.setBlock(i+9, j+12, k+7, Block.getBlockById(0), 0, 2);
	world.setBlock(i+0, j+12, k+8, Block.getBlockById(0), 0, 2);
	world.setBlock(i+1, j+12, k+8, Block.getBlockById(133), 0, 2);
	world.setBlock(i+2, j+12, k+8, Block.getBlockById(133), 0, 2);
	world.setBlock(i+3, j+12, k+8, Block.getBlockById(133), 0, 2);
	world.setBlock(i+4, j+12, k+8, Block.getBlockById(133), 0, 2);
	world.setBlock(i+5, j+12, k+8, Block.getBlockById(133), 0, 2);
	world.setBlock(i+6, j+12, k+8, Block.getBlockById(133), 0, 2);
	world.setBlock(i+7, j+12, k+8, Block.getBlockById(133), 0, 2);
	world.setBlock(i+8, j+12, k+8, Block.getBlockById(133), 0, 2);
	world.setBlock(i+9, j+12, k+8, Block.getBlockById(0), 0, 2);
	world.setBlock(i+0, j+12, k+9, Block.getBlockById(0), 0, 2);
	world.setBlock(i+1, j+12, k+9, Block.getBlockById(0), 0, 2);
	world.setBlock(i+2, j+12, k+9, Block.getBlockById(0), 0, 2);
	world.setBlock(i+3, j+12, k+9, Block.getBlockById(0), 0, 2);
	world.setBlock(i+4, j+12, k+9, Block.getBlockById(0), 0, 2);
	world.setBlock(i+5, j+12, k+9, Block.getBlockById(0), 0, 2);
	world.setBlock(i+6, j+12, k+9, Block.getBlockById(0), 0, 2);
	world.setBlock(i+7, j+12, k+9, Block.getBlockById(0), 0, 2);
	world.setBlock(i+8, j+12, k+9, Block.getBlockById(0), 0, 2);
	world.setBlock(i+9, j+12, k+9, Block.getBlockById(0), 0, 2);
	world.setBlock(i+0, j+13, k+0, Block.getBlockById(0), 0, 2);
	world.setBlock(i+1, j+13, k+0, Block.getBlockById(0), 0, 2);
	world.setBlock(i+2, j+13, k+0, Block.getBlockById(0), 0, 2);
	world.setBlock(i+3, j+13, k+0, Block.getBlockById(0), 0, 2);
	world.setBlock(i+4, j+13, k+0, Block.getBlockById(0), 0, 2);
	world.setBlock(i+5, j+13, k+0, Block.getBlockById(0), 0, 2);
	world.setBlock(i+6, j+13, k+0, Block.getBlockById(0), 0, 2);
	world.setBlock(i+7, j+13, k+0, Block.getBlockById(0), 0, 2);
	world.setBlock(i+8, j+13, k+0, Block.getBlockById(0), 0, 2);
	world.setBlock(i+9, j+13, k+0, Block.getBlockById(0), 0, 2);
	world.setBlock(i+0, j+13, k+1, Block.getBlockById(0), 0, 2);
	world.setBlock(i+1, j+13, k+1, Block.getBlockById(133), 0, 2);
	world.setBlock(i+2, j+13, k+1, Block.getBlockById(133), 0, 2);
	world.setBlock(i+3, j+13, k+1, Block.getBlockById(133), 0, 2);
	world.setBlock(i+4, j+13, k+1, Block.getBlockById(133), 0, 2);
	world.setBlock(i+5, j+13, k+1, Block.getBlockById(133), 0, 2);
	world.setBlock(i+6, j+13, k+1, Block.getBlockById(133), 0, 2);
	world.setBlock(i+7, j+13, k+1, Block.getBlockById(133), 0, 2);
	world.setBlock(i+8, j+13, k+1, Block.getBlockById(133), 0, 2);
	world.setBlock(i+9, j+13, k+1, Block.getBlockById(0), 0, 2);
	world.setBlock(i+0, j+13, k+2, Block.getBlockById(0), 0, 2);
	world.setBlock(i+1, j+13, k+2, Block.getBlockById(133), 0, 2);
	world.setBlock(i+2, j+13, k+2, Block.getBlockById(46), 0, 2);
	world.setBlock(i+3, j+13, k+2, Block.getBlockById(89), 0, 2);
	world.setBlock(i+4, j+13, k+2, Block.getBlockById(0), 0, 2);
	world.setBlock(i+5, j+13, k+2, Block.getBlockById(0), 0, 2);
	world.setBlock(i+6, j+13, k+2, Block.getBlockById(89), 0, 2);
	world.setBlock(i+7, j+13, k+2, Block.getBlockById(46), 0, 2);
	world.setBlock(i+8, j+13, k+2, Block.getBlockById(133), 0, 2);
	world.setBlock(i+9, j+13, k+2, Block.getBlockById(0), 0, 2);
	world.setBlock(i+0, j+13, k+3, Block.getBlockById(0), 0, 2);
	world.setBlock(i+1, j+13, k+3, Block.getBlockById(173), 0, 2);
	world.setBlock(i+2, j+13, k+3, Block.getBlockById(89), 0, 2);
	world.setBlock(i+3, j+13, k+3, Block.getBlockById(0), 0, 2);
	world.setBlock(i+4, j+13, k+3, Block.getBlockById(0), 0, 2);
	world.setBlock(i+5, j+13, k+3, Block.getBlockById(0), 0, 2);
	world.setBlock(i+6, j+13, k+3, Block.getBlockById(0), 0, 2);
	world.setBlock(i+7, j+13, k+3, Block.getBlockById(89), 0, 2);
	world.setBlock(i+8, j+13, k+3, Block.getBlockById(133), 0, 2);
	world.setBlock(i+9, j+13, k+3, Block.getBlockById(0), 0, 2);
	world.setBlock(i+0, j+13, k+4, Block.getBlockById(0), 0, 2);
	world.setBlock(i+1, j+13, k+4, Block.getBlockById(173), 0, 2);
	world.setBlock(i+2, j+13, k+4, Block.getBlockById(0), 0, 2);
	world.setBlock(i+3, j+13, k+4, Block.getBlockById(0), 0, 2);
	world.setBlock(i+4, j+13, k+4, Block.getBlockById(0), 0, 2);
	world.setBlock(i+5, j+13, k+4, Block.getBlockById(0), 0, 2);
	world.setBlock(i+6, j+13, k+4, Block.getBlockById(0), 0, 2);
	world.setBlock(i+7, j+13, k+4, Block.getBlockById(0), 0, 2);
	world.setBlock(i+8, j+13, k+4, Block.getBlockById(133), 0, 2);
	world.setBlock(i+9, j+13, k+4, Block.getBlockById(0), 0, 2);
	world.setBlock(i+0, j+13, k+5, Block.getBlockById(0), 0, 2);
	world.setBlock(i+1, j+13, k+5, Block.getBlockById(173), 0, 2);
	world.setBlock(i+2, j+13, k+5, Block.getBlockById(0), 0, 2);
	world.setBlock(i+3, j+13, k+5, Block.getBlockById(0), 0, 2);
	world.setBlock(i+4, j+13, k+5, Block.getBlockById(0), 0, 2);
	world.setBlock(i+5, j+13, k+5, Block.getBlockById(0), 0, 2);
	world.setBlock(i+6, j+13, k+5, Block.getBlockById(0), 0, 2);
	world.setBlock(i+7, j+13, k+5, Block.getBlockById(0), 0, 2);
	world.setBlock(i+8, j+13, k+5, Block.getBlockById(133), 0, 2);
	world.setBlock(i+9, j+13, k+5, Block.getBlockById(0), 0, 2);
	world.setBlock(i+0, j+13, k+6, Block.getBlockById(0), 0, 2);
	world.setBlock(i+1, j+13, k+6, Block.getBlockById(173), 0, 2);
	world.setBlock(i+2, j+13, k+6, Block.getBlockById(89), 0, 2);
	world.setBlock(i+3, j+13, k+6, Block.getBlockById(0), 0, 2);
	world.setBlock(i+4, j+13, k+6, Block.getBlockById(0), 0, 2);
	world.setBlock(i+5, j+13, k+6, Block.getBlockById(0), 0, 2);
	world.setBlock(i+6, j+13, k+6, Block.getBlockById(0), 0, 2);
	world.setBlock(i+7, j+13, k+6, Block.getBlockById(89), 0, 2);
	world.setBlock(i+8, j+13, k+6, Block.getBlockById(133), 0, 2);
	world.setBlock(i+9, j+13, k+6, Block.getBlockById(0), 0, 2);
	world.setBlock(i+0, j+13, k+7, Block.getBlockById(0), 0, 2);
	world.setBlock(i+1, j+13, k+7, Block.getBlockById(133), 0, 2);
	world.setBlock(i+2, j+13, k+7, Block.getBlockById(46), 0, 2);
	world.setBlock(i+3, j+13, k+7, Block.getBlockById(89), 0, 2);
	world.setBlock(i+4, j+13, k+7, Block.getBlockById(0), 0, 2);
	world.setBlock(i+5, j+13, k+7, Block.getBlockById(0), 0, 2);
	world.setBlock(i+6, j+13, k+7, Block.getBlockById(89), 0, 2);
	world.setBlock(i+7, j+13, k+7, Block.getBlockById(46), 0, 2);
	world.setBlock(i+8, j+13, k+7, Block.getBlockById(133), 0, 2);
	world.setBlock(i+9, j+13, k+7, Block.getBlockById(0), 0, 2);
	world.setBlock(i+0, j+13, k+8, Block.getBlockById(0), 0, 2);
	world.setBlock(i+1, j+13, k+8, Block.getBlockById(133), 0, 2);
	world.setBlock(i+2, j+13, k+8, Block.getBlockById(133), 0, 2);
	world.setBlock(i+3, j+13, k+8, Block.getBlockById(133), 0, 2);
	world.setBlock(i+4, j+13, k+8, Block.getBlockById(133), 0, 2);
	world.setBlock(i+5, j+13, k+8, Block.getBlockById(133), 0, 2);
	world.setBlock(i+6, j+13, k+8, Block.getBlockById(133), 0, 2);
	world.setBlock(i+7, j+13, k+8, Block.getBlockById(133), 0, 2);
	world.setBlock(i+8, j+13, k+8, Block.getBlockById(133), 0, 2);
	world.setBlock(i+9, j+13, k+8, Block.getBlockById(0), 0, 2);
	world.setBlock(i+0, j+13, k+9, Block.getBlockById(0), 0, 2);
	world.setBlock(i+1, j+13, k+9, Block.getBlockById(0), 0, 2);
	world.setBlock(i+2, j+13, k+9, Block.getBlockById(0), 0, 2);
	world.setBlock(i+3, j+13, k+9, Block.getBlockById(0), 0, 2);
	world.setBlock(i+4, j+13, k+9, Block.getBlockById(0), 0, 2);
	world.setBlock(i+5, j+13, k+9, Block.getBlockById(0), 0, 2);
	world.setBlock(i+6, j+13, k+9, Block.getBlockById(0), 0, 2);
	world.setBlock(i+7, j+13, k+9, Block.getBlockById(0), 0, 2);
	world.setBlock(i+8, j+13, k+9, Block.getBlockById(0), 0, 2);
	world.setBlock(i+9, j+13, k+9, Block.getBlockById(0), 0, 2);
	world.setBlock(i+0, j+14, k+0, Block.getBlockById(0), 0, 2);
	world.setBlock(i+1, j+14, k+0, Block.getBlockById(0), 0, 2);
	world.setBlock(i+2, j+14, k+0, Block.getBlockById(0), 0, 2);
	world.setBlock(i+3, j+14, k+0, Block.getBlockById(0), 0, 2);
	world.setBlock(i+4, j+14, k+0, Block.getBlockById(0), 0, 2);
	world.setBlock(i+5, j+14, k+0, Block.getBlockById(0), 0, 2);
	world.setBlock(i+6, j+14, k+0, Block.getBlockById(0), 0, 2);
	world.setBlock(i+7, j+14, k+0, Block.getBlockById(0), 0, 2);
	world.setBlock(i+8, j+14, k+0, Block.getBlockById(0), 0, 2);
	world.setBlock(i+9, j+14, k+0, Block.getBlockById(0), 0, 2);
	world.setBlock(i+0, j+14, k+1, Block.getBlockById(0), 0, 2);
	world.setBlock(i+1, j+14, k+1, Block.getBlockById(133), 0, 2);
	world.setBlock(i+2, j+14, k+1, Block.getBlockById(133), 0, 2);
	world.setBlock(i+3, j+14, k+1, Block.getBlockById(133), 0, 2);
	world.setBlock(i+4, j+14, k+1, Block.getBlockById(133), 0, 2);
	world.setBlock(i+5, j+14, k+1, Block.getBlockById(133), 0, 2);
	world.setBlock(i+6, j+14, k+1, Block.getBlockById(133), 0, 2);
	world.setBlock(i+7, j+14, k+1, Block.getBlockById(133), 0, 2);
	world.setBlock(i+8, j+14, k+1, Block.getBlockById(133), 0, 2);
	world.setBlock(i+9, j+14, k+1, Block.getBlockById(0), 0, 2);
	world.setBlock(i+0, j+14, k+2, Block.getBlockById(0), 0, 2);
	world.setBlock(i+1, j+14, k+2, Block.getBlockById(133), 0, 2);
	world.setBlock(i+2, j+14, k+2, Block.getBlockById(46), 0, 2);
	world.setBlock(i+3, j+14, k+2, Block.getBlockById(89), 0, 2);
	world.setBlock(i+4, j+14, k+2, Block.getBlockById(0), 0, 2);
	world.setBlock(i+5, j+14, k+2, Block.getBlockById(0), 0, 2);
	world.setBlock(i+6, j+14, k+2, Block.getBlockById(89), 0, 2);
	world.setBlock(i+7, j+14, k+2, Block.getBlockById(46), 0, 2);
	world.setBlock(i+8, j+14, k+2, Block.getBlockById(133), 0, 2);
	world.setBlock(i+9, j+14, k+2, Block.getBlockById(0), 0, 2);
	world.setBlock(i+0, j+14, k+3, Block.getBlockById(0), 0, 2);
	world.setBlock(i+1, j+14, k+3, Block.getBlockById(133), 0, 2);
	world.setBlock(i+2, j+14, k+3, Block.getBlockById(89), 0, 2);
	world.setBlock(i+3, j+14, k+3, Block.getBlockById(0), 0, 2);
	world.setBlock(i+4, j+14, k+3, Block.getBlockById(0), 0, 2);
	world.setBlock(i+5, j+14, k+3, Block.getBlockById(0), 0, 2);
	world.setBlock(i+6, j+14, k+3, Block.getBlockById(0), 0, 2);
	world.setBlock(i+7, j+14, k+3, Block.getBlockById(89), 0, 2);
	world.setBlock(i+8, j+14, k+3, Block.getBlockById(133), 0, 2);
	world.setBlock(i+9, j+14, k+3, Block.getBlockById(0), 0, 2);
	world.setBlock(i+0, j+14, k+4, Block.getBlockById(0), 0, 2);
	world.setBlock(i+1, j+14, k+4, Block.getBlockById(173), 0, 2);
	world.setBlock(i+2, j+14, k+4, Block.getBlockById(0), 0, 2);
	world.setBlock(i+3, j+14, k+4, Block.getBlockById(0), 0, 2);
	world.setBlock(i+4, j+14, k+4, Block.getBlockById(0), 0, 2);
	world.setBlock(i+5, j+14, k+4, Block.getBlockById(0), 0, 2);
	world.setBlock(i+6, j+14, k+4, Block.getBlockById(0), 0, 2);
	world.setBlock(i+7, j+14, k+4, Block.getBlockById(0), 0, 2);
	world.setBlock(i+8, j+14, k+4, Block.getBlockById(133), 0, 2);
	world.setBlock(i+9, j+14, k+4, Block.getBlockById(0), 0, 2);
	world.setBlock(i+0, j+14, k+5, Block.getBlockById(0), 0, 2);
	world.setBlock(i+1, j+14, k+5, Block.getBlockById(173), 0, 2);
	world.setBlock(i+2, j+14, k+5, Block.getBlockById(0), 0, 2);
	world.setBlock(i+3, j+14, k+5, Block.getBlockById(0), 0, 2);
	world.setBlock(i+4, j+14, k+5, Block.getBlockById(0), 0, 2);
	world.setBlock(i+5, j+14, k+5, Block.getBlockById(0), 0, 2);
	world.setBlock(i+6, j+14, k+5, Block.getBlockById(0), 0, 2);
	world.setBlock(i+7, j+14, k+5, Block.getBlockById(0), 0, 2);
	world.setBlock(i+8, j+14, k+5, Block.getBlockById(133), 0, 2);
	world.setBlock(i+9, j+14, k+5, Block.getBlockById(0), 0, 2);
	world.setBlock(i+0, j+14, k+6, Block.getBlockById(0), 0, 2);
	world.setBlock(i+1, j+14, k+6, Block.getBlockById(133), 0, 2);
	world.setBlock(i+2, j+14, k+6, Block.getBlockById(89), 0, 2);
	world.setBlock(i+3, j+14, k+6, Block.getBlockById(0), 0, 2);
	world.setBlock(i+4, j+14, k+6, Block.getBlockById(0), 0, 2);
	world.setBlock(i+5, j+14, k+6, Block.getBlockById(0), 0, 2);
	world.setBlock(i+6, j+14, k+6, Block.getBlockById(0), 0, 2);
	world.setBlock(i+7, j+14, k+6, Block.getBlockById(89), 0, 2);
	world.setBlock(i+8, j+14, k+6, Block.getBlockById(133), 0, 2);
	world.setBlock(i+9, j+14, k+6, Block.getBlockById(0), 0, 2);
	world.setBlock(i+0, j+14, k+7, Block.getBlockById(0), 0, 2);
	world.setBlock(i+1, j+14, k+7, Block.getBlockById(133), 0, 2);
	world.setBlock(i+2, j+14, k+7, Block.getBlockById(46), 0, 2);
	world.setBlock(i+3, j+14, k+7, Block.getBlockById(89), 0, 2);
	world.setBlock(i+4, j+14, k+7, Block.getBlockById(0), 0, 2);
	world.setBlock(i+5, j+14, k+7, Block.getBlockById(0), 0, 2);
	world.setBlock(i+6, j+14, k+7, Block.getBlockById(89), 0, 2);
	world.setBlock(i+7, j+14, k+7, Block.getBlockById(46), 0, 2);
	world.setBlock(i+8, j+14, k+7, Block.getBlockById(133), 0, 2);
	world.setBlock(i+9, j+14, k+7, Block.getBlockById(0), 0, 2);
	world.setBlock(i+0, j+14, k+8, Block.getBlockById(0), 0, 2);
	world.setBlock(i+1, j+14, k+8, Block.getBlockById(133), 0, 2);
	world.setBlock(i+2, j+14, k+8, Block.getBlockById(133), 0, 2);
	world.setBlock(i+3, j+14, k+8, Block.getBlockById(133), 0, 2);
	world.setBlock(i+4, j+14, k+8, Block.getBlockById(133), 0, 2);
	world.setBlock(i+5, j+14, k+8, Block.getBlockById(133), 0, 2);
	world.setBlock(i+6, j+14, k+8, Block.getBlockById(133), 0, 2);
	world.setBlock(i+7, j+14, k+8, Block.getBlockById(133), 0, 2);
	world.setBlock(i+8, j+14, k+8, Block.getBlockById(133), 0, 2);
	world.setBlock(i+9, j+14, k+8, Block.getBlockById(0), 0, 2);
	world.setBlock(i+0, j+14, k+9, Block.getBlockById(0), 0, 2);
	world.setBlock(i+1, j+14, k+9, Block.getBlockById(0), 0, 2);
	world.setBlock(i+2, j+14, k+9, Block.getBlockById(0), 0, 2);
	world.setBlock(i+3, j+14, k+9, Block.getBlockById(0), 0, 2);
	world.setBlock(i+4, j+14, k+9, Block.getBlockById(0), 0, 2);
	world.setBlock(i+5, j+14, k+9, Block.getBlockById(0), 0, 2);
	world.setBlock(i+6, j+14, k+9, Block.getBlockById(0), 0, 2);
	world.setBlock(i+7, j+14, k+9, Block.getBlockById(0), 0, 2);
	world.setBlock(i+8, j+14, k+9, Block.getBlockById(0), 0, 2);
	world.setBlock(i+9, j+14, k+9, Block.getBlockById(0), 0, 2);
	world.setBlock(i+0, j+15, k+0, Block.getBlockById(0), 0, 2);
	world.setBlock(i+1, j+15, k+0, Block.getBlockById(0), 0, 2);
	world.setBlock(i+2, j+15, k+0, Block.getBlockById(0), 0, 2);
	world.setBlock(i+3, j+15, k+0, Block.getBlockById(0), 0, 2);
	world.setBlock(i+4, j+15, k+0, Block.getBlockById(0), 0, 2);
	world.setBlock(i+5, j+15, k+0, Block.getBlockById(0), 0, 2);
	world.setBlock(i+6, j+15, k+0, Block.getBlockById(0), 0, 2);
	world.setBlock(i+7, j+15, k+0, Block.getBlockById(0), 0, 2);
	world.setBlock(i+8, j+15, k+0, Block.getBlockById(0), 0, 2);
	world.setBlock(i+9, j+15, k+0, Block.getBlockById(0), 0, 2);
	world.setBlock(i+0, j+15, k+1, Block.getBlockById(0), 0, 2);
	world.setBlock(i+1, j+15, k+1, Block.getBlockById(133), 0, 2);
	world.setBlock(i+2, j+15, k+1, Block.getBlockById(133), 0, 2);
	world.setBlock(i+3, j+15, k+1, Block.getBlockById(133), 0, 2);
	world.setBlock(i+4, j+15, k+1, Block.getBlockById(133), 0, 2);
	world.setBlock(i+5, j+15, k+1, Block.getBlockById(133), 0, 2);
	world.setBlock(i+6, j+15, k+1, Block.getBlockById(133), 0, 2);
	world.setBlock(i+7, j+15, k+1, Block.getBlockById(133), 0, 2);
	world.setBlock(i+8, j+15, k+1, Block.getBlockById(133), 0, 2);
	world.setBlock(i+9, j+15, k+1, Block.getBlockById(0), 0, 2);
	world.setBlock(i+0, j+15, k+2, Block.getBlockById(0), 0, 2);
	world.setBlock(i+1, j+15, k+2, Block.getBlockById(173), 0, 2);
	world.setBlock(i+2, j+15, k+2, Block.getBlockById(46), 0, 2);
	world.setBlock(i+3, j+15, k+2, Block.getBlockById(89), 0, 2);
	world.setBlock(i+4, j+15, k+2, Block.getBlockById(0), 0, 2);
	world.setBlock(i+5, j+15, k+2, Block.getBlockById(0), 0, 2);
	world.setBlock(i+6, j+15, k+2, Block.getBlockById(89), 0, 2);
	world.setBlock(i+7, j+15, k+2, Block.getBlockById(46), 0, 2);
	world.setBlock(i+8, j+15, k+2, Block.getBlockById(133), 0, 2);
	world.setBlock(i+9, j+15, k+2, Block.getBlockById(0), 0, 2);
	world.setBlock(i+0, j+15, k+3, Block.getBlockById(0), 0, 2);
	world.setBlock(i+1, j+15, k+3, Block.getBlockById(173), 0, 2);
	world.setBlock(i+2, j+15, k+3, Block.getBlockById(89), 0, 2);
	world.setBlock(i+3, j+15, k+3, Block.getBlockById(0), 0, 2);
	world.setBlock(i+4, j+15, k+3, Block.getBlockById(0), 0, 2);
	world.setBlock(i+5, j+15, k+3, Block.getBlockById(0), 0, 2);
	world.setBlock(i+6, j+15, k+3, Block.getBlockById(0), 0, 2);
	world.setBlock(i+7, j+15, k+3, Block.getBlockById(89), 0, 2);
	world.setBlock(i+8, j+15, k+3, Block.getBlockById(133), 0, 2);
	world.setBlock(i+9, j+15, k+3, Block.getBlockById(0), 0, 2);
	world.setBlock(i+0, j+15, k+4, Block.getBlockById(0), 0, 2);
	world.setBlock(i+1, j+15, k+4, Block.getBlockById(133), 0, 2);
	world.setBlock(i+2, j+15, k+4, Block.getBlockById(0), 0, 2);
	world.setBlock(i+3, j+15, k+4, Block.getBlockById(0), 0, 2);
	world.setBlock(i+4, j+15, k+4, Block.getBlockById(0), 0, 2);
	world.setBlock(i+5, j+15, k+4, Block.getBlockById(0), 0, 2);
	world.setBlock(i+6, j+15, k+4, Block.getBlockById(0), 0, 2);
	world.setBlock(i+7, j+15, k+4, Block.getBlockById(0), 0, 2);
	world.setBlock(i+8, j+15, k+4, Block.getBlockById(133), 0, 2);
	world.setBlock(i+9, j+15, k+4, Block.getBlockById(0), 0, 2);
	world.setBlock(i+0, j+15, k+5, Block.getBlockById(0), 0, 2);
	world.setBlock(i+1, j+15, k+5, Block.getBlockById(133), 0, 2);
	world.setBlock(i+2, j+15, k+5, Block.getBlockById(0), 0, 2);
	world.setBlock(i+3, j+15, k+5, Block.getBlockById(0), 0, 2);
	world.setBlock(i+4, j+15, k+5, Block.getBlockById(0), 0, 2);
	world.setBlock(i+5, j+15, k+5, Block.getBlockById(0), 0, 2);
	world.setBlock(i+6, j+15, k+5, Block.getBlockById(0), 0, 2);
	world.setBlock(i+7, j+15, k+5, Block.getBlockById(0), 0, 2);
	world.setBlock(i+8, j+15, k+5, Block.getBlockById(133), 0, 2);
	world.setBlock(i+9, j+15, k+5, Block.getBlockById(0), 0, 2);
	world.setBlock(i+0, j+15, k+6, Block.getBlockById(0), 0, 2);
	world.setBlock(i+1, j+15, k+6, Block.getBlockById(173), 0, 2);
	world.setBlock(i+2, j+15, k+6, Block.getBlockById(89), 0, 2);
	world.setBlock(i+3, j+15, k+6, Block.getBlockById(0), 0, 2);
	world.setBlock(i+4, j+15, k+6, Block.getBlockById(0), 0, 2);
	world.setBlock(i+5, j+15, k+6, Block.getBlockById(0), 0, 2);
	world.setBlock(i+6, j+15, k+6, Block.getBlockById(0), 0, 2);
	world.setBlock(i+7, j+15, k+6, Block.getBlockById(89), 0, 2);
	world.setBlock(i+8, j+15, k+6, Block.getBlockById(133), 0, 2);
	world.setBlock(i+9, j+15, k+6, Block.getBlockById(0), 0, 2);
	world.setBlock(i+0, j+15, k+7, Block.getBlockById(0), 0, 2);
	world.setBlock(i+1, j+15, k+7, Block.getBlockById(173), 0, 2);
	world.setBlock(i+2, j+15, k+7, Block.getBlockById(46), 0, 2);
	world.setBlock(i+3, j+15, k+7, Block.getBlockById(89), 0, 2);
	world.setBlock(i+4, j+15, k+7, Block.getBlockById(0), 0, 2);
	world.setBlock(i+5, j+15, k+7, Block.getBlockById(0), 0, 2);
	world.setBlock(i+6, j+15, k+7, Block.getBlockById(89), 0, 2);
	world.setBlock(i+7, j+15, k+7, Block.getBlockById(46), 0, 2);
	world.setBlock(i+8, j+15, k+7, Block.getBlockById(133), 0, 2);
	world.setBlock(i+9, j+15, k+7, Block.getBlockById(0), 0, 2);
	world.setBlock(i+0, j+15, k+8, Block.getBlockById(0), 0, 2);
	world.setBlock(i+1, j+15, k+8, Block.getBlockById(133), 0, 2);
	world.setBlock(i+2, j+15, k+8, Block.getBlockById(133), 0, 2);
	world.setBlock(i+3, j+15, k+8, Block.getBlockById(133), 0, 2);
	world.setBlock(i+4, j+15, k+8, Block.getBlockById(133), 0, 2);
	world.setBlock(i+5, j+15, k+8, Block.getBlockById(133), 0, 2);
	world.setBlock(i+6, j+15, k+8, Block.getBlockById(133), 0, 2);
	world.setBlock(i+7, j+15, k+8, Block.getBlockById(133), 0, 2);
	world.setBlock(i+8, j+15, k+8, Block.getBlockById(133), 0, 2);
	world.setBlock(i+9, j+15, k+8, Block.getBlockById(0), 0, 2);
	world.setBlock(i+0, j+15, k+9, Block.getBlockById(0), 0, 2);
	world.setBlock(i+1, j+15, k+9, Block.getBlockById(0), 0, 2);
	world.setBlock(i+2, j+15, k+9, Block.getBlockById(0), 0, 2);
	world.setBlock(i+3, j+15, k+9, Block.getBlockById(0), 0, 2);
	world.setBlock(i+4, j+15, k+9, Block.getBlockById(0), 0, 2);
	world.setBlock(i+5, j+15, k+9, Block.getBlockById(0), 0, 2);
	world.setBlock(i+6, j+15, k+9, Block.getBlockById(0), 0, 2);
